Workbook

Sheet Full Schedule
A1: do
D2: Sunday | F2: Monday | H2: Tuesday | J2: Wednesday | L2: Thursday | N2: Friday | P2: Saturday | R2: Standings
B4: Week | D4: 11 | F4: 12 | H4: 13 | J4: 14 | L4: 15 | N4: 16 | P4: 17 | R4: ZMD (Zeg) (17-3) (95-46)
B5: 1 | D5: ALL GAME TIMES ARE EASTERN!!!!! | J5: ASP (Dhmon) vs. FB (Saintz) | L5: AP (Alpha) vs ASC (Regresser) | P5: GLV (Priest) vs TB (Silva) | R5: MAB (Zim) (15-5) (85-57)
F6: No Games | H6: No Games | J6: MAB (Zim) vs. TR (Beam) | R6: ASP (Dhmon) (15-5) (86-50)
R7: AP (Alpha) (13-7) (79-69)
R8: TR (Beam) (11-9) (74-73)
R9: ASC (Regresser) (11-9) (80-61)
B10: Week | D10: 18 | F10: 19 | H10: 20 | J10: 21 | L10: 22 | N10: 23 | P10: 24 | R10: ------------------------------------
B11: 2 | H11: FB (Saintz) vs. TR (Beam) 11/19 | J11: TB (Silva) vs. AP (Alpha) | L11: USA (Dig) vs. MAB (Zim) | N11: ZMD (Zeg) vs. TB (Silva) | R11: U.S.A. (Dig) (9-9) (64-65)
H12: FB (Saintz) vs. AJYD (Nkot) | J12: ZMD (Zeg) vs. ASC (Regresser) 11/18 | L12: ZMD (Zeg) vs. AP (Alpha) | P12: MAB (Zim) vs. GLV (Priest) | R12: AJYD (Nkot) (6-14) (55-88)
J13: ASP (Dhmon) vs. USA (Dig) | R13: FB (Saintz) (4-14) (47-76)
R14: GLV (Priest) (4-16) (48-92)
R15: TB (Silva) (3-17) (51-91)
B16: Week | D16: 25 | F16: 26 | H16: 27 | J16: 28 | L16: 29 | N16: 30 | P16: 31
B17: 3 | D17: AJYD (Nkot) vs MAB (Zim) | F17: ZMD (Zeg) vs. TR (Beam) (Game 1) | H17: TB (Silva) vs. FB (Saintz) 11/24 | J17: FB (Saintz) vs. ASC (Regresser) | L17: ZMD (Zeg) vs. USA (Dig) | N17: FB (Saintz) vs. MAB (Zim) 11/5 | R17: Green = Game Played
H18: AJYD (Nkot) vs. TR (Beam) 11/3 | J18: MAB (Zim) vs. AP (Alpha) | L18: ASP (Dhmon) vs. MAB (Zim) 11/23 | N18: ASP (Dhmon) vs. GLV (Priest) | R18: Red = Game Unplayed
H19: ASP (Dhmon) vs. ASC (Regresser) | J19: USA (Dig) vs. TB (Silva) | L19: GLV (Priest) vs AP (Alpha) 11/12 | R19: Yellow = Rescheduled
L20: ASP (Dhmon) vs. AP (Alpha) | R20: Orange = Moved game
F21: November
B22: Week | D22: 1 | E22: 2 | F22: 2 | H22: 3 | J22: 4 | L22: 5 | N22: 6 | P22: 7
B23: 4 | F23: ZMD (Zeg) vs. TR (Beam) (Game 2) | J23: TR (Beam) vs. TB (Silva) 11/21 | L23: GLV (Priest) vs ZMD (Zeg) | N23: ZMD (Zeg) vs. FB (Saintz) 11/20
F24: AJYD (Nkot) vs. TR (Beam) | H24: ASP (Dhmon) vs. AJYD (Nkot) | J24: AP (Alpha) vs. TR (Beam) 11/25 | L24: TB (Silva) vs. ASP (Dhmon) (11/14?) | N24: MAB (Zim) vs. ASC (Regresser) 11/11 | P24: AJYD (Nkot) vs. ASC (Regresser)
F25: MAB (Zim) vs. ZMD (Zeg) | L25: AJYD (Nkot) vs. USA (Dig) | N25: FB (Saintz) vs. GLV (Priest) | P25: TR (Beam) vs. ASP (Dhmon) 11/6
B28: Week | D28: 8 | F28: 9 | H28: 10 | J28: 11 | L28: 12 | N28: 13 | P28: 14
B29: 5 | J29: TB (Silva) vs. ASC (Regresser) | L29: FB (Saintz) vs. USA (Dig) (11/24) FF | P29: GLV (Priest) vs. ASC (Regresser)
F30: ASP (Dhmon) vs. ZMD (Zeg) | H30: TB (Silva) vs. AJYD (Nkot) (W4) | L30: GLV (Priest) vs. TR (Beam) 10/? | N30: MAB (Zim) vs. TB (Silva) 11/10
H31: USA (Dig) vs. AP (Alpha) | L31: AP (Alpha) vs. AJYD (Nkot) 11/18
H32: USA (Dig) vs. TR (Beam)
B1006: Week | D1006: 15 | F1006: 16 | H1006: 17 | J1006: 18 | L1006: 19 | N1006: 20 | P1006: 21
B1007: 6 | J1007: ASC (Regresser) vs. TR (Beam) (11/4?) | L1007: USA (Dig) vs. ASC (Regresser) 11/22
J1008: AP (Alpha) vs. FB (Saintz) | L1008: GLV (Priest) vs. USA (Dig) | P1008: GLV (Priest) vs. AJYD (Nkot) 11/21
L1009: AJYD (Nkot) vs. ZMD (Zeg)

Sheet Stats
A1: Team | B1: Player | C1: Games | D1: Wins | E1: Losses | F1: Goals | G1: Kills | H1: Assists | I1: Deaths | J1: Time | K1: K-D | L1: (K-D)/min) | M1: Stops | N1: Doubles | O1: Triples | P1: Over+ | Q1: Sprees | R1: Exterm | S1: Sword Spree | T1: AVG Life | U1: K/W
A2: G&tC | B2: Priest XYZ | C2: 15 | D2: 3 | E2: 12 | F2: =sum('G&tC'!C3,'G&tC'!T3,'G&tC'!C12,'G&tC'!T12,'G&tC'!C21,'G&tC'!T21,'G&tC'!C30,'G&tC'!T30,'G&tC'!C39,'G&tC'!T39,'G&tC'!C48,'G&tC'!T48,'G&tC'!C57,'G&tC'!T57,'G&tC'!C66,'G&tC'!T66,'G&tC'!C75,'G&tC'!T75,'G&tC'!C84,'G&tC'!T84) -> 23 | G2: =sum('G&tC'!D3,'G&tC'!U3,'G&tC'!D12,'G&tC'!U12,'G&tC'!D21,'G&tC'!U21,'G&tC'!D30,'G&tC'!U30,'G&tC'!D39,'G&tC'!U39,'G&tC'!D48,'G&tC'!U48,'G&tC'!D57,'G&tC'!U57,'G&tC'!D66,'G&tC'!U66,'G&tC'!D75,'G&tC'!U75,'G&tC'!D84,'G&tC'!U84) -> 697 | H2: =sum('G&tC'!E3,'G&tC'!V3,'G&tC'!E12,'G&tC'!V12,'G&tC'!E21,'G&tC'!V21,'G&tC'!E30,'G&tC'!V30,'G&tC'!E39,'G&tC'!V39,'G&tC'!E48,'G&tC'!V48,'G&tC'!E57,'G&tC'!V57,'G&tC'!E66,'G&tC'!V66,'G&tC'!E75,'G&tC'!V75,'G&tC'!E84,'G&tC'!V84) -> 8 | I2: =sum('G&tC'!F3,'G&tC'!W3,'G&tC'!F12,'G&tC'!W12,'G&tC'!F21,'G&tC'!W21,'G&tC'!F30,'G&tC'!W30,'G&tC'!F39,'G&tC'!W39,'G&tC'!F48,'G&tC'!W48,'G&tC'!F57,'G&tC'!W57,'G&tC'!F66,'G&tC'!W66,'G&tC'!F75,'G&tC'!W75,'G&tC'!F84,'G&tC'!W84) -> 1022 | J2: =sum('G&tC'!G3,'G&tC'!X3,'G&tC'!G12,'G&tC'!X12,'G&tC'!G21,'G&tC'!X21,'G&tC'!G30,'G&tC'!X30,'G&tC'!G39,'G&tC'!X39,'G&tC'!G48,'G&tC'!X48,'G&tC'!G57,'G&tC'!X57,'G&tC'!G66,'G&tC'!X66,'G&tC'!G75,'G&tC'!X75,'G&tC'!G84,'G&tC'!X84) -> 0.29304398 | K2: =sum('G&tC'!H3,'G&tC'!Y3,'G&tC'!H12,'G&tC'!Y12,'G&tC'!H21,'G&tC'!Y21,'G&tC'!H30,'G&tC'!Y30,'G&tC'!H39,'G&tC'!Y39,'G&tC'!H48,'G&tC'!Y48,'G&tC'!H57,'G&tC'!Y57,'G&tC'!H66,'G&tC'!Y66,'G&tC'!H75,'G&tC'!Y75,'G&tC'!H84,'G&tC'!Y84) -> -325 | L2: =K2/(HOUR(J2)*60+(MINUTE(J2)+((SECOND(J2)/60)))) -> -0.7701726 | M2: =sum('G&tC'!J3,'G&tC'!AA3,'G&tC'!J12,'G&tC'!AA12,'G&tC'!J21,'G&tC'!AA21,'G&tC'!J30,'G&tC'!AA30,'G&tC'!J39,'G&tC'!AA39,'G&tC'!J48,'G&tC'!AA48,'G&tC'!J57,'G&tC'!AA57,'G&tC'!J66,'G&tC'!AA66,'G&tC'!J75,'G&tC'!AA75,'G&tC'!J84,'G&tC'!AA84) -> 42 | N2: =sum('G&tC'!K3,'G&tC'!AB3,'G&tC'!K12,'G&tC'!AB12,'G&tC'!K21,'G&tC'!AB21,'G&tC'!K30,'G&tC'!AB30,'G&tC'!K39,'G&tC'!AB39,'G&tC'!K48,'G&tC'!AB48,'G&tC'!K57,'G&tC'!AB57,'G&tC'!K66,'G&tC'!AB66,'G&tC'!K75,'G&tC'!AB75,'G&tC'!K84,'G&tC'!AB84) -> 49 | O2: =sum('G&tC'!L3,'G&tC'!AC3,'G&tC'!L12,'G&tC'!AC12,'G&tC'!L21,'G&tC'!AC21,'G&tC'!L30,'G&tC'!AC30,'G&tC'!L39,'G&tC'!AC39,'G&tC'!L48,'G&tC'!AC48,'G&tC'!L57,'G&tC'!AC57,'G&tC'!L66,'G&tC'!AC66,'G&tC'!L75,'G&tC'!AC75,'G&tC'!L84,'G&tC'!AC84) -> 8 | P2: =sum('G&tC'!M3,'G&tC'!AD3,'G&tC'!M12,'G&tC'!AD12,'G&tC'!M21,'G&tC'!AD21,'G&tC'!M30,'G&tC'!AD30,'G&tC'!M39,'G&tC'!AD39,'G&tC'!M48,'G&tC'!AD48,'G&tC'!M57,'G&tC'!AD57,'G&tC'!M66,'G&tC'!AD66,'G&tC'!M75,'G&tC'!AD75,'G&tC'!M84,'G&tC'!AD84) -> 2 | Q2: =sum('G&tC'!N3,'G&tC'!AE3,'G&tC'!N12,'G&tC'!AE12,'G&tC'!N21,'G&tC'!AE21,'G&tC'!N30,'G&tC'!AE30,'G&tC'!N39,'G&tC'!AE39,'G&tC'!N48,'G&tC'!AE48,'G&tC'!N57,'G&tC'!AE57,'G&tC'!N66,'G&tC'!AE66,'G&tC'!N75,'G&tC'!AE75,'G&tC'!N84,'G&tC'!AE84) -> 11 | R2: =sum('G&tC'!O3,'G&tC'!AF3,'G&tC'!O12,'G&tC'!AF12,'G&tC'!O21,'G&tC'!AF21,'G&tC'!O30,'G&tC'!AF30,'G&tC'!O39,'G&tC'!AF39,'G&tC'!O48,'G&tC'!AF48,'G&tC'!O57,'G&tC'!AF57,'G&tC'!O66,'G&tC'!AF66,'G&tC'!O75,'G&tC'!AF75,'G&tC'!O84,'G&tC'!AF84) -> 0 | S2: =sum('G&tC'!P3,'G&tC'!AG3,'G&tC'!P12,'G&tC'!AG12,'G&tC'!P21,'G&tC'!AG21,'G&tC'!P30,'G&tC'!AG30,'G&tC'!P39,'G&tC'!AG39,'G&tC'!P48,'G&tC'!AG48,'G&tC'!P57,'G&tC'!AG57,'G&tC'!P66,'G&tC'!AG66,'G&tC'!P75,'G&tC'!AG75,'G&tC'!P84,'G&tC'!AG84) -> 0 | T2: =J2/I2 -> 0.00028673579 | U2: =G2/D2 -> 232.33333
B3: Galvann (to AJYD) | C3: 12 | D3: 4 | E3: 10 | F3: =sum('G&tC'!C4,'G&tC'!T4,'G&tC'!C13,'G&tC'!T13,'G&tC'!C22,'G&tC'!T22,'G&tC'!C31,'G&tC'!T31,'G&tC'!C40,'G&tC'!T40,'G&tC'!C49,'G&tC'!T49) -> 9 | G3: =sum('G&tC'!D4,'G&tC'!U4,'G&tC'!D13,'G&tC'!U13,'G&tC'!D22,'G&tC'!U22,'G&tC'!D31,'G&tC'!U31,'G&tC'!D40,'G&tC'!U40,'G&tC'!D49,'G&tC'!U49) -> 1386 | H3: =sum('G&tC'!E4,'G&tC'!V4,'G&tC'!E13,'G&tC'!V13,'G&tC'!E22,'G&tC'!V22,'G&tC'!E31,'G&tC'!V31,'G&tC'!E40,'G&tC'!V40,'G&tC'!E49,'G&tC'!V49) -> 7 | I3: =sum('G&tC'!F4,'G&tC'!W4,'G&tC'!F13,'G&tC'!W13,'G&tC'!F22,'G&tC'!W22,'G&tC'!F31,'G&tC'!W31,'G&tC'!F40,'G&tC'!W40,'G&tC'!F49,'G&tC'!W49) -> 1324 | J3: =sum('G&tC'!G4,'G&tC'!X4,'G&tC'!G13,'G&tC'!X13,'G&tC'!G22,'G&tC'!X22,'G&tC'!G31,'G&tC'!X31,'G&tC'!G40,'G&tC'!X40,'G&tC'!G49,'G&tC'!X49) -> 0.24054398 | K3: =sum('G&tC'!H4,'G&tC'!Y4,'G&tC'!H13,'G&tC'!Y13,'G&tC'!H22,'G&tC'!Y22,'G&tC'!H31,'G&tC'!Y31,'G&tC'!H40,'G&tC'!Y40,'G&tC'!H49,'G&tC'!Y49) -> 62 | L3: =K3/(HOUR(J3)*60+(MINUTE(J3)+((SECOND(J3)/60)))) -> 0.17899245 | M3: =sum('G&tC'!J4,'G&tC'!AA4,'G&tC'!J13,'G&tC'!AA13,'G&tC'!J22,'G&tC'!AA22,'G&tC'!J31,'G&tC'!AA31,'G&tC'!J40,'G&tC'!AA40,'G&tC'!J49,'G&tC'!AA49) -> 47 | N3: =sum('G&tC'!K4,'G&tC'!AB4,'G&tC'!K13,'G&tC'!AB13,'G&tC'!K22,'G&tC'!AB22,'G&tC'!K31,'G&tC'!AB31,'G&tC'!K40,'G&tC'!AB40,'G&tC'!K49,'G&tC'!AB49) -> 235 | O3: =sum('G&tC'!L4,'G&tC'!AC4,'G&tC'!L13,'G&tC'!AC13,'G&tC'!L22,'G&tC'!AC22,'G&tC'!L31,'G&tC'!AC31,'G&tC'!L40,'G&tC'!AC40,'G&tC'!L49,'G&tC'!AC49) -> 57 | P3: =sum('G&tC'!M4,'G&tC'!AD4,'G&tC'!M13,'G&tC'!AD13,'G&tC'!M22,'G&tC'!AD22,'G&tC'!M31,'G&tC'!AD31,'G&tC'!M40,'G&tC'!AD40,'G&tC'!M49,'G&tC'!AD49) -> 14 | Q3: =sum('G&tC'!N4,'G&tC'!AE4,'G&tC'!N13,'G&tC'!AE13,'G&tC'!N22,'G&tC'!AE22,'G&tC'!N31,'G&tC'!AE31,'G&tC'!N40,'G&tC'!AE40,'G&tC'!N49,'G&tC'!AE49) -> 28 | R3: =sum('G&tC'!O4,'G&tC'!AF4,'G&tC'!O13,'G&tC'!AF13,'G&tC'!O22,'G&tC'!AF22,'G&tC'!O31,'G&tC'!AF31,'G&tC'!O40,'G&tC'!AF40,'G&tC'!O49,'G&tC'!AF49) -> 0 | S3: =sum('G&tC'!P4,'G&tC'!AG4,'G&tC'!P13,'G&tC'!AG13,'G&tC'!P22,'G&tC'!AG22,'G&tC'!P31,'G&tC'!AG31,'G&tC'!P40,'G&tC'!AG40,'G&tC'!P49,'G&tC'!AG49) -> 0 | T3: =J3/I3 -> 0.00018167974 | U3: =G3/D3 -> 346.5
B4: n Canon | C4: 16 | D4: 4 | E4: 12 | F4: =sum('G&tC'!C5,'G&tC'!T5,'G&tC'!C14,'G&tC'!T14,'G&tC'!C23,'G&tC'!T23,'G&tC'!C32,'G&tC'!T32,'G&tC'!C41,'G&tC'!T41,'G&tC'!C50,'G&tC'!T50,'G&tC'!C59,'G&tC'!T59,'G&tC'!C68,'G&tC'!T68,'G&tC'!C77,'G&tC'!T77,'G&tC'!C86,'G&tC'!T86) -> 5 | G4: =sum('G&tC'!D5,'G&tC'!U5,'G&tC'!D14,'G&tC'!U14,'G&tC'!D23,'G&tC'!U23,'G&tC'!D32,'G&tC'!U32,'G&tC'!D41,'G&tC'!U41,'G&tC'!D50,'G&tC'!U50,'G&tC'!D59,'G&tC'!U59,'G&tC'!D68,'G&tC'!U68,'G&tC'!D77,'G&tC'!U77,'G&tC'!D86,'G&tC'!U86) -> 1266 | H4: =sum('G&tC'!E5,'G&tC'!V5,'G&tC'!E14,'G&tC'!V14,'G&tC'!E23,'G&tC'!V23,'G&tC'!E32,'G&tC'!V32,'G&tC'!E41,'G&tC'!V41,'G&tC'!E50,'G&tC'!V50,'G&tC'!E59,'G&tC'!V59,'G&tC'!E68,'G&tC'!V68,'G&tC'!E77,'G&tC'!V77,'G&tC'!E86,'G&tC'!V86) -> 6 | I4: =sum('G&tC'!F5,'G&tC'!W5,'G&tC'!F14,'G&tC'!W14,'G&tC'!F23,'G&tC'!W23,'G&tC'!F32,'G&tC'!W32,'G&tC'!F41,'G&tC'!W41,'G&tC'!F50,'G&tC'!W50,'G&tC'!F59,'G&tC'!W59,'G&tC'!F68,'G&tC'!W68,'G&tC'!F77,'G&tC'!W77,'G&tC'!F86,'G&tC'!W86) -> 1278 | J4: =sum('G&tC'!G5,'G&tC'!X5,'G&tC'!G14,'G&tC'!X14,'G&tC'!G23,'G&tC'!X23,'G&tC'!G32,'G&tC'!X32,'G&tC'!G41,'G&tC'!X41,'G&tC'!G50,'G&tC'!X50,'G&tC'!G59,'G&tC'!X59,'G&tC'!G68,'G&tC'!X68,'G&tC'!G77,'G&tC'!X77,'G&tC'!G86,'G&tC'!X86) -> 0.28791667 | K4: =sum('G&tC'!H5,'G&tC'!Y5,'G&tC'!H14,'G&tC'!Y14,'G&tC'!H23,'G&tC'!Y23,'G&tC'!H32,'G&tC'!Y32,'G&tC'!H41,'G&tC'!Y41,'G&tC'!H50,'G&tC'!Y50,'G&tC'!H59,'G&tC'!Y59,'G&tC'!H68,'G&tC'!Y68,'G&tC'!H77,'G&tC'!Y77,'G&tC'!H86,'G&tC'!Y86) -> -12 | L4: =K4/(HOUR(J4)*60+(MINUTE(J4)+((SECOND(J4)/60)))) -> -0.02894356 | M4: =sum('G&tC'!J5,'G&tC'!AA5,'G&tC'!J14,'G&tC'!AA14,'G&tC'!J23,'G&tC'!AA23,'G&tC'!J32,'G&tC'!AA32,'G&tC'!J41,'G&tC'!AA41,'G&tC'!J50,'G&tC'!AA50,'G&tC'!J59,'G&tC'!AA59,'G&tC'!J68,'G&tC'!AA68,'G&tC'!J77,'G&tC'!AA77,'G&tC'!J86,'G&tC'!AA86) -> 68 | N4: =sum('G&tC'!K5,'G&tC'!AB5,'G&tC'!K14,'G&tC'!AB14,'G&tC'!K23,'G&tC'!AB23,'G&tC'!K32,'G&tC'!AB32,'G&tC'!K41,'G&tC'!AB41,'G&tC'!K50,'G&tC'!AB50,'G&tC'!K59,'G&tC'!AB59,'G&tC'!K68,'G&tC'!AB68,'G&tC'!K77,'G&tC'!AB77,'G&tC'!K86,'G&tC'!AB86) -> 162 | O4: =sum('G&tC'!L5,'G&tC'!AC5,'G&tC'!L14,'G&tC'!AC14,'G&tC'!L23,'G&tC'!AC23,'G&tC'!L32,'G&tC'!AC32,'G&tC'!L41,'G&tC'!AC41,'G&tC'!L50,'G&tC'!AC50,'G&tC'!L59,'G&tC'!AC59,'G&tC'!L68,'G&tC'!AC68,'G&tC'!L77,'G&tC'!AC77,'G&tC'!L86,'G&tC'!AC86) -> 25 | P4: =sum('G&tC'!M5,'G&tC'!AD5,'G&tC'!M14,'G&tC'!AD14,'G&tC'!M23,'G&tC'!AD23,'G&tC'!M32,'G&tC'!AD32,'G&tC'!M41,'G&tC'!AD41,'G&tC'!M50,'G&tC'!AD50,'G&tC'!M59,'G&tC'!AD59,'G&tC'!M68,'G&tC'!AD68,'G&tC'!M77,'G&tC'!AD77,'G&tC'!M86,'G&tC'!AD86) -> 15 | Q4: =sum('G&tC'!N5,'G&tC'!AE5,'G&tC'!N14,'G&tC'!AE14,'G&tC'!N23,'G&tC'!AE23,'G&tC'!N32,'G&tC'!AE32,'G&tC'!N41,'G&tC'!AE41,'G&tC'!N50,'G&tC'!AE50,'G&tC'!N59,'G&tC'!AE59,'G&tC'!N68,'G&tC'!AE68,'G&tC'!N77,'G&tC'!AE77,'G&tC'!N86,'G&tC'!AE86) -> 26 | R4: =sum('G&tC'!O5,'G&tC'!AF5,'G&tC'!O14,'G&tC'!AF14,'G&tC'!O23,'G&tC'!AF23,'G&tC'!O32,'G&tC'!AF32,'G&tC'!O41,'G&tC'!AF41,'G&tC'!O50,'G&tC'!AF50,'G&tC'!O59,'G&tC'!AF59,'G&tC'!O68,'G&tC'!AF68,'G&tC'!O77,'G&tC'!AF77,'G&tC'!O86,'G&tC'!AF86) -> 5 | S4: =sum('G&tC'!P5,'G&tC'!AG5,'G&tC'!P14,'G&tC'!AG14,'G&tC'!P23,'G&tC'!AG23,'G&tC'!P32,'G&tC'!AG32,'G&tC'!P41,'G&tC'!AG41,'G&tC'!P50,'G&tC'!AG50,'G&tC'!P59,'G&tC'!AG59,'G&tC'!P68,'G&tC'!AG68,'G&tC'!P77,'G&tC'!AG77,'G&tC'!P86,'G&tC'!AG86) -> 0 | T4: =J4/I4 -> 0.00022528691 | U4: =G4/D4 -> 316.5
B5: NOPLEX (to AJYD) | C5: 4 | E5: 4 | F5: =sum('G&tC'!C6,'G&tC'!T6,'G&tC'!C15,'G&tC'!T15,'G&tC'!C24,'G&tC'!T24,'G&tC'!C33,'G&tC'!T33,'G&tC'!C42,'G&tC'!T42,'G&tC'!C51,'G&tC'!T51) -> 0 | G5: =sum('G&tC'!D6,'G&tC'!U6,'G&tC'!D15,'G&tC'!U15,'G&tC'!D24,'G&tC'!U24,'G&tC'!D33,'G&tC'!U33,'G&tC'!D42,'G&tC'!U42,'G&tC'!D51,'G&tC'!U51,'G&tC'!D60,'G&tC'!U60,'G&tC'!D69,'G&tC'!U69,'G&tC'!D78,'G&tC'!U78,'G&tC'!D87,'G&tC'!U87) -> 656 | H5: =sum('G&tC'!E6,'G&tC'!V6,'G&tC'!E15,'G&tC'!V15,'G&tC'!E24,'G&tC'!V24,'G&tC'!E33,'G&tC'!V33,'G&tC'!E42,'G&tC'!V42,'G&tC'!E51,'G&tC'!V51,'G&tC'!E60,'G&tC'!V60,'G&tC'!E69,'G&tC'!V69,'G&tC'!E78,'G&tC'!V78,'G&tC'!E87,'G&tC'!V87) -> 4 | I5: =sum('G&tC'!F6,'G&tC'!W6,'G&tC'!F15,'G&tC'!W15,'G&tC'!F24,'G&tC'!W24,'G&tC'!F33,'G&tC'!W33,'G&tC'!F42,'G&tC'!W42,'G&tC'!F51,'G&tC'!W51,'G&tC'!F60,'G&tC'!W60,'G&tC'!F69,'G&tC'!W69,'G&tC'!F78,'G&tC'!W78,'G&tC'!F87,'G&tC'!W87) -> 739 | J5: =sum('G&tC'!G6,'G&tC'!X6,'G&tC'!G15,'G&tC'!X15,'G&tC'!G24,'G&tC'!X24,'G&tC'!G33,'G&tC'!X33,'G&tC'!G42,'G&tC'!X42,'G&tC'!G51,'G&tC'!X51,'G&tC'!G60,'G&tC'!X60,'G&tC'!G69,'G&tC'!X69,'G&tC'!G78,'G&tC'!X78,'G&tC'!G87,'G&tC'!X87) -> 0.15138889 | K5: =sum('G&tC'!H6,'G&tC'!Y6,'G&tC'!H15,'G&tC'!Y15,'G&tC'!H24,'G&tC'!Y24,'G&tC'!H33,'G&tC'!Y33,'G&tC'!H42,'G&tC'!Y42,'G&tC'!H51,'G&tC'!Y51,'G&tC'!H60,'G&tC'!Y60,'G&tC'!H69,'G&tC'!Y69,'G&tC'!H78,'G&tC'!Y78,'G&tC'!H87,'G&tC'!Y87) -> -83 | L5: =K5/(HOUR(J5)*60+(MINUTE(J5)+((SECOND(J5)/60)))) -> -0.38073395 | M5: =sum('G&tC'!J6,'G&tC'!AA6,'G&tC'!J15,'G&tC'!AA15,'G&tC'!J24,'G&tC'!AA24,'G&tC'!J33,'G&tC'!AA33,'G&tC'!J42,'G&tC'!AA42,'G&tC'!J51,'G&tC'!AA51,'G&tC'!J60,'G&tC'!AA60,'G&tC'!J69,'G&tC'!AA69,'G&tC'!J78,'G&tC'!AA78,'G&tC'!J87,'G&tC'!AA87) -> 26 | N5: =sum('G&tC'!K6,'G&tC'!AB6,'G&tC'!K15,'G&tC'!AB15,'G&tC'!K24,'G&tC'!AB24,'G&tC'!K33,'G&tC'!AB33,'G&tC'!K42,'G&tC'!AB42,'G&tC'!K51,'G&tC'!AB51,'G&tC'!K60,'G&tC'!AB60,'G&tC'!K69,'G&tC'!AB69,'G&tC'!K78,'G&tC'!AB78,'G&tC'!K87,'G&tC'!AB87) -> 96 | O5: =sum('G&tC'!L6,'G&tC'!AC6,'G&tC'!L15,'G&tC'!AC15,'G&tC'!L24,'G&tC'!AC24,'G&tC'!L33,'G&tC'!AC33,'G&tC'!L42,'G&tC'!AC42,'G&tC'!L51,'G&tC'!AC51,'G&tC'!L60,'G&tC'!AC60,'G&tC'!L69,'G&tC'!AC69,'G&tC'!L78,'G&tC'!AC78,'G&tC'!L87,'G&tC'!AC87) -> 20 | P5: =sum('G&tC'!M6,'G&tC'!AD6,'G&tC'!M15,'G&tC'!AD15,'G&tC'!M24,'G&tC'!AD24,'G&tC'!M33,'G&tC'!AD33,'G&tC'!M42,'G&tC'!AD42,'G&tC'!M51,'G&tC'!AD51,'G&tC'!M60,'G&tC'!AD60,'G&tC'!M69,'G&tC'!AD69,'G&tC'!M78,'G&tC'!AD78,'G&tC'!M87,'G&tC'!AD87) -> 4 | Q5: =sum('G&tC'!N6,'G&tC'!AE6,'G&tC'!N15,'G&tC'!AE15,'G&tC'!N24,'G&tC'!AE24,'G&tC'!N33,'G&tC'!AE33,'G&tC'!N42,'G&tC'!AE42,'G&tC'!N51,'G&tC'!AE51,'G&tC'!N60,'G&tC'!AE60,'G&tC'!N69,'G&tC'!AE69,'G&tC'!N78,'G&tC'!AE78,'G&tC'!N87,'G&tC'!AE87) -> 10 | R5: =sum('G&tC'!O6,'G&tC'!AF6,'G&tC'!O15,'G&tC'!AF15,'G&tC'!O24,'G&tC'!AF24,'G&tC'!O33,'G&tC'!AF33,'G&tC'!O42,'G&tC'!AF42,'G&tC'!O51,'G&tC'!AF51,'G&tC'!O60,'G&tC'!AF60,'G&tC'!O69,'G&tC'!AF69,'G&tC'!O78,'G&tC'!AF78,'G&tC'!O87,'G&tC'!AF87) -> 0 | S5: =sum('G&tC'!P6,'G&tC'!AG6,'G&tC'!P15,'G&tC'!AG15,'G&tC'!P24,'G&tC'!AG24,'G&tC'!P33,'G&tC'!AG33,'G&tC'!P42,'G&tC'!AG42,'G&tC'!P51,'G&tC'!AG51,'G&tC'!P60,'G&tC'!AG60,'G&tC'!P69,'G&tC'!AG69,'G&tC'!P78,'G&tC'!AG78,'G&tC'!P87,'G&tC'!AG87) -> 0 | T5: =J5/I5 -> 0.00020485641
B6: Samuel Adams | C6: 10 | D6: 3 | E6: 7 | F6: =sum('G&tC'!C7,'G&tC'!T7,'G&tC'!C16,'G&tC'!T16,'G&tC'!C25,'G&tC'!T25,'G&tC'!C34,'G&tC'!T34,'G&tC'!C43,'G&tC'!T43,'G&tC'!C52,'G&tC'!T52,'G&tC'!C61,'G&tC'!T61,'G&tC'!C70,'G&tC'!T70,'G&tC'!C79,'G&tC'!T79,'G&tC'!C88,'G&tC'!T88) -> 5 | G6: =sum('G&tC'!D7,'G&tC'!U7,'G&tC'!D16,'G&tC'!U16,'G&tC'!D25,'G&tC'!U25,'G&tC'!D34,'G&tC'!U34,'G&tC'!D43,'G&tC'!U43,'G&tC'!D52,'G&tC'!U52,'G&tC'!D61,'G&tC'!U61,'G&tC'!D70,'G&tC'!U70,'G&tC'!D79,'G&tC'!U79,'G&tC'!D88,'G&tC'!U88) -> 643 | H6: =sum('G&tC'!E7,'G&tC'!V7,'G&tC'!E16,'G&tC'!V16,'G&tC'!E25,'G&tC'!V25,'G&tC'!E34,'G&tC'!V34,'G&tC'!E43,'G&tC'!V43,'G&tC'!E52,'G&tC'!V52,'G&tC'!E61,'G&tC'!V61,'G&tC'!E70,'G&tC'!V70,'G&tC'!E79,'G&tC'!V79,'G&tC'!E88,'G&tC'!V88) -> 5 | I6: =sum('G&tC'!F7,'G&tC'!W7,'G&tC'!F16,'G&tC'!W16,'G&tC'!F25,'G&tC'!W25,'G&tC'!F34,'G&tC'!W34,'G&tC'!F43,'G&tC'!W43,'G&tC'!F52,'G&tC'!W52,'G&tC'!F61,'G&tC'!W61,'G&tC'!F70,'G&tC'!W70,'G&tC'!F79,'G&tC'!W79,'G&tC'!F88,'G&tC'!W88) -> 782 | J6: =sum('G&tC'!G7,'G&tC'!X7,'G&tC'!G16,'G&tC'!X16,'G&tC'!G25,'G&tC'!X25,'G&tC'!G34,'G&tC'!X34,'G&tC'!G43,'G&tC'!X43,'G&tC'!G52,'G&tC'!X52,'G&tC'!G61,'G&tC'!X61,'G&tC'!G70,'G&tC'!X70,'G&tC'!G79,'G&tC'!X79,'G&tC'!G88,'G&tC'!X88) -> 0.16108796 | K6: =sum('G&tC'!H7,'G&tC'!Y7,'G&tC'!H16,'G&tC'!Y16,'G&tC'!H25,'G&tC'!Y25,'G&tC'!H34,'G&tC'!Y34,'G&tC'!H43,'G&tC'!Y43,'G&tC'!H52,'G&tC'!Y52,'G&tC'!H61,'G&tC'!Y61,'G&tC'!H70,'G&tC'!Y70,'G&tC'!H79,'G&tC'!Y79,'G&tC'!H88,'G&tC'!Y88) -> -139 | L6: =K6/(HOUR(J6)*60+(MINUTE(J6)+((SECOND(J6)/60)))) -> -0.59922403 | M6: =sum('G&tC'!J7,'G&tC'!AA7,'G&tC'!J16,'G&tC'!AA16,'G&tC'!J25,'G&tC'!AA25,'G&tC'!J34,'G&tC'!AA34,'G&tC'!J43,'G&tC'!AA43,'G&tC'!J52,'G&tC'!AA52,'G&tC'!J61,'G&tC'!AA61,'G&tC'!J70,'G&tC'!AA70,'G&tC'!J79,'G&tC'!AA79,'G&tC'!J88,'G&tC'!AA88) -> 23 | N6: =sum('G&tC'!K7,'G&tC'!AB7,'G&tC'!K16,'G&tC'!AB16,'G&tC'!K25,'G&tC'!AB25,'G&tC'!K34,'G&tC'!AB34,'G&tC'!K43,'G&tC'!AB43,'G&tC'!K52,'G&tC'!AB52,'G&tC'!K61,'G&tC'!AB61,'G&tC'!K70,'G&tC'!AB70,'G&tC'!K79,'G&tC'!AB79,'G&tC'!K88,'G&tC'!AB88) -> 100 | O6: =sum('G&tC'!L7,'G&tC'!AC7,'G&tC'!L16,'G&tC'!AC16,'G&tC'!L25,'G&tC'!AC25,'G&tC'!L34,'G&tC'!AC34,'G&tC'!L43,'G&tC'!AC43,'G&tC'!L52,'G&tC'!AC52,'G&tC'!L61,'G&tC'!AC61,'G&tC'!L70,'G&tC'!AC70,'G&tC'!L79,'G&tC'!AC79,'G&tC'!L88,'G&tC'!AC88) -> 15 | P6: =sum('G&tC'!M7,'G&tC'!AD7,'G&tC'!M16,'G&tC'!AD16,'G&tC'!M25,'G&tC'!AD25,'G&tC'!M34,'G&tC'!AD34,'G&tC'!M43,'G&tC'!AD43,'G&tC'!M52,'G&tC'!AD52,'G&tC'!M61,'G&tC'!AD61,'G&tC'!M70,'G&tC'!AD70,'G&tC'!M79,'G&tC'!AD79,'G&tC'!M88,'G&tC'!AD88) -> 8 | Q6: =sum('G&tC'!N7,'G&tC'!AE7,'G&tC'!N16,'G&tC'!AE16,'G&tC'!N25,'G&tC'!AE25,'G&tC'!N34,'G&tC'!AE34,'G&tC'!N43,'G&tC'!AE43,'G&tC'!N52,'G&tC'!AE52,'G&tC'!N61,'G&tC'!AE61,'G&tC'!N70,'G&tC'!AE70,'G&tC'!N79,'G&tC'!AE79,'G&tC'!N88,'G&tC'!AE88) -> 12 | R6: =sum('G&tC'!O7,'G&tC'!AF7,'G&tC'!O16,'G&tC'!AF16,'G&tC'!O25,'G&tC'!AF25,'G&tC'!O34,'G&tC'!AF34,'G&tC'!O43,'G&tC'!AF43,'G&tC'!O52,'G&tC'!AF52,'G&tC'!O61,'G&tC'!AF61,'G&tC'!O70,'G&tC'!AF70,'G&tC'!O79,'G&tC'!AF79,'G&tC'!O88,'G&tC'!AF88) -> 2 | S6: =sum('G&tC'!P7,'G&tC'!AG7,'G&tC'!P16,'G&tC'!AG16,'G&tC'!P25,'G&tC'!AG25,'G&tC'!P34,'G&tC'!AG34,'G&tC'!P43,'G&tC'!AG43,'G&tC'!P52,'G&tC'!AG52,'G&tC'!P61,'G&tC'!AG61,'G&tC'!P70,'G&tC'!AG70,'G&tC'!P79,'G&tC'!AG79,'G&tC'!P88,'G&tC'!AG88) -> 0 | T6: =J6/I6 -> 0.00020599484 | U6: =G6/D6 -> 214.33333
B7: SaltyPeterBread | C7: 8 | D7: 2 | E7: 6 | F7: =sum('G&tC'!C8,'G&tC'!T8,'G&tC'!C17,'G&tC'!T17,'G&tC'!C26,'G&tC'!T26,'G&tC'!C35,'G&tC'!T35,'G&tC'!C44,'G&tC'!T44,'G&tC'!C53,'G&tC'!T53,'G&tC'!C62,'G&tC'!T62,'G&tC'!C71,'G&tC'!T71,'G&tC'!C80,'G&tC'!T80,'G&tC'!C89,'G&tC'!T89) -> 1 | G7: =sum('G&tC'!D8,'G&tC'!U8,'G&tC'!D17,'G&tC'!U17,'G&tC'!D26,'G&tC'!U26,'G&tC'!D35,'G&tC'!U35,'G&tC'!D44,'G&tC'!U44,'G&tC'!D53,'G&tC'!U53,'G&tC'!D62,'G&tC'!U62,'G&tC'!D71,'G&tC'!U71,'G&tC'!D80,'G&tC'!U80,'G&tC'!D89,'G&tC'!U89) -> 835 | H7: =sum('G&tC'!E8,'G&tC'!V8,'G&tC'!E17,'G&tC'!V17,'G&tC'!E26,'G&tC'!V26,'G&tC'!E35,'G&tC'!V35,'G&tC'!E44,'G&tC'!V44,'G&tC'!E53,'G&tC'!V53,'G&tC'!E62,'G&tC'!V62,'G&tC'!E71,'G&tC'!V71,'G&tC'!E80,'G&tC'!V80,'G&tC'!E89,'G&tC'!V89) -> 3 | I7: =sum('G&tC'!F8,'G&tC'!W8,'G&tC'!F17,'G&tC'!W17,'G&tC'!F26,'G&tC'!W26,'G&tC'!F35,'G&tC'!W35,'G&tC'!F44,'G&tC'!W44,'G&tC'!F53,'G&tC'!W53,'G&tC'!F62,'G&tC'!W62,'G&tC'!F71,'G&tC'!W71,'G&tC'!F80,'G&tC'!W80,'G&tC'!F89,'G&tC'!W89) -> 999 | J7: =sum('G&tC'!G8,'G&tC'!X8,'G&tC'!G17,'G&tC'!X17,'G&tC'!G26,'G&tC'!X26,'G&tC'!G35,'G&tC'!X35,'G&tC'!G44,'G&tC'!X44,'G&tC'!G53,'G&tC'!X53,'G&tC'!G62,'G&tC'!X62,'G&tC'!G71,'G&tC'!X71,'G&tC'!G80,'G&tC'!X80,'G&tC'!G89,'G&tC'!X89) -> 0.16945602 | K7: =sum('G&tC'!H8,'G&tC'!Y8,'G&tC'!H17,'G&tC'!Y17,'G&tC'!H26,'G&tC'!Y26,'G&tC'!H35,'G&tC'!Y35,'G&tC'!H44,'G&tC'!Y44,'G&tC'!H53,'G&tC'!Y53,'G&tC'!H62,'G&tC'!Y62,'G&tC'!H71,'G&tC'!Y71,'G&tC'!H80,'G&tC'!Y80,'G&tC'!H89,'G&tC'!Y89) -> -164 | L7: =K7/(HOUR(J7)*60+(MINUTE(J7)+((SECOND(J7)/60)))) -> -0.67208524 | M7: =sum('G&tC'!J8,'G&tC'!AA8,'G&tC'!J17,'G&tC'!AA17,'G&tC'!J26,'G&tC'!AA26,'G&tC'!J35,'G&tC'!AA35,'G&tC'!J44,'G&tC'!AA44,'G&tC'!J53,'G&tC'!AA53,'G&tC'!J62,'G&tC'!AA62,'G&tC'!J71,'G&tC'!AA71,'G&tC'!J80,'G&tC'!AA80,'G&tC'!J89,'G&tC'!AA89) -> 21 | N7: =sum('G&tC'!K8,'G&tC'!AB8,'G&tC'!K17,'G&tC'!AB17,'G&tC'!K26,'G&tC'!AB26,'G&tC'!K35,'G&tC'!AB35,'G&tC'!K44,'G&tC'!AB44,'G&tC'!K53,'G&tC'!AB53,'G&tC'!K62,'G&tC'!AB62,'G&tC'!K71,'G&tC'!AB71,'G&tC'!K80,'G&tC'!AB80,'G&tC'!K89,'G&tC'!AB89) -> 113 | O7: =sum('G&tC'!L8,'G&tC'!AC8,'G&tC'!L17,'G&tC'!AC17,'G&tC'!L26,'G&tC'!AC26,'G&tC'!L35,'G&tC'!AC35,'G&tC'!L44,'G&tC'!AC44,'G&tC'!L53,'G&tC'!AC53,'G&tC'!L62,'G&tC'!AC62,'G&tC'!L71,'G&tC'!AC71,'G&tC'!L80,'G&tC'!AC80,'G&tC'!L89,'G&tC'!AC89) -> 20 | P7: =sum('G&tC'!M8,'G&tC'!AD8,'G&tC'!M17,'G&tC'!AD17,'G&tC'!M26,'G&tC'!AD26,'G&tC'!M35,'G&tC'!AD35,'G&tC'!M44,'G&tC'!AD44,'G&tC'!M53,'G&tC'!AD53,'G&tC'!M62,'G&tC'!AD62,'G&tC'!M71,'G&tC'!AD71,'G&tC'!M80,'G&tC'!AD80,'G&tC'!M89,'G&tC'!AD89) -> 9 | Q7: =sum('G&tC'!N8,'G&tC'!AE8,'G&tC'!N17,'G&tC'!AE17,'G&tC'!N26,'G&tC'!AE26,'G&tC'!N35,'G&tC'!AE35,'G&tC'!N44,'G&tC'!AE44,'G&tC'!N53,'G&tC'!AE53,'G&tC'!N62,'G&tC'!AE62,'G&tC'!N71,'G&tC'!AE71,'G&tC'!N80,'G&tC'!AE80,'G&tC'!N89,'G&tC'!AE89) -> 16 | R7: =sum('G&tC'!O8,'G&tC'!AF8,'G&tC'!O17,'G&tC'!AF17,'G&tC'!O26,'G&tC'!AF26,'G&tC'!O35,'G&tC'!AF35,'G&tC'!O44,'G&tC'!AF44,'G&tC'!O53,'G&tC'!AF53,'G&tC'!O62,'G&tC'!AF62,'G&tC'!O71,'G&tC'!AF71,'G&tC'!O80,'G&tC'!AF80,'G&tC'!O89,'G&tC'!AF89) -> 2 | S7: =sum('G&tC'!P8,'G&tC'!AG8,'G&tC'!P17,'G&tC'!AG17,'G&tC'!P26,'G&tC'!AG26,'G&tC'!P35,'G&tC'!AG35,'G&tC'!P44,'G&tC'!AG44,'G&tC'!P53,'G&tC'!AG53,'G&tC'!P62,'G&tC'!AG62,'G&tC'!P71,'G&tC'!AG71,'G&tC'!P80,'G&tC'!AG80,'G&tC'!P89,'G&tC'!AG89) -> 0 | T7: =J7/I7 -> 0.00016962564 | U7: =G7/D7 -> 417.5
B8: ixGingy (from AJYD) | C8: 8 | E8: 8 | F8: =sum('G&tC'!C58,'G&tC'!T58,'G&tC'!C67,'G&tC'!T67,'G&tC'!C76,'G&tC'!T76,'G&tC'!C85,'G&tC'!T85) -> 2 | G8: =sum('G&tC'!D58,'G&tC'!U58,'G&tC'!D67,'G&tC'!U67,'G&tC'!D76,'G&tC'!U76,'G&tC'!D85,'G&tC'!U85) -> 723 | H8: =sum('G&tC'!E58,'G&tC'!V58,'G&tC'!E67,'G&tC'!V67,'G&tC'!E76,'G&tC'!V76,'G&tC'!E85,'G&tC'!V85) -> 3 | I8: =sum('G&tC'!F58,'G&tC'!W58,'G&tC'!F67,'G&tC'!W67,'G&tC'!F76,'G&tC'!W76,'G&tC'!F85,'G&tC'!W85) -> 638 | J8: =sum('G&tC'!G58,'G&tC'!X58,'G&tC'!G67,'G&tC'!X67,'G&tC'!G76,'G&tC'!X76,'G&tC'!G85,'G&tC'!X85) -> 0.12971065 | K8: =sum('G&tC'!H58,'G&tC'!Y58,'G&tC'!H67,'G&tC'!Y67,'G&tC'!H76,'G&tC'!Y76,'G&tC'!H85,'G&tC'!Y85) -> 85 | L8: =K8/(HOUR(J8)*60+(MINUTE(J8)+((SECOND(J8)/60)))) -> 0.45507272 | M8: =sum('G&tC'!J58,'G&tC'!AA58,'G&tC'!J67,'G&tC'!AA67,'G&tC'!J76,'G&tC'!AA76,'G&tC'!J85,'G&tC'!AA85) -> 27 | N8: =sum('G&tC'!K58,'G&tC'!AB58,'G&tC'!K67,'G&tC'!AB67,'G&tC'!K76,'G&tC'!AB76,'G&tC'!K85,'G&tC'!AB85) -> 101 | O8: =sum('G&tC'!L58,'G&tC'!AC58,'G&tC'!L67,'G&tC'!AC67,'G&tC'!L76,'G&tC'!AC76,'G&tC'!L85,'G&tC'!AC85) -> 27 | P8: =sum('G&tC'!M58,'G&tC'!AD58,'G&tC'!M67,'G&tC'!AD67,'G&tC'!M76,'G&tC'!AD76,'G&tC'!M85,'G&tC'!AD85) -> 12 | Q8: =sum('G&tC'!N58,'G&tC'!AE58,'G&tC'!N67,'G&tC'!AE67,'G&tC'!N76,'G&tC'!AE76,'G&tC'!N85,'G&tC'!AE85) -> 30 | R8: =sum('G&tC'!O58,'G&tC'!AF58,'G&tC'!O67,'G&tC'!AF67,'G&tC'!O76,'G&tC'!AF76,'G&tC'!O85,'G&tC'!AF85) -> 0 | S8: =sum('G&tC'!P58,'G&tC'!AG58,'G&tC'!P67,'G&tC'!AG67,'G&tC'!P76,'G&tC'!AG76,'G&tC'!P85,'G&tC'!AG85) -> 0 | T8: =J8/I8 -> 0.00020330823
B9: ixSqueeps (from AJYD/G&tC)
B10: Atone/Aware/Tommy (sub) | C10: 6 | E10: 5 | F10: =sum('G&tC'!C78,'G&tC'!T78,'G&tC'!C90,'G&tC'!C91,'G&tC'!T90,'G&tC'!T91) -> 3 | G10: =sum('G&tC'!D78,'G&tC'!U78,'G&tC'!D90,'G&tC'!D91,'G&tC'!U90,'G&tC'!U91) -> 487 | H10: =sum('G&tC'!E78,'G&tC'!V78,'G&tC'!E90,'G&tC'!E91,'G&tC'!V90,'G&tC'!V91) -> 5 | I10: =sum('G&tC'!F78,'G&tC'!W78,'G&tC'!F90,'G&tC'!F91,'G&tC'!W90,'G&tC'!W91) -> 532 | J10: =sum('G&tC'!G78,'G&tC'!X78,'G&tC'!G90,'G&tC'!G91,'G&tC'!X90,'G&tC'!X91) -> 0.10627315 | K10: =sum('G&tC'!H78,'G&tC'!Y78,'G&tC'!H90,'G&tC'!H91,'G&tC'!Y90,'G&tC'!Y91) -> -45 | L10: =K10/(HOUR(J10)*60+(MINUTE(J10)+((SECOND(J10)/60)))) -> -0.29405358 | M10: =sum('G&tC'!J78,'G&tC'!AA78,'G&tC'!J90,'G&tC'!J91,'G&tC'!AA90,'G&tC'!AA91) -> 21 | N10: =sum('G&tC'!K78,'G&tC'!AB78,'G&tC'!K90,'G&tC'!K91,'G&tC'!AB90,'G&tC'!AB91) -> 73 | O10: =sum('G&tC'!L78,'G&tC'!AC78,'G&tC'!L90,'G&tC'!L91,'G&tC'!AC90,'G&tC'!AC91) -> 11 | P10: =sum('G&tC'!M78,'G&tC'!AD78,'G&tC'!M90,'G&tC'!M91,'G&tC'!AD90,'G&tC'!AD91) -> 2 | Q10: =sum('G&tC'!N78,'G&tC'!AE78,'G&tC'!N90,'G&tC'!N91,'G&tC'!AE90,'G&tC'!AE91) -> 11 | R10: =sum('G&tC'!O78,'G&tC'!AF78,'G&tC'!O90,'G&tC'!O91,'G&tC'!AF90,'G&tC'!AF91) -> 0 | S10: =sum('G&tC'!P78,'G&tC'!AG78,'G&tC'!P90,'G&tC'!P91,'G&tC'!AG90,'G&tC'!AG91) -> 0 | T10: =J10/I10 -> 0.00019976156
A11: 43937 | B11: Totals: | C11: =MAX(C2:C10) -> 16 | D11: =MAX(D2:D10) -> 4 | E11: =MAX(E2:E10)+E10-1 -> 16 | F11: =sum(F2:F10) -> 48 | G11: =sum(G2:G10) -> 6693 | H11: =sum(H2:H10) -> 41 | I11: =sum(I2:I10) -> 7314 | J11: =J3+J8 -> 0.37025463 | K11: =sum(K2:K10) -> -621 | L11: =K11/(HOUR(J11)*60+(MINUTE(J11)+((SECOND(J11)/60)))) -> -1.164739 | M11: =sum(M2:M10) -> 275 | N11: =sum(N2:N10) -> 929 | O11: =sum(O2:O10) -> 183 | P11: =sum(P2:P10) -> 66 | Q11: =sum(Q2:Q10) -> 144 | R11: =sum(R2:R10) -> 9 | S11: =sum(S2:S10) -> 0 | U11: =sum(U2:U7) -> 1527.1667
A13: Team Rocket | B13: Beam1n1 | C13: 17 | D13: 11 | E13: 6 | F13: =sum(t.Rocket!C3,t.Rocket!T3,t.Rocket!C12,t.Rocket!T12,t.Rocket!C21,t.Rocket!T21,t.Rocket!C30,t.Rocket!T30,t.Rocket!C39,t.Rocket!T39,t.Rocket!C48,t.Rocket!T48,t.Rocket!C57,t.Rocket!T57,t.Rocket!C66,t.Rocket!T66,t.Rocket!C75,t.Rocket!T75,t.Rocket!C84,t.Rocket!T84) -> 3 | G13: =sum(t.Rocket!D3,t.Rocket!U3,t.Rocket!D12,t.Rocket!U12,t.Rocket!D21,t.Rocket!U21,t.Rocket!D30,t.Rocket!U30,t.Rocket!D39,t.Rocket!U39,t.Rocket!D48,t.Rocket!U48,t.Rocket!D57,t.Rocket!U57,t.Rocket!D66,t.Rocket!U66,t.Rocket!D75,t.Rocket!U75,t.Rocket!D84,t.Rocket!U84) -> 1476 | H13: =sum(t.Rocket!E3,t.Rocket!V3,t.Rocket!E12,t.Rocket!V12,t.Rocket!E21,t.Rocket!V21,t.Rocket!E30,t.Rocket!V30,t.Rocket!E39,t.Rocket!V39,t.Rocket!E48,t.Rocket!V48,t.Rocket!E57,t.Rocket!V57,t.Rocket!E66,t.Rocket!V66,t.Rocket!E75,t.Rocket!V75,t.Rocket!E84,t.Rocket!V84) -> 11 | I13: =sum(t.Rocket!F3,t.Rocket!W3,t.Rocket!F12,t.Rocket!W12,t.Rocket!F21,t.Rocket!W21,t.Rocket!F30,t.Rocket!W30,t.Rocket!F39,t.Rocket!W39,t.Rocket!F48,t.Rocket!W48,t.Rocket!F57,t.Rocket!W57,t.Rocket!F66,t.Rocket!W66,t.Rocket!F75,t.Rocket!W75,t.Rocket!F84,t.Rocket!W84) -> 1661 | J13: =sum(t.Rocket!G3,t.Rocket!X3,t.Rocket!G12,t.Rocket!X12,t.Rocket!G21,t.Rocket!X21,t.Rocket!G30,t.Rocket!X30,t.Rocket!G39,t.Rocket!X39,t.Rocket!G48,t.Rocket!X48,t.Rocket!G57,t.Rocket!X57,t.Rocket!G66,t.Rocket!X66,t.Rocket!G75,t.Rocket!X75,t.Rocket!G84,t.Rocket!X84) -> 0.35300926 | K13: =sum(t.Rocket!H3,t.Rocket!Y3,t.Rocket!H12,t.Rocket!Y12,t.Rocket!H21,t.Rocket!Y21,t.Rocket!H30,t.Rocket!Y30,t.Rocket!H39,t.Rocket!Y39,t.Rocket!H48,t.Rocket!Y48,t.Rocket!H57,t.Rocket!Y57,t.Rocket!H66,t.Rocket!Y66,t.Rocket!H75,t.Rocket!Y75,t.Rocket!H84,t.Rocket!Y84) -> -185 | L13: =K13/(HOUR(J13)*60+(MINUTE(J13)+((SECOND(J13)/60)))) -> -0.36393443 | M13: =sum(t.Rocket!J3,t.Rocket!AA3,t.Rocket!J12,t.Rocket!AA12,t.Rocket!J21,t.Rocket!AA21,t.Rocket!J30,t.Rocket!AA30,t.Rocket!J39,t.Rocket!AA39,t.Rocket!J48,t.Rocket!AA48,t.Rocket!J57,t.Rocket!AA57,t.Rocket!J66,t.Rocket!AA66,t.Rocket!J75,t.Rocket!AA75,t.Rocket!J84,t.Rocket!AA84) -> 47 | N13: =sum(t.Rocket!K3,t.Rocket!AB3,t.Rocket!K12,t.Rocket!AB12,t.Rocket!K21,t.Rocket!AB21,t.Rocket!K30,t.Rocket!AB30,t.Rocket!K39,t.Rocket!AB39,t.Rocket!K48,t.Rocket!AB48,t.Rocket!K57,t.Rocket!AB57,t.Rocket!K66,t.Rocket!AB66,t.Rocket!K75,t.Rocket!AB75,t.Rocket!K84,t.Rocket!AB84) -> 188 | O13: =sum(t.Rocket!L3,t.Rocket!AC3,t.Rocket!L12,t.Rocket!AC12,t.Rocket!L21,t.Rocket!AC21,t.Rocket!L30,t.Rocket!AC30,t.Rocket!L39,t.Rocket!AC39,t.Rocket!L48,t.Rocket!AC48,t.Rocket!L57,t.Rocket!AC57,t.Rocket!L66,t.Rocket!AC66,t.Rocket!L75,t.Rocket!AC75,t.Rocket!L84,t.Rocket!AC84) -> 33 | P13: =sum(t.Rocket!M3,t.Rocket!AD3,t.Rocket!M12,t.Rocket!AD12,t.Rocket!M21,t.Rocket!AD21,t.Rocket!M30,t.Rocket!AD30,t.Rocket!M39,t.Rocket!AD39,t.Rocket!M48,t.Rocket!AD48,t.Rocket!M57,t.Rocket!AD57,t.Rocket!M66,t.Rocket!AD66,t.Rocket!M75,t.Rocket!AD75,t.Rocket!M84,t.Rocket!AD84) -> 10 | Q13: =sum(t.Rocket!N3,t.Rocket!AE3,t.Rocket!N12,t.Rocket!AE12,t.Rocket!N21,t.Rocket!AE21,t.Rocket!N30,t.Rocket!AE30,t.Rocket!N39,t.Rocket!AE39,t.Rocket!N48,t.Rocket!AE48,t.Rocket!N57,t.Rocket!AE57,t.Rocket!N66,t.Rocket!AE66,t.Rocket!N75,t.Rocket!AE75,t.Rocket!N84,t.Rocket!AE84) -> 23 | R13: =sum(t.Rocket!O3,t.Rocket!AF3,t.Rocket!O12,t.Rocket!AF12,t.Rocket!O21,t.Rocket!AF21,t.Rocket!O30,t.Rocket!AF30,t.Rocket!O39,t.Rocket!AF39,t.Rocket!O48,t.Rocket!AF48,t.Rocket!O57,t.Rocket!AF57,t.Rocket!O66,t.Rocket!AF66,t.Rocket!O75,t.Rocket!AF75,t.Rocket!O84,t.Rocket!AF84) -> 1 | S13: =sum(t.Rocket!P3,t.Rocket!AG3,t.Rocket!P12,t.Rocket!AG12,t.Rocket!P21,t.Rocket!AG21,t.Rocket!P30,t.Rocket!AG30,t.Rocket!P39,t.Rocket!AG39,t.Rocket!P48,t.Rocket!AG48,t.Rocket!P57,t.Rocket!AG57,t.Rocket!P66,t.Rocket!AG66,t.Rocket!P75,t.Rocket!AG75,t.Rocket!P84,t.Rocket!AG84) -> 0 | T13: =J13/I13 -> 0.00021252815 | U13: =G13/D13 -> 134.18182
B14: halfbreed105 | C14: 20 | D14: 11 | E14: 9 | F14: =sum(t.Rocket!C4,t.Rocket!T4,t.Rocket!C13,t.Rocket!T13,t.Rocket!C22,t.Rocket!T22,t.Rocket!C31,t.Rocket!T31,t.Rocket!C40,t.Rocket!T40,t.Rocket!C49,t.Rocket!T49,t.Rocket!C58,t.Rocket!T58,t.Rocket!C67,t.Rocket!T67,t.Rocket!C76,t.Rocket!T76,t.Rocket!C85,t.Rocket!T85) -> 8 | G14: =sum(t.Rocket!D4,t.Rocket!U4,t.Rocket!D13,t.Rocket!U13,t.Rocket!D22,t.Rocket!U22,t.Rocket!D31,t.Rocket!U31,t.Rocket!D40,t.Rocket!U40,t.Rocket!D49,t.Rocket!U49,t.Rocket!D58,t.Rocket!U58,t.Rocket!D67,t.Rocket!U67,t.Rocket!D76,t.Rocket!U76,t.Rocket!D85,t.Rocket!U85) -> 2535 | H14: =sum(t.Rocket!E4,t.Rocket!V4,t.Rocket!E13,t.Rocket!V13,t.Rocket!E22,t.Rocket!V22,t.Rocket!E31,t.Rocket!V31,t.Rocket!E40,t.Rocket!V40,t.Rocket!E49,t.Rocket!V49,t.Rocket!E58,t.Rocket!V58,t.Rocket!E67,t.Rocket!V67,t.Rocket!E76,t.Rocket!V76,t.Rocket!E85,t.Rocket!V85) -> 11 | I14: =sum(t.Rocket!F4,t.Rocket!W4,t.Rocket!F13,t.Rocket!W13,t.Rocket!F22,t.Rocket!W22,t.Rocket!F31,t.Rocket!W31,t.Rocket!F40,t.Rocket!W40,t.Rocket!F49,t.Rocket!W49,t.Rocket!F58,t.Rocket!W58,t.Rocket!F67,t.Rocket!W67,t.Rocket!F76,t.Rocket!W76,t.Rocket!F85,t.Rocket!W85) -> 1984 | J14: =sum(t.Rocket!G4,t.Rocket!X4,t.Rocket!G13,t.Rocket!X13,t.Rocket!G22,t.Rocket!X22,t.Rocket!G31,t.Rocket!X31,t.Rocket!G40,t.Rocket!X40,t.Rocket!G49,t.Rocket!X49,t.Rocket!G58,t.Rocket!X58,t.Rocket!G67,t.Rocket!X67,t.Rocket!G76,t.Rocket!X76,t.Rocket!G85,t.Rocket!X85) -> 0.43783565 | K14: =sum(t.Rocket!H4,t.Rocket!Y4,t.Rocket!H13,t.Rocket!Y13,t.Rocket!H22,t.Rocket!Y22,t.Rocket!H31,t.Rocket!Y31,t.Rocket!H40,t.Rocket!Y40,t.Rocket!H49,t.Rocket!Y49,t.Rocket!H58,t.Rocket!Y58,t.Rocket!H67,t.Rocket!Y67,t.Rocket!H76,t.Rocket!Y76,t.Rocket!H85,t.Rocket!Y85) -> 551 | L14: =K14/(HOUR(J14)*60+(MINUTE(J14)+((SECOND(J14)/60)))) -> 0.8739327 | M14: =sum(t.Rocket!J4,t.Rocket!AA4,t.Rocket!J13,t.Rocket!AA13,t.Rocket!J22,t.Rocket!AA22,t.Rocket!J31,t.Rocket!AA31,t.Rocket!J40,t.Rocket!AA40,t.Rocket!J49,t.Rocket!AA49,t.Rocket!J58,t.Rocket!AA58,t.Rocket!J67,t.Rocket!AA67,t.Rocket!J76,t.Rocket!AA76,t.Rocket!J85,t.Rocket!AA85) -> 88 | N14: =sum(t.Rocket!K4,t.Rocket!AB4,t.Rocket!K13,t.Rocket!AB13,t.Rocket!K22,t.Rocket!AB22,t.Rocket!K31,t.Rocket!AB31,t.Rocket!K40,t.Rocket!AB40,t.Rocket!K49,t.Rocket!AB49,t.Rocket!K58,t.Rocket!AB58,t.Rocket!K67,t.Rocket!AB67,t.Rocket!K76,t.Rocket!AB76,t.Rocket!K85,t.Rocket!AB85) -> 407 | O14: =sum(t.Rocket!L4,t.Rocket!AC4,t.Rocket!L13,t.Rocket!AC13,t.Rocket!L22,t.Rocket!AC22,t.Rocket!L31,t.Rocket!AC31,t.Rocket!L40,t.Rocket!AC40,t.Rocket!L49,t.Rocket!AC49,t.Rocket!L58,t.Rocket!AC58,t.Rocket!L67,t.Rocket!AC67,t.Rocket!L76,t.Rocket!AC76,t.Rocket!L85,t.Rocket!AC85) -> 97 | P14: =sum(t.Rocket!M4,t.Rocket!AD4,t.Rocket!M13,t.Rocket!AD13,t.Rocket!M22,t.Rocket!AD22,t.Rocket!M31,t.Rocket!AD31,t.Rocket!M40,t.Rocket!AD40,t.Rocket!M49,t.Rocket!AD49,t.Rocket!M58,t.Rocket!AD58,t.Rocket!M67,t.Rocket!AD67,t.Rocket!M76,t.Rocket!AD76,t.Rocket!M85,t.Rocket!AD85) -> 34 | Q14: =sum(t.Rocket!N4,t.Rocket!AE4,t.Rocket!N13,t.Rocket!AE13,t.Rocket!N22,t.Rocket!AE22,t.Rocket!N31,t.Rocket!AE31,t.Rocket!N40,t.Rocket!AE40,t.Rocket!N49,t.Rocket!AE49,t.Rocket!N58,t.Rocket!AE58,t.Rocket!N67,t.Rocket!AE67,t.Rocket!N76,t.Rocket!AE76,t.Rocket!N85,t.Rocket!AE85) -> 79 | R14: =sum(t.Rocket!O4,t.Rocket!AF4,t.Rocket!O13,t.Rocket!AF13,t.Rocket!O22,t.Rocket!AF22,t.Rocket!O31,t.Rocket!AF31,t.Rocket!O40,t.Rocket!AF40,t.Rocket!O49,t.Rocket!AF49,t.Rocket!O58,t.Rocket!AF58,t.Rocket!O67,t.Rocket!AF67,t.Rocket!O76,t.Rocket!AF76,t.Rocket!O85,t.Rocket!AF85) -> 1 | S14: =sum(t.Rocket!P4,t.Rocket!AG4,t.Rocket!P13,t.Rocket!AG13,t.Rocket!P22,t.Rocket!AG22,t.Rocket!P31,t.Rocket!AG31,t.Rocket!P40,t.Rocket!AG40,t.Rocket!P49,t.Rocket!AG49,t.Rocket!P58,t.Rocket!AG58,t.Rocket!P67,t.Rocket!AG67,t.Rocket!P76,t.Rocket!AG76,t.Rocket!P85,t.Rocket!AG85) -> 0 | T14: =J14/I14 -> 0.00022068329 | U14: =G14/D14 -> 230.45455
B15: its bck | C15: 20 | D15: 11 | E15: 9 | F15: =sum(t.Rocket!C5,t.Rocket!T5,t.Rocket!C14,t.Rocket!T14,t.Rocket!C23,t.Rocket!T23,t.Rocket!C32,t.Rocket!T32,t.Rocket!C41,t.Rocket!T41,t.Rocket!C50,t.Rocket!T50,t.Rocket!C59,t.Rocket!T59,t.Rocket!C68,t.Rocket!T68,t.Rocket!C77,t.Rocket!T77,t.Rocket!C86,t.Rocket!T86) -> 60 | G15: =sum(t.Rocket!D5,t.Rocket!U5,t.Rocket!D14,t.Rocket!U14,t.Rocket!D23,t.Rocket!U23,t.Rocket!D32,t.Rocket!U32,t.Rocket!D41,t.Rocket!U41,t.Rocket!D50,t.Rocket!U50,t.Rocket!D59,t.Rocket!U59,t.Rocket!D68,t.Rocket!U68,t.Rocket!D77,t.Rocket!U77,t.Rocket!D86,t.Rocket!U86) -> 1422 | H15: =sum(t.Rocket!E5,t.Rocket!V5,t.Rocket!E14,t.Rocket!V14,t.Rocket!E23,t.Rocket!V23,t.Rocket!E32,t.Rocket!V32,t.Rocket!E41,t.Rocket!V41,t.Rocket!E50,t.Rocket!V50,t.Rocket!E59,t.Rocket!V59,t.Rocket!E68,t.Rocket!V68,t.Rocket!E77,t.Rocket!V77,t.Rocket!E86,t.Rocket!V86) -> 8 | I15: =sum(t.Rocket!F5,t.Rocket!W5,t.Rocket!F14,t.Rocket!W14,t.Rocket!F23,t.Rocket!W23,t.Rocket!F32,t.Rocket!W32,t.Rocket!F41,t.Rocket!W41,t.Rocket!F50,t.Rocket!W50,t.Rocket!F59,t.Rocket!W59,t.Rocket!F68,t.Rocket!W68,t.Rocket!F77,t.Rocket!W77,t.Rocket!F86,t.Rocket!W86) -> 1579 | J15: =sum(t.Rocket!G5,t.Rocket!X5,t.Rocket!G14,t.Rocket!X14,t.Rocket!G23,t.Rocket!X23,t.Rocket!G32,t.Rocket!X32,t.Rocket!G41,t.Rocket!X41,t.Rocket!G50,t.Rocket!X50,t.Rocket!G59,t.Rocket!X59,t.Rocket!G68,t.Rocket!X68,t.Rocket!G77,t.Rocket!X77,t.Rocket!G86,t.Rocket!X86) -> 0.43783565 | K15: =sum(t.Rocket!H5,t.Rocket!Y5,t.Rocket!H14,t.Rocket!Y14,t.Rocket!H23,t.Rocket!Y23,t.Rocket!H32,t.Rocket!Y32,t.Rocket!H41,t.Rocket!Y41,t.Rocket!H50,t.Rocket!Y50,t.Rocket!H59,t.Rocket!Y59,t.Rocket!H68,t.Rocket!Y68,t.Rocket!H77,t.Rocket!Y77,t.Rocket!H86,t.Rocket!Y86) -> -157 | L15: =K15/(HOUR(J15)*60+(MINUTE(J15)+((SECOND(J15)/60)))) -> -0.24901531 | M15: =sum(t.Rocket!J5,t.Rocket!AA5,t.Rocket!J14,t.Rocket!AA14,t.Rocket!J23,t.Rocket!AA23,t.Rocket!J32,t.Rocket!AA32,t.Rocket!J41,t.Rocket!AA41,t.Rocket!J50,t.Rocket!AA50,t.Rocket!J59,t.Rocket!AA59,t.Rocket!J68,t.Rocket!AA68,t.Rocket!J77,t.Rocket!AA77,t.Rocket!J86,t.Rocket!AA86) -> 83 | N15: =sum(t.Rocket!K5,t.Rocket!AB5,t.Rocket!K14,t.Rocket!AB14,t.Rocket!K23,t.Rocket!AB23,t.Rocket!K32,t.Rocket!AB32,t.Rocket!K41,t.Rocket!AB41,t.Rocket!K50,t.Rocket!AB50,t.Rocket!K59,t.Rocket!AB59,t.Rocket!K68,t.Rocket!AB68,t.Rocket!K77,t.Rocket!AB77,t.Rocket!K86,t.Rocket!AB86) -> 182 | O15: =sum(t.Rocket!L5,t.Rocket!AC5,t.Rocket!L14,t.Rocket!AC14,t.Rocket!L23,t.Rocket!AC23,t.Rocket!L32,t.Rocket!AC32,t.Rocket!L41,t.Rocket!AC41,t.Rocket!L50,t.Rocket!AC50,t.Rocket!L59,t.Rocket!AC59,t.Rocket!L68,t.Rocket!AC68,t.Rocket!L77,t.Rocket!AC77,t.Rocket!L86,t.Rocket!AC86) -> 27 | P15: =sum(t.Rocket!M5,t.Rocket!AD5,t.Rocket!M14,t.Rocket!AD14,t.Rocket!M23,t.Rocket!AD23,t.Rocket!M32,t.Rocket!AD32,t.Rocket!M41,t.Rocket!AD41,t.Rocket!M50,t.Rocket!AD50,t.Rocket!M59,t.Rocket!AD59,t.Rocket!M68,t.Rocket!AD68,t.Rocket!M77,t.Rocket!AD77,t.Rocket!M86,t.Rocket!AD86) -> 1 | Q15: =sum(t.Rocket!N5,t.Rocket!AE5,t.Rocket!N14,t.Rocket!AE14,t.Rocket!N23,t.Rocket!AE23,t.Rocket!N32,t.Rocket!AE32,t.Rocket!N41,t.Rocket!AE41,t.Rocket!N50,t.Rocket!AE50,t.Rocket!N59,t.Rocket!AE59,t.Rocket!N68,t.Rocket!AE68,t.Rocket!N77,t.Rocket!AE77,t.Rocket!N86,t.Rocket!AE86) -> 40 | R15: =sum(t.Rocket!O5,t.Rocket!AF5,t.Rocket!O14,t.Rocket!AF14,t.Rocket!O23,t.Rocket!AF23,t.Rocket!O32,t.Rocket!AF32,t.Rocket!O41,t.Rocket!AF41,t.Rocket!O50,t.Rocket!AF50,t.Rocket!O59,t.Rocket!AF59,t.Rocket!O68,t.Rocket!AF68,t.Rocket!O77,t.Rocket!AF77,t.Rocket!O86,t.Rocket!AF86) -> 0 | S15: =sum(t.Rocket!P5,t.Rocket!AG5,t.Rocket!P14,t.Rocket!AG14,t.Rocket!P23,t.Rocket!AG23,t.Rocket!P32,t.Rocket!AG32,t.Rocket!P41,t.Rocket!AG41,t.Rocket!P50,t.Rocket!AG50,t.Rocket!P59,t.Rocket!AG59,t.Rocket!P68,t.Rocket!AG68,t.Rocket!P77,t.Rocket!AG77,t.Rocket!P86,t.Rocket!AG86) -> 0 | T15: =J15/I15 -> 0.00027728667 | U15: =G15/D15 -> 129.27273
B16: godwit1ivy (to MAB) | C16: 1 | E16: 1 | F16: =sum(t.Rocket!C6,t.Rocket!T6,t.Rocket!C15,t.Rocket!T15,t.Rocket!C24,t.Rocket!T24,t.Rocket!C33,t.Rocket!T33,t.Rocket!C42) -> 0 | G16: =sum(t.Rocket!D6,t.Rocket!U6,t.Rocket!D15,t.Rocket!U15,t.Rocket!D24,t.Rocket!U24,t.Rocket!D33,t.Rocket!U33,t.Rocket!D42) -> 59 | H16: =sum(t.Rocket!E6,t.Rocket!V6,t.Rocket!E15,t.Rocket!V15,t.Rocket!E24,t.Rocket!V24,t.Rocket!E33,t.Rocket!V33,t.Rocket!E42) -> 0 | I16: =sum(t.Rocket!F6,t.Rocket!W6,t.Rocket!F15,t.Rocket!W15,t.Rocket!F24,t.Rocket!W24,t.Rocket!F33,t.Rocket!W33,t.Rocket!F42) -> 87 | J16: =sum(t.Rocket!G6,t.Rocket!X6,t.Rocket!G15,t.Rocket!X15,t.Rocket!G24,t.Rocket!X24,t.Rocket!G33,t.Rocket!X33,t.Rocket!G42) -> 0.020601852 | K16: =sum(t.Rocket!H6,t.Rocket!Y6,t.Rocket!H15,t.Rocket!Y15,t.Rocket!H24,t.Rocket!Y24,t.Rocket!H33,t.Rocket!Y33,t.Rocket!H42) -> -28 | L16: =K16/(HOUR(J16)*60+(MINUTE(J16)+((SECOND(J16)/60)))) -> -0.94382022 | M16: =sum(t.Rocket!J6,t.Rocket!AA6,t.Rocket!J15,t.Rocket!AA15,t.Rocket!J24,t.Rocket!AA24,t.Rocket!J33,t.Rocket!AA33,t.Rocket!J42) -> 3 | N16: =sum(t.Rocket!K6,t.Rocket!AB6,t.Rocket!K15,t.Rocket!AB15,t.Rocket!K24,t.Rocket!AB24,t.Rocket!K33,t.Rocket!AB33,t.Rocket!K42) -> 6 | O16: =sum(t.Rocket!L6,t.Rocket!AC6,t.Rocket!L15,t.Rocket!AC15,t.Rocket!L24,t.Rocket!AC24,t.Rocket!L33,t.Rocket!AC33,t.Rocket!L42) -> 0 | P16: =sum(t.Rocket!M6,t.Rocket!AD6,t.Rocket!M15,t.Rocket!AD15,t.Rocket!M24,t.Rocket!AD24,t.Rocket!M33,t.Rocket!AD33,t.Rocket!M42) -> 0 | Q16: =sum(t.Rocket!N6,t.Rocket!AE6,t.Rocket!N15,t.Rocket!AE15,t.Rocket!N24,t.Rocket!AE24,t.Rocket!N33,t.Rocket!AE33,t.Rocket!N42) -> 1 | R16: =sum(t.Rocket!O6,t.Rocket!AF6,t.Rocket!O15,t.Rocket!AF15,t.Rocket!O24,t.Rocket!AF24,t.Rocket!O33,t.Rocket!AF33,t.Rocket!O42) -> 0 | S16: =sum(t.Rocket!P6,t.Rocket!AG6,t.Rocket!P15,t.Rocket!AG15,t.Rocket!P24,t.Rocket!AG24,t.Rocket!P33,t.Rocket!AG33,t.Rocket!P42) -> 0 | T16: =J16/I16 -> 0.00023680289 | W16: =(sum(J97,J89,J81,J73,J65,J57,J49,J40,J31,J21,J11)) -> 4.1177083 | X16: =W16/'Game Results'!G2/2 -> 0.019063465
B17: ixSqueeps (to AJYD/G&tC) | C17: 2 | E17: 2 | F17: =sum(t.Rocket!C7,t.Rocket!T7,t.Rocket!C16,t.Rocket!T16,t.Rocket!C25,t.Rocket!T25,t.Rocket!C34,t.Rocket!T34,t.Rocket!C43,t.Rocket!T43) -> 0 | G17: =sum(t.Rocket!D7,t.Rocket!U7,t.Rocket!D16,t.Rocket!U16,t.Rocket!D25,t.Rocket!U25,t.Rocket!D34,t.Rocket!U34,t.Rocket!D43,t.Rocket!U43) -> 187 | H17: =sum(t.Rocket!E7,t.Rocket!V7,t.Rocket!E16,t.Rocket!V16,t.Rocket!E25,t.Rocket!V25,t.Rocket!E34,t.Rocket!V34,t.Rocket!E43,t.Rocket!V43) -> 1 | I17: =sum(t.Rocket!F7,t.Rocket!W7,t.Rocket!F16,t.Rocket!W16,t.Rocket!F25,t.Rocket!W25,t.Rocket!F34,t.Rocket!W34,t.Rocket!F43,t.Rocket!W43) -> 222 | J17: =sum(t.Rocket!G7,t.Rocket!X7,t.Rocket!G16,t.Rocket!X16,t.Rocket!G25,t.Rocket!X25,t.Rocket!G34,t.Rocket!X34,t.Rocket!G43,t.Rocket!X43) -> 0.045115741 | K17: =sum(t.Rocket!H7,t.Rocket!Y7,t.Rocket!H16,t.Rocket!Y16,t.Rocket!H25,t.Rocket!Y25,t.Rocket!H34,t.Rocket!Y34,t.Rocket!H43,t.Rocket!Y43) -> -35 | L17: =K17/(HOUR(J17)*60+(MINUTE(J17)+((SECOND(J17)/60)))) -> -0.53873781 | M17: =sum(t.Rocket!J7,t.Rocket!AA7,t.Rocket!J16,t.Rocket!AA16,t.Rocket!J25,t.Rocket!AA25,t.Rocket!J34,t.Rocket!AA34,t.Rocket!J43,t.Rocket!AA43) -> 9 | N17: =sum(t.Rocket!K7,t.Rocket!AB7,t.Rocket!K16,t.Rocket!AB16,t.Rocket!K25,t.Rocket!AB25,t.Rocket!K34,t.Rocket!AB34,t.Rocket!K43,t.Rocket!AB43) -> 26 | O17: =sum(t.Rocket!L7,t.Rocket!AC7,t.Rocket!L16,t.Rocket!AC16,t.Rocket!L25,t.Rocket!AC25,t.Rocket!L34,t.Rocket!AC34,t.Rocket!L43,t.Rocket!AC43) -> 3 | P17: =sum(t.Rocket!M7,t.Rocket!AD7,t.Rocket!M16,t.Rocket!AD16,t.Rocket!M25,t.Rocket!AD25,t.Rocket!M34,t.Rocket!AD34,t.Rocket!M43,t.Rocket!AD43) -> 1 | Q17: =sum(t.Rocket!N7,t.Rocket!AE7,t.Rocket!N16,t.Rocket!AE16,t.Rocket!N25,t.Rocket!AE25,t.Rocket!N34,t.Rocket!AE34,t.Rocket!N43,t.Rocket!AE43) -> 3 | R17: =sum(t.Rocket!O7,t.Rocket!AF7,t.Rocket!O16,t.Rocket!AF16,t.Rocket!O25,t.Rocket!AF25,t.Rocket!O34,t.Rocket!AF34,t.Rocket!O43,t.Rocket!AF43) -> 0 | S17: =sum(t.Rocket!P7,t.Rocket!AG7,t.Rocket!P16,t.Rocket!AG16,t.Rocket!P25,t.Rocket!AG25,t.Rocket!P34,t.Rocket!AG34,t.Rocket!P43,t.Rocket!AG43) -> 0 | T17: =J17/I17 -> 0.00020322406
B18: Grunt Padre | C18: 15 | D18: 9 | E18: 6 | F18: =sum(t.Rocket!C8,t.Rocket!T8,t.Rocket!C17,t.Rocket!T17,t.Rocket!C26,t.Rocket!T26,t.Rocket!C35,t.Rocket!T35,t.Rocket!C44,t.Rocket!T44,t.Rocket!C53,t.Rocket!T53,t.Rocket!C62,t.Rocket!T62,t.Rocket!C71,t.Rocket!T71,t.Rocket!C80,t.Rocket!T80,t.Rocket!C89,t.Rocket!T89) -> 2 | G18: =sum(t.Rocket!D8,t.Rocket!U8,t.Rocket!D17,t.Rocket!U17,t.Rocket!D26,t.Rocket!U26,t.Rocket!D35,t.Rocket!U35,t.Rocket!D44,t.Rocket!U44,t.Rocket!D53,t.Rocket!U53,t.Rocket!D62,t.Rocket!U62,t.Rocket!D71,t.Rocket!U71,t.Rocket!D80,t.Rocket!U80,t.Rocket!D89,t.Rocket!U89) -> 1669 | H18: =sum(t.Rocket!E8,t.Rocket!V8,t.Rocket!E17,t.Rocket!V17,t.Rocket!E26,t.Rocket!V26,t.Rocket!E35,t.Rocket!V35,t.Rocket!E44,t.Rocket!V44,t.Rocket!E53,t.Rocket!V53,t.Rocket!E62,t.Rocket!V62,t.Rocket!E71,t.Rocket!V71,t.Rocket!E80,t.Rocket!V80,t.Rocket!E89,t.Rocket!V89) -> 12 | I18: =sum(t.Rocket!F8,t.Rocket!W8,t.Rocket!F17,t.Rocket!W17,t.Rocket!F26,t.Rocket!W26,t.Rocket!F35,t.Rocket!W35,t.Rocket!F44,t.Rocket!W44,t.Rocket!F53,t.Rocket!W53,t.Rocket!F62,t.Rocket!W62,t.Rocket!F71,t.Rocket!W71,t.Rocket!F80,t.Rocket!W80,t.Rocket!F89,t.Rocket!W89) -> 2070 | J18: =sum(t.Rocket!G8,t.Rocket!X8,t.Rocket!G17,t.Rocket!X17,t.Rocket!G26,t.Rocket!X26,t.Rocket!G35,t.Rocket!X35,t.Rocket!G44,t.Rocket!X44,t.Rocket!G53,t.Rocket!X53,t.Rocket!G62,t.Rocket!X62,t.Rocket!G71,t.Rocket!X71,t.Rocket!G80,t.Rocket!X80,t.Rocket!G89,t.Rocket!X89) -> 0.33918981 | K18: =sum(t.Rocket!H8,t.Rocket!Y8,t.Rocket!H17,t.Rocket!Y17,t.Rocket!H26,t.Rocket!Y26,t.Rocket!H35,t.Rocket!Y35,t.Rocket!H44,t.Rocket!Y44,t.Rocket!H53,t.Rocket!Y53,t.Rocket!H62,t.Rocket!Y62,t.Rocket!H71,t.Rocket!Y71,t.Rocket!H80,t.Rocket!Y80,t.Rocket!H89,t.Rocket!Y89) -> -401 | L18: =K18/(HOUR(J18)*60+(MINUTE(J18)+((SECOND(J18)/60)))) -> -0.82099229 | M18: =sum(t.Rocket!J8,t.Rocket!AA8,t.Rocket!J17,t.Rocket!AA17,t.Rocket!J26,t.Rocket!AA26,t.Rocket!J35,t.Rocket!AA35,t.Rocket!J44,t.Rocket!AA44,t.Rocket!J53,t.Rocket!AA53,t.Rocket!J62,t.Rocket!AA62,t.Rocket!J71,t.Rocket!AA71,t.Rocket!J80,t.Rocket!AA80,t.Rocket!J89,t.Rocket!AA89) -> 55 | N18: =sum(t.Rocket!K8,t.Rocket!AB8,t.Rocket!K17,t.Rocket!AB17,t.Rocket!K26,t.Rocket!AB26,t.Rocket!K35,t.Rocket!AB35,t.Rocket!K44,t.Rocket!AB44,t.Rocket!K53,t.Rocket!AB53,t.Rocket!K62,t.Rocket!AB62,t.Rocket!K71,t.Rocket!AB71,t.Rocket!K80,t.Rocket!AB80,t.Rocket!K89,t.Rocket!AB89) -> 264 | O18: =sum(t.Rocket!L8,t.Rocket!AC8,t.Rocket!L17,t.Rocket!AC17,t.Rocket!L26,t.Rocket!AC26,t.Rocket!L35,t.Rocket!AC35,t.Rocket!L44,t.Rocket!AC44,t.Rocket!L53,t.Rocket!AC53,t.Rocket!L62,t.Rocket!AC62,t.Rocket!L71,t.Rocket!AC71,t.Rocket!L80,t.Rocket!AC80,t.Rocket!L89,t.Rocket!AC89) -> 73 | P18: =sum(t.Rocket!M8,t.Rocket!AD8,t.Rocket!M17,t.Rocket!AD17,t.Rocket!M26,t.Rocket!AD26,t.Rocket!M35,t.Rocket!AD35,t.Rocket!M44,t.Rocket!AD44,t.Rocket!M53,t.Rocket!AD53,t.Rocket!M62,t.Rocket!AD62,t.Rocket!M71,t.Rocket!AD71,t.Rocket!M80,t.Rocket!AD80,t.Rocket!M89,t.Rocket!AD89) -> 20 | Q18: =sum(t.Rocket!N8,t.Rocket!AE8,t.Rocket!N17,t.Rocket!AE17,t.Rocket!N26,t.Rocket!AE26,t.Rocket!N35,t.Rocket!AE35,t.Rocket!N44,t.Rocket!AE44,t.Rocket!N53,t.Rocket!AE53,t.Rocket!N62,t.Rocket!AE62,t.Rocket!N71,t.Rocket!AE71,t.Rocket!N80,t.Rocket!AE80,t.Rocket!N89,t.Rocket!AE89) -> 21 | R18: =sum(t.Rocket!O8,t.Rocket!AF8,t.Rocket!O17,t.Rocket!AF17,t.Rocket!O26,t.Rocket!AF26,t.Rocket!O35,t.Rocket!AF35,t.Rocket!O44,t.Rocket!AF44,t.Rocket!O53,t.Rocket!AF53,t.Rocket!O62,t.Rocket!AF62,t.Rocket!O71,t.Rocket!AF71,t.Rocket!O80,t.Rocket!AF80,t.Rocket!O89,t.Rocket!AF89) -> 0 | S18: =sum(t.Rocket!P8,t.Rocket!AG8,t.Rocket!P17,t.Rocket!AG17,t.Rocket!P26,t.Rocket!AG26,t.Rocket!P35,t.Rocket!AG35,t.Rocket!P44,t.Rocket!AG44,t.Rocket!P53,t.Rocket!AG53,t.Rocket!P62,t.Rocket!AG62,t.Rocket!P71,t.Rocket!AG71,t.Rocket!P80,t.Rocket!AG80,t.Rocket!P89,t.Rocket!AG89) -> 0 | T18: =J18/I18 -> 0.00016385981 | U18: =G18/D18 -> 185.44444
B19: TommyWstSide (from AJYD) | C19: 4 | D19: 2 | E19: 2 | F19: =sum(t.Rocket!C52,t.Rocket!T52,t.Rocket!C61,t.Rocket!T61,t.Rocket!C70,t.Rocket!T70,t.Rocket!C79,t.Rocket!T79,t.Rocket!C88,t.Rocket!T88) -> 1 | G19: =sum(t.Rocket!D52,t.Rocket!U52,t.Rocket!D61,t.Rocket!U61,t.Rocket!D70,t.Rocket!U70,t.Rocket!D79,t.Rocket!U79,t.Rocket!D88,t.Rocket!U88) -> 460 | H19: =sum(t.Rocket!E52,t.Rocket!V52,t.Rocket!E61,t.Rocket!V61,t.Rocket!E70,t.Rocket!V70,t.Rocket!E79,t.Rocket!V79,t.Rocket!E88,t.Rocket!V88) -> 1 | I19: =sum(t.Rocket!F52,t.Rocket!W52,t.Rocket!F61,t.Rocket!W61,t.Rocket!F70,t.Rocket!W70,t.Rocket!F79,t.Rocket!W79,t.Rocket!F88,t.Rocket!W88) -> 593 | J19: =sum(t.Rocket!G52,t.Rocket!X52,t.Rocket!G61,t.Rocket!X61,t.Rocket!G70,t.Rocket!X70,t.Rocket!G79,t.Rocket!X79,t.Rocket!G88,t.Rocket!X88) -> 0.11071759 | K19: =sum(t.Rocket!H52,t.Rocket!Y52,t.Rocket!H61,t.Rocket!Y61,t.Rocket!H70,t.Rocket!Y70,t.Rocket!H79,t.Rocket!Y79,t.Rocket!H88,t.Rocket!Y88) -> -133 | L19: =K19/(HOUR(J19)*60+(MINUTE(J19)+((SECOND(J19)/60)))) -> -0.83420447 | M19: =sum(t.Rocket!J52,t.Rocket!AA52,t.Rocket!J61,t.Rocket!AA61,t.Rocket!J70,t.Rocket!AA70,t.Rocket!J79,t.Rocket!AA79,t.Rocket!J88,t.Rocket!AA88) -> 16 | N19: =sum(t.Rocket!K52,t.Rocket!AB52,t.Rocket!K61,t.Rocket!AB61,t.Rocket!K70,t.Rocket!AB70,t.Rocket!K79,t.Rocket!AB79,t.Rocket!K88,t.Rocket!AB88) -> 54 | O19: =sum(t.Rocket!L52,t.Rocket!AC52,t.Rocket!L61,t.Rocket!AC61,t.Rocket!L70,t.Rocket!AC70,t.Rocket!L79,t.Rocket!AC79,t.Rocket!L88,t.Rocket!AC88) -> 11 | P19: =sum(t.Rocket!M52,t.Rocket!AD52,t.Rocket!M61,t.Rocket!AD61,t.Rocket!M70,t.Rocket!AD70,t.Rocket!M79,t.Rocket!AD79,t.Rocket!M88,t.Rocket!AD88) -> 1 | Q19: =sum(t.Rocket!N52,t.Rocket!AE52,t.Rocket!N61,t.Rocket!AE61,t.Rocket!N70,t.Rocket!AE70,t.Rocket!N79,t.Rocket!AE79,t.Rocket!N88,t.Rocket!AE88) -> 6 | R19: =sum(t.Rocket!O52,t.Rocket!AF52,t.Rocket!O61,t.Rocket!AF61,t.Rocket!O70,t.Rocket!AF70,t.Rocket!O79,t.Rocket!AF79,t.Rocket!O88,t.Rocket!AF88) -> 0 | S19: =sum(t.Rocket!P52,t.Rocket!AG52,t.Rocket!P61,t.Rocket!AG61,t.Rocket!P70,t.Rocket!AG70,t.Rocket!P79,t.Rocket!AG79,t.Rocket!P88,t.Rocket!AG88) -> 0
B20: Scarhead1995 (from MAB) | C20: 1 | E20: 1 | F20: =sum(t.Rocket!T87) -> 0 | G20: =sum(t.Rocket!U87) -> 49 | H20: =sum(t.Rocket!V87) -> 1 | I20: =sum(t.Rocket!W87) -> 62 | J20: =sum(t.Rocket!X87) -> 0.007037037 | K20: =sum(t.Rocket!Y87) -> -13 | L20: =K20/(HOUR(J20)*60+(MINUTE(J20)+((SECOND(J20)/60)))) -> -1.2828947 | M20: =sum(t.Rocket!AA87) -> 1 | N20: =sum(t.Rocket!AB87) -> 4 | O20: =sum(t.Rocket!AC87) -> 0 | P20: =sum(t.Rocket!AD87) -> 0 | Q20: =sum(t.Rocket!AE87) -> 0 | R20: =sum(t.Rocket!AF87) -> 0 | S20: =sum(t.Rocket!AG87) -> 0 | T20: =J20/I20 -> 0.0001135006
A21: 44144 | B21: Totals: | C21: =MAX(C13:C20) -> 20 | D21: =MAX(D13:D20) -> 11 | E21: =MAX(E13:E20) -> 9 | F21: =sum(F13:F19) -> 74 | G21: =sum(G13:G19) -> 7808 | H21: =sum(H13:H19) -> 44 | I21: =sum(I13:I19) -> 8196 | J21: =J14 -> 0.43783565 | K21: =sum(K13:K19) -> -388 | L21: =K21/(HOUR(J21)*60+(MINUTE(J21)+((SECOND(J21)/60)))) -> -0.61540088 | M21: =sum(M13:M19) -> 301 | N21: =sum(N13:N19) -> 1127 | O21: =sum(O13:O19) -> 244 | P21: =sum(P13:P19) -> 67 | Q21: =sum(Q13:Q19) -> 173 | R21: =sum(R13:R19) -> 2 | S21: =sum(S13:S19) -> 0 | U21: =sum(U13:U20) -> 679.35354
A23: AJYD | B23: nkotb4evah | C23: 20 | D23: 6 | E23: 14 | F23: =sum(AJYD!C3,AJYD!T3,AJYD!C12,AJYD!T12,AJYD!C21,AJYD!T21,AJYD!C30,AJYD!T30,AJYD!C39,AJYD!T39,AJYD!C48,AJYD!T48,AJYD!C57,AJYD!T57,AJYD!C66,AJYD!T66,AJYD!C75,AJYD!T75,AJYD!C84,AJYD!T84) -> 35 | G23: =sum(AJYD!D3,AJYD!U3,AJYD!D12,AJYD!U12,AJYD!D21,AJYD!U21,AJYD!D30,AJYD!U30,AJYD!D39,AJYD!U39,AJYD!D48,AJYD!U48,AJYD!D57,AJYD!U57,AJYD!D66,AJYD!U66,AJYD!D75,AJYD!U75,AJYD!D84,AJYD!U84) -> 1446 | H23: =sum(AJYD!E3,AJYD!V3,AJYD!E12,AJYD!V12,AJYD!E21,AJYD!V21,AJYD!E30,AJYD!V30,AJYD!E39,AJYD!V39,AJYD!E48,AJYD!V48,AJYD!E57,AJYD!V57,AJYD!E66,AJYD!V66,AJYD!E75,AJYD!V75,AJYD!E84,AJYD!V84) -> 16 | I23: =sum(AJYD!F3,AJYD!W3,AJYD!F12,AJYD!W12,AJYD!F21,AJYD!W21,AJYD!F30,AJYD!W30,AJYD!F39,AJYD!W39,AJYD!F48,AJYD!W48,AJYD!F57,AJYD!W57,AJYD!F66,AJYD!W66,AJYD!F75,AJYD!W75,AJYD!F84,AJYD!W84) -> 1764 | J23: =sum(AJYD!G3,AJYD!X3,AJYD!G12,AJYD!X12,AJYD!G21,AJYD!X21,AJYD!G30,AJYD!X30,AJYD!G39,AJYD!X39,AJYD!G48,AJYD!X48,AJYD!G57,AJYD!X57,AJYD!G66,AJYD!X66,AJYD!G75,AJYD!X75,AJYD!G84,AJYD!X84) -> 0.39857639 | K23: =sum(AJYD!H3,AJYD!Y3,AJYD!H12,AJYD!Y12,AJYD!H21,AJYD!Y21,AJYD!H30,AJYD!Y30,AJYD!H39,AJYD!Y39,AJYD!H48,AJYD!Y48,AJYD!H57,AJYD!Y57,AJYD!H66,AJYD!Y66,AJYD!H75,AJYD!Y75,AJYD!H84,AJYD!Y84) -> -318 | L23: =K23/(HOUR(J23)*60+(MINUTE(J23)+((SECOND(J23)/60)))) -> -0.55405523 | M23: =sum(AJYD!J3,AJYD!AA3,AJYD!J12,AJYD!AA12,AJYD!J21,AJYD!AA21,AJYD!J30,AJYD!AA30,AJYD!J39,AJYD!AA39,AJYD!J48,AJYD!AA48,AJYD!J57,AJYD!AA57,AJYD!J66,AJYD!AA66,AJYD!J75,AJYD!AA75,AJYD!J84,AJYD!AA84) -> 66 | N23: =sum(AJYD!K3,AJYD!AB3,AJYD!K12,AJYD!AB12,AJYD!K21,AJYD!AB21,AJYD!K30,AJYD!AB30,AJYD!K39,AJYD!AB39,AJYD!K48,AJYD!AB48,AJYD!K57,AJYD!AB57,AJYD!K66,AJYD!AB66,AJYD!K75,AJYD!AB75,AJYD!K84,AJYD!AB84) -> 169 | O23: =sum(AJYD!L3,AJYD!AC3,AJYD!L12,AJYD!AC12,AJYD!L21,AJYD!AC21,AJYD!L30,AJYD!AC30,AJYD!L39,AJYD!AC39,AJYD!L48,AJYD!AC48,AJYD!L57,AJYD!AC57,AJYD!L66,AJYD!AC66,AJYD!L75,AJYD!AC75,AJYD!L84,AJYD!AC84) -> 31 | P23: =sum(AJYD!M3,AJYD!AD3,AJYD!M12,AJYD!AD12,AJYD!M21,AJYD!AD21,AJYD!M30,AJYD!AD30,AJYD!M39,AJYD!AD39,AJYD!M48,AJYD!AD48,AJYD!M57,AJYD!AD57,AJYD!M66,AJYD!AD66,AJYD!M75,AJYD!AD75,AJYD!M84,AJYD!AD84) -> 4 | Q23: =sum(AJYD!N3,AJYD!AE3,AJYD!N12,AJYD!AE12,AJYD!N21,AJYD!AE21,AJYD!N30,AJYD!AE30,AJYD!N39,AJYD!AE39,AJYD!N48,AJYD!AE48,AJYD!N57,AJYD!AE57,AJYD!N66,AJYD!AE66,AJYD!N75,AJYD!AE75,AJYD!N84,AJYD!AE84) -> 33 | R23: =sum(AJYD!O3,AJYD!AF3,AJYD!O12,AJYD!AF12,AJYD!O21,AJYD!AF21,AJYD!O30,AJYD!AF30,AJYD!O39,AJYD!AF39,AJYD!O48,AJYD!AF48,AJYD!O57,AJYD!AF57,AJYD!O66,AJYD!AF66,AJYD!O75,AJYD!AF75,AJYD!O84,AJYD!AF84) -> 1 | S23: =sum(AJYD!P3,AJYD!AG3,AJYD!P12,AJYD!AG12,AJYD!P21,AJYD!AG21,AJYD!P30,AJYD!AG30,AJYD!P39,AJYD!AG39,AJYD!P48,AJYD!AG48,AJYD!P57,AJYD!AG57,AJYD!P66,AJYD!AG66,AJYD!P75,AJYD!AG75,AJYD!P84,AJYD!AG84) -> 0 | T23: =J23/I23 -> 0.00022595033 | U23: =G23/D23 -> 241
B24: ixGingy (to G&tC) | C24: 12 | D24: 3 | E24: 9 | F24: =sum(AJYD!C4,AJYD!T4,AJYD!C13,AJYD!T13,AJYD!C22,AJYD!T22,AJYD!C31,AJYD!T31,AJYD!C40,AJYD!T40,AJYD!C49,AJYD!T49) -> 14 | G24: =sum(AJYD!D4,AJYD!U4,AJYD!D13,AJYD!U13,AJYD!D22,AJYD!U22,AJYD!D31,AJYD!U31,AJYD!D40,AJYD!U40,AJYD!D49,AJYD!U49) -> 1622 | H24: =sum(AJYD!E4,AJYD!V4,AJYD!E13,AJYD!V13,AJYD!E22,AJYD!V22,AJYD!E31,AJYD!V31,AJYD!E40,AJYD!V40,AJYD!E49,AJYD!V49) -> 5 | I24: =sum(AJYD!F4,AJYD!W4,AJYD!F13,AJYD!W13,AJYD!F22,AJYD!W22,AJYD!F31,AJYD!W31,AJYD!F40,AJYD!W40,AJYD!F49,AJYD!W49) -> 1300 | J24: =sum(AJYD!G4,AJYD!X4,AJYD!G13,AJYD!X13,AJYD!G22,AJYD!X22,AJYD!G31,AJYD!X31,AJYD!G40,AJYD!X40,AJYD!G49,AJYD!X49) -> 0.29020833 | K24: =sum(AJYD!H4,AJYD!Y4,AJYD!H13,AJYD!Y13,AJYD!H22,AJYD!Y22,AJYD!H31,AJYD!Y31,AJYD!H40,AJYD!Y40,AJYD!H49,AJYD!Y49) -> 322 | L24: =K24/(HOUR(J24)*60+(MINUTE(J24)+((SECOND(J24)/60)))) -> 0.77051926 | M24: =sum(AJYD!J4,AJYD!AA4,AJYD!J13,AJYD!AA13,AJYD!J22,AJYD!AA22,AJYD!J31,AJYD!AA31,AJYD!J40,AJYD!AA40,AJYD!J49,AJYD!AA49) -> 48 | N24: =sum(AJYD!K4,AJYD!AB4,AJYD!K13,AJYD!AB13,AJYD!K22,AJYD!AB22,AJYD!K31,AJYD!AB31,AJYD!K40,AJYD!AB40,AJYD!K49,AJYD!AB49) -> 241 | O24: =sum(AJYD!L4,AJYD!AC4,AJYD!L13,AJYD!AC13,AJYD!L22,AJYD!AC22,AJYD!L31,AJYD!AC31,AJYD!L40,AJYD!AC40,AJYD!L49,AJYD!AC49) -> 61 | P24: =sum(AJYD!M4,AJYD!AD4,AJYD!M13,AJYD!AD13,AJYD!M22,AJYD!AD22,AJYD!M31,AJYD!AD31,AJYD!M40,AJYD!AD40,AJYD!M49,AJYD!AD49) -> 20 | Q24: =sum(AJYD!N4,AJYD!AE4,AJYD!N13,AJYD!AE13,AJYD!N22,AJYD!AE22,AJYD!N31,AJYD!AE31,AJYD!N40,AJYD!AE40,AJYD!N49,AJYD!AE49) -> 51 | R24: =sum(AJYD!O4,AJYD!AF4,AJYD!O13,AJYD!AF13,AJYD!O22,AJYD!AF22,AJYD!O31,AJYD!AF31,AJYD!O40,AJYD!AF40,AJYD!O49,AJYD!AF49) -> 0 | S24: =sum(AJYD!P4,AJYD!AG4,AJYD!P13,AJYD!AG13,AJYD!P22,AJYD!AG22,AJYD!P31,AJYD!AG31,AJYD!P40,AJYD!AG40,AJYD!P49,AJYD!AG49) -> 0 | T24: =J24/I24 -> 0.00022323718 | U24: =G24/D24 -> 540.66667
B25: Its Rainin MenZ | C25: 18 | D25: 6 | E25: 12 | F25: =sum(AJYD!C5,AJYD!T5,AJYD!C14,AJYD!T14,AJYD!C23,AJYD!T23,AJYD!C32,AJYD!T32,AJYD!C41,AJYD!T41,AJYD!C50,AJYD!T50,AJYD!C59,AJYD!T59,AJYD!C68,AJYD!T68,AJYD!C77,AJYD!T77,AJYD!C86,AJYD!T86) -> 3 | G25: =sum(AJYD!D5,AJYD!U5,AJYD!D14,AJYD!U14,AJYD!D23,AJYD!U23,AJYD!D32,AJYD!U32,AJYD!D41,AJYD!U41,AJYD!D50,AJYD!U50,AJYD!D59,AJYD!U59,AJYD!D68,AJYD!U68,AJYD!D77,AJYD!U77,AJYD!D86,AJYD!U86) -> 1855 | H25: =sum(AJYD!E5,AJYD!V5,AJYD!E14,AJYD!V14,AJYD!E23,AJYD!V23,AJYD!E32,AJYD!V32,AJYD!E41,AJYD!V41,AJYD!E50,AJYD!V50,AJYD!E59,AJYD!V59,AJYD!E68,AJYD!V68,AJYD!E77,AJYD!V77,AJYD!E86,AJYD!V86) -> 15 | I25: =sum(AJYD!F5,AJYD!W5,AJYD!F14,AJYD!W14,AJYD!F23,AJYD!W23,AJYD!F32,AJYD!W32,AJYD!F41,AJYD!W41,AJYD!F50,AJYD!W50,AJYD!F59,AJYD!W59,AJYD!F68,AJYD!W68,AJYD!F77,AJYD!W77,AJYD!F86,AJYD!W86) -> 1776 | J25: =sum(AJYD!G5,AJYD!X5,AJYD!G14,AJYD!X14,AJYD!G23,AJYD!X23,AJYD!G32,AJYD!X32,AJYD!G41,AJYD!X41,AJYD!G50,AJYD!X50,AJYD!G59,AJYD!X59,AJYD!G68,AJYD!X68,AJYD!G77,AJYD!X77,AJYD!G86,AJYD!X86) -> 0.37565972 | K25: =sum(AJYD!H5,AJYD!Y5,AJYD!H14,AJYD!Y14,AJYD!H23,AJYD!Y23,AJYD!H32,AJYD!Y32,AJYD!H41,AJYD!Y41,AJYD!H50,AJYD!Y50,AJYD!H59,AJYD!Y59,AJYD!H68,AJYD!Y68,AJYD!H77,AJYD!Y77,AJYD!H86,AJYD!Y86) -> 79 | L25: =K25/(HOUR(J25)*60+(MINUTE(J25)+((SECOND(J25)/60)))) -> 0.14603938 | M25: =sum(AJYD!J5,AJYD!AA5,AJYD!J14,AJYD!AA14,AJYD!J23,AJYD!AA23,AJYD!J32,AJYD!AA32,AJYD!J41,AJYD!AA41,AJYD!J50,AJYD!AA50,AJYD!J59,AJYD!AA59,AJYD!J68,AJYD!AA68,AJYD!J77,AJYD!AA77,AJYD!J86,AJYD!AA86) -> 56 | N25: =sum(AJYD!K5,AJYD!AB5,AJYD!K14,AJYD!AB14,AJYD!K23,AJYD!AB23,AJYD!K32,AJYD!AB32,AJYD!K41,AJYD!AB41,AJYD!K50,AJYD!AB50,AJYD!K59,AJYD!AB59,AJYD!K68,AJYD!AB68,AJYD!K77,AJYD!AB77,AJYD!K86,AJYD!AB86) -> 278 | O25: =sum(AJYD!L5,AJYD!AC5,AJYD!L14,AJYD!AC14,AJYD!L23,AJYD!AC23,AJYD!L32,AJYD!AC32,AJYD!L41,AJYD!AC41,AJYD!L50,AJYD!AC50,AJYD!L59,AJYD!AC59,AJYD!L68,AJYD!AC68,AJYD!L77,AJYD!AC77,AJYD!L86,AJYD!AC86) -> 60 | P25: =sum(AJYD!M5,AJYD!AD5,AJYD!M14,AJYD!AD14,AJYD!M23,AJYD!AD23,AJYD!M32,AJYD!AD32,AJYD!M41,AJYD!AD41,AJYD!M50,AJYD!AD50,AJYD!M59,AJYD!AD59,AJYD!M68,AJYD!AD68,AJYD!M77,AJYD!AD77,AJYD!M86,AJYD!AD86) -> 27 | Q25: =sum(AJYD!N5,AJYD!AE5,AJYD!N14,AJYD!AE14,AJYD!N23,AJYD!AE23,AJYD!N32,AJYD!AE32,AJYD!N41,AJYD!AE41,AJYD!N50,AJYD!AE50,AJYD!N59,AJYD!AE59,AJYD!N68,AJYD!AE68,AJYD!N77,AJYD!AE77,AJYD!N86,AJYD!AE86) -> 42 | R25: =sum(AJYD!O5,AJYD!AF5,AJYD!O14,AJYD!AF14,AJYD!O23,AJYD!AF23,AJYD!O32,AJYD!AF32,AJYD!O41,AJYD!AF41,AJYD!O50,AJYD!AF50,AJYD!O59,AJYD!AF59,AJYD!O68,AJYD!AF68,AJYD!O77,AJYD!AF77,AJYD!O86,AJYD!AF86) -> 1 | S25: =sum(AJYD!P5,AJYD!AG5,AJYD!P14,AJYD!AG14,AJYD!P23,AJYD!AG23,AJYD!P32,AJYD!AG32,AJYD!P41,AJYD!AG41,AJYD!P50,AJYD!AG50,AJYD!P59,AJYD!AG59,AJYD!P68,AJYD!AG68,AJYD!P77,AJYD!AG77,AJYD!P86,AJYD!AG86) -> 0 | T25: =J25/I25 -> 0.00021152011 | U25: =G25/D25 -> 309.16667
B26: TommyWstSide (to Team Rocket) | C26: 8 | D26: 2 | E26: 6 | F26: =sum(AJYD!C6,AJYD!T6,AJYD!C15,AJYD!T15,AJYD!C24,AJYD!T24,AJYD!C33,AJYD!T33,AJYD!C42,AJYD!T42,AJYD!C51,AJYD!T51,AJYD!C60,AJYD!T60,AJYD!C69,AJYD!T69,AJYD!C78,AJYD!T78,AJYD!C87,AJYD!T87) -> 0 | G26: =sum(AJYD!D6,AJYD!U6,AJYD!D15,AJYD!U15,AJYD!D24,AJYD!U24,AJYD!D33,AJYD!U33,AJYD!D42,AJYD!U42,AJYD!D51,AJYD!U51,AJYD!D60,AJYD!U60,AJYD!D69,AJYD!U69,AJYD!D78,AJYD!U78,AJYD!D87,AJYD!U87) -> 714 | H26: =sum(AJYD!E6,AJYD!V6,AJYD!E15,AJYD!V15,AJYD!E24,AJYD!V24,AJYD!E33,AJYD!V33,AJYD!E42,AJYD!V42,AJYD!E51,AJYD!V51,AJYD!E60,AJYD!V60,AJYD!E69,AJYD!V69,AJYD!E78,AJYD!V78,AJYD!E87,AJYD!V87) -> 8 | I26: =sum(AJYD!F6,AJYD!W6,AJYD!F15,AJYD!W15,AJYD!F24,AJYD!W24,AJYD!F33,AJYD!W33,AJYD!F42,AJYD!W42,AJYD!F51,AJYD!W51,AJYD!F60,AJYD!W60,AJYD!F69,AJYD!W69,AJYD!F78,AJYD!W78,AJYD!F87,AJYD!W87) -> 863 | J26: =sum(AJYD!G6,AJYD!X6,AJYD!G15,AJYD!X15,AJYD!G24,AJYD!X24,AJYD!G33,AJYD!X33,AJYD!G42,AJYD!X42,AJYD!G51,AJYD!X51,AJYD!G60,AJYD!X60,AJYD!G69,AJYD!X69,AJYD!G78,AJYD!X78,AJYD!G87,AJYD!X87) -> 0.16747685 | K26: =sum(AJYD!H6,AJYD!Y6,AJYD!H15,AJYD!Y15,AJYD!H24,AJYD!Y24,AJYD!H33,AJYD!Y33,AJYD!H42,AJYD!Y42,AJYD!H51,AJYD!Y51,AJYD!H60,AJYD!Y60,AJYD!H69,AJYD!Y69,AJYD!H78,AJYD!Y78,AJYD!H87,AJYD!Y87) -> -149 | L26: =K26/(HOUR(J26)*60+(MINUTE(J26)+((SECOND(J26)/60)))) -> -0.61782999 | M26: =sum(AJYD!J6,AJYD!AA6,AJYD!J15,AJYD!AA15,AJYD!J24,AJYD!AA24,AJYD!J33,AJYD!AA33,AJYD!J42,AJYD!AA42,AJYD!J51,AJYD!AA51,AJYD!J60,AJYD!AA60,AJYD!J69,AJYD!AA69,AJYD!J78,AJYD!AA78,AJYD!J87,AJYD!AA87) -> 27 | N26: =sum(AJYD!K6,AJYD!AB6,AJYD!K15,AJYD!AB15,AJYD!K24,AJYD!AB24,AJYD!K33,AJYD!AB33,AJYD!K42,AJYD!AB42,AJYD!K51,AJYD!AB51,AJYD!K60,AJYD!AB60,AJYD!K69,AJYD!AB69,AJYD!K78,AJYD!AB78,AJYD!K87,AJYD!AB87) -> 98 | O26: =sum(AJYD!L6,AJYD!AC6,AJYD!L15,AJYD!AC15,AJYD!L24,AJYD!AC24,AJYD!L33,AJYD!AC33,AJYD!L42,AJYD!AC42,AJYD!L51,AJYD!AC51,AJYD!L60,AJYD!AC60,AJYD!L69,AJYD!AC69,AJYD!L78,AJYD!AC78,AJYD!L87,AJYD!AC87) -> 17 | P26: =sum(AJYD!M6,AJYD!AD6,AJYD!M15,AJYD!AD15,AJYD!M24,AJYD!AD24,AJYD!M33,AJYD!AD33,AJYD!M42,AJYD!AD42,AJYD!M51,AJYD!AD51,AJYD!M60,AJYD!AD60,AJYD!M69,AJYD!AD69,AJYD!M78,AJYD!AD78,AJYD!M87,AJYD!AD87) -> 5 | Q26: =sum(AJYD!N6,AJYD!AE6,AJYD!N15,AJYD!AE15,AJYD!N24,AJYD!AE24,AJYD!N33,AJYD!AE33,AJYD!N42,AJYD!AE42,AJYD!N51,AJYD!AE51,AJYD!N60,AJYD!AE60,AJYD!N69,AJYD!AE69,AJYD!N78,AJYD!AE78,AJYD!N87,AJYD!AE87) -> 10 | R26: =sum(AJYD!O6,AJYD!AF6,AJYD!O15,AJYD!AF15,AJYD!O24,AJYD!AF24,AJYD!O33,AJYD!AF33,AJYD!O42,AJYD!AF42,AJYD!O51,AJYD!AF51,AJYD!O60,AJYD!AF60,AJYD!O69,AJYD!AF69,AJYD!O78,AJYD!AF78,AJYD!O87,AJYD!AF87) -> 0 | S26: =sum(AJYD!P6,AJYD!AG6,AJYD!P15,AJYD!AG15,AJYD!P24,AJYD!AG24,AJYD!P33,AJYD!AG33,AJYD!P42,AJYD!AG42,AJYD!P51,AJYD!AG51,AJYD!P60,AJYD!AG60,AJYD!P69,AJYD!AG69,AJYD!P78,AJYD!AG78,AJYD!P87,AJYD!AG87) -> 0 | T26: =J26/I26 -> 0.00019406356 | U26: =G26/D26 -> 357
