Workbook

Sheet Team Statistics
C1: Statistics for the Halo Reach Event of DJBluePDX's Grifball Summer Series presented by Dreamhack and powered by PlayGrifball.com
A2: Team | B2: Player | C2: Games | D2: Wins | E2: Minutes | F2: Score | G2: Kills | H2: Assists | I2: Deaths | J2: Spread | K2: K/D Ratio | L2: Average Life | M2: Medals | N2: Medals Recorded? | O2: Minutes | P2: Double Kill | Q2: Triple Kill | R2: Overkill | S2: Killtacular | T2: Killing Spree | U2: Killing Frenzy | V2: Sword Spree | W2: Extermination | X2: Running Riot | Y2: Rampage | Z2: Killtrocity | AA2: Killmanjaro | AB2: Killpocalypse | AC2: Killtastrophe | AD2: Killionaire
A3: Noble Team | B3: TheNobleTV | C3: 5 | D3: =SUM('Game Results'!C56+'Game Results'!C121+'Game Results'!C225+'Game Results'!C282+'Game Results'!C295) -> 3 | E3: =SUM('Game Results'!D56+'Game Results'!D121+'Game Results'!D225+'Game Results'!D282+'Game Results'!D295) -> 118.9 | F3: =SUM('Game Results'!E56+'Game Results'!E121+'Game Results'!E225+'Game Results'!E282+'Game Results'!E295) -> 0 | G3: =SUM('Game Results'!F56+'Game Results'!F121+'Game Results'!F225+'Game Results'!F282+'Game Results'!F295) -> 414 | H3: =SUM('Game Results'!G56+'Game Results'!G121+'Game Results'!G225+'Game Results'!G282+'Game Results'!G295) -> 34 | I3: =SUM('Game Results'!H56+'Game Results'!H121+'Game Results'!H225+'Game Results'!H282+'Game Results'!H295) -> 509 | J3: =SUM('Game Results'!I56+'Game Results'!I121+'Game Results'!I225+'Game Results'!I282+'Game Results'!I295) -> -95 | K3: =SUM(G3/I3) -> 0.81335953 | L3: =SUM((E3*60)/I3) -> 14.015717 | M3: =SUM('Game Results'!L56+'Game Results'!L121+'Game Results'!L225+'Game Results'!L282+'Game Results'!L295) -> 655 | N3: =SUM('Game Results'!M56+'Game Results'!M121+'Game Results'!M225+'Game Results'!M282+'Game Results'!M295) -> 5 | O3: =SUM('Game Results'!N56+'Game Results'!N121+'Game Results'!N225+'Game Results'!N282+'Game Results'!N295) -> 118.9 | P3: =SUM('Game Results'!O56+'Game Results'!O121+'Game Results'!O225+'Game Results'!O282+'Game Results'!O295) -> 52 | Q3: =SUM('Game Results'!P56+'Game Results'!P121+'Game Results'!P225+'Game Results'!P282+'Game Results'!P295) -> 9 | R3: =SUM('Game Results'!Q56+'Game Results'!Q121+'Game Results'!Q225+'Game Results'!Q282+'Game Results'!Q295) -> 3 | S3: =SUM('Game Results'!R56+'Game Results'!R121+'Game Results'!R225+'Game Results'!R282+'Game Results'!R295) -> 0 | T3: =SUM('Game Results'!S56+'Game Results'!S121+'Game Results'!S225+'Game Results'!S282+'Game Results'!S295) -> 2 | ... AD3: =SUM('Game Results'!AC56+'Game Results'!AC121+'Game Results'!AC225+'Game Results'!AC282+'Game Results'!AC295) -> 0
A4: Noble Team | B4: Ace B S1lentND1 | C4: 5 | D4: =SUM('Game Results'!C57+'Game Results'!C122+'Game Results'!C226+'Game Results'!C283+'Game Results'!C296) -> 3 | E4: =SUM('Game Results'!D57+'Game Results'!D122+'Game Results'!D226+'Game Results'!D283+'Game Results'!D296) -> 118.9 | F4: =SUM('Game Results'!E57+'Game Results'!E122+'Game Results'!E226+'Game Results'!E283+'Game Results'!E296) -> 3 | G4: =SUM('Game Results'!F57+'Game Results'!F122+'Game Results'!F226+'Game Results'!F283+'Game Results'!F296) -> 557 | H4: =SUM('Game Results'!G57+'Game Results'!G122+'Game Results'!G226+'Game Results'!G283+'Game Results'!G296) -> 49 | I4: =SUM('Game Results'!H57+'Game Results'!H122+'Game Results'!H226+'Game Results'!H283+'Game Results'!H296) -> 494 | J4: =SUM('Game Results'!I57+'Game Results'!I122+'Game Results'!I226+'Game Results'!I283+'Game Results'!I296) -> 63 | K4: =SUM(G4/I4) -> 1.1275304 | L4: =SUM((E4*60)/I4) -> 14.441296 | M4: =SUM('Game Results'!L57+'Game Results'!L122+'Game Results'!L226+'Game Results'!L283+'Game Results'!L296) -> 958 | N4: =SUM('Game Results'!M57+'Game Results'!M122+'Game Results'!M226+'Game Results'!M283+'Game Results'!M296) -> 5 | O4: =SUM('Game Results'!N57+'Game Results'!N122+'Game Results'!N226+'Game Results'!N283+'Game Results'!N296) -> 118.9 | P4: =SUM('Game Results'!O57+'Game Results'!O122+'Game Results'!O226+'Game Results'!O283+'Game Results'!O296) -> 113 | Q4: =SUM('Game Results'!P57+'Game Results'!P122+'Game Results'!P226+'Game Results'!P283+'Game Results'!P296) -> 22 | R4: =SUM('Game Results'!Q57+'Game Results'!Q122+'Game Results'!Q226+'Game Results'!Q283+'Game Results'!Q296) -> 5 | S4: =SUM('Game Results'!R57+'Game Results'!R122+'Game Results'!R226+'Game Results'!R283+'Game Results'!R296) -> 1 | T4: =SUM('Game Results'!S57+'Game Results'!S122+'Game Results'!S226+'Game Results'!S283+'Game Results'!S296) -> 14 | ... AD4: =SUM('Game Results'!AC57+'Game Results'!AC122+'Game Results'!AC226+'Game Results'!AC283+'Game Results'!AC296) -> 0
A5: Noble Team | B5: DCleak | C5: 5 | D5: =SUM('Game Results'!C58+'Game Results'!C123+'Game Results'!C227+'Game Results'!C284+'Game Results'!C297) -> 3 | E5: =SUM('Game Results'!D58+'Game Results'!D123+'Game Results'!D227+'Game Results'!D284+'Game Results'!D297) -> 118.9 | F5: =SUM('Game Results'!E58+'Game Results'!E123+'Game Results'!E227+'Game Results'!E284+'Game Results'!E297) -> 1 | G5: =SUM('Game Results'!F58+'Game Results'!F123+'Game Results'!F227+'Game Results'!F284+'Game Results'!F297) -> 487 | H5: =SUM('Game Results'!G58+'Game Results'!G123+'Game Results'!G227+'Game Results'!G284+'Game Results'!G297) -> 44 | I5: =SUM('Game Results'!H58+'Game Results'!H123+'Game Results'!H227+'Game Results'!H284+'Game Results'!H297) -> 530 | J5: =SUM('Game Results'!I58+'Game Results'!I123+'Game Results'!I227+'Game Results'!I284+'Game Results'!I297) -> -43 | K5: =SUM(G5/I5) -> 0.91886792 | L5: =SUM((E5*60)/I5) -> 13.460377 | M5: =SUM('Game Results'!L58+'Game Results'!L123+'Game Results'!L227+'Game Results'!L284+'Game Results'!L297) -> 784 | N5: =SUM('Game Results'!M58+'Game Results'!M123+'Game Results'!M227+'Game Results'!M284+'Game Results'!M297) -> 5 | O5: =SUM('Game Results'!N58+'Game Results'!N123+'Game Results'!N227+'Game Results'!N284+'Game Results'!N297) -> 118.9 | P5: =SUM('Game Results'!O58+'Game Results'!O123+'Game Results'!O227+'Game Results'!O284+'Game Results'!O297) -> 80 | Q5: =SUM('Game Results'!P58+'Game Results'!P123+'Game Results'!P227+'Game Results'!P284+'Game Results'!P297) -> 13 | R5: =SUM('Game Results'!Q58+'Game Results'!Q123+'Game Results'!Q227+'Game Results'!Q284+'Game Results'!Q297) -> 1 | S5: =SUM('Game Results'!R58+'Game Results'!R123+'Game Results'!R227+'Game Results'!R284+'Game Results'!R297) -> 0 | T5: =SUM('Game Results'!S58+'Game Results'!S123+'Game Results'!S227+'Game Results'!S284+'Game Results'!S297) -> 2 | ... AD5: =SUM('Game Results'!AC58+'Game Results'!AC123+'Game Results'!AC227+'Game Results'!AC284+'Game Results'!AC297) -> 0
A6: Noble Team | B6: Ouglaf11 | C6: 5 | D6: =SUM('Game Results'!C59+'Game Results'!C124+'Game Results'!C228+'Game Results'!C285+'Game Results'!C298) -> 3 | E6: =SUM('Game Results'!D59+'Game Results'!D124+'Game Results'!D228+'Game Results'!D285+'Game Results'!D298) -> 118.9 | F6: =SUM('Game Results'!E59+'Game Results'!E124+'Game Results'!E228+'Game Results'!E285+'Game Results'!E298) -> 13 | G6: =SUM('Game Results'!F59+'Game Results'!F124+'Game Results'!F228+'Game Results'!F285+'Game Results'!F298) -> 393 | H6: =SUM('Game Results'!G59+'Game Results'!G124+'Game Results'!G228+'Game Results'!G285+'Game Results'!G298) -> 6 | I6: =SUM('Game Results'!H59+'Game Results'!H124+'Game Results'!H228+'Game Results'!H285+'Game Results'!H298) -> 376 | J6: =SUM('Game Results'!I59+'Game Results'!I124+'Game Results'!I228+'Game Results'!I285+'Game Results'!I298) -> 17 | K6: =SUM(G6/I6) -> 1.0452128 | L6: =SUM((E6*60)/I6) -> 18.973404 | M6: =SUM('Game Results'!L59+'Game Results'!L124+'Game Results'!L228+'Game Results'!L285+'Game Results'!L298) -> 636 | N6: =SUM('Game Results'!M59+'Game Results'!M124+'Game Results'!M228+'Game Results'!M285+'Game Results'!M298) -> 5 | O6: =SUM('Game Results'!N59+'Game Results'!N124+'Game Results'!N228+'Game Results'!N285+'Game Results'!N298) -> 118.9 | P6: =SUM('Game Results'!O59+'Game Results'!O124+'Game Results'!O228+'Game Results'!O285+'Game Results'!O298) -> 35 | Q6: =SUM('Game Results'!P59+'Game Results'!P124+'Game Results'!P228+'Game Results'!P285+'Game Results'!P298) -> 7 | R6: =SUM('Game Results'!Q59+'Game Results'!Q124+'Game Results'!Q228+'Game Results'!Q285+'Game Results'!Q298) -> 0 | S6: =SUM('Game Results'!R59+'Game Results'!R124+'Game Results'!R228+'Game Results'!R285+'Game Results'!R298) -> 0 | T6: =SUM('Game Results'!S59+'Game Results'!S124+'Game Results'!S228+'Game Results'!S285+'Game Results'!S298) -> 8 | ... AD6: =SUM('Game Results'!AC59+'Game Results'!AC124+'Game Results'!AC228+'Game Results'!AC285+'Game Results'!AC298) -> 0
A7: Totals: | C7: =SUM(C3:C6)/4 -> 5 | D7: =SUM(D3:D6)/4 -> 3 | E7: =SUM(E3:E6)/4 -> 118.9 | F7: =SUM(F3:F6) -> 17 | G7: =SUM(G3:G6) -> 1851 | H7: =SUM(H3:H6) -> 133 | I7: =SUM(I3:I6) -> 1909 | J7: =SUM(J3:J6) -> -58 | K7: =G7/I7 -> 0.9696176 | L7: =SUM(L3:L6)/4 -> 15.222699 | M7: =SUM(M3:M6) -> 3033 | N7: =SUM(N3:N6) -> 20 | O7: =SUM(O3:O6) -> 475.6 | P7: =SUM(P3:P6) -> 280 | Q7: =SUM(Q3:Q6) -> 51 | R7: =SUM(R3:R6) -> 9 | S7: =SUM(S3:S6) -> 1 | T7: =SUM(T3:T6) -> 26 | ... AD7: =SUM(AD3:AD6) -> 0
A8: Salvatores | B8: ADhillyy | C8: 2 | D8: =SUM('Game Results'!C35+'Game Results'!C74) -> 0 | E8: =SUM('Game Results'!D35+'Game Results'!D74) -> 58.8 | F8: =SUM('Game Results'!E35+'Game Results'!E74) -> 0 | G8: =SUM('Game Results'!F35+'Game Results'!F74) -> 261 | H8: =SUM('Game Results'!G35+'Game Results'!G74) -> 16 | I8: =SUM('Game Results'!H35+'Game Results'!H74) -> 270 | J8: =SUM('Game Results'!I35+'Game Results'!I74) -> -9 | K8: =SUM(G8/I8) -> 0.96666667 | L8: =SUM((E8*60)/I8) -> 13.066667 | M8: =SUM('Game Results'!L35+'Game Results'!L74) -> 403 | N8: =SUM('Game Results'!M35+'Game Results'!M74) -> 2 | O8: =SUM('Game Results'!N35+'Game Results'!N74) -> 58.8 | P8: =SUM('Game Results'!O35+'Game Results'!O74) -> 49 | Q8: =SUM('Game Results'!P35+'Game Results'!P74) -> 7 | R8: =SUM('Game Results'!Q35+'Game Results'!Q74) -> 3 | S8: =SUM('Game Results'!R35+'Game Results'!R74) -> 1 | T8: =SUM('Game Results'!S35+'Game Results'!S74) -> 4 | ... AD8: =SUM('Game Results'!AC35+'Game Results'!AC74) -> 0
A9: Salvatores | B9: Yejis Aegyo | C9: 2 | D9: =SUM('Game Results'!C36+'Game Results'!C75) -> 0 | E9: =SUM('Game Results'!D36+'Game Results'!D75) -> 58.8 | F9: =SUM('Game Results'!E36+'Game Results'!E75) -> 2 | G9: =SUM('Game Results'!F36+'Game Results'!F75) -> 326 | H9: =SUM('Game Results'!G36+'Game Results'!G75) -> 14 | I9: =SUM('Game Results'!H36+'Game Results'!H75) -> 280 | J9: =SUM('Game Results'!I36+'Game Results'!I75) -> 46 | K9: =SUM(G9/I9) -> 1.1642857 | L9: =SUM((E9*60)/I9) -> 12.6 | M9: =SUM('Game Results'!L36+'Game Results'!L75) -> 520 | N9: =SUM('Game Results'!M36+'Game Results'!M75) -> 2 | O9: =SUM('Game Results'!N36+'Game Results'!N75) -> 58.8 | P9: =SUM('Game Results'!O36+'Game Results'!O75) -> 62 | Q9: =SUM('Game Results'!P36+'Game Results'!P75) -> 11 | R9: =SUM('Game Results'!Q36+'Game Results'!Q75) -> 1 | S9: =SUM('Game Results'!R36+'Game Results'!R75) -> 0 | T9: =SUM('Game Results'!S36+'Game Results'!S75) -> 2 | ... AD9: =SUM('Game Results'!AC36+'Game Results'!AC75) -> 0
A10: Salvatores | B10: Myst the Cold | C10: 2 | D10: =SUM('Game Results'!C37+'Game Results'!C76) -> 0 | E10: =SUM('Game Results'!D37+'Game Results'!D76) -> 58.8 | F10: =SUM('Game Results'!E37+'Game Results'!E76) -> 0 | G10: =SUM('Game Results'!F37+'Game Results'!F76) -> 249 | H10: =SUM('Game Results'!G37+'Game Results'!G76) -> 21 | I10: =SUM('Game Results'!H37+'Game Results'!H76) -> 280 | J10: =SUM('Game Results'!I37+'Game Results'!I76) -> -31 | K10: =SUM(G10/I10) -> 0.88928571 | L10: =SUM((E10*60)/I10) -> 12.6 | M10: =SUM('Game Results'!L37+'Game Results'!L76) -> 398 | N10: =SUM('Game Results'!M37+'Game Results'!M76) -> 2 | O10: =SUM('Game Results'!N37+'Game Results'!N76) -> 58.8 | P10: =SUM('Game Results'!O37+'Game Results'!O76) -> 43 | Q10: =SUM('Game Results'!P37+'Game Results'!P76) -> 3 | R10: =SUM('Game Results'!Q37+'Game Results'!Q76) -> 0 | S10: =SUM('Game Results'!R37+'Game Results'!R76) -> 0 | T10: =SUM('Game Results'!S37+'Game Results'!S76) -> 1 | ... AD10: =SUM('Game Results'!AC37+'Game Results'!AC76) -> 0
A11: Salvatores | B11: Beam1N1 | C11: 2 | D11: =SUM('Game Results'!C38+'Game Results'!C77) -> 0 | E11: =SUM('Game Results'!D38+'Game Results'!D77) -> 58.8 | F11: =SUM('Game Results'!E38+'Game Results'!E77) -> 2 | G11: =SUM('Game Results'!F38+'Game Results'!F77) -> 147 | H11: =SUM('Game Results'!G38+'Game Results'!G77) -> 4 | I11: =SUM('Game Results'!H38+'Game Results'!H77) -> 175 | J11: =SUM('Game Results'!I38+'Game Results'!I77) -> -28 | K11: =SUM(G11/I11) -> 0.84 | L11: =SUM((E11*60)/I11) -> 20.16 | M11: =SUM('Game Results'!L38+'Game Results'!L77) -> 225 | N11: =SUM('Game Results'!M38+'Game Results'!M77) -> 2 | O11: =SUM('Game Results'!N38+'Game Results'!N77) -> 58.8 | P11: =SUM('Game Results'!O38+'Game Results'!O77) -> 18 | Q11: =SUM('Game Results'!P38+'Game Results'!P77) -> 5 | R11: =SUM('Game Results'!Q38+'Game Results'!Q77) -> 0 | S11: =SUM('Game Results'!R38+'Game Results'!R77) -> 0 | T11: =SUM('Game Results'!S38+'Game Results'!S77) -> 1 | ... AD11: =SUM('Game Results'!AC38+'Game Results'!AC77) -> 0
A12: Totals: | C12: =SUM(C8:C11)/4 -> 2 | D12: =SUM(D8:D11)/4 -> 0 | E12: =SUM(E8:E11)/4 -> 58.8 | F12: =SUM(F8:F11) -> 4 | G12: =SUM(G8:G11) -> 983 | H12: =SUM(H8:H11) -> 55 | I12: =SUM(I8:I11) -> 1005 | J12: =SUM(J8:J11) -> -22 | K12: =G12/I12 -> 0.97810945 | L12: =SUM(L8:L11)/4 -> 14.606667 | M12: =SUM(M8:M11) -> 1546 | N12: =SUM(N8:N11) -> 8 | O12: =SUM(O8:O11) -> 235.2 | P12: =SUM(P8:P11) -> 172 | Q12: =SUM(Q8:Q11) -> 26 | R12: =SUM(R8:R11) -> 4 | S12: =SUM(S8:S11) -> 1 | T12: =SUM(T8:T11) -> 8 | ... AD12: =SUM(AD8:AD11) -> 0
A13: Goon Squad | B13: MsWolv3rine | C13: 2 | D13: =SUM('Game Results'!C126+'Game Results'!C178) -> 0 | E13: =SUM('Game Results'!D126+'Game Results'!D178) -> 53.2 | F13: =SUM('Game Results'!E126+'Game Results'!E178) -> 1 | G13: =SUM('Game Results'!F126+'Game Results'!F178) -> 185 | H13: =SUM('Game Results'!G126+'Game Results'!G178) -> 12 | I13: =SUM('Game Results'!H126+'Game Results'!H178) -> 238 | J13: =SUM('Game Results'!I126+'Game Results'!I178) -> -53 | K13: =SUM(G13/I13) -> 0.77731092 | L13: =SUM((E13*60)/I13) -> 13.411765 | M13: =SUM('Game Results'!L126+'Game Results'!L178) -> 276 | N13: =SUM('Game Results'!M126+'Game Results'!M178) -> 2 | O13: =SUM('Game Results'!N126+'Game Results'!N178) -> 53.2 | P13: =SUM('Game Results'!O126+'Game Results'!O178) -> 19 | Q13: =SUM('Game Results'!P126+'Game Results'!P178) -> 3 | R13: =SUM('Game Results'!Q126+'Game Results'!Q178) -> 0 | S13: =SUM('Game Results'!R126+'Game Results'!R178) -> 0 | T13: =SUM('Game Results'!S126+'Game Results'!S178) -> 1 | ... AD13: =SUM('Game Results'!AC126+'Game Results'!AC178) -> 0
A14: Goon Squad | B14: AJ DaJuiceMayne | C14: 2 | D14: =SUM('Game Results'!C127+'Game Results'!C179) -> 0 | E14: =SUM('Game Results'!D127+'Game Results'!D179) -> 53.2 | F14: =SUM('Game Results'!E127+'Game Results'!E179) -> 0 | G14: =SUM('Game Results'!F127+'Game Results'!F179) -> 249 | H14: =SUM('Game Results'!G127+'Game Results'!G179) -> 17 | I14: =SUM('Game Results'!H127+'Game Results'!H179) -> 192 | J14: =SUM('Game Results'!I127+'Game Results'!I179) -> 57 | K14: =SUM(G14/I14) -> 1.296875 | L14: =SUM((E14*60)/I14) -> 16.625 | M14: =SUM('Game Results'!L127+'Game Results'!L179) -> 419 | N14: =SUM('Game Results'!M127+'Game Results'!M179) -> 2 | O14: =SUM('Game Results'!N127+'Game Results'!N179) -> 53.2 | P14: =SUM('Game Results'!O127+'Game Results'!O179) -> 49 | Q14: =SUM('Game Results'!P127+'Game Results'!P179) -> 12 | R14: =SUM('Game Results'!Q127+'Game Results'!Q179) -> 3 | S14: =SUM('Game Results'!R127+'Game Results'!R179) -> 0 | T14: =SUM('Game Results'!S127+'Game Results'!S179) -> 6 | ... AD14: =SUM('Game Results'!AC127+'Game Results'!AC179) -> 0
A15: Goon Squad | B15: MysticalNovice | C15: 2 | D15: =SUM('Game Results'!C128+'Game Results'!C180) -> 0 | E15: =SUM('Game Results'!D128+'Game Results'!D180) -> 53.2 | F15: =SUM('Game Results'!E128+'Game Results'!E180) -> 0 | G15: =SUM('Game Results'!F128+'Game Results'!F180) -> 204 | H15: =SUM('Game Results'!G128+'Game Results'!G180) -> 18 | I15: =SUM('Game Results'!H128+'Game Results'!H180) -> 248 | J15: =SUM('Game Results'!I128+'Game Results'!I180) -> -44 | K15: =SUM(G15/I15) -> 0.82258065 | L15: =SUM((E15*60)/I15) -> 12.870968 | M15: =SUM('Game Results'!L128+'Game Results'!L180) -> 306 | N15: =SUM('Game Results'!M128+'Game Results'!M180) -> 2 | O15: =SUM('Game Results'!N128+'Game Results'!N180) -> 53.2 | P15: =SUM('Game Results'!O128+'Game Results'!O180) -> 32 | Q15: =SUM('Game Results'!P128+'Game Results'!P180) -> 2 | R15: =SUM('Game Results'!Q128+'Game Results'!Q180) -> 0 | S15: =SUM('Game Results'!R128+'Game Results'!R180) -> 0 | T15: =SUM('Game Results'!S128+'Game Results'!S180) -> 0 | ... AD15: =SUM('Game Results'!AC128+'Game Results'!AC180) -> 0
A16: Goon Squad | B16: MuNgO PuNgO | C16: 2 | D16: =SUM('Game Results'!C129+'Game Results'!C181) -> 0 | E16: =SUM('Game Results'!D129+'Game Results'!D181) -> 53.2 | F16: =SUM('Game Results'!E129+'Game Results'!E181) -> 1 | G16: =SUM('Game Results'!F129+'Game Results'!F181) -> 130 | H16: =SUM('Game Results'!G129+'Game Results'!G181) -> 8 | I16: =SUM('Game Results'!H129+'Game Results'!H181) -> 162 | J16: =SUM('Game Results'!I129+'Game Results'!I181) -> -32 | K16: =SUM(G16/I16) -> 0.80246914 | L16: =SUM((E16*60)/I16) -> 19.703704 | M16: =SUM('Game Results'!L129+'Game Results'!L181) -> 198 | N16: =SUM('Game Results'!M129+'Game Results'!M181) -> 2 | O16: =SUM('Game Results'!N129+'Game Results'!N181) -> 53.2 | P16: =SUM('Game Results'!O129+'Game Results'!O181) -> 10 | Q16: =SUM('Game Results'!P129+'Game Results'!P181) -> 2 | R16: =SUM('Game Results'!Q129+'Game Results'!Q181) -> 0 | S16: =SUM('Game Results'!R129+'Game Results'!R181) -> 0 | T16: =SUM('Game Results'!S129+'Game Results'!S181) -> 2 | ... AD16: =SUM('Game Results'!AC129+'Game Results'!AC181) -> 0
A17: Totals: | C17: =SUM(C13:C16)/4 -> 2 | D17: =SUM(D13:D16)/4 -> 0 | E17: =SUM(E13:E16)/4 -> 53.2 | F17: =SUM(F13:F16) -> 2 | G17: =SUM(G13:G16) -> 768 | H17: =SUM(H13:H16) -> 55 | I17: =SUM(I13:I16) -> 840 | J17: =SUM(J13:J16) -> -72 | K17: =G17/I17 -> 0.91428571 | L17: =SUM(L13:L16)/4 -> 15.652859 | M17: =SUM(M13:M16) -> 1199 | N17: =SUM(N13:N16) -> 8 | O17: =SUM(O13:O16) -> 212.8 | P17: =SUM(P13:P16) -> 110 | Q17: =SUM(Q13:Q16) -> 19 | R17: =SUM(R13:R16) -> 3 | S17: =SUM(S13:S16) -> 0 | T17: =SUM(T13:T16) -> 9 | ... AD17: =SUM(AD13:AD16) -> 0
A18: BOGO Margs | B18: TommyWstSide | C18: 5 | D18: =SUM('Game Results'!C9+'Game Results'!C173+'Game Results'!C199+'Game Results'!C238+'Game Results'!C269) -> 3 | E18: =SUM('Game Results'!D9+'Game Results'!D173+'Game Results'!D199+'Game Results'!D238+'Game Results'!D269) -> 169.85 | F18: =SUM('Game Results'!E9+'Game Results'!E173+'Game Results'!E199+'Game Results'!E238+'Game Results'!E269) -> 16 | G18: =SUM('Game Results'!F9+'Game Results'!F173+'Game Results'!F199+'Game Results'!F238+'Game Results'!F269) -> 446 | H18: =SUM('Game Results'!G9+'Game Results'!G173+'Game Results'!G199+'Game Results'!G238+'Game Results'!G269) -> 13 | I18: =SUM('Game Results'!H9+'Game Results'!H173+'Game Results'!H199+'Game Results'!H238+'Game Results'!H269) -> 389 | J18: =SUM('Game Results'!I9+'Game Results'!I173+'Game Results'!I199+'Game Results'!I238+'Game Results'!I269) -> 57 | K18: =SUM(G18/I18) -> 1.1465296 | L18: =SUM((E18*60)/I18) -> 26.197943 | M18: =SUM('Game Results'!L9+'Game Results'!L173+'Game Results'!L199+'Game Results'!L238+'Game Results'!L269) -> 693 | N18: =SUM('Game Results'!M9+'Game Results'!M173+'Game Results'!M199+'Game Results'!M238+'Game Results'!M269) -> 5 | O18: =SUM('Game Results'!N9+'Game Results'!N173+'Game Results'!N199+'Game Results'!N238+'Game Results'!N269) -> 169.85 | P18: =SUM('Game Results'!O9+'Game Results'!O173+'Game Results'!O199+'Game Results'!O238+'Game Results'!O269) -> 30 | Q18: =SUM('Game Results'!P9+'Game Results'!P173+'Game Results'!P199+'Game Results'!P238+'Game Results'!P269) -> 2 | R18: =SUM('Game Results'!Q9+'Game Results'!Q173+'Game Results'!Q199+'Game Results'!Q238+'Game Results'!Q269) -> 0 | S18: =SUM('Game Results'!R9+'Game Results'!R173+'Game Results'!R199+'Game Results'!R238+'Game Results'!R269) -> 0 | T18: =SUM('Game Results'!S9+'Game Results'!S173+'Game Results'!S199+'Game Results'!S238+'Game Results'!S269) -> 10 | ... AD18: =SUM('Game Results'!AC9+'Game Results'!AC173+'Game Results'!AC199+'Game Results'!AC238+'Game Results'!AC269) -> 0
A19: BOGO Margs | B19: Judasey | C19: 5 | D19: =SUM('Game Results'!C10+'Game Results'!C174+'Game Results'!C200+'Game Results'!C239+'Game Results'!C270) -> 3 | E19: =SUM('Game Results'!D10+'Game Results'!D174+'Game Results'!D200+'Game Results'!D239+'Game Results'!D270) -> 169.85 | F19: =SUM('Game Results'!E10+'Game Results'!E174+'Game Results'!E200+'Game Results'!E239+'Game Results'!E270) -> 2 | G19: =SUM('Game Results'!F10+'Game Results'!F174+'Game Results'!F200+'Game Results'!F239+'Game Results'!F270) -> 859 | H19: =SUM('Game Results'!G10+'Game Results'!G174+'Game Results'!G200+'Game Results'!G239+'Game Results'!G270) -> 55 | I19: =SUM('Game Results'!H10+'Game Results'!H174+'Game Results'!H200+'Game Results'!H239+'Game Results'!H270) -> 667 | J19: =SUM('Game Results'!I10+'Game Results'!I174+'Game Results'!I200+'Game Results'!I239+'Game Results'!I270) -> 192 | K19: =SUM(G19/I19) -> 1.2878561 | L19: =SUM((E19*60)/I19) -> 15.278861 | M19: =SUM('Game Results'!L10+'Game Results'!L174+'Game Results'!L200+'Game Results'!L239+'Game Results'!L270) -> 1443 | N19: =SUM('Game Results'!M10+'Game Results'!M174+'Game Results'!M200+'Game Results'!M239+'Game Results'!M270) -> 5 | O19: =SUM('Game Results'!N10+'Game Results'!N174+'Game Results'!N200+'Game Results'!N239+'Game Results'!N270) -> 169.85 | P19: =SUM('Game Results'!O10+'Game Results'!O174+'Game Results'!O200+'Game Results'!O239+'Game Results'!O270) -> 185 | Q19: =SUM('Game Results'!P10+'Game Results'!P174+'Game Results'!P200+'Game Results'!P239+'Game Results'!P270) -> 61 | R19: =SUM('Game Results'!Q10+'Game Results'!Q174+'Game Results'!Q200+'Game Results'!Q239+'Game Results'!Q270) -> 16 | S19: =SUM('Game Results'!R10+'Game Results'!R174+'Game Results'!R200+'Game Results'!R239+'Game Results'!R270) -> 3 | T19: =SUM('Game Results'!S10+'Game Results'!S174+'Game Results'!S200+'Game Results'!S239+'Game Results'!S270) -> 23 | ... AD19: =SUM('Game Results'!AC10+'Game Results'!AC174+'Game Results'!AC200+'Game Results'!AC239+'Game Results'!AC270) -> 0
A20: BOGO Margs | B20: ManCanonPls | C20: 5 | D20: =SUM('Game Results'!C11+'Game Results'!C175+'Game Results'!C201+'Game Results'!C240+'Game Results'!C271) -> 3 | E20: =SUM('Game Results'!D11+'Game Results'!D175+'Game Results'!D201+'Game Results'!D240+'Game Results'!D271) -> 169.85 | F20: =SUM('Game Results'!E11+'Game Results'!E175+'Game Results'!E201+'Game Results'!E240+'Game Results'!E271) -> 2 | G20: =SUM('Game Results'!F11+'Game Results'!F175+'Game Results'!F201+'Game Results'!F240+'Game Results'!F271) -> 629 | H20: =SUM('Game Results'!G11+'Game Results'!G175+'Game Results'!G201+'Game Results'!G240+'Game Results'!G271) -> 32 | I20: =SUM('Game Results'!H11+'Game Results'!H175+'Game Results'!H201+'Game Results'!H240+'Game Results'!H271) -> 642 | J20: =SUM('Game Results'!I11+'Game Results'!I175+'Game Results'!I201+'Game Results'!I240+'Game Results'!I271) -> -13 | K20: =SUM(G20/I20) -> 0.97975078 | L20: =SUM((E20*60)/I20) -> 15.873832 | M20: =SUM('Game Results'!L11+'Game Results'!L175+'Game Results'!L201+'Game Results'!L240+'Game Results'!L271) -> 929 | N20: =SUM('Game Results'!M11+'Game Results'!M175+'Game Results'!M201+'Game Results'!M240+'Game Results'!M271) -> 5 | O20: =SUM('Game Results'!N11+'Game Results'!N175+'Game Results'!N201+'Game Results'!N240+'Game Results'!N271) -> 169.85 | P20: =SUM('Game Results'!O11+'Game Results'!O175+'Game Results'!O201+'Game Results'!O240+'Game Results'!O271) -> 95 | Q20: =SUM('Game Results'!P11+'Game Results'!P175+'Game Results'!P201+'Game Results'!P240+'Game Results'!P271) -> 15 | R20: =SUM('Game Results'!Q11+'Game Results'!Q175+'Game Results'!Q201+'Game Results'!Q240+'Game Results'!Q271) -> 2 | S20: =SUM('Game Results'!R11+'Game Results'!R175+'Game Results'!R201+'Game Results'!R240+'Game Results'!R271) -> 0 | T20: =SUM('Game Results'!S11+'Game Results'!S175+'Game Results'!S201+'Game Results'!S240+'Game Results'!S271) -> 3 | ... AD20: =SUM('Game Results'!AC11+'Game Results'!AC175+'Game Results'!AC201+'Game Results'!AC240+'Game Results'!AC271) -> 0
A21: BOGO Margs | B21: MoldyVolts | C21: 5 | D21: =SUM('Game Results'!C12+'Game Results'!C176+'Game Results'!C202+'Game Results'!C241+'Game Results'!C272) -> 3 | E21: =SUM('Game Results'!D12+'Game Results'!D176+'Game Results'!D202+'Game Results'!D241+'Game Results'!D272) -> 169.85 | F21: =SUM('Game Results'!E12+'Game Results'!E176+'Game Results'!E202+'Game Results'!E241+'Game Results'!E272) -> 2 | G21: =SUM('Game Results'!F12+'Game Results'!F176+'Game Results'!F202+'Game Results'!F241+'Game Results'!F272) -> 651 | H21: =SUM('Game Results'!G12+'Game Results'!G176+'Game Results'!G202+'Game Results'!G241+'Game Results'!G272) -> 52 | I21: =SUM('Game Results'!H12+'Game Results'!H176+'Game Results'!H202+'Game Results'!H241+'Game Results'!H272) -> 657 | J21: =SUM('Game Results'!I12+'Game Results'!I176+'Game Results'!I202+'Game Results'!I241+'Game Results'!I272) -> -6 | K21: =SUM(G21/I21) -> 0.99086758 | L21: =SUM((E21*60)/I21) -> 15.511416 | M21: =SUM('Game Results'!L12+'Game Results'!L176+'Game Results'!L202+'Game Results'!L241+'Game Results'!L272) -> 1055 | N21: =SUM('Game Results'!M12+'Game Results'!M176+'Game Results'!M202+'Game Results'!M241+'Game Results'!M272) -> 5 | O21: =SUM('Game Results'!N12+'Game Results'!N176+'Game Results'!N202+'Game Results'!N241+'Game Results'!N272) -> 169.85 | P21: =SUM('Game Results'!O12+'Game Results'!O176+'Game Results'!O202+'Game Results'!O241+'Game Results'!O272) -> 106 | Q21: =SUM('Game Results'!P12+'Game Results'!P176+'Game Results'!P202+'Game Results'!P241+'Game Results'!P272) -> 19 | R21: =SUM('Game Results'!Q12+'Game Results'!Q176+'Game Results'!Q202+'Game Results'!Q241+'Game Results'!Q272) -> 2 | S21: =SUM('Game Results'!R12+'Game Results'!R176+'Game Results'!R202+'Game Results'!R241+'Game Results'!R272) -> 1 | T21: =SUM('Game Results'!S12+'Game Results'!S176+'Game Results'!S202+'Game Results'!S241+'Game Results'!S272) -> 9 | ... AD21: =SUM('Game Results'!AC12+'Game Results'!AC176+'Game Results'!AC202+'Game Results'!AC241+'Game Results'!AC272) -> 0
A22: Totals: | C22: =SUM(C18:C21)/4 -> 5 | D22: =SUM(D18:D21)/4 -> 3 | E22: =SUM(E18:E21)/4 -> 169.85 | F22: =SUM(F18:F21) -> 22 | G22: =SUM(G18:G21) -> 2585 | H22: =SUM(H18:H21) -> 152 | I22: =SUM(I18:I21) -> 2355 | J22: =SUM(J18:J21) -> 230 | K22: =G22/I22 -> 1.0976645 | L22: =SUM(L18:L21)/4 -> 18.215513 | M22: =SUM(M18:M21) -> 4120 | N22: =SUM(N18:N21) -> 20 | O22: =SUM(O18:O21) -> 679.4 | P22: =SUM(P18:P21) -> 416 | Q22: =SUM(Q18:Q21) -> 97 | R22: =SUM(R18:R21) -> 20 | S22: =SUM(S18:S21) -> 4 | T22: =SUM(T18:T21) -> 45 | ... AD22: =SUM(AD18:AD21) -> 0
A23: Minor Threat | B23: Dat Twinkie | C23: 2 | D23: =SUM('Game Results'!C48+'Game Results'!C152) -> 0 | E23: =SUM('Game Results'!D48+'Game Results'!D152) -> 82.7 | F23: =SUM('Game Results'!E48+'Game Results'!E152) -> 0 | G23: =SUM('Game Results'!F48+'Game Results'!F152) -> 399 | H23: =SUM('Game Results'!G48+'Game Results'!G152) -> 33 | I23: =SUM('Game Results'!H48+'Game Results'!H152) -> 411 | J23: =SUM('Game Results'!I48+'Game Results'!I152) -> -12 | K23: =SUM(G23/I23) -> 0.97080292 | L23: =SUM((E23*60)/I23) -> 12.072993 | M23: =SUM('Game Results'!L48+'Game Results'!L152) -> 634 | N23: =SUM('Game Results'!M48+'Game Results'!M152) -> 2 | O23: =SUM('Game Results'!N48+'Game Results'!N152) -> 82.7 | P23: =SUM('Game Results'!O48+'Game Results'!O152) -> 54 | Q23: =SUM('Game Results'!P48+'Game Results'!P152) -> 20 | R23: =SUM('Game Results'!Q48+'Game Results'!Q152) -> 4 | S23: =SUM('Game Results'!R48+'Game Results'!R152) -> 2 | T23: =SUM('Game Results'!S48+'Game Results'!S152) -> 3 | ... AD23: =SUM('Game Results'!AC48+'Game Results'!AC152) -> 0
A24: Minor Threat | B24: cxrnchip | C24: 2 | D24: =SUM('Game Results'!C49+'Game Results'!C153) -> 0 | E24: =SUM('Game Results'!D49+'Game Results'!D153) -> 86.166667 | F24: =SUM('Game Results'!E49+'Game Results'!E153) -> 0 | G24: =SUM('Game Results'!F49+'Game Results'!F153) -> 339 | H24: =SUM('Game Results'!G49+'Game Results'!G153) -> 26 | I24: =SUM('Game Results'!H49+'Game Results'!H153) -> 271 | J24: =SUM('Game Results'!I49+'Game Results'!I153) -> 68 | K24: =SUM(G24/I24) -> 1.2509225 | L24: =SUM((E24*60)/I24) -> 19.077491 | M24: =SUM('Game Results'!L49+'Game Results'!L153) -> 557 | N24: =SUM('Game Results'!M49+'Game Results'!M153) -> 2 | O24: =SUM('Game Results'!N49+'Game Results'!N153) -> 86.166667 | P24: =SUM('Game Results'!O49+'Game Results'!O153) -> 51 | Q24: =SUM('Game Results'!P49+'Game Results'!P153) -> 6 | R24: =SUM('Game Results'!Q49+'Game Results'!Q153) -> 0 | S24: =SUM('Game Results'!R49+'Game Results'!R153) -> 0 | T24: =SUM('Game Results'!S49+'Game Results'!S153) -> 2 | ... AD24: =SUM('Game Results'!AC49+'Game Results'!AC153) -> 0
A25: Minor Threat | B25: Doerstopper | C25: 2 | D25: =SUM('Game Results'!C50+'Game Results'!C154) -> 0 | E25: =SUM('Game Results'!D50+'Game Results'!D154) -> 85.4 | F25: =SUM('Game Results'!E50+'Game Results'!E154) -> 3 | G25: =SUM('Game Results'!F50+'Game Results'!F154) -> 197 | H25: =SUM('Game Results'!G50+'Game Results'!G154) -> 11 | I25: =SUM('Game Results'!H50+'Game Results'!H154) -> 302 | J25: =SUM('Game Results'!I50+'Game Results'!I154) -> -105 | K25: =SUM(G25/I25) -> 0.65231788 | L25: =SUM((E25*60)/I25) -> 16.966887 | M25: =SUM('Game Results'!L50+'Game Results'!L154) -> 307 | N25: =SUM('Game Results'!M50+'Game Results'!M154) -> 2 | O25: =SUM('Game Results'!N50+'Game Results'!N154) -> 85.4 | P25: =SUM('Game Results'!O50+'Game Results'!O154) -> 20 | Q25: =SUM('Game Results'!P50+'Game Results'!P154) -> 2 | R25: =SUM('Game Results'!Q50+'Game Results'!Q154) -> 0 | S25: =SUM('Game Results'!R50+'Game Results'!R154) -> 0 | T25: =SUM('Game Results'!S50+'Game Results'!S154) -> 1 | ... AD25: =SUM('Game Results'!AC50+'Game Results'!AC154) -> 0
A26: Minor Threat | B26: You heard of us | C26: 2 | D26: =SUM('Game Results'!C51+'Game Results'!C155) -> 0 | E26: =SUM('Game Results'!D51+'Game Results'!D155) -> 83.45 | F26: =SUM('Game Results'!E51+'Game Results'!E155) -> 0 | G26: =SUM('Game Results'!F51+'Game Results'!F155) -> 342 | H26: =SUM('Game Results'!G51+'Game Results'!G155) -> 20 | I26: =SUM('Game Results'!H51+'Game Results'!H155) -> 423 | J26: =SUM('Game Results'!I51+'Game Results'!I155) -> -81 | K26: =SUM(G26/I26) -> 0.80851064 | L26: =SUM((E26*60)/I26) -> 11.836879 | M26: =SUM('Game Results'!L51+'Game Results'!L155) -> 528 | N26: =SUM('Game Results'!M51+'Game Results'!M155) -> 2 | O26: =SUM('Game Results'!N51+'Game Results'!N155) -> 83.45 | P26: =SUM('Game Results'!O51+'Game Results'!O155) -> 52 | Q26: =SUM('Game Results'!P51+'Game Results'!P155) -> 9 | R26: =SUM('Game Results'!Q51+'Game Results'!Q155) -> 1 | S26: =SUM('Game Results'!R51+'Game Results'!R155) -> 0 | T26: =SUM('Game Results'!S51+'Game Results'!S155) -> 1 | ... AD26: =SUM('Game Results'!AC51+'Game Results'!AC155) -> 0
A27: Totals: | C27: =SUM(C23:C26)/4 -> 2 | D27: =SUM(D23:D26)/4 -> 0 | E27: =SUM(E23:E26)/4 -> 84.429167 | F27: =SUM(F23:F26) -> 3 | G27: =SUM(G23:G26) -> 1277 | H27: =SUM(H23:H26) -> 90 | I27: =SUM(I23:I26) -> 1407 | J27: =SUM(J23:J26) -> -130 | K27: =G27/I27 -> 0.90760483 | L27: =SUM(L23:L26)/4 -> 14.988563 | M27: =SUM(M23:M26) -> 2026 | N27: =SUM(N23:N26) -> 8 | O27: =SUM(O23:O26) -> 337.71667 | P27: =SUM(P23:P26) -> 177 | Q27: =SUM(Q23:Q26) -> 37 | R27: =SUM(R23:R26) -> 5 | S27: =SUM(S23:S26) -> 2 | T27: =SUM(T23:T26) -> 7 | ... AD27: =SUM(AD23:AD26) -> 0
A28: Eurostars | B28: CaptainSev004 | C28: 4 | D28: =SUM('Game Results'!C17+'Game Results'!C100+'Game Results'!C147+'Game Results'!C191) -> 2 | E28: =SUM('Game Results'!D17+'Game Results'!D100+'Game Results'!D147+'Game Results'!D191) -> 206.9 | F28: =SUM('Game Results'!E17+'Game Results'!E100+'Game Results'!E147+'Game Results'!E191) -> 2 | G28: =SUM('Game Results'!F17+'Game Results'!F100+'Game Results'!F147+'Game Results'!F191) -> 787 | H28: =SUM('Game Results'!G17+'Game Results'!G100+'Game Results'!G147+'Game Results'!G191) -> 34 | I28: =SUM('Game Results'!H17+'Game Results'!H100+'Game Results'!H147+'Game Results'!H191) -> 842 | J28: =SUM('Game Results'!I17+'Game Results'!I100+'Game Results'!I147+'Game Results'!I191) -> -55 | K28: =SUM(G28/I28) -> 0.93467933 | L28: =SUM((E28*60)/I28) -> 14.743468 | M28: =SUM('Game Results'!L17+'Game Results'!L100+'Game Results'!L147+'Game Results'!L191) -> 1137 | N28: =SUM('Game Results'!M17+'Game Results'!M100+'Game Results'!M147+'Game Results'!M191) -> 4 | O28: =SUM('Game Results'!N17+'Game Results'!N100+'Game Results'!N147+'Game Results'!N191) -> 206.9 | P28: =SUM('Game Results'!O17+'Game Results'!O100+'Game Results'!O147+'Game Results'!O191) -> 96 | Q28: =SUM('Game Results'!P17+'Game Results'!P100+'Game Results'!P147+'Game Results'!P191) -> 16 | R28: =SUM('Game Results'!Q17+'Game Results'!Q100+'Game Results'!Q147+'Game Results'!Q191) -> 3 | S28: =SUM('Game Results'!R17+'Game Results'!R100+'Game Results'!R147+'Game Results'!R191) -> 0 | T28: =SUM('Game Results'!S17+'Game Results'!S100+'Game Results'!S147+'Game Results'!S191) -> 5 | ... AD28: =SUM('Game Results'!AC17+'Game Results'!AC100+'Game Results'!AC147+'Game Results'!AC191) -> 0
A29: Eurostars | B29: oDhmon | C29: 4 | D29: =SUM('Game Results'!C18+'Game Results'!C101+'Game Results'!C148+'Game Results'!C192) -> 2 | E29: =SUM('Game Results'!D18+'Game Results'!D101+'Game Results'!D148+'Game Results'!D192) -> 206.9 | F29: =SUM('Game Results'!E18+'Game Results'!E101+'Game Results'!E148+'Game Results'!E192) -> 4 | G29: =SUM('Game Results'!F18+'Game Results'!F101+'Game Results'!F148+'Game Results'!F192) -> 938 | H29: =SUM('Game Results'!G18+'Game Results'!G101+'Game Results'!G148+'Game Results'!G192) -> 65 | I29: =SUM('Game Results'!H18+'Game Results'!H101+'Game Results'!H148+'Game Results'!H192) -> 765 | J29: =SUM('Game Results'!I18+'Game Results'!I101+'Game Results'!I148+'Game Results'!I192) -> 173 | K29: =SUM(G29/I29) -> 1.2261438 | L29: =SUM((E29*60)/I29) -> 16.227451 | M29: =SUM('Game Results'!L18+'Game Results'!L101+'Game Results'!L148+'Game Results'!L192) -> 1511 | N29: =SUM('Game Results'!M18+'Game Results'!M101+'Game Results'!M148+'Game Results'!M192) -> 4 | O29: =SUM('Game Results'!N18+'Game Results'!N101+'Game Results'!N148+'Game Results'!N192) -> 206.9 | P29: =SUM('Game Results'!O18+'Game Results'!O101+'Game Results'!O148+'Game Results'!O192) -> 152 | Q29: =SUM('Game Results'!P18+'Game Results'!P101+'Game Results'!P148+'Game Results'!P192) -> 35 | R29: =SUM('Game Results'!Q18+'Game Results'!Q101+'Game Results'!Q148+'Game Results'!Q192) -> 8 | S29: =SUM('Game Results'!R18+'Game Results'!R101+'Game Results'!R148+'Game Results'!R192) -> 0 | T29: =SUM('Game Results'!S18+'Game Results'!S101+'Game Results'!S148+'Game Results'!S192) -> 23 | ... AD29: =SUM('Game Results'!AC18+'Game Results'!AC101+'Game Results'!AC148+'Game Results'!AC192) -> 0
A30: Eurostars | B30: SlMQ | C30: 4 | D30: =SUM('Game Results'!C19+'Game Results'!C102+'Game Results'!C149+'Game Results'!C193) -> 2 | E30: =SUM('Game Results'!D19+'Game Results'!D102+'Game Results'!D149+'Game Results'!D193) -> 206.9 | F30: =SUM('Game Results'!E19+'Game Results'!E102+'Game Results'!E149+'Game Results'!E193) -> 2 | G30: =SUM('Game Results'!F19+'Game Results'!F102+'Game Results'!F149+'Game Results'!F193) -> 756 | H30: =SUM('Game Results'!G19+'Game Results'!G102+'Game Results'!G149+'Game Results'!G193) -> 68 | I30: =SUM('Game Results'!H19+'Game Results'!H102+'Game Results'!H149+'Game Results'!H193) -> 793 | J30: =SUM('Game Results'!I19+'Game Results'!I102+'Game Results'!I149+'Game Results'!I193) -> -37 | K30: =SUM(G30/I30) -> 0.95334174 | L30: =SUM((E30*60)/I30) -> 15.654477 | M30: =SUM('Game Results'!L19+'Game Results'!L102+'Game Results'!L149+'Game Results'!L193) -> 1149 | N30: =SUM('Game Results'!M19+'Game Results'!M102+'Game Results'!M149+'Game Results'!M193) -> 4 | O30: =SUM('Game Results'!N19+'Game Results'!N102+'Game Results'!N149+'Game Results'!N193) -> 206.9 | P30: =SUM('Game Results'!O19+'Game Results'!O102+'Game Results'!O149+'Game Results'!O193) -> 98 | Q30: =SUM('Game Results'!P19+'Game Results'!P102+'Game Results'!P149+'Game Results'!P193) -> 13 | R30: =SUM('Game Results'!Q19+'Game Results'!Q102+'Game Results'!Q149+'Game Results'!Q193) -> 2 | S30: =SUM('Game Results'!R19+'Game Results'!R102+'Game Results'!R149+'Game Results'!R193) -> 2 | T30: =SUM('Game Results'!S19+'Game Results'!S102+'Game Results'!S149+'Game Results'!S193) -> 6 | ... AD30: =SUM('Game Results'!AC19+'Game Results'!AC102+'Game Results'!AC149+'Game Results'!AC193) -> 0
A31: Eurostars | B31: AwareMosquito | C31: 4 | D31: =SUM('Game Results'!C20+'Game Results'!C103+'Game Results'!C150+'Game Results'!C194) -> 2 | E31: =SUM('Game Results'!D20+'Game Results'!D103+'Game Results'!D150+'Game Results'!D194) -> 206.9 | F31: =SUM('Game Results'!E20+'Game Results'!E103+'Game Results'!E150+'Game Results'!E194) -> 7 | G31: =SUM('Game Results'!F20+'Game Results'!F103+'Game Results'!F150+'Game Results'!F194) -> 593 | H31: =SUM('Game Results'!G20+'Game Results'!G103+'Game Results'!G150+'Game Results'!G194) -> 8 | I31: =SUM('Game Results'!H20+'Game Results'!H103+'Game Results'!H150+'Game Results'!H194) -> 617 | J31: =SUM('Game Results'!I20+'Game Results'!I103+'Game Results'!I150+'Game Results'!I194) -> -24 | K31: =SUM(G31/I31) -> 0.96110211 | L31: =SUM((E31*60)/I31) -> 20.119935 | M31: =SUM('Game Results'!L20+'Game Results'!L103+'Game Results'!L150+'Game Results'!L194) -> 813 | N31: =SUM('Game Results'!M20+'Game Results'!M103+'Game Results'!M150+'Game Results'!M194) -> 4 | O31: =SUM('Game Results'!N20+'Game Results'!N103+'Game Results'!N150+'Game Results'!N194) -> 206.9 | P31: =SUM('Game Results'!O20+'Game Results'!O103+'Game Results'!O150+'Game Results'!O194) -> 54 | Q31: =SUM('Game Results'!P20+'Game Results'!P103+'Game Results'!P150+'Game Results'!P194) -> 6 | R31: =SUM('Game Results'!Q20+'Game Results'!Q103+'Game Results'!Q150+'Game Results'!Q194) -> 1 | S31: =SUM('Game Results'!R20+'Game Results'!R103+'Game Results'!R150+'Game Results'!R194) -> 1 | T31: =SUM('Game Results'!S20+'Game Results'!S103+'Game Results'!S150+'Game Results'!S194) -> 4 | ... AD31: =SUM('Game Results'!AC20+'Game Results'!AC103+'Game Results'!AC150+'Game Results'!AC194) -> 0
A32: Totals: | C32: =SUM(C28:C31)/4 -> 4 | D32: =SUM(D28:D31)/4 -> 2 | E32: =SUM(E28:E31)/4 -> 206.9 | F32: =SUM(F28:F31) -> 15 | G32: =SUM(G28:G31) -> 3074 | H32: =SUM(H28:H31) -> 175 | I32: =SUM(I28:I31) -> 3017 | J32: =SUM(J28:J31) -> 57 | K32: =G32/I32 -> 1.0188929 | L32: =SUM(L28:L31)/4 -> 16.686333 | M32: =SUM(M28:M31) -> 4610 | N32: =SUM(N28:N31) -> 16 | O32: =SUM(O28:O31) -> 827.6 | P32: =SUM(P28:P31) -> 400 | Q32: =SUM(Q28:Q31) -> 70 | R32: =SUM(R28:R31) -> 14 | S32: =SUM(S28:S31) -> 3 | T32: =SUM(T28:T31) -> 38 | ... AD32: =SUM(AD28:AD31) -> 0
A33: Spam Folder | B33: ixjaga | C33: 8 | D33: =SUM('Game Results'!C4+'Game Results'!C87+'Game Results'!C134+'Game Results'!C186+'Game Results'!C251+'Game Results'!C264+'Game Results'!C290+'Game Results'!C308) -> 6 | E33: =SUM('Game Results'!D4+'Game Results'!D87+'Game Results'!D134+'Game Results'!D186+'Game Results'!D251+'Game Results'!D264+'Game Results'!D290+'Game Results'!D308) -> 282 | F33: =SUM('Game Results'!E4+'Game Results'!E87+'Game Results'!E134+'Game Results'!E186+'Game Results'!E251+'Game Results'!E264+'Game Results'!E290+'Game Results'!E308) -> 3 | G33: =SUM('Game Results'!F4+'Game Results'!F87+'Game Results'!F134+'Game Results'!F186+'Game Results'!F251+'Game Results'!F264+'Game Results'!F290+'Game Results'!F308) -> 1128 | H33: =SUM('Game Results'!G4+'Game Results'!G87+'Game Results'!G134+'Game Results'!G186+'Game Results'!G251+'Game Results'!G264+'Game Results'!G290+'Game Results'!G308) -> 83 | I33: =SUM('Game Results'!H4+'Game Results'!H87+'Game Results'!H134+'Game Results'!H186+'Game Results'!H251+'Game Results'!H264+'Game Results'!H290+'Game Results'!H308) -> 1144 | J33: =SUM('Game Results'!I4+'Game Results'!I87+'Game Results'!I134+'Game Results'!I186+'Game Results'!I251+'Game Results'!I264+'Game Results'!I290+'Game Results'!I308) -> -16 | K33: =SUM(G33/I33) -> 0.98601399 | L33: =SUM((E33*60)/I33) -> 14.79021 | M33: =SUM('Game Results'!L4+'Game Results'!L87+'Game Results'!L134+'Game Results'!L186+'Game Results'!L251+'Game Results'!L264+'Game Results'!L290+'Game Results'!L308) -> 1777 | N33: =SUM('Game Results'!M4+'Game Results'!M87+'Game Results'!M134+'Game Results'!M186+'Game Results'!M251+'Game Results'!M264+'Game Results'!M290+'Game Results'!M308) -> 8 | O33: =SUM('Game Results'!N4+'Game Results'!N87+'Game Results'!N134+'Game Results'!N186+'Game Results'!N251+'Game Results'!N264+'Game Results'!N290+'Game Results'!N308) -> 282 | P33: =SUM('Game Results'!O4+'Game Results'!O87+'Game Results'!O134+'Game Results'!O186+'Game Results'!O251+'Game Results'!O264+'Game Results'!O290+'Game Results'!O308) -> 160 | Q33: =SUM('Game Results'!P4+'Game Results'!P87+'Game Results'!P134+'Game Results'!P186+'Game Results'!P251+'Game Results'!P264+'Game Results'!P290+'Game Results'!P308) -> 16 | R33: =SUM('Game Results'!Q4+'Game Results'!Q87+'Game Results'!Q134+'Game Results'!Q186+'Game Results'!Q251+'Game Results'!Q264+'Game Results'!Q290+'Game Results'!Q308) -> 1 | S33: =SUM('Game Results'!R4+'Game Results'!R87+'Game Results'!R134+'Game Results'!R186+'Game Results'!R251+'Game Results'!R264+'Game Results'!R290+'Game Results'!R308) -> 1 | T33: =SUM('Game Results'!S4+'Game Results'!S87+'Game Results'!S134+'Game Results'!S186+'Game Results'!S251+'Game Results'!S264+'Game Results'!S290+'Game Results'!S308) -> 13 | ... AD33: =SUM('Game Results'!AC4+'Game Results'!AC87+'Game Results'!AC134+'Game Results'!AC186+'Game Results'!AC251+'Game Results'!AC264+'Game Results'!AC290+'Game Results'!AC308) -> 0
A34: Spam Folder | B34: Icey Tanker | C34: 8 | D34: =SUM('Game Results'!C5+'Game Results'!C88+'Game Results'!C135+'Game Results'!C187+'Game Results'!C252+'Game Results'!C265+'Game Results'!C291+'Game Results'!C309) -> 6 | E34: =SUM('Game Results'!D5+'Game Results'!D88+'Game Results'!D135+'Game Results'!D187+'Game Results'!D252+'Game Results'!D265+'Game Results'!D291+'Game Results'!D309) -> 282 | F34: =SUM('Game Results'!E5+'Game Results'!E88+'Game Results'!E135+'Game Results'!E187+'Game Results'!E252+'Game Results'!E265+'Game Results'!E291+'Game Results'!E309) -> 9 | G34: =SUM('Game Results'!F5+'Game Results'!F88+'Game Results'!F135+'Game Results'!F187+'Game Results'!F252+'Game Results'!F265+'Game Results'!F291+'Game Results'!F309) -> 1227 | H34: =SUM('Game Results'!G5+'Game Results'!G88+'Game Results'!G135+'Game Results'!G187+'Game Results'!G252+'Game Results'!G265+'Game Results'!G291+'Game Results'!G309) -> 65 | I34: =SUM('Game Results'!H5+'Game Results'!H88+'Game Results'!H135+'Game Results'!H187+'Game Results'!H252+'Game Results'!H265+'Game Results'!H291+'Game Results'!H309) -> 928 | J34: =SUM('Game Results'!I5+'Game Results'!I88+'Game Results'!I135+'Game Results'!I187+'Game Results'!I252+'Game Results'!I265+'Game Results'!I291+'Game Results'!I309) -> 299 | K34: =SUM(G34/I34) -> 1.3221983 | L34: =SUM((E34*60)/I34) -> 18.232759 | M34: =SUM('Game Results'!L5+'Game Results'!L88+'Game Results'!L135+'Game Results'!L187+'Game Results'!L252+'Game Results'!L265+'Game Results'!L291+'Game Results'!L309) -> 2057 | N34: =SUM('Game Results'!M5+'Game Results'!M88+'Game Results'!M135+'Game Results'!M187+'Game Results'!M252+'Game Results'!M265+'Game Results'!M291+'Game Results'!M309) -> 8 | O34: =SUM('Game Results'!N5+'Game Results'!N88+'Game Results'!N135+'Game Results'!N187+'Game Results'!N252+'Game Results'!N265+'Game Results'!N291+'Game Results'!N309) -> 282 | P34: =SUM('Game Results'!O5+'Game Results'!O88+'Game Results'!O135+'Game Results'!O187+'Game Results'!O252+'Game Results'!O265+'Game Results'!O291+'Game Results'!O309) -> 223 | Q34: =SUM('Game Results'!P5+'Game Results'!P88+'Game Results'!P135+'Game Results'!P187+'Game Results'!P252+'Game Results'!P265+'Game Results'!P291+'Game Results'!P309) -> 65 | R34: =SUM('Game Results'!Q5+'Game Results'!Q88+'Game Results'!Q135+'Game Results'!Q187+'Game Results'!Q252+'Game Results'!Q265+'Game Results'!Q291+'Game Results'!Q309) -> 16 | S34: =SUM('Game Results'!R5+'Game Results'!R88+'Game Results'!R135+'Game Results'!R187+'Game Results'!R252+'Game Results'!R265+'Game Results'!R291+'Game Results'!R309) -> 4 | T34: =SUM('Game Results'!S5+'Game Results'!S88+'Game Results'!S135+'Game Results'!S187+'Game Results'!S252+'Game Results'!S265+'Game Results'!S291+'Game Results'!S309) -> 33 | ... AD34: =SUM('Game Results'!AC5+'Game Results'!AC88+'Game Results'!AC135+'Game Results'!AC187+'Game Results'!AC252+'Game Results'!AC265+'Game Results'!AC291+'Game Results'!AC309) -> 0
A35: Spam Folder | B35: Grunt Padre | C35: 8 | D35: =SUM('Game Results'!C6+'Game Results'!C89+'Game Results'!C136+'Game Results'!C188+'Game Results'!C253+'Game Results'!C266+'Game Results'!C292+'Game Results'!C310) -> 6 | E35: =SUM('Game Results'!D6+'Game Results'!D89+'Game Results'!D136+'Game Results'!D188+'Game Results'!D253+'Game Results'!D266+'Game Results'!D292+'Game Results'!D310) -> 282 | F35: =SUM('Game Results'!E6+'Game Results'!E89+'Game Results'!E136+'Game Results'!E188+'Game Results'!E253+'Game Results'!E266+'Game Results'!E292+'Game Results'!E310) -> 2 | G35: =SUM('Game Results'!F6+'Game Results'!F89+'Game Results'!F136+'Game Results'!F188+'Game Results'!F253+'Game Results'!F266+'Game Results'!F292+'Game Results'!F310) -> 1096 | H35: =SUM('Game Results'!G6+'Game Results'!G89+'Game Results'!G136+'Game Results'!G188+'Game Results'!G253+'Game Results'!G266+'Game Results'!G292+'Game Results'!G310) -> 77 | I35: =SUM('Game Results'!H6+'Game Results'!H89+'Game Results'!H136+'Game Results'!H188+'Game Results'!H253+'Game Results'!H266+'Game Results'!H292+'Game Results'!H310) -> 1360 | J35: =SUM('Game Results'!I6+'Game Results'!I89+'Game Results'!I136+'Game Results'!I188+'Game Results'!I253+'Game Results'!I266+'Game Results'!I292+'Game Results'!I310) -> -264 | K35: =SUM(G35/I35) -> 0.80588235 | L35: =SUM((E35*60)/I35) -> 12.441176 | M35: =SUM('Game Results'!L6+'Game Results'!L89+'Game Results'!L136+'Game Results'!L188+'Game Results'!L253+'Game Results'!L266+'Game Results'!L292+'Game Results'!L310) -> 1732 | N35: =SUM('Game Results'!M6+'Game Results'!M89+'Game Results'!M136+'Game Results'!M188+'Game Results'!M253+'Game Results'!M266+'Game Results'!M292+'Game Results'!M310) -> 8 | O35: =SUM('Game Results'!N6+'Game Results'!N89+'Game Results'!N136+'Game Results'!N188+'Game Results'!N253+'Game Results'!N266+'Game Results'!N292+'Game Results'!N310) -> 282 | P35: =SUM('Game Results'!O6+'Game Results'!O89+'Game Results'!O136+'Game Results'!O188+'Game Results'!O253+'Game Results'!O266+'Game Results'!O292+'Game Results'!O310) -> 185 | Q35: =SUM('Game Results'!P6+'Game Results'!P89+'Game Results'!P136+'Game Results'!P188+'Game Results'!P253+'Game Results'!P266+'Game Results'!P292+'Game Results'!P310) -> 35 | R35: =SUM('Game Results'!Q6+'Game Results'!Q89+'Game Results'!Q136+'Game Results'!Q188+'Game Results'!Q253+'Game Results'!Q266+'Game Results'!Q292+'Game Results'!Q310) -> 8 | S35: =SUM('Game Results'!R6+'Game Results'!R89+'Game Results'!R136+'Game Results'!R188+'Game Results'!R253+'Game Results'!R266+'Game Results'!R292+'Game Results'!R310) -> 2 | T35: =SUM('Game Results'!S6+'Game Results'!S89+'Game Results'!S136+'Game Results'!S188+'Game Results'!S253+'Game Results'!S266+'Game Results'!S292+'Game Results'!S310) -> 16 | ... AD35: =SUM('Game Results'!AC6+'Game Results'!AC89+'Game Results'!AC136+'Game Results'!AC188+'Game Results'!AC253+'Game Results'!AC266+'Game Results'!AC292+'Game Results'!AC310) -> 0
A36: Spam Folder | B36: The Scet | C36: 8 | D36: =SUM('Game Results'!C7+'Game Results'!C90+'Game Results'!C137+'Game Results'!C189+'Game Results'!C254+'Game Results'!C267+'Game Results'!C293+'Game Results'!C311) -> 6 | E36: =SUM('Game Results'!D7+'Game Results'!D90+'Game Results'!D137+'Game Results'!D189+'Game Results'!D254+'Game Results'!D267+'Game Results'!D293+'Game Results'!D311) -> 282 | F36: =SUM('Game Results'!E7+'Game Results'!E90+'Game Results'!E137+'Game Results'!E189+'Game Results'!E254+'Game Results'!E267+'Game Results'!E293+'Game Results'!E311) -> 19 | G36: =SUM('Game Results'!F7+'Game Results'!F90+'Game Results'!F137+'Game Results'!F189+'Game Results'!F254+'Game Results'!F267+'Game Results'!F293+'Game Results'!F311) -> 608 | H36: =SUM('Game Results'!G7+'Game Results'!G90+'Game Results'!G137+'Game Results'!G189+'Game Results'!G254+'Game Results'!G267+'Game Results'!G293+'Game Results'!G311) -> 18 | I36: =SUM('Game Results'!H7+'Game Results'!H90+'Game Results'!H137+'Game Results'!H189+'Game Results'!H254+'Game Results'!H267+'Game Results'!H293+'Game Results'!H311) -> 886 | J36: =SUM('Game Results'!I7+'Game Results'!I90+'Game Results'!I137+'Game Results'!I189+'Game Results'!I254+'Game Results'!I267+'Game Results'!I293+'Game Results'!I311) -> -278 | K36: =SUM(G36/I36) -> 0.68623025 | L36: =SUM((E36*60)/I36) -> 19.097065 | M36: =SUM('Game Results'!L7+'Game Results'!L90+'Game Results'!L137+'Game Results'!L189+'Game Results'!L254+'Game Results'!L267+'Game Results'!L293+'Game Results'!L311) -> 862 | N36: =SUM('Game Results'!M7+'Game Results'!M90+'Game Results'!M137+'Game Results'!M189+'Game Results'!M254+'Game Results'!M267+'Game Results'!M293+'Game Results'!M311) -> 8 | O36: =SUM('Game Results'!N7+'Game Results'!N90+'Game Results'!N137+'Game Results'!N189+'Game Results'!N254+'Game Results'!N267+'Game Results'!N293+'Game Results'!N311) -> 282 | P36: =SUM('Game Results'!O7+'Game Results'!O90+'Game Results'!O137+'Game Results'!O189+'Game Results'!O254+'Game Results'!O267+'Game Results'!O293+'Game Results'!O311) -> 59 | Q36: =SUM('Game Results'!P7+'Game Results'!P90+'Game Results'!P137+'Game Results'!P189+'Game Results'!P254+'Game Results'!P267+'Game Results'!P293+'Game Results'!P311) -> 8 | R36: =SUM('Game Results'!Q7+'Game Results'!Q90+'Game Results'!Q137+'Game Results'!Q189+'Game Results'!Q254+'Game Results'!Q267+'Game Results'!Q293+'Game Results'!Q311) -> 0 | S36: =SUM('Game Results'!R7+'Game Results'!R90+'Game Results'!R137+'Game Results'!R189+'Game Results'!R254+'Game Results'!R267+'Game Results'!R293+'Game Results'!R311) -> 0 | T36: =SUM('Game Results'!S7+'Game Results'!S90+'Game Results'!S137+'Game Results'!S189+'Game Results'!S254+'Game Results'!S267+'Game Results'!S293+'Game Results'!S311) -> 0 | ... AD36: =SUM('Game Results'!AC7+'Game Results'!AC90+'Game Results'!AC137+'Game Results'!AC189+'Game Results'!AC254+'Game Results'!AC267+'Game Results'!AC293+'Game Results'!AC311) -> 0
A37: Totals: | C37: =SUM(C33:C36)/4 -> 8 | D37: =SUM(D33:D36)/4 -> 6 | E37: =SUM(E33:E36)/4 -> 282 | F37: =SUM(F33:F36) -> 33 | G37: =SUM(G33:G36) -> 4059 | H37: =SUM(H33:H36) -> 243 | I37: =SUM(I33:I36) -> 4318 | J37: =SUM(J33:J36) -> -259 | K37: =G37/I37 -> 0.94001853 | L37: =SUM(L33:L36)/4 -> 16.140303 | M37: =SUM(M33:M36) -> 6428 | N37: =SUM(N33:N36) -> 32 | O37: =SUM(O33:O36) -> 1128 | P37: =SUM(P33:P36) -> 627 | Q37: =SUM(Q33:Q36) -> 124 | R37: =SUM(R33:R36) -> 25 | S37: =SUM(S33:S36) -> 7 | T37: =SUM(T33:T36) -> 62 | ... AD37: =SUM(AD33:AD36) -> 0
A38: Like Clockwork | B38: yLuxe | C38: 2 | D38: =SUM('Game Results'!C61+'Game Results'!C139) -> 0 | E38: =SUM('Game Results'!D61+'Game Results'!D139) -> 39.4 | F38: =SUM('Game Results'!E61+'Game Results'!E139) -> 4 | G38: =SUM('Game Results'!F61+'Game Results'!F139) -> 159 | H38: =SUM('Game Results'!G61+'Game Results'!G139) -> 5 | I38: =SUM('Game Results'!H61+'Game Results'!H139) -> 161 | J38: =SUM('Game Results'!I61+'Game Results'!I139) -> -2 | K38: =SUM(G38/I38) -> 0.98757764 | L38: =SUM((E38*60)/I38) -> 14.68323 | M38: =SUM('Game Results'!L61+'Game Results'!L139) -> 264 | N38: =SUM('Game Results'!M61+'Game Results'!M139) -> 2 | O38: =SUM('Game Results'!N61+'Game Results'!N139) -> 39.4 | P38: =SUM('Game Results'!O61+'Game Results'!O139) -> 27 | Q38: =SUM('Game Results'!P61+'Game Results'!P139) -> 5 | R38: =SUM('Game Results'!Q61+'Game Results'!Q139) -> 1 | S38: =SUM('Game Results'!R61+'Game Results'!R139) -> 1 | T38: =SUM('Game Results'!S61+'Game Results'!S139) -> 3 | ... AD38: =SUM('Game Results'!AC61+'Game Results'!AC139) -> 0
A39: Like Clockwork | B39: Fanciest Pants | C39: 2 | D39: =SUM('Game Results'!C62+'Game Results'!C140) -> 0 | E39: =SUM('Game Results'!D62+'Game Results'!D140) -> 39.4 | F39: =SUM('Game Results'!E62+'Game Results'!E140) -> 0 | G39: =SUM('Game Results'!F62+'Game Results'!F140) -> 184 | H39: =SUM('Game Results'!G62+'Game Results'!G140) -> 19 | I39: =SUM('Game Results'!H62+'Game Results'!H140) -> 173 | J39: =SUM('Game Results'!I62+'Game Results'!I140) -> 11 | K39: =SUM(G39/I39) -> 1.0635838 | L39: =SUM((E39*60)/I39) -> 13.66474 | M39: =SUM('Game Results'!L62+'Game Results'!L140) -> 314 | N39: =SUM('Game Results'!M62+'Game Results'!M140) -> 2 | O39: =SUM('Game Results'!N62+'Game Results'!N140) -> 39.4 | P39: =SUM('Game Results'!O62+'Game Results'!O140) -> 34 | Q39: =SUM('Game Results'!P62+'Game Results'!P140) -> 5 | R39: =SUM('Game Results'!Q62+'Game Results'!Q140) -> 2 | S39: =SUM('Game Results'!R62+'Game Results'!R140) -> 1 | T39: =SUM('Game Results'!S62+'Game Results'!S140) -> 4 | ... AD39: =SUM('Game Results'!AC62+'Game Results'!AC140) -> 0
A40: Like Clockwork | B40: mstell96 | C40: 2 | D40: =SUM('Game Results'!C63+'Game Results'!C141) -> 0 | E40: =SUM('Game Results'!D63+'Game Results'!D141) -> 39.4 | F40: =SUM('Game Results'!E63+'Game Results'!E141) -> 1 | G40: =SUM('Game Results'!F63+'Game Results'!F141) -> 131 | H40: =SUM('Game Results'!G63+'Game Results'!G141) -> 16 | I40: =SUM('Game Results'!H63+'Game Results'!H141) -> 162 | J40: =SUM('Game Results'!I63+'Game Results'!I141) -> -31 | K40: =SUM(G40/I40) -> 0.80864198 | L40: =SUM((E40*60)/I40) -> 14.592593 | M40: =SUM('Game Results'!L63+'Game Results'!L141) -> 213 | N40: =SUM('Game Results'!M63+'Game Results'!M141) -> 2 | O40: =SUM('Game Results'!N63+'Game Results'!N141) -> 39.4 | P40: =SUM('Game Results'!O63+'Game Results'!O141) -> 13 | Q40: =SUM('Game Results'!P63+'Game Results'!P141) -> 1 | R40: =SUM('Game Results'!Q63+'Game Results'!Q141) -> 1 | S40: =SUM('Game Results'!R63+'Game Results'!R141) -> 0 | T40: =SUM('Game Results'!S63+'Game Results'!S141) -> 2 | ... AD40: =SUM('Game Results'!AC63+'Game Results'!AC141) -> 0
...

Sheet Player Leaderboards
C1: Statistics for the Halo Reach Event of DJBluePDX's Grifball Summer Series presented by Dreamhack and powered by PlayGrifball.com
A2: Team | B2: Player | C2: Games | D2: Wins | E2: Minutes | F2: Score | G2: Kills | H2: Assists | I2: Deaths | J2: Spread | K2: K/D Ratio | L2: Average Life | M2: Medals | N2: Medals Recorded? | O2: Minutes | P2: Double Kill | Q2: Triple Kill | R2: Overkill | S2: Killtacular | T2: Killing Spree | U2: Killing Frenzy | V2: Sword Spree | W2: Extermination | X2: Running Riot | Y2: Rampage | Z2: Killtrocity | AA2: Killmanjaro | AB2: Killpocalypse | AC2: Killtastrophe | AD2: Killionaire | AE2: Rampage | AF2: Killtrocity | AG2: Killmanjaro | AH2: Killpocalypse | AI2: Killtastrophe | AJ2: Killionaire
A3: ='Team Statistics'!A34 -> Spam Folder | B3: ='Team Statistics'!B34 -> Icey Tanker | C3: ='Team Statistics'!C34 -> 8 | D3: ='Team Statistics'!D34 -> 6 | E3: ='Team Statistics'!E34 -> 282 | F3: ='Team Statistics'!F34 -> 9 | G3: ='Team Statistics'!G34 -> 1227 | H3: ='Team Statistics'!H34 -> 65 | ... AD3: ='Team Statistics'!AD34 -> 0 | AE3: =#REF! -> #REF! | AF3: =#REF! -> #REF! | AG3: =#REF! -> #REF! | AH3: =#REF! -> #REF! | AI3: =#REF! -> #REF! | AJ3: =#REF! -> #REF!
A4: ='Team Statistics'!A19 -> BOGO Margs | B4: ='Team Statistics'!B19 -> Judasey | C4: ='Team Statistics'!C19 -> 5 | D4: ='Team Statistics'!D19 -> 3 | E4: ='Team Statistics'!E19 -> 169.85 | F4: ='Team Statistics'!F19 -> 2 | G4: ='Team Statistics'!G19 -> 859 | H4: ='Team Statistics'!H19 -> 55 | ... AD4: ='Team Statistics'!AD19 -> 0 | AE4: =#REF! -> #REF! | AF4: =#REF! -> #REF! | AG4: =#REF! -> #REF! | AH4: =#REF! -> #REF! | AI4: =#REF! -> #REF! | AJ4: =#REF! -> #REF!
A5: ='Team Statistics'!A35 -> Spam Folder | B5: ='Team Statistics'!B35 -> Grunt Padre | C5: ='Team Statistics'!C35 -> 8 | D5: ='Team Statistics'!D35 -> 6 | E5: ='Team Statistics'!E35 -> 282 | F5: ='Team Statistics'!F35 -> 2 | G5: ='Team Statistics'!G35 -> 1096 | H5: ='Team Statistics'!H35 -> 77 | ... AD5: ='Team Statistics'!AD35 -> 0 | AE5: =#REF! -> #REF! | AF5: =#REF! -> #REF! | AG5: =#REF! -> #REF! | AH5: =#REF! -> #REF! | AI5: =#REF! -> #REF! | AJ5: =#REF! -> #REF!
A6: ='Team Statistics'!A29 -> Eurostars | B6: ='Team Statistics'!B29 -> oDhmon | C6: ='Team Statistics'!C29 -> 4 | D6: ='Team Statistics'!D29 -> 2 | E6: ='Team Statistics'!E29 -> 206.9 | F6: ='Team Statistics'!F29 -> 4 | G6: ='Team Statistics'!G29 -> 938 | H6: ='Team Statistics'!H29 -> 65 | ... AD6: ='Team Statistics'!AD29 -> 0 | AE6: =#REF! -> #REF! | AF6: =#REF! -> #REF! | AG6: =#REF! -> #REF! | AH6: =#REF! -> #REF! | AI6: =#REF! -> #REF! | AJ6: =#REF! -> #REF!
A7: ='Team Statistics'!A63 -> Originals | B7: ='Team Statistics'!B63 -> Galvann | C7: ='Team Statistics'!C63 -> 5 | D7: ='Team Statistics'!D63 -> 5 | E7: ='Team Statistics'!E63 -> 65 | F7: ='Team Statistics'!F63 -> 1 | G7: ='Team Statistics'!G63 -> 354 | H7: ='Team Statistics'!H63 -> 29 | ... AD7: ='Team Statistics'!AD63 -> 0 | AE7: =#REF! -> #REF! | AF7: =#REF! -> #REF! | AG7: =#REF! -> #REF! | AH7: =#REF! -> #REF! | AI7: =#REF! -> #REF! | AJ7: =#REF! -> #REF!
A8: ='Team Statistics'!A4 -> Noble Team | B8: ='Team Statistics'!B4 -> Ace B S1lentND1 | C8: ='Team Statistics'!C4 -> 5 | D8: ='Team Statistics'!D4 -> 3 | E8: ='Team Statistics'!E4 -> 118.9 | F8: ='Team Statistics'!F4 -> 3 | G8: ='Team Statistics'!G4 -> 557 | H8: ='Team Statistics'!H4 -> 49 | ... AD8: ='Team Statistics'!AD4 -> 0 | AE8: =#REF! -> #REF! | AF8: =#REF! -> #REF! | AG8: =#REF! -> #REF! | AH8: =#REF! -> #REF! | AI8: =#REF! -> #REF! | AJ8: =#REF! -> #REF!
A9: ='Team Statistics'!A23 -> Minor Threat | B9: ='Team Statistics'!B23 -> Dat Twinkie | C9: ='Team Statistics'!C23 -> 2 | D9: ='Team Statistics'!D23 -> 0 | E9: ='Team Statistics'!E23 -> 82.7 | F9: ='Team Statistics'!F23 -> 0 | G9: ='Team Statistics'!G23 -> 399 | H9: ='Team Statistics'!H23 -> 33 | ... AD9: ='Team Statistics'!AD23 -> 0 | AE9: =#REF! -> #REF! | AF9: =#REF! -> #REF! | AG9: =#REF! -> #REF! | AH9: =#REF! -> #REF! | AI9: =#REF! -> #REF! | AJ9: =#REF! -> #REF!
A10: ='Team Statistics'!A28 -> Eurostars | B10: ='Team Statistics'!B28 -> CaptainSev004 | C10: ='Team Statistics'!C28 -> 4 | D10: ='Team Statistics'!D28 -> 2 | E10: ='Team Statistics'!E28 -> 206.9 | F10: ='Team Statistics'!F28 -> 2 | G10: ='Team Statistics'!G28 -> 787 | H10: ='Team Statistics'!H28 -> 34 | ... AD10: ='Team Statistics'!AD28 -> 0 | AE10: =#REF! -> #REF! | AF10: =#REF! -> #REF! | AG10: =#REF! -> #REF! | AH10: =#REF! -> #REF! | AI10: =#REF! -> #REF! | AJ10: =#REF! -> #REF!
A11: ='Team Statistics'!A14 -> Goon Squad | B11: ='Team Statistics'!B14 -> AJ DaJuiceMayne | C11: ='Team Statistics'!C14 -> 2 | D11: ='Team Statistics'!D14 -> 0 | E11: ='Team Statistics'!E14 -> 53.2 | F11: ='Team Statistics'!F14 -> 0 | G11: ='Team Statistics'!G14 -> 249 | H11: ='Team Statistics'!H14 -> 17 | ... AD11: ='Team Statistics'!AD14 -> 0 | AE11: =#REF! -> #REF! | AF11: =#REF! -> #REF! | AG11: =#REF! -> #REF! | AH11: =#REF! -> #REF! | AI11: =#REF! -> #REF! | AJ11: =#REF! -> #REF!
