Workbook
Name LL_S7: LL_Data_Aggregate!$A$1:$S$79
Name LL_S6: LL_Data_Aggregate!$A$81:$S$139
Name Grade_Num: 'Player Comparison'!$U$17:$V$23
Name Signed: Signed!$A$1:$C$44

Sheet HistoryHalo4
B1: DJ Tourny 12/04 | C1: DJ Tourny 11/13 | D1: DJ Tourny 10/23 | E1: DJ Tourny 12/04 | F1: DJ Tourny 11/13 | G1: DJ Tourny 10/23 | H1: DJ Tourny 12/04 | I1: DJ Tourny 11/13 | J1: DJ Tourny 10/23 | K1: DJ Tourny 12/04 | L1: DJ Tourny 11/13 | M1: DJ Tourny 10/23 | N1: DJ Tourny 12/04 | O1: DJ Tourny 11/13 | P1: DJ Tourny 10/23 | Q1: LL Season 7 | R1: LL Season 6 | S1: LL Season 7 | T1: LL Season 6 | U1: AGLA Ammy Trio Season | V1: AGLA Ammy Trio Season | W1: AGLA Pro Trio Season | X1: AGLA Pro Trio Season | Y1: AGLA Combined Season | Z1: AGLA Combined Season | AA1: Averaged Rank
A2: Player | B2: Player Efficiency (All vs Top Player) | C2: Player Efficiency (All vs Top Player) | D2: Player Efficiency (All vs Top Player) | E2: Player Efficiency (All vs God Player) | F2: Player Efficiency (All vs God Player) | G2: Player Efficiency (All vs God Player) | H2: Hexas | I2: Hexas | J2: Hexas | K2: Player Grade | L2: Player Grade | M2: Player Grade | N2: Player Grade Math | O2: Player Grade Math | P2: Player Grade Math | Q2: Player Grade | R2: Player Grade | S2: Player Grade Math | T2: Player Grade Math | U2: Player Grade | V2: Player Grade Math | W2: Player Grade | X2: Player Grade Math | Y2: Player Grade | Z2: Player Grade Math
A3: ACE B S1lentND1 | B3: 0.8481 | C3: 0.8769 | D3: 0.98 | F3: 0.7613 | G3: 0.7994 | H3: 2.079 | I3: 4.371 | J3: 2.6854212 | K3: B | L3: A | M3: A | N3: 18.9 | O3: 23.4 | P3: 22.3 | Q3: A | R3: S | S3: 22.8 | T3: 15.5 | AA3: A-S
A4: ActiveHate
A5: ADhillyy
A6: AdminSharky | D6: 0.4931 | G6: 0.5757 | J6: 1.1204894 | M6: D | P6: 11.1 | AA6: D
A7: AJ DaJuiceMayne | D7: 0.3221 | G7: 0.6985 | J7: 0.17946162 | M7: E | P7: 7.9 | Q7: D | R7: A | S7: 11.2 | T7: 13.2 | W7: D | X7: 7.9 | Y7: D | Z7: 7.1 | AA7: D
A8: AKAShadowFax
A9: Almighty Tycoon | B9: 0.5178 | C9: 0.603 | F9: 0.6625 | H9: 0.432 | I9: 0.983 | K9: C | L9: C | N9: 16.1 | O9: 16.3 | Q9: B | S9: 17.1 | AA9: C
A10: Amnatu
A11: Armanama | B11: 0.5603 | K11: E | N11: 9
A12: ASpence501 | B12: 0.7497 | D12: 0.6831 | G12: 0.6338 | H12: 3.179 | J12: 4.0043159 | K12: B | M12: B | N12: 18.5 | P12: 20.1 | Q12: A | R12: B | S12: 23 | T12: 10.5 | U12: A | V12: 15.7 | Y12: A | Z12: 14.2 | AA12: B-A
A13: AtoneMilitant | C13: 0.6926 | D13: 0.4196 | F13: 0.6948 | G13: 0.6089 | I13: 1.16 | J13: 1.2942192 | L13: C | M13: C | O13: 15.7 | P13: 16.2 | Q13: D | R13: B | S13: 11.8 | T13: 11.6 | U13: B | V13: 13.1 | Y13: B | Z13: 12.6 | AA13: C
A14: AwareMosquito | B14: 0.8458 | C14: 0.6527 | F14: 0.6805 | H14: 1.019 | I14: 0.244 | K14: C | L14: D | N14: 16.6 | O14: 9.8 | Q14: B | R14: D | S14: 18.6 | T14: 6.8 | U14: D | V14: 7.2 | Y14: E | Z14: 5.7 | AA14: C-B
A15: BeaM1n1 | C15: 0.7577 | D15: 0.5285 | F15: 0.7183 | G15: 0.6459 | I15: 0.156 | J15: 1.1178622 | L15: E | M15: C | O15: 9 | P15: 15.5 | Q15: D | S15: 10.7 | U15: B | V15: 11.9 | Y15: B | Z15: 11.5 | AA15: C
A16: Bear is Clutch | B16: 0.4363 | H16: -0.214 | K16: E | N16: 6.6
A17: BLOODEN NICK | B17: 0.707 | C17: 0.418 | D17: 0.5559 | F17: 0.5958 | G17: 0.6552 | H17: 1.312 | I17: 0.897 | J17: 0.7057377 | K17: A | L17: B | M17: C | N17: 20.9 | O17: 18 | P17: 14.4 | Q17: C | R17: D | S17: 13.3 | T17: 6.7 | AA17: C
A18: BowerPowerHour
A19: CaptainSev004 | B19: 0.6349 | C19: 0.6035 | D19: 0.4856 | F19: 0.6627 | G19: 0.6313 | H19: 1.558 | I19: 0.449 | J19: 0.54496605 | K19: C | L19: C | M19: B | N19: 16.5 | O19: 15 | P19: 19.1 | Q19: C | R19: D | S19: 15.7 | T19: 7.4 | U19: B | V19: 12.2 | Y19: C | Z19: 9.6 | AA19: C
A20: Conra4859 | Q20: C | R20: E | S20: 16.1 | T20: 5.1 | U20: E | V20: 4.4 | Y20: E | Z20: 4 | AA20: D
A21: cxrnchip | B21: 0.6568 | C21: 0.5858 | D21: 0.6968 | F21: 0.6563 | G21: 0.7031 | H21: 1.417 | I21: 1.915 | J21: 1.8104672 | K21: B | L21: B | M21: A | N21: 17.6 | O21: 17.9 | P21: 22.4 | Q21: B | R21: D | S21: 17.4 | T21: 7.1 | U21: A | V21: 14.7 | W21: E | X21: 4.8 | Y21: B | Z21: 12 | AA21: B
A22: Dabb | B22: 0.7755 | C22: 0.7803 | F22: 0.7265 | H22: 2.604 | I22: 2.684 | K22: A | L22: A | N22: 22 | O22: 23.3 | Q22: B | R22: A | S22: 18.6 | T22: 13.7 | U22: A | V22: 15.7 | Y22: A | Z22: 14.9 | AA22: A
A23: Dat Twinkie | Q23: E | R23: D | S23: 7.7 | T23: 6.3 | U23: E | V23: 5.3 | Y23: E | Z23: 4.1 | AA23: E
A24: DCleak | C24: 0.6806 | D24: 0.4989 | F24: 0.6905 | G24: 0.6358 | I24: 1.062 | J24: 0.68137366 | L24: B | M24: C | O24: 19.1 | P24: 16.2 | Q24: C | R24: C | S24: 16.6 | T24: 8.2 | W24: A | X24: 15.3 | Y24: A | Z24: 13.9 | AA24: B
A25: DlGITAL PAIN | Q25: A | R25: B | S25: 20.7 | T25: 12 | W25: A | X25: 14.8 | Y25: A | Z25: 14.4 | AA25: A
A26: Doerstopper | C26: 0.4542 | D26: 0.3493 | F26: 0.6089 | G26: 0.5849 | I26: -0.28 | J26: 0.11964108 | L26: D | M26: C | O26: 12.2 | P26: 15.8 | Q26: D | R26: D | S26: 10 | T26: 5.9 | U26: D | V26: 7.7 | W26: E | X26: 5.3 | Y26: E | Z26: 5.8 | AA26: D
A27: drez
A28: Eastbrookk | Q28: D | S28: 10.2 | AA28: D
A29: Edle 6
A30: elementary
A31: EllisGotMyPills | R31: A | T31: 12.8 | U31: D | V31: 6.5 | Y31: E | Z31: 5.1 | AA31: D
A32: eTazedd | C32: 0.6137 | F32: 0.6664 | I32: 2.102 | L32: B | O32: 17.3 | Q32: D | R32: A | S32: 12.1 | T32: 13 | W32: B | X32: 11.7 | Y32: B | Z32: 11.4 | AA32: B
A33: F-Ed Boy
A34: Fanciest Pants | B34: 0.6137 | C34: 0.642 | F34: 0.6766 | H34: 1.365 | I34: 0.726 | K34: B | L34: C | N34: 16.7 | O34: 15 | Q34: D | R34: B | S34: 12.6 | T34: 10.5 | W34: C | X34: 11.2 | Y34: C | Z34: 10.1 | AA34: C-B
A35: Frnzh | B35: 0.6888 | C35: 0.7455 | D35: 0.4334 | F35: 0.7139 | G35: 0.6135 | H35: 1.173 | I35: 0.89 | J35: 0.56074783 | K35: B | L35: B | M35: C | N35: 18.7 | O35: 20 | P35: 15.3 | Q35: C | R35: C | S35: 13.7 | T35: 9.9 | U35: D | V35: 7.8 | W35: A | X35: 14.5 | Y35: D | Z35: 8.3 | AA35: C-B
A36: G3Ohh | B36: 66.21.% | H36: 0.39 | K36: B | N36: 17.2
A37: gaebpls | B37: 0.4415 | H37: -1.393 | K37: E | N37: 6.1
A38: Galvann | D38: 0.8447 | G38: 0.7534 | J38: 3.5997992 | M38: A | P38: 23.6 | Q38: S | R38: S | S38: 24.4 | T38: 15.7 | W38: C | X38: 10.1 | Y38: C | Z38: 9.3 | AA38: A-S
A39: GodSnipezX | B39: 0.98 | C39: 0.6383 | D39: 0.7236 | F39: 0.6753 | G39: 0.7122 | H39: 3.384 | I39: 1.722 | J39: 1.9975339 | K39: A | L39: B | M39: B | N39: 23.3 | O39: 17.4 | P39: 18.3 | Q39: A | R39: A | S39: 21.8 | T39: 14.1 | W39: A | X39: 15.6 | Y39: A | Z39: 15 | AA39: B-A
A40: Goldenstunfisk | B40: 0.4507 | H40: -2 | K40: E | N40: 6.9
...

Sheet Player Comparison
C1: DJ Tourny 12/04 | D1: DJ Tourny 11/13 | E1: DJ Tourny 10/23 | F1: DJ Tourny 12/04 | G1: DJ Tourny 11/13 | H1: DJ Tourny 10/23 | I1: DJ Tourny 12/04 | J1: DJ Tourny 11/13 | K1: DJ Tourny 10/23 | L1: DJ Tourny 12/04 | M1: DJ Tourny 11/13 | N1: DJ Tourny 10/23 | O1: DJ Tourny 12/04 | P1: DJ Tourny 11/13 | Q1: DJ Tourny 10/23 | R1: LL Season 7 | S1: LL Season 6 | T1: LL Season 7 | U1: LL Season 6 | V1: AGLA Ammy Trio Season | W1: AGLA Ammy Trio Season | X1: AGLA Pro Trio Season | Y1: AGLA Pro Trio Season | Z1: AGLA Combined Season | AA1: AGLA Combined Season | AB1: Averaged Rank
C2: Player Efficiency (All vs Top Player) | D2: Player Efficiency (All vs Top Player) | E2: Player Efficiency (All vs Top Player) | F2: Player Efficiency (All vs God Player) | G2: Player Efficiency (All vs God Player) | H2: Player Efficiency (All vs God Player) | I2: Hexas | J2: Hexas | K2: Hexas | L2: Player Grade | M2: Player Grade | N2: Player Grade | O2: Player Grade Math | P2: Player Grade Math | Q2: Player Grade Math | R2: Player Grade | S2: Player Grade | T2: Player Grade Math | U2: Player Grade Math | V2: Player Grade | W2: Player Grade Math | X2: Player Grade | Y2: Player Grade Math | Z2: Player Grade | AA2: Player Grade Math
A3: Player 1
A4: JollyJhadIst | B4: {=INDEX(HistoryHalo4!$A$1:$AA$148,Match(A4,HistoryHalo4!A:A,0),0)} -> JollyJhadIst
A5: Against-Player 2 | C5: =IFERROR(IfS(AND(C4<0,C6<0),UMINUS((C4-C6)/C6),C6<0,UMINUS((C4-C6)/C6),C4<0,UMINUS((C4-C6)/C6),AND(C4>0,C6>0),(C4-C6)/C6),) | D5: =IFERROR(IfS(AND(D4<0,D6<0),UMINUS((D4-D6)/D6),D6<0,UMINUS((D4-D6)/D6),D4<0,UMINUS((D4-D6)/D6),AND(D4>0,D6>0),(D4-D6)/D6),) | E5: =IFERROR(IfS(AND(E4<0,E6<0),UMINUS((E4-E6)/E6),E6<0,UMINUS((E4-E6)/E6),E4<0,UMINUS((E4-E6)/E6),AND(E4>0,E6>0),(E4-E6)/E6),) | F5: =IFERROR(IfS(AND(F4<0,F6<0),UMINUS((F4-F6)/F6),F6<0,UMINUS((F4-F6)/F6),F4<0,UMINUS((F4-F6)/F6),AND(F4>0,F6>0),(F4-F6)/F6),) | G5: =IFERROR(IfS(AND(G4<0,G6<0),UMINUS((G4-G6)/G6),G6<0,UMINUS((G4-G6)/G6),G4<0,UMINUS((G4-G6)/G6),AND(G4>0,G6>0),(G4-G6)/G6),) | H5: =IFERROR(IfS(AND(H4<0,H6<0),UMINUS((H4-H6)/H6),H6<0,UMINUS((H4-H6)/H6),H4<0,UMINUS((H4-H6)/H6),AND(H4>0,H6>0),(H4-H6)/H6),) | I5: =IFERROR(IfS(AND(I4<0,I6<0),UMINUS((I4-I6)/I6),I6<0,UMINUS((I4-I6)/I6),I4<0,UMINUS((I4-I6)/I6),AND(I4>0,I6>0),(I4-I6)/I6),) | J5: =IFERROR(IfS(AND(J4<0,J6<0),UMINUS((J4-J6)/J6),J6<0,UMINUS((J4-J6)/J6),J4<0,UMINUS((J4-J6)/J6),AND(J4>0,J6>0),(J4-J6)/J6),) | K5: =IFERROR(IfS(AND(K4<0,K6<0),UMINUS((K4-K6)/K6),K6<0,UMINUS((K4-K6)/K6),K4<0,UMINUS((K4-K6)/K6),AND(K4>0,K6>0),(K4-K6)/K6),) | L5: {=IFERROR(Ifs(INDEX(Grade_Num,Match(L4,$U$17:$U$23,1),2)>INDEX(Grade_Num,Match(L6,$U$17:$U$23,1),2),"+",INDEX(Grade_Num,Match(L4,$U17:$U23,1),2)<INDEX(Grade_Num,Match(L6,$U$17:$U$23,1),2),"-",INDEX(Grade_Num,Match(L4,$U$17:$U$23,1),2)=INDEX(Grade_Num,Match(L6,$U$17:$U$23,1),2),"="),)} | M5: {=IFERROR(Ifs(INDEX(Grade_Num,Match(M4,$U$17:$U$23,1),2)>INDEX(Grade_Num,Match(M6,$U$17:$U$23,1),2),"+",INDEX(Grade_Num,Match(M4,$U17:$U23,1),2)<INDEX(Grade_Num,Match(M6,$U$17:$U$23,1),2),"-",INDEX(Grade_Num,Match(M4,$U$17:$U$23,1),2)=INDEX(Grade_Num,Match(M6,$U$17:$U$23,1),2),"="),)} | N5: {=IFERROR(Ifs(INDEX(Grade_Num,Match(N4,$U$17:$U$23,1),2)>INDEX(Grade_Num,Match(N6,$U$17:$U$23,1),2),"+",INDEX(Grade_Num,Match(N4,$U17:$U23,1),2)<INDEX(Grade_Num,Match(N6,$U$17:$U$23,1),2),"-",INDEX(Grade_Num,Match(N4,$U$17:$U$23,1),2)=INDEX(Grade_Num,Match(N6,$U$17:$U$23,1),2),"="),)} | O5: =IFERROR(IfS(AND(O4<0,O6<0),UMINUS((O4-O6)/O6),O6<0,UMINUS((O4-O6)/O6),O4<0,UMINUS((O4-O6)/O6),AND(O4>0,O6>0),(O4-O6)/O6),) | P5: =IFERROR(IfS(AND(P4<0,P6<0),UMINUS((P4-P6)/P6),P6<0,UMINUS((P4-P6)/P6),P4<0,UMINUS((P4-P6)/P6),AND(P4>0,P6>0),(P4-P6)/P6),) | Q5: =IFERROR(IfS(AND(Q4<0,Q6<0),UMINUS((Q4-Q6)/Q6),Q6<0,UMINUS((Q4-Q6)/Q6),Q4<0,UMINUS((Q4-Q6)/Q6),AND(Q4>0,Q6>0),(Q4-Q6)/Q6),) | R5: {=IFERROR(Ifs(INDEX(Grade_Num,Match(R4,$U$17:$U$23,1),2)>INDEX(Grade_Num,Match(R6,$U$17:$U$23,1),2),"+",INDEX(Grade_Num,Match(R4,$U17:$U23,1),2)<INDEX(Grade_Num,Match(R6,$U$17:$U$23,1),2),"-",INDEX(Grade_Num,Match(R4,$U$17:$U$23,1),2)=INDEX(Grade_Num,Match(R6,$U$17:$U$23,1),2),"="),)} | S5: {=IFERROR(Ifs(INDEX(Grade_Num,Match(S4,$U$17:$U$23,1),2)>INDEX(Grade_Num,Match(S6,$U$17:$U$23,1),2),"+",INDEX(Grade_Num,Match(S4,$U17:$U23,1),2)<INDEX(Grade_Num,Match(S6,$U$17:$U$23,1),2),"-",INDEX(Grade_Num,Match(S4,$U$17:$U$23,1),2)=INDEX(Grade_Num,Match(S6,$U$17:$U$23,1),2),"="),)} | T5: =IFERROR(IfS(AND(T4<0,T6<0),UMINUS((T4-T6)/T6),T6<0,UMINUS((T4-T6)/T6),T4<0,UMINUS((T4-T6)/T6),AND(T4>0,T6>0),(T4-T6)/T6),) | U5: =IFERROR(IfS(AND(U4<0,U6<0),UMINUS((U4-U6)/U6),U6<0,UMINUS((U4-U6)/U6),U4<0,UMINUS((U4-U6)/U6),AND(U4>0,U6>0),(U4-U6)/U6),) | V5: {=IFERROR(Ifs(INDEX(Grade_Num,Match(V4,$U$17:$U$23,1),2)>INDEX(Grade_Num,Match(V6,$U$17:$U$23,1),2),"+",INDEX(Grade_Num,Match(V4,$U17:$U23,1),2)<INDEX(Grade_Num,Match(V6,$U$17:$U$23,1),2),"-",INDEX(Grade_Num,Match(V4,$U$17:$U$23,1),2)=INDEX(Grade_Num,Match(V6,$U$17:$U$23,1),2),"="),)} | W5: =IFERROR(IfS(AND(W4<0,W6<0),UMINUS((W4-W6)/W6),W6<0,UMINUS((W4-W6)/W6),W4<0,UMINUS((W4-W6)/W6),AND(W4>0,W6>0),(W4-W6)/W6),) | X5: {=IFERROR(Ifs(INDEX(Grade_Num,Match(X4,$U$17:$U$23,1),2)>INDEX(Grade_Num,Match(X6,$U$17:$U$23,1),2),"+",INDEX(Grade_Num,Match(X4,$U17:$U23,1),2)<INDEX(Grade_Num,Match(X6,$U$17:$U$23,1),2),"-",INDEX(Grade_Num,Match(X4,$U$17:$U$23,1),2)=INDEX(Grade_Num,Match(X6,$U$17:$U$23,1),2),"="),)} | Y5: =IFERROR(IfS(AND(Y4<0,Y6<0),UMINUS((Y4-Y6)/Y6),Y6<0,UMINUS((Y4-Y6)/Y6),Y4<0,UMINUS((Y4-Y6)/Y6),AND(Y4>0,Y6>0),(Y4-Y6)/Y6),) | Z5: {=IFERROR(Ifs(INDEX(Grade_Num,Match(Z4,$U$17:$U$23,1),2)>INDEX(Grade_Num,Match(Z6,$U$17:$U$23,1),2),"+",INDEX(Grade_Num,Match(Z4,$U17:$U23,1),2)<INDEX(Grade_Num,Match(Z6,$U$17:$U$23,1),2),"-",INDEX(Grade_Num,Match(Z4,$U$17:$U$23,1),2)=INDEX(Grade_Num,Match(Z6,$U$17:$U$23,1),2),"="),)} | AA5: =IFERROR(IfS(AND(AA4<0,AA6<0),UMINUS((AA4-AA6)/AA6),AA6<0,UMINUS((AA4-AA6)/AA6),AA4<0,UMINUS((AA4-AA6)/AA6),AND(AA4>0,AA6>0),(AA4-AA6)/AA6),)
A6: Amnatu | B6: {=INDEX(HistoryHalo4!$A$1:$AA$148,Match(A6,HistoryHalo4!A:A,0),0)} -> Amnatu
A11: Late League
A12: Player 1
A13: gaebpls | C13: Goals PM | D13: KD PM | E13: Stops PM | F13: Sprees PM | G13: Doubles PM | H13: Triples PM | I13: Defense | J13: PlayMaking | K13: Goals PM | L13: KD PM | M13: Stops PM | N13: Sprees PM | O13: Doubles PM | P13: Triples PM | Q13: Defense | R13: PlayMaking | S13: Grade AVG | T13: gAVGmath
A14: Season 8 | B14: =INDEX(LL_S8,Match(A13,LL_Data_Aggregate!,0)) -> #ERROR!
A15: Change | C15: =IFERROR(IfS(AND(C14<0,C16<0),UMINUS((C14-C16)/C16),C16<0,UMINUS((C14-C16)/C16),C14<0,UMINUS((C14-C16)/C16),AND(C14>0,C16>0),(C14-C16)/C16),) | D15: =IFERROR(IfS(AND(D14<0,D16<0),UMINUS((D14-D16)/D16),D16<0,UMINUS((D14-D16)/D16),D14<0,UMINUS((D14-D16)/D16),AND(D14>0,D16>0),(D14-D16)/D16),) | E15: =IFERROR(IfS(AND(E14<0,E16<0),UMINUS((E14-E16)/E16),E16<0,UMINUS((E14-E16)/E16),E14<0,UMINUS((E14-E16)/E16),AND(E14>0,E16>0),(E14-E16)/E16),) | F15: =IFERROR(IfS(AND(F14<0,F16<0),UMINUS((F14-F16)/F16),F16<0,UMINUS((F14-F16)/F16),F14<0,UMINUS((F14-F16)/F16),AND(F14>0,F16>0),(F14-F16)/F16),) | G15: =IFERROR(IfS(AND(G14<0,G16<0),UMINUS((G14-G16)/G16),G16<0,UMINUS((G14-G16)/G16),G14<0,UMINUS((G14-G16)/G16),AND(G14>0,G16>0),(G14-G16)/G16),) | H15: =IFERROR(IfS(AND(H14<0,H16<0),UMINUS((H14-H16)/H16),H16<0,UMINUS((H14-H16)/H16),H14<0,UMINUS((H14-H16)/H16),AND(H14>0,H16>0),(H14-H16)/H16),) | I15: =IFERROR(IfS(AND(I14<0,I16<0),UMINUS((I14-I16)/I16),I16<0,UMINUS((I14-I16)/I16),I14<0,UMINUS((I14-I16)/I16),AND(I14>0,I16>0),(I14-I16)/I16),) | J15: =IFERROR(IfS(AND(J14<0,J16<0),UMINUS((J14-J16)/J16),J16<0,UMINUS((J14-J16)/J16),J14<0,UMINUS((J14-J16)/J16),AND(J14>0,J16>0),(J14-J16)/J16),)
A16: Season 7 | B16: {=INDEX(LL_S7,Match(A13,LL_Data_Aggregate!A1:A79,0))} -> #N/A
A17: Change | C17: =IFERROR(IfS(AND(C16<0,C18<0),UMINUS((C16-C18)/C18),C18<0,UMINUS((C16-C18)/C18),C16<0,UMINUS((C16-C18)/C18),AND(C16>0,C18>0),(C16-C18)/C18),) | D17: =IFERROR(IfS(AND(D16<0,D18<0),UMINUS((D16-D18)/D18),D18<0,UMINUS((D16-D18)/D18),D16<0,UMINUS((D16-D18)/D18),AND(D16>0,D18>0),(D16-D18)/D18),) | E17: =IFERROR(IfS(AND(E16<0,E18<0),UMINUS((E16-E18)/E18),E18<0,UMINUS((E16-E18)/E18),E16<0,UMINUS((E16-E18)/E18),AND(E16>0,E18>0),(E16-E18)/E18),) | F17: =IFERROR(IfS(AND(F16<0,F18<0),UMINUS((F16-F18)/F18),F18<0,UMINUS((F16-F18)/F18),F16<0,UMINUS((F16-F18)/F18),AND(F16>0,F18>0),(F16-F18)/F18),) | G17: =IFERROR(IfS(AND(G16<0,G18<0),UMINUS((G16-G18)/G18),G18<0,UMINUS((G16-G18)/G18),G16<0,UMINUS((G16-G18)/G18),AND(G16>0,G18>0),(G16-G18)/G18),) | H17: =IFERROR(IfS(AND(H16<0,H18<0),UMINUS((H16-H18)/H18),H18<0,UMINUS((H16-H18)/H18),H16<0,UMINUS((H16-H18)/H18),AND(H16>0,H18>0),(H16-H18)/H18),) | I17: =IFERROR(IfS(AND(I16<0,I18<0),UMINUS((I16-I18)/I18),I18<0,UMINUS((I16-I18)/I18),I16<0,UMINUS((I16-I18)/I18),AND(I16>0,I18>0),(I16-I18)/I18),) | J17: =IFERROR(IfS(AND(J16<0,J18<0),UMINUS((J16-J18)/J18),J18<0,UMINUS((J16-J18)/J18),J16<0,UMINUS((J16-J18)/J18),AND(J16>0,J18>0),(J16-J18)/J18),) | K17: {=IFERROR(Ifs(INDEX(Grade_Num,Match(K16,$U$17:$U$23,0),2)>INDEX(Grade_Num,Match(K18,$U$17:$U$23,0),2),"+",INDEX(Grade_Num,Match(K16,$U17:$U23,0),2)<INDEX(Grade_Num,Match(K18,$U$17:$U$23,0),2),"-",INDEX(Grade_Num,Match(K16,$U$17:$U$23,0),2)=INDEX(Grade_Num,Match(K18,$U$17:$U$23,0),2),"="),)} | L17: {=IFERROR(Ifs(INDEX(Grade_Num,Match(L16,$U$17:$U$23,0),2)>INDEX(Grade_Num,Match(L18,$U$17:$U$23,0),2),"+",INDEX(Grade_Num,Match(L16,$U17:$U23,0),2)<INDEX(Grade_Num,Match(L18,$U$17:$U$23,0),2),"-",INDEX(Grade_Num,Match(L16,$U$17:$U$23,0),2)=INDEX(Grade_Num,Match(L18,$U$17:$U$23,0),2),"="),)} | M17: {=IFERROR(Ifs(INDEX(Grade_Num,Match(M16,$U$17:$U$23,0),2)>INDEX(Grade_Num,Match(M18,$U$17:$U$23,0),2),"+",INDEX(Grade_Num,Match(M16,$U17:$U23,0),2)<INDEX(Grade_Num,Match(M18,$U$17:$U$23,0),2),"-",INDEX(Grade_Num,Match(M16,$U$17:$U$23,0),2)=INDEX(Grade_Num,Match(M18,$U$17:$U$23,0),2),"="),)} | N17: {=IFERROR(Ifs(INDEX(Grade_Num,Match(N16,$U$17:$U$23,0),2)>INDEX(Grade_Num,Match(N18,$U$17:$U$23,0),2),"+",INDEX(Grade_Num,Match(N16,$U17:$U23,0),2)<INDEX(Grade_Num,Match(N18,$U$17:$U$23,0),2),"-",INDEX(Grade_Num,Match(N16,$U$17:$U$23,0),2)=INDEX(Grade_Num,Match(N18,$U$17:$U$23,0),2),"="),)} | O17: {=IFERROR(Ifs(INDEX(Grade_Num,Match(O16,$U$17:$U$23,0),2)>INDEX(Grade_Num,Match(O18,$U$17:$U$23,0),2),"+",INDEX(Grade_Num,Match(O16,$U17:$U23,0),2)<INDEX(Grade_Num,Match(O18,$U$17:$U$23,0),2),"-",INDEX(Grade_Num,Match(O16,$U$17:$U$23,0),2)=INDEX(Grade_Num,Match(O18,$U$17:$U$23,0),2),"="),)} | P17: {=IFERROR(Ifs(INDEX(Grade_Num,Match(P16,$U$17:$U$23,0),2)>INDEX(Grade_Num,Match(P18,$U$17:$U$23,0),2),"+",INDEX(Grade_Num,Match(P16,$U17:$U23,0),2)<INDEX(Grade_Num,Match(P18,$U$17:$U$23,0),2),"-",INDEX(Grade_Num,Match(P16,$U$17:$U$23,0),2)=INDEX(Grade_Num,Match(P18,$U$17:$U$23,0),2),"="),)} | Q17: {=IFERROR(Ifs(INDEX(Grade_Num,Match(Q16,$U$17:$U$23,0),2)>INDEX(Grade_Num,Match(Q18,$U$17:$U$23,0),2),"+",INDEX(Grade_Num,Match(Q16,$U17:$U23,0),2)<INDEX(Grade_Num,Match(Q18,$U$17:$U$23,0),2),"-",INDEX(Grade_Num,Match(Q16,$U$17:$U$23,0),2)=INDEX(Grade_Num,Match(Q18,$U$17:$U$23,0),2),"="),)} | R17: {=IFERROR(Ifs(INDEX(Grade_Num,Match(R16,$U$17:$U$23,0),2)>INDEX(Grade_Num,Match(R18,$U$17:$U$23,0),2),"+",INDEX(Grade_Num,Match(R16,$U17:$U23,0),2)<INDEX(Grade_Num,Match(R18,$U$17:$U$23,0),2),"-",INDEX(Grade_Num,Match(R16,$U$17:$U$23,0),2)=INDEX(Grade_Num,Match(R18,$U$17:$U$23,0),2),"="),)} | S17: {=IFERROR(Ifs(INDEX(Grade_Num,Match(S16,$U$17:$U$23,0),2)>INDEX(Grade_Num,Match(S18,$U$17:$U$23,0),2),"+",INDEX(Grade_Num,Match(S16,$U17:$U23,0),2)<INDEX(Grade_Num,Match(S18,$U$17:$U$23,0),2),"-",INDEX(Grade_Num,Match(S16,$U$17:$U$23,0),2)=INDEX(Grade_Num,Match(S18,$U$17:$U$23,0),2),"="),)} | T17: =IfS(AND(T16<0,T18<0),UMINUS((T16-T18)/T18),T18<0,UMINUS((T16-T18)/T18),T16<0,UMINUS((T16-T18)/T18),AND(T16>0,T18>0),(T16-T18)/T18) -> #N/A | U17: S | V17: 7
A18: Season 6 | B18: {=INDEX(LL_S6,Match(A13,LL_Data_Aggregate!A81:A138,0))} -> #N/A | U18: A | V18: 6
K19: {=INDEX(Grade_Num,Match(A16,U17:U23,1),2)} -> 1 | U19: B | V19: 5
A20: Player 2 | U20: C | V20: 4
A21: JollyJhadIst | U21: D | V21: 3
A22: Season 8 | B22: =INDEX(LL_S8,Match(A21,LL_Data_Aggregate!,0)) -> #ERROR! | U22: E | V22: 2
A23: Change | C23: =IFERROR(IfS(AND(C22<0,C24<0),UMINUS((C22-C24)/C24),C24<0,UMINUS((C22-C24)/C24),C22<0,UMINUS((C22-C24)/C24),AND(C22>0,C24>0),(C22-C24)/C24),) | D23: =IFERROR(IfS(AND(D22<0,D24<0),UMINUS((D22-D24)/D24),D24<0,UMINUS((D22-D24)/D24),D22<0,UMINUS((D22-D24)/D24),AND(D22>0,D24>0),(D22-D24)/D24),) | E23: =IFERROR(IfS(AND(E22<0,E24<0),UMINUS((E22-E24)/E24),E24<0,UMINUS((E22-E24)/E24),E22<0,UMINUS((E22-E24)/E24),AND(E22>0,E24>0),(E22-E24)/E24),) | F23: =IFERROR(IfS(AND(F22<0,F24<0),UMINUS((F22-F24)/F24),F24<0,UMINUS((F22-F24)/F24),F22<0,UMINUS((F22-F24)/F24),AND(F22>0,F24>0),(F22-F24)/F24),) | G23: =IFERROR(IfS(AND(G22<0,G24<0),UMINUS((G22-G24)/G24),G24<0,UMINUS((G22-G24)/G24),G22<0,UMINUS((G22-G24)/G24),AND(G22>0,G24>0),(G22-G24)/G24),) | H23: =IFERROR(IfS(AND(H22<0,H24<0),UMINUS((H22-H24)/H24),H24<0,UMINUS((H22-H24)/H24),H22<0,UMINUS((H22-H24)/H24),AND(H22>0,H24>0),(H22-H24)/H24),) | I23: =IFERROR(IfS(AND(I22<0,I24<0),UMINUS((I22-I24)/I24),I24<0,UMINUS((I22-I24)/I24),I22<0,UMINUS((I22-I24)/I24),AND(I22>0,I24>0),(I22-I24)/I24),) | J23: =IFERROR(IfS(AND(J22<0,J24<0),UMINUS((J22-J24)/J24),J24<0,UMINUS((J22-J24)/J24),J22<0,UMINUS((J22-J24)/J24),AND(J22>0,J24>0),(J22-J24)/J24),) | U23: F | V23: 1
A24: Season 7 | B24: {=INDEX(LL_S7,Match(A21,LL_Data_Aggregate!A1:A79,0))} -> #N/A
A25: Change | C25: =IFERROR(IfS(AND(C24<0,C26<0),UMINUS((C24-C26)/C26),C26<0,UMINUS((C24-C26)/C26),C24<0,UMINUS((C24-C26)/C26),AND(C24>0,C26>0),(C24-C26)/C26),) | D25: =IFERROR(IfS(AND(D24<0,D26<0),UMINUS((D24-D26)/D26),D26<0,UMINUS((D24-D26)/D26),D24<0,UMINUS((D24-D26)/D26),AND(D24>0,D26>0),(D24-D26)/D26),) | E25: =IFERROR(IfS(AND(E24<0,E26<0),UMINUS((E24-E26)/E26),E26<0,UMINUS((E24-E26)/E26),E24<0,UMINUS((E24-E26)/E26),AND(E24>0,E26>0),(E24-E26)/E26),) | F25: =IFERROR(IfS(AND(F24<0,F26<0),UMINUS((F24-F26)/F26),F26<0,UMINUS((F24-F26)/F26),F24<0,UMINUS((F24-F26)/F26),AND(F24>0,F26>0),(F24-F26)/F26),) | G25: =IFERROR(IfS(AND(G24<0,G26<0),UMINUS((G24-G26)/G26),G26<0,UMINUS((G24-G26)/G26),G24<0,UMINUS((G24-G26)/G26),AND(G24>0,G26>0),(G24-G26)/G26),) | H25: =IFERROR(IfS(AND(H24<0,H26<0),UMINUS((H24-H26)/H26),H26<0,UMINUS((H24-H26)/H26),H24<0,UMINUS((H24-H26)/H26),AND(H24>0,H26>0),(H24-H26)/H26),) | I25: =IFERROR(IfS(AND(I24<0,I26<0),UMINUS((I24-I26)/I26),I26<0,UMINUS((I24-I26)/I26),I24<0,UMINUS((I24-I26)/I26),AND(I24>0,I26>0),(I24-I26)/I26),) | J25: =IFERROR(IfS(AND(J24<0,J26<0),UMINUS((J24-J26)/J26),J26<0,UMINUS((J24-J26)/J26),J24<0,UMINUS((J24-J26)/J26),AND(J24>0,J26>0),(J24-J26)/J26),) | K25: {=IFERROR(Ifs(INDEX(Grade_Num,Match(K24,$U$17:$U$23,0),2)>INDEX(Grade_Num,Match(K26,$U$17:$U$23,0),2),"+",INDEX(Grade_Num,Match(K24,$U17:$U23,0),2)<INDEX(Grade_Num,Match(K26,$U$17:$U$23,0),2),"-",INDEX(Grade_Num,Match(K24,$U$17:$U$23,0),2)=INDEX(Grade_Num,Match(K26,$U$17:$U$23,0),2),"="),)} | L25: {=IFERROR(Ifs(INDEX(Grade_Num,Match(L24,$U$17:$U$23,0),2)>INDEX(Grade_Num,Match(L26,$U$17:$U$23,0),2),"+",INDEX(Grade_Num,Match(L24,$U17:$U23,0),2)<INDEX(Grade_Num,Match(L26,$U$17:$U$23,0),2),"-",INDEX(Grade_Num,Match(L24,$U$17:$U$23,0),2)=INDEX(Grade_Num,Match(L26,$U$17:$U$23,0),2),"="),)} | M25: {=IFERROR(Ifs(INDEX(Grade_Num,Match(M24,$U$17:$U$23,0),2)>INDEX(Grade_Num,Match(M26,$U$17:$U$23,0),2),"+",INDEX(Grade_Num,Match(M24,$U17:$U23,0),2)<INDEX(Grade_Num,Match(M26,$U$17:$U$23,0),2),"-",INDEX(Grade_Num,Match(M24,$U$17:$U$23,0),2)=INDEX(Grade_Num,Match(M26,$U$17:$U$23,0),2),"="),)} | N25: {=IFERROR(Ifs(INDEX(Grade_Num,Match(N24,$U$17:$U$23,0),2)>INDEX(Grade_Num,Match(N26,$U$17:$U$23,0),2),"+",INDEX(Grade_Num,Match(N24,$U17:$U23,0),2)<INDEX(Grade_Num,Match(N26,$U$17:$U$23,0),2),"-",INDEX(Grade_Num,Match(N24,$U$17:$U$23,0),2)=INDEX(Grade_Num,Match(N26,$U$17:$U$23,0),2),"="),)} | O25: {=IFERROR(Ifs(INDEX(Grade_Num,Match(O24,$U$17:$U$23,0),2)>INDEX(Grade_Num,Match(O26,$U$17:$U$23,0),2),"+",INDEX(Grade_Num,Match(O24,$U17:$U23,0),2)<INDEX(Grade_Num,Match(O26,$U$17:$U$23,0),2),"-",INDEX(Grade_Num,Match(O24,$U$17:$U$23,0),2)=INDEX(Grade_Num,Match(O26,$U$17:$U$23,0),2),"="),)} | P25: {=IFERROR(Ifs(INDEX(Grade_Num,Match(P24,$U$17:$U$23,0),2)>INDEX(Grade_Num,Match(P26,$U$17:$U$23,0),2),"+",INDEX(Grade_Num,Match(P24,$U17:$U23,0),2)<INDEX(Grade_Num,Match(P26,$U$17:$U$23,0),2),"-",INDEX(Grade_Num,Match(P24,$U$17:$U$23,0),2)=INDEX(Grade_Num,Match(P26,$U$17:$U$23,0),2),"="),)} | Q25: {=IFERROR(Ifs(INDEX(Grade_Num,Match(Q24,$U$17:$U$23,0),2)>INDEX(Grade_Num,Match(Q26,$U$17:$U$23,0),2),"+",INDEX(Grade_Num,Match(Q24,$U17:$U23,0),2)<INDEX(Grade_Num,Match(Q26,$U$17:$U$23,0),2),"-",INDEX(Grade_Num,Match(Q24,$U$17:$U$23,0),2)=INDEX(Grade_Num,Match(Q26,$U$17:$U$23,0),2),"="),)} | R25: {=IFERROR(Ifs(INDEX(Grade_Num,Match(R24,$U$17:$U$23,0),2)>INDEX(Grade_Num,Match(R26,$U$17:$U$23,0),2),"+",INDEX(Grade_Num,Match(R24,$U17:$U23,0),2)<INDEX(Grade_Num,Match(R26,$U$17:$U$23,0),2),"-",INDEX(Grade_Num,Match(R24,$U$17:$U$23,0),2)=INDEX(Grade_Num,Match(R26,$U$17:$U$23,0),2),"="),)} | S25: {=IFERROR(Ifs(INDEX(Grade_Num,Match(S24,$U$17:$U$23,0),2)>INDEX(Grade_Num,Match(S26,$U$17:$U$23,0),2),"+",INDEX(Grade_Num,Match(S24,$U17:$U23,0),2)<INDEX(Grade_Num,Match(S26,$U$17:$U$23,0),2),"-",INDEX(Grade_Num,Match(S24,$U$17:$U$23,0),2)=INDEX(Grade_Num,Match(S26,$U$17:$U$23,0),2),"="),)} | T25: =IfS(AND(T24<0,T26<0),UMINUS((T24-T26)/T26),T26<0,UMINUS((T24-T26)/T26),T24<0,UMINUS((T24-T26)/T26),AND(T24>0,T26>0),(T24-T26)/T26) -> #N/A
A26: Season 6 | B26: {=INDEX(LL_S6,Match(A21,LL_Data_Aggregate!A81:A138,0))} -> #N/A

Sheet LL_Data_Aggregate
A1: Players | B1: Goals PM | C1: KD PM | D1: Stops PM | E1: Sprees PM | F1: Doubles PM | G1: Triples PM | H1: Defense | I1: PlayMaking | J1: Goals PM | K1: KD PM | L1: Stops PM | M1: Sprees PM | N1: Doubles PM | O1: Triples PM | P1: Defense | Q1: PlayMaking | R1: Grade AVG | S1: gAVGmath
A2: ACE B S1lentND1 | B2: 0.09 | C2: 0.698 | D2: 0.224 | E2: 0.09 | F2: 0.767 | G2: 0.175 | H2: 0.375 | I2: 0.037 | J2: S | K2: S | L2: S | M2: S | N2: S | O2: S | P2: S | Q2: B | R2: S | S2: 24.7
A3: AJ DaJuiceMayne | B3: 0 | C3: -0.182 | D3: 0.084 | E3: 0.028 | F3: 0.505 | G3: 0.098 | H3: 0.126 | I3: 0.042 | J3: F | K3: C | L3: F | M3: D | N3: C | O3: C | P3: F | Q3: A | R3: D | S3: 12.2
A4: Almighty Tycoon | B4: 0.054 | C4: -0.387 | D4: 0.142 | E4: 0.042 | F4: 0.486 | G4: 0.123 | H4: 0.276 | I4: 0.05 | J4: B | K4: D | L4: C | M4: C | N4: C | O4: B | P4: B | Q4: S | R4: B | S4: 17.6
A5: ArmanMaNarma | B5: 0.067 | C5: -1.646 | D5: 0.117 | E5: 0.003 | F5: 0.28 | G5: 0.027 | H5: 0.213 | I5: 0.027 | J5: B | K5: F | L5: D | M5: F | N5: E | O5: F | P5: D | Q5: D | R5: E | S5: 8.1
A6: ASpence501 | B6: 0.038 | C6: 0.635 | D6: 0.197 | E6: 0.096 | F6: 0.918 | G6: 0.26 | H6: 0.318 | I6: 0.034 | J6: C | K6: S | L6: A | M6: S | N6: S | O6: S | P6: A | Q6: B | R6: A | S6: 23
A7: AtoneMilitant | B7: 0.03 | C7: -0.746 | D7: 0.15 | E7: 0.032 | F7: 0.428 | G7: 0.091 | H7: 0.258 | I7: 0.028 | J7: D | K7: E | L7: B | M7: D | N7: E | O7: D | P7: B | Q7: D | R7: D | S7: 11.8
A8: AwareMosquito | B8: 0.036 | C8: 0.071 | D8: 0.284 | E8: 0.071 | F8: 0.639 | G8: 0.071 | H8: 0.426 | I8: 0.036 | J8: D | K8: S | L8: S | M8: S | N8: A | O8: E | P8: S | Q8: B | R8: B | S8: 20.1
A9: BeaM1n1 | B9: 0.03 | C9: -0.585 | D9: 0.09 | E9: 0.015 | F9: 0.555 | G9: 0.09 | H9: 0.225 | I9: 0.015 | J9: D | K9: D | L9: F | M9: E | N9: B | O9: D | P9: D | Q9: E | R9: D | S9: 10.4
A10: Bear is Clutch | B10: 0 | C10: -0.519 | D10: 0.065 | E10: 0.029 | F10: 0.466 | G10: 0.106 | H10: 0.115 | I10: 0 | J10: F | K10: D | L10: F | M10: D | N10: D | O10: C | P10: F | Q10: F | R10: E | S10: 8.3
A11: BLOODEN NICK | B11: 0.006 | C11: -1.057 | D11: 0.206 | E11: 0.013 | F11: 0.601 | G11: 0.131 | H11: 0.325 | I11: 0.013 | J11: F | K11: E | L11: S | M11: E | N11: A | O11: B | P11: A | Q11: F | R11: C | S11: 13.3
A12: CaptainSev004 | B12: 0.055 | C12: -0.244 | D12: 0.206 | E12: 0.032 | F12: 0.447 | G12: 0.072 | H12: 0.371 | I12: 0.032 | J12: B | K12: C | L12: A | M12: D | N12: D | O12: E | P12: S | Q12: C | R12: C | S12: 15.2
A13: Conra4859 | B13: 0.038 | C13: -1.99 | D13: 0.188 | E13: 0 | F13: 0.526 | G13: 0.188 | H13: 0.375 | I13: 0.038 | J13: C | K13: F | L13: A | M13: F | N13: C | O13: S | P13: S | Q13: B | R13: C | S13: 16.4
... A79: yLuxe | B79: 0.104 | C79: -0.05 | D79: 0.241 | E79: 0.068 | F79: 0.578 | G79: 0.159 | H79: 0.414 | I79: 0.061 | J79: S | K79: B | L79: S | M79: A | N79: A | O79: A | P79: S | Q79: S | R79: A | S79: 23.4
A81: Players | B81: Goals PM | C81: KD PM | D81: Stops PM | E81: Sprees PM | F81: Doubles PM | G81: Triples PM | H81: Defense | I81: PlayMaking | J81: Goals PM | K81: KD PM | L81: Stops PM | M81: Sprees PM | N81: Doubles PM | O81: Triples PM | P81: Defense | Q81: PlayMaking | R81: Grade AVG | S81: gAVGmath
A82: ACE B S1lentND1 | B82: 0.113 | C82: 0.872 | D82: 0.048 | E82: 0.084 | F82: 0.836 | G82: 0.191 | H82: 0.084 | I82: 0.018 | J82: S | K82: S | L82: A | M82: S | N82: S | O82: A | P82: A | Q82: S | R82: S | S82: 15.5
A83: AJ DaJuiceMayne | B83: 0.049 | C83: 0.114 | D83: 0 | E83: 0.131 | F83: 0.784 | G83: 0.294 | H83: 0 | I83: 0 | J83: C | K83: B | L83: F | M83: S | N83: A | O83: S | P83: F | Q83: F | R83: A | S83: 13.2
A84: ASpence501 | B84: 0.014 | C84: -0.201 | D84: 0.023 | E84: 0.056 | F84: 0.708 | G84: 0.19 | H84: 0.044 | I84: 0.009 | J84: F | K84: B | L84: C | M84: B | N84: A | O84: A | P84: C | Q84: B | R84: B | S84: 10.5
A85: AtoneMilitant | B85: 0.044 | C85: 0.166 | D85: 0.14 | E85: 0.044 | F85: 0.665 | G85: 0.123 | H85: 0.21 | I85: 0.026 | J85: C | K85: A | L85: S | M85: C | N85: A | O85: B | P85: S | Q85: S | R85: B | S85: 11.6
A86: AwareMosquito | B86: 0.028 | C86: -0.289 | D86: 0.048 | E86: 0.034 | F86: 0.529 | G86: 0.091 | H86: 0.085 | I86: 0.002 | J86: E | K86: D | L86: A | M86: D | N86: C | O86: D | P86: A | Q86: D | R86: D | S86: 6.8
A87: BLOODEN NICK | B87: 0.048 | C87: -1.116 | D87: 0 | E87: 0.038 | F87: 0.505 | G87: 0.067 | H87: 0 | I87: 0 | J87: C | K87: E | L87: F | M87: D | N87: C | O87: E | P87: F | Q87: F | R87: D | S87: 6.7
A88: CaptainSev004 | B88: 0.071 | C88: -0.509 | D88: 0 | E88: 0.021 | F88: 0.36 | G88: 0.064 | H88: 0 | I88: 0 | J88: A | K88: D | L88: F | M88: D | N88: E | O88: E | P88: F | Q88: F | R88: D | S88: 7.4
A89: Conra4859 | B89: 0.032 | C89: -1.409 | D89: 0.007 | E89: 0.013 | F89: 0.374 | G89: 0.046 | H89: 0.011 | I89: 0.001 | J89: D | K89: E | L89: D | M89: E | N89: E | O89: E | P89: D | Q89: D | R89: E | S89: 5.1
A90: cxrnchip | B90: 0.076 | C90: -0.436 | D90: 0.083 | E90: 0.016 | F90: 0.446 | G90: 0.057 | H90: 0.143 | I90: 0.025 | J90: A | K90: D | L90: S | M90: E | N90: E | O90: E | P90: S | Q90: S | R90: D | S90: 7.1
A91: Dabb | B91: 0.127 | C91: 0.818 | D91: 0 | E91: 0.105 | F91: 0.594 | G91: 0.119 | H91: 0 | I91: 0 | J91: S | K91: S | L91: F | M91: S | N91: C | O91: B | P91: F | Q91: F | R91: A | S91: 13.7
A92: Dat Twinkie | B92: 0.055 | C92: -0.766 | D92: 0.164 | E92: 0 | F92: 0.328 | G92: 0.055 | H92: 0.219 | I92: 0 | J92: B | K92: D | L92: S | M92: F | N92: E | O92: E | P92: S | Q92: F | R92: D | S92: 6.3
A93: DCleak | B93: 0.081 | C93: -0.666 | D93: 0.026 | E93: 0.01 | F93: 0.501 | G93: 0.103 | H93: 0.055 | I93: 0.013 | J93: A | K93: D | L93: B | M93: F | N93: C | O93: D | P93: B | Q93: B | R93: C | S93: 8.2
... A138: You heard of us | B138: 0.027 | C138: -1.609 | D138: 0 | E138: 0.013 | F138: 0.362 | G138: 0.04 | H138: 0 | I138: 0 | J138: E | K138: F | L138: F | M138: E | N138: E | O138: E | P138: F | Q138: F | R138: E | S138: 4.1

Sheet Signed
A1: GamerTag | B1: Grade | C1: Bid Value | D1: Captain Pool | F1: Location | H1: Sun | I1: Mon | J1: Tue | K1: Wed | L1: Thu | M1: Fri | N1: Sat
A2: ASpence501 | B2: =IFERROR(VLOOKUP(A2,'Bid Values'!A:F,2,0),) -> A | C2: =IFERROR(VLOOKUP(A2,'Bid Values'!A:F,3,0),) -> 198 | D2: =600-C2 -> 402 | F2: East | H2: 44750 | I2: 44750 | J2: 44750 | K2: 44750 | L2: 44750 | M2: 7-9:30 | N2: 7-9:30 | Q2: # | R2: per round
A3: Dabb | B3: =IFERROR(VLOOKUP(A3,'Bid Values'!A:F,2,0),) -> A | C3: =IFERROR(VLOOKUP(A3,'Bid Values'!A:F,3,0),) -> 198 | D3: =600-C3 -> 402 | F3: North Central | H3: 44750 | I3: 44750 | J3: 44750 | K3: 44750 | L3: 44750 | M3: 44750 | N3: 44750 | P3: A | Q3: 4 | R3: 1
A4: Godsnipezx | B4: =IFERROR(VLOOKUP(A4,'Bid Values'!A:F,2,0),) -> A | C4: =IFERROR(VLOOKUP(A4,'Bid Values'!A:F,3,0),) -> 198 | D4: =600-C4 -> 402 | F4: South Central | H4: 8 | I4: 8 | J4: 8 | K4: 8 | L4: 8 | M4: 8 | N4: 8 | P4: B | Q4: 2 | R4: 1
A5: MysticalNovice | B5: =IFERROR(VLOOKUP(A5,'Bid Values'!A:F,2,0),) -> A | C5: =IFERROR(VLOOKUP(A5,'Bid Values'!A:F,3,0),) -> 198 | D5: =600-C5 -> 402 | F5: West | H5: 8:30-11 | I5: 8:30-11 | J5: 8:30-11 | K5: 8:30-11 | L5: 8:30-11 | M5: 8:30-11 | N5: 8:30-11 | P5: C | Q5: 9 | R5: 2
A6: Solace VIII | B6: =IFERROR(VLOOKUP(A6,'Bid Values'!A:F,2,0),) -> A | C6: =IFERROR(VLOOKUP(A6,'Bid Values'!A:F,3,0),) -> 198 | D6: =600-C6 -> 402 | F6: North Central | H6: 7-10:30 | I6: 7-10:30 | J6: NA | K6: NA | L6: NA | M6: NA | N6: 7-10:30 | P6: D | Q6: 11 | R6: 3
A7: yLuxe | B7: =IFERROR(VLOOKUP(A7,'Bid Values'!A:F,2,0),) -> A | C7: =IFERROR(VLOOKUP(A7,'Bid Values'!A:F,3,0),) -> 198 | D7: =600-C7 -> 402 | F7: East | H7: 7:30-11 | I7: 7:30-11 | J7: 7:30-11 | K7: 7:30-11 | L7: 7:30-11 | M7: 7:30-11 | N7: 7:30-11 | P7: E | Q7: 7 | R7: 2
A8: BLOODEN NICK | B8: B | C8: 150 | D8: =600-C8 -> 450 | F8: North Central | H8: 44753 | I8: 44815 | J8: 44815 | K8: 44815 | L8: 911 | M8: 44815 | N8: 44815
A9: cxrnchip | B9: =IFERROR(VLOOKUP(A9,'Bid Values'!A:F,2,0),) -> B | C9: =IFERROR(VLOOKUP(A9,'Bid Values'!A:F,3,0),) -> 150 | D9: =600-C9 -> 450 | F9: West | H9: 44753 | I9: 44753 | J9: 44753 | K9: 44753 | L9: 44753 | M9: 44753 | N9: 44753
A10: oDhmon | B10: B | C10: 150 | D10: =600-C10 -> 450 | F10: East | H10: 44784 | I10: 44784 | J10: 44750 | K10: 44750 | L10: 44750 | M10: 44750 | N10: 44751
A11: Rage More Nerd | B11: =IFERROR(VLOOKUP(A11,'Bid Values'!A:F,2,0),) -> B | C11: =IFERROR(VLOOKUP(A11,'Bid Values'!A:F,3,0),) -> 150 | D11: =600-C11 -> 450 | F11: West | H11: NA | I11: NA | J11: NA | K11: 9 | L11: 9 | M11: 9 | N11: 7
A12: Scomancer | B12: =IFERROR(VLOOKUP(A12,'Bid Values'!A:F,2,0),) -> B | C12: =IFERROR(VLOOKUP(A12,'Bid Values'!A:F,3,0),) -> 150 | D12: =600-C12 -> 450 | F12: East | H12: 44753 | I12: 44753 | J12: 10:30-11 | K12: 44753 | L12: 44753 | M12: 44753 | N12: 10:30-11
A13: Almighty Tycoon | B13: =IFERROR(VLOOKUP(A13,'Bid Values'!A:F,2,0),) -> C | C13: =IFERROR(VLOOKUP(A13,'Bid Values'!A:F,3,0),) -> 60 | D13: =600-C13 -> 540 | F13: West | H13: 44750 | I13: 7 | J13: 44750 | K13: 7 | L13: 44750 | M13: 7 | N13: 44750
A14: AwareMosquito | B14: =IFERROR(VLOOKUP(A14,'Bid Values'!A:F,2,0),) -> C | C14: =IFERROR(VLOOKUP(A14,'Bid Values'!A:F,3,0),) -> 60 | D14: =600-C14 -> 540 | F14: EU | H14: 44750 | I14: 44750 | J14: 44750 | K14: 44750 | L14: 44750 | M14: 44752 | N14: 44752
A15: Beam1n1 | B15: =IFERROR(VLOOKUP(A15,'Bid Values'!A:F,2,0),) -> C | C15: =IFERROR(VLOOKUP(A15,'Bid Values'!A:F,3,0),) -> 60 | D15: =600-C15 -> 540 | F15: East | H15: 7-8:30 | I15: 7-8:30 | J15: 7-8:30 | K15: 7-8:30 | L15: 7-8:30 | M15: 7-8:30 | N15: 7-8:30
A16: CaptainSev004 | B16: =IFERROR(VLOOKUP(A16,'Bid Values'!A:F,2,0),) -> C | C16: =IFERROR(VLOOKUP(A16,'Bid Values'!A:F,3,0),) -> 60 | D16: =600-C16 -> 540 | F16: EU | H16: 7-9:30 | I16: 7-9:30 | J16: 7-9:30 | K16: 7-9:30 | L16: 7-9:30 | M16: NA | N16: NA
A17: Eternlx | B17: =IFERROR(VLOOKUP(A17,'Bid Values'!A:F,2,0),) -> C | C17: =IFERROR(VLOOKUP(A17,'Bid Values'!A:F,3,0),) -> 60 | D17: =600-C17 -> 540 | F17: EU | H17: 7 | I17: 7 | J17: 7 | K17: 44750 | L17: 7 | M17: 44750 | N17: 7
A18: G3Ohh | B18: =IFERROR(VLOOKUP(A18,'Bid Values'!A:F,2,0),) -> C | C18: =IFERROR(VLOOKUP(A18,'Bid Values'!A:F,3,0),) -> 60 | D18: =600-C18 -> 540 | F18: West | H18: 44753 | I18: 44753 | J18: 44753 | K18: 44753 | L18: 44753 | M18: 44753 | N18: 44753
A19: Havoc Puppies | B19: =IFERROR(VLOOKUP(A19,'Bid Values'!A:F,2,0),) -> C | C19: =IFERROR(VLOOKUP(A19,'Bid Values'!A:F,3,0),) -> 60 | D19: =600-C19 -> 540 | F19: West | H19: NA | I19: 44753 | J19: 44753 | K19: 44753 | L19: 44753 | M19: 44753 | N19: 44753
A20: Into Sublime | B20: =IFERROR(VLOOKUP(A20,'Bid Values'!A:F,2,0),) -> C | C20: =IFERROR(VLOOKUP(A20,'Bid Values'!A:F,3,0),) -> 60 | D20: =600-C20 -> 540 | F20: East | H20: 8:30-10:30 | I20: 8:30-10:30 | J20: 8:30-10:30 | K20: 8:30-10:30 | L20: 8:30-10:30 | M20: 8:30-10:30 | N20: 8:30-10:30
A21: Myst the Cold | B21: =IFERROR(VLOOKUP(A21,'Bid Values'!A:F,2,0),) -> C | C21: =IFERROR(VLOOKUP(A21,'Bid Values'!A:F,3,0),) -> 60 | D21: =600-C21 -> 540 | F21: South Central | H21: 8 | I21: 8 | J21: 8 | K21: 8 | L21: 8 | M21: 8 | N21: 8
A22: Reyas | B22: =IFERROR(VLOOKUP(A22,'Bid Values'!A:F,2,0),) -> C | C22: =IFERROR(VLOOKUP(A22,'Bid Values'!A:F,3,0),) -> 60 | D22: =600-C22 -> 540 | F22: EU | H22: 44753 | I22: 44753 | J22: 44750 | K22: 44750 | L22: 44750 | M22: 44750 | N22: 44751
A23: slayers0n | B23: =IFERROR(VLOOKUP(A23,'Bid Values'!A:F,2,0),) -> C | C23: =IFERROR(VLOOKUP(A23,'Bid Values'!A:F,3,0),) -> 60 | D23: =600-C23 -> 540 | F23: South Central | H23: 44753 | I23: NA | J23: 44815 | K23: NA | L23: 44815 | M23: NA | N23: 44753
A24: TheAlphaTurtle | B24: =IFERROR(VLOOKUP(A24,'Bid Values'!A:F,2,0),) -> C | C24: =IFERROR(VLOOKUP(A24,'Bid Values'!A:F,3,0),) -> 60 | D24: =600-C24 -> 540 | F24: East | H24: 7-10:30 | I24: 10-10:30 | J24: 7-10:30 | K24: 8:30-10:30 | L24: 7-10:30 | M24: 44751 | N24: 7-10:30
A25: TommyWstSide | B25: =IFERROR(VLOOKUP(A25,'Bid Values'!A:F,2,0),) -> C | C25: =IFERROR(VLOOKUP(A25,'Bid Values'!A:F,3,0),) -> 60 | D25: =600-C25 -> 540 | F25: North Central | H25: 44751 | I25: 44751 | J25: 44751 | K25: 44751 | L25: 44751 | M25: 44751 | N25: 44751
A26: Doerstopper | B26: =IFERROR(VLOOKUP(A26,'Bid Values'!A:F,2,0),) -> D | C26: =IFERROR(VLOOKUP(A26,'Bid Values'!A:F,3,0),) -> 60 | D26: =600-C26 -> 540 | F26: North Central | H26: 9:30-11 | I26: 9:30-11 | J26: 9:30-11 | K26: 9:30-11 | L26: 9:30-11 | M26: 9:30-11 | N26: 9:30-11
A27: LilSkelR1926 | B27: =IFERROR(VLOOKUP(A27,'Bid Values'!A:F,2,0),) -> D | C27: =IFERROR(VLOOKUP(A27,'Bid Values'!A:F,3,0),) -> 60 | D27: =600-C27 -> 540 | F27: East | H27: 11 | I27: 7 | J27: 7 | K27: 11 | L27: 11 | M27: 11 | N27: 44753
A28: Mavbrid | B28: =IFERROR(VLOOKUP(A28,'Bid Values'!A:F,2,0),) -> D | C28: =IFERROR(VLOOKUP(A28,'Bid Values'!A:F,3,0),) -> 60 | D28: =600-C28 -> 540 | F28: East | H28: 44753 | I28: 44753 | J28: 44753 | K28: 44753 | L28: 44753 | M28: 44753 | N28: 44753
A29: MoldyVolts | B29: =IFERROR(VLOOKUP(A29,'Bid Values'!A:F,2,0),) -> D | C29: =IFERROR(VLOOKUP(A29,'Bid Values'!A:F,3,0),) -> 60 | D29: =600-C29 -> 540 | F29: North Central | H29: 44751 | I29: 44751 | J29: 44751 | K29: 44751 | L29: 44751 | M29: 44751 | N29: 44753
A30: Mr Epic Beast | B30: =IFERROR(VLOOKUP(A30,'Bid Values'!A:F,2,0),) -> D | C30: =IFERROR(VLOOKUP(A30,'Bid Values'!A:F,3,0),) -> 60 | D30: =600-C30 -> 540 | F30: West | H30: 44753 | I30: 8:30-11 | J30: 8:30-11 | K30: 8:30-11 | L30: 8:30-11 | M30: 8:30-11 | N30: 44753
A31: mstell96 | B31: =IFERROR(VLOOKUP(A31,'Bid Values'!A:F,2,0),) -> D | C31: =IFERROR(VLOOKUP(A31,'Bid Values'!A:F,3,0),) -> 60 | D31: =600-C31 -> 540 | F31: North Central | H31: 44753 | I31: 44815 | J31: 44815 | K31: 44815 | L31: 44815 | M31: 44815 | N31: 44753
A32: MuNgO PuNgO | B32: =IFERROR(VLOOKUP(A32,'Bid Values'!A:F,2,0),) -> D | C32: =IFERROR(VLOOKUP(A32,'Bid Values'!A:F,3,0),) -> 60 | D32: =600-C32 -> 540 | F32: East | H32: 44753 | I32: NA | J32: NA | K32: NA | L32: NA | M32: 44753 | N32: 44753
A33: Priest XYZ | B33: =IFERROR(VLOOKUP(A33,'Bid Values'!A:F,2,0),) -> D | C33: =IFERROR(VLOOKUP(A33,'Bid Values'!A:F,3,0),) -> 60 | D33: =600-C33 -> 540 | F33: Central | H33: 7-10:30 | I33: 44814 | J33: NA | K33: NA | L33: NA | M33: NA | N33: 7-10:30
A34: Valatino | B34: D | C34: 60 | D34: =600-C34 -> 540 | F34: South Central | H34: 9 | I34: 8-8:30 | J34: 8-8:30 | K34: 8-8:30 | L34: 8-8:30 | M34: 8-8:30 | N34: 8:30-9
A35: x Greenthumb | B35: D | C35: 60 | D35: =600-C35 -> 540 | F35: East | H35: 9:30-11 | I35: 9:30-11 | J35: 9:30-11 | K35: 9:30-11 | L35: 9:30-11 | M35: 9:30-11 | N35: 9:30-11
A36: Zavi | B36: D | C36: 60 | D36: =600-C36 -> 540 | F36: EU | H36: 44753 | I36: NA | J36: NA | K36: NA | L36: NA | M36: 7-10:30 | N36: 44751
A37: Amnatu | B37: =IFERROR(VLOOKUP(A37,'Bid Values'!A:F,2,0),) -> E | C37: =IFERROR(VLOOKUP(A37,'Bid Values'!A:F,3,0),) -> 30 | D37: =600-C37 -> 570 | F37: West | H37: 44750 | I37: 44750 | J37: NA | K37: NA | L37: NA | M37: NA | N37: NA
A38: Bear is Clutch | B38: =IFERROR(VLOOKUP(A38,'Bid Values'!A:F,2,0),) -> E | C38: =IFERROR(VLOOKUP(A38,'Bid Values'!A:F,3,0),) -> 30 | D38: =600-C38 -> 570 | F38: West | H38: 44845 | I38: 44845 | J38: 44845 | K38: 44845 | L38: 44845 | M38: 44845 | N38: 44845
A39: gaebpls | B39: =IFERROR(VLOOKUP(A39,'Bid Values'!A:F,2,0),) -> E | C39: =IFERROR(VLOOKUP(A39,'Bid Values'!A:F,3,0),) -> 30 | D39: =600-C39 -> 570 | F39: EU | H39: 7-9:30 | I39: 7-9:30 | J39: 7-9:30 | K39: 7-9:30 | L39: 7-9:30 | M39: 44753 | N39: 44753
A40: JollyJhadIst | B40: =IFERROR(VLOOKUP(A40,'Bid Values'!A:F,2,0),) -> E | C40: =IFERROR(VLOOKUP(A40,'Bid Values'!A:F,3,0),) -> 30 | D40: =600-C40 -> 570 | F40: West | H40: 0.3125 | I40: 0.3125 | J40: 0.3125 | K40: 0.3125 | L40: 0.3125 | M40: 0.3125 | N40: 0.3125
...

Sheet Bid Values
A1: Player Names | B1: Perceived Grade | C1: Bid Value | D1: Console/XBOX | E1: Captain Starting Pool | F1: Stage | G1: Mixed Stage | M1: Percentage of base credits | N1: Base Credits
A2: Dabb | B2: A | C2: =$L$3 -> 198 | E2: =$N$2-C2 -> 402 | F2: Stage 1 | G2: Stage 1 | H2: Stage | I2: Time | J2: Estimated Base Credit Value | K2: S | L2: =$N$2*M2 -> 198 | M2: 0.33 | N2: 600
A3: DlGITAL PAIN | B3: A | C3: =$L$3 -> 198 | E3: =$N$2-C3 -> 402 | F3: Stage 1 | G3: Stage 1 | H3: 1 | I3: 1 day | K3: A | L3: =$N$2*M3 -> 198 | M3: 0.33
A4: Icey Tanker | B4: A | C4: =$L$3 -> 198 | E4: =$N$2-C4 -> 402 | F4: Stage 1 | G4: Stage 1 | H4: 2 | I4: 1 day | K4: B | L4: =$N$2*M4 -> 150 | M4: 0.25
A5: ixGingy | B5: A | C5: =$L$3 -> 198 | E5: =$N$2-C5 -> 402 | F5: Stage 1 | G5: Stage 2 | H5: 3 | I5: 1 day | K5: C | L5: =$N$2*M5 -> 60 | M5: 0.1
A6: Solace VIII | B6: A | C6: =$L$3 -> 198 | E6: =$N$2-C6 -> 402 | F6: Stage 1 | G6: Stage 2 | H6: 4 | I6: 1 day | K6: D | L6: =$N$2*M6 -> 60 | M6: 0.1
A7: yLuxe | B7: A | C7: =$L$3 -> 198 | E7: =$N$2-C7 -> 402 | F7: Stage 1 | G7: Stage 2 | K7: E | L7: =$N$2*M7 -> 30 | M7: 0.05
A8: ASpence501 | B8: A | C8: =$L$3 -> 198 | E8: =$N$2-C8 -> 402 | F8: Stage 1 | G8: Stage 1 | K8: F | L8: =$N$2*M8 -> 30 | M8: 0.05
A9: GodSnipezX | B9: A | C9: =$L$3 -> 198 | E9: =$N$2-C9 -> 402 | F9: Stage 1 | G9: Stage 3
A10: MysticalNovice | B10: A | C10: =$L$3 -> 198 | E10: =$N$2-C10 -> 402 | F10: Stage 1 | G10: Stage 3
A11: Sabasauros rex | B11: A | C11: =$L$3 -> 198 | E11: =$N$2-C11 -> 402 | F11: Stage 1 | G11: Stage 2
A12: Yejis Aegyo | B12: A | C12: =$L$3 -> 198 | E12: =$N$2-C12 -> 402 | F12: Stage 1 | G12: Stage 3 | J12: 6+5+4+3
A13: ACE B S1lentND1 | B13: S | C13: =$L$2 -> 198 | E13: =$N$2-C13 -> 402 | F13: Stage 1 | G13: Stage 4
A14: Galvann | B14: S | C14: =$L$2 -> 198 | E14: =$N$2-C14 -> 402 | F14: Stage 1 | G14: Stage 4
A15: Wrecking Nerds | B15: B | C15: =$L$4 -> 150 | E15: =$N$2-C15 -> 450 | F15: Stage 2 | G15: Stage 1
A16: cxrnchip | B16: B | C16: =$L$4 -> 150 | E16: =$N$2-C16 -> 450 | F16: Stage 2 | G16: Stage 2
A17: DCleak | B17: B | C17: =$L$4 -> 150 | E17: =$N$2-C17 -> 450 | F17: Stage 2 | G17: Stage 3
A18: eTazedd | B18: B | C18: =$L$4 -> 150 | E18: =$N$2-C18 -> 450 | F18: Stage 2 | G18: Stage 4
A19: Invayda Zim | B19: B | C19: =$L$4 -> 150 | E19: =$N$2-C19 -> 450 | F19: Stage 2 | G19: Stage 1
A20: Regresser | B20: B | C20: =$L$4 -> 150 | E20: =$N$2-C20 -> 450 | F20: Stage 2 | G20: Stage 2
A21: Ming Crusader | B21: B | C21: =$L$4 -> 150 | E21: =$N$2-C21 -> 450 | F21: Stage 2 | G21: Stage 3
A22: QueOtaSaintz | B22: B | C22: =$L$4 -> 150 | E22: =$N$2-C22 -> 450 | F22: Stage 2 | G22: Stage 4
A23: Rage More Nerd | B23: B | C23: =$L$4 -> 150 | E23: =$N$2-C23 -> 450 | F23: Stage 2 | G23: Stage 1
A24: Scomancer | B24: B | C24: =$L$4 -> 150 | E24: =$N$2-C24 -> 450 | F24: Stage 2 | G24: Stage 2
A25: Silva | B25: B | C25: =$L$4 -> 150 | E25: =$N$2-C25 -> 450 | F25: Stage 2 | G25: Stage 3
A26: The Piggies | B26: C | C26: =$L$5 -> 60 | E26: =$N$2-C26 -> 540 | F26: Stage 3 | G26: Stage 1
A27: AwareMosquito | B27: C | C27: =$L$5 -> 60 | E27: =$N$2-C27 -> 540 | F27: Stage 3 | G27: Stage 2
A28: Fanciest Pants | B28: C | C28: =$L$5 -> 60 | E28: =$N$2-C28 -> 540 | F28: Stage 3 | G28: Stage 3
A29: Eternlx | B29: C | C29: =$L$5 -> 60 | E29: =$N$2-C29 -> 540 | F29: Stage 3 | G29: Stage 4
A30: Halfbreed | B30: C | C30: =$L$5 -> 60 | E30: =$N$2-C30 -> 540 | F30: Stage 3
A31: oDhmon | B31: C | C31: =$L$5 -> 60 | E31: =$N$2-C31 -> 540 | F31: Stage 3
A32: Almighty Tycoon | B32: C | C32: =$L$5 -> 60 | E32: =$N$2-C32 -> 540 | F32: Stage 3
A33: AtoneMilitant | B33: C | C33: =$L$5 -> 60 | E33: =$N$2-C33 -> 540 | F33: Stage 3
A34: BeaM1n1 | B34: C | C34: =$L$5 -> 60 | E34: =$N$2-C34 -> 540 | F34: Stage 3
A35: BLOODEN NICK | B35: C | C35: =$L$5 -> 60 | E35: =$N$2-C35 -> 540 | F35: Stage 3
A36: CaptainSev004 | B36: C | C36: =$L$5 -> 60 | E36: =$N$2-C36 -> 540 | F36: Stage 3
A37: Havoc Puppies | B37: C | C37: =$L$5 -> 60 | E37: =$N$2-C37 -> 540 | F37: Stage 3
A38: imShad | B38: C | C38: =$L$5 -> 60 | E38: =$N$2-C38 -> 540 | F38: Stage 3
A39: Into Sublime | B39: C | C39: =$L$5 -> 60 | E39: =$N$2-C39 -> 540 | F39: Stage 3
A40: ixSqueeps | B40: C | C40: =$L$5 -> 60 | E40: =$N$2-C40 -> 540 | F40: Stage 3
...

Sheet Potential Scheduling
A1: Sun | B1: Mon | C1: Tue | D1: Wed | E1: Thu | F1: Fri | G1: Sat | J1: Sun | K1: Mon | L1: Tue | M1: Wed | N1: Thu | O1: Fri | P1: Sat | T1: Sun | U1: Mon | V1: Tue | W1: Wed | X1: Thu | Y1: Fri | Z1: Sat
A2: 0.3125 | B2: 0.3125 | C2: 0.3125 | D2: 0.3125 | E2: 0.3125 | F2: 0.3125 | G2: 0.3125 | I2: Mavbrid | J2: 44753 | K2: 44753 | L2: 44753 | M2: 44753 | N2: 44753 | O2: 44753 | P2: 44753 | S2: CaptainSev004 | T2: 7-10:30 | U2: 44752 | V2: 44752 | W2: 44752 | X2: 7-9:30 | Y2: NA | Z2: NA
A3: 7 | B3: 7 | C3: 7 | D3: 7 | E3: 7 | F3: 7 | G3: 7 | I3: TommyWstSide | J3: 44752 | K3: 44752 | L3: 44752 | M3: 44752 | N3: 44752 | O3: 44752 | P3: 44752 | S3: Reyas | T3: 44753 | U3: 44753 | V3: 44751 | W3: 44751 | X3: 44751 | Y3: 7-8:30 | Z3: 44751
A4: 8 | B4: 7 | C4: 7 | D4: 8 | E4: 8 | F4: 8 | G4: 7 | I4: Havoc Puppies | J4: NA | K4: 44753 | L4: 44753 | M4: 44753 | N4: 44753 | O4: 44753 | P4: 44753 | S4: Godsnipezx | T4: 8 | U4: 8 | V4: 8 | W4: 8 | X4: 8 | Y4: 8 | Z4: 8
A5: 8 | B5: 7 | C5: 8 | D5: 8 | E5: 8 | F5: 8 | G5: 8 | I5: MoldyVolts | J5: 8-11 (7-9) | K5: 8-11 (7-9) | L5: 8-11 (7-9) | M5: 8-11 (7-9) | N5: 8-11 (7-9) | O5: 8-11 (7-9) | P5: 8-11 (7-11) | S5: Sherbski | T5: 44753 | U5: 44784 | V5: 44815 | W5: 44784 | X5: 44815 | Y5: 44753 | Z5: 44753
A6: 9 | B6: 8 | C6: 8 | D6: 9 | E6: 9 | F6: 9 | G6: 8 | J6: no | K6: 44783 | L6: 44783 | M6: 44783 | N6: 44783 | O6: 44783 | P6: 44783 | T6: 8-10:30 | U6: 44783 | V6: 44782 | W6: 44782 | X6: 44782 | Y6: 8-8:30 | Z6: 44783
A7: 11 | B7: 8 | C7: 44750 | D7: 11 | E7: 11 | F7: 11 | G7: 44750 | I7: TheAlphaTurtle | J7: 7-10:30 | K7: NA | L7: 7-10:30 | M7: 8:30-10:30 | N7: 7-10:30 | O7: 44751 | P7: 44753 | S7: G3Ohh | T7: 44753 | U7: 44753 | V7: 44753 | W7: 44753 | X7: 44753 | Y7: 44753 | Z7: 44753
A8: 44750 | B8: 44750 | C8: 44750 | D8: 44750 | E8: 911 | F8: 44750 | G8: 44750 | I8: Beam1n1 | J8: 44753 | K8: NA | L8: 44753 | M8: 44753 | N8: 44753 | O8: 44753 | P8: 44753 | S8: MuNgO PuNgO | T8: 44753 | U8: NA | V8: NA | W8: NA | X8: NA | Y8: 44753 | Z8: 44753
A9: 44750 | B9: 44750 | C9: 44750 | D9: 44750 | E9: 44750 | F9: 44750 | G9: 44750 | I9: Almighty Tycoon | J9: 44750 | K9: 7 | L9: 44750 | M9: 7 | N9: 44750 | O9: 7 | P9: 44750 | S9: Into Sublime | T9: 8:30-10:30 | U9: 8:30-10:30 | V9: 8:30-10:30 | W9: 8:30-10:30 | X9: 8:30-10:30 | Y9: 8:30-10:30 | Z9: 8:30-10:30
A10: 44750 | B10: 44750 | C10: 44750 | D10: 44750 | E10: 44750 | F10: 44750 | G10: 44751 | I10: Scomancer | J10: 44753 | K10: 44753 | L10: 44845 | M10: 44753 | N10: 44753 | O10: 44753 | P10: 44845 | S10: Zavi | T10: 44753 | U10: NA | V10: NA | W10: NA | X10: NA | Y10: 7-10:30 | Z10: 44751
A11: 44750 | B11: 44750 | C11: 44750 | D11: 44750 | E11: 44750 | F11: 44750 | G11: 44751 | J11: 44750 | K11: No | L11: 44845 | M11: 8:30-10:30 | N11: 7-10:30 | O11: 44751 | P11: 44845 | T11: 8:30-10:30 | U11: no | V11: no | W11: no | X11: no | Y11: 8:30-10:30 | Z11: 8:30-9
A12: 44750 | B12: 44750 | C12: 44750 | D12: 44750 | E12: 44750 | F12: 44750 | G12: 44751 | I12: cxrnchip | J12: 44753 | K12: 44753 | L12: 44753 | M12: 44753 | N12: 44753 | O12: 44753 | P12: 44753 | S12: Eternlx | T12: 7 | U12: 7 | V12: 7 | W12: 44750 | X12: 7 | Y12: 44750 | Z12: 7
A13: 44750 | B13: 44751 | C13: 44750 | D13: 44750 | E13: 44750 | F13: 44751 | G13: 44751 | I13: MysticalNovice | J13: 8:30-11 | K13: 8:30-11 | L13: 8:30-11 | M13: 8:30-11 | N13: 8:30-11 | O13: 8:30-11 | P13: 8:30-11 | S13: Doerstopper | T13: 44815 | U13: 44815 | V13: 44815 | W13: 44815 | X13: 44815 | Y13: 44815 | Z13: 44815
A14: 44751 | B14: 44751 | C14: 44751 | D14: 44750 | E14: 44750 | F14: 44751 | G14: 44752 | I14: PoisonxPoptart | J14: NA | K14: 8-9:30 | L14: 8-9:30 | M14: 8-9:30 | N14: 8-9:30 | O14: 8-9:30 | P14: NA | S14: Priest XYZ | T14: 7-10:30 | U14: 44814 | V14: NA | W14: NA | X14: NA | Y14: NA | Z14: 7-10:30
A15: 44751 | B15: 44753 | C15: 44751 | D15: 44751 | E15: 44750 | F15: 44751 | G15: 44753 | I15: x Greenthumb | J15: 9:30-11 | K15: 9:30-11 | L15: 9:30-11 | M15: 9:30-11 | N15: 9:30-11 | O15: 9:30-11 | P15: 9:30-11 | S15: JollyJhadIst | T15: 0.3125 | U15: 0.3125 | V15: 0.3125 | W15: 0.3125 | X15: 0.3125 | Y15: 0.3125 | Z15: 0.3125
A16: 44753 | B16: 44753 | C16: 44753 | D16: 44751 | E16: 44751 | F16: 44752 | G16: 44753 | J16: 9:30-11 | K16: 8:30-9:30 | L16: 8:30-9:30 | M16: 8:30-9:30 | N16: 8:30-9:30 | O16: 8:30-9:30 | P16: 9:30-11 | T16: 9-10:30 | U16: 44814 | V16: no | W16: no | X16: no | Y16: no | Z16: 9-10:30
A17: 44753 | B17: 44753 | C17: 44753 | D17: 44753 | E17: 44751 | F17: 44753 | G17: 44753 | I17: Bear is Clutch | J17: 44845 | K17: 44845 | L17: 44845 | M17: 44845 | N17: 44845 | O17: 44845 | P17: 44845 | S17: Solace | T17: 7-10:30 | U17: 7-10:30 | V17: NA | W17: NA | X17: NA | Y17: NA | Z17: 7-10:30
A18: 44753 | B18: 44753 | C18: 44753 | D18: 44753 | E18: 44753 | F18: 44753 | G18: 44753 | I18: ASpence501 | J18: 44753 | K18: 44753 | L18: 44753 | M18: 44753 | N18: 44753 | O18: 44753 | P18: 44753 | S18: Myst the Cold | T18: 8 | U18: 8 | V18: 8 | W18: 8 | X18: 8 | Y18: 8 | Z18: 8
A19: 44753 | B19: 44753 | C19: 44753 | D19: 44753 | E19: 44753 | F19: 44753 | G19: 44753 | I19: Mr Epic Beast | J19: 44753 | K19: 8:30-11 | L19: 8:30-11 | M19: 8:30-11 | N19: 8:30-11 | O19: 8:30-11 | P19: 44753 | S19: BLOODEN NICK | T19: 44753 | U19: 44815 | V19: 44815 | W19: 44815 | X19: 911 | Y19: 44815 | Z19: 44815
A20: 44753 | B20: 44753 | C20: 44784 | D20: 44753 | E20: 44753 | F20: 44753 | G20: 44753 | I20: Óðinn Æsir | J20: 7 | K20: 7 | L20: 7 | M20: 7 | N20: 7 | O20: 7 | P20: 7 | S20: kev1897 | T20: 44784 | U20: 44784 | V20: 44784 | W20: 44784 | X20: 44784 | Y20: 44784 | Z20: 8-10:30
A21: 44753 | B21: 44784 | C21: 44815 | D21: 44753 | E21: 44753 | F21: 44753 | G21: 44753 | J21: 44845 | K21: 44845 | L21: 44845 | M21: 8:30-11 | N21: 8:30-11 | O21: 44845 | P21: 44845 | T21: 8-10:30 | U21: 8-10:30 | V21: no | W21: no | X21: no | Y21: no | Z21: 8-10:30
A22: 44753 | B22: 44784 | C22: 44815 | D22: 44784 | E22: 44753 | F22: 44753 | G22: 44753 | M22: 7 (2nd) | N22: 7 (3rd) | S22: yLuxe | T22: 7:30-11 | U22: 7:30-11 | V22: 7:30-11 | W22: 7:30-11 | X22: 7:30-11 | Y22: 7:30-11 | Z22: 7:30-11
A23: 44753 | B23: 44784 | C23: 44815 | D23: 44784 | E23: 44784 | F23: 44753 | G23: 44753 | M23: 7 (9th) | N23: 7 (10th) | S23: LilSkelR1926 | T23: 11 | U23: 7 | V23: 7 | W23: 11 | X23: 11 | Y23: 11 | Z23: 44753
A24: 44753 | B24: 44815 | C24: 44815 | D24: 44815 | E24: 44815 | F24: 44753 | G24: 44753 | S24: oDhmon | T24: 44753 | U24: 44753 | V24: 44753 | W24: 44753 | X24: 44753 | Y24: 44753 | Z24: 44753
A25: 44753 | B25: 44815 | C25: 44845 | D25: 44815 | E25: 44815 | F25: 44784 | G25: 44753 | L25: mon/tue/fri/sat | S25: AwareMosquito | T25: 7-8:30 | U25: 7-8:30 | V25: 7-8:30 | W25: 7-8:30 | X25: 7-8:30 | Y25: 44752 | Z25: 44752
A26: 44753 | B26: 44845 | C26: 10:30-11 | D26: 44845 | E26: 44815 | F26: 44815 | G26: 44753 | K26: Check | L26: Changed | T26: 7-8:30 | U26: 7:30-11 | V26: 7:30-11 | W26: 7:30-8:30 | X26: 7:30-8:30 | Y26: 7:30-10 | Z26: 7:30-10
A27: 44753 | B27: 10-10:30 | C27: 7-10:30 | D27: 7-8:30 | E27: 44845 | F27: 44815 | G27: 44815 | S27: Rage More Nerd | T27: 44753 | U27: NA | V27: NA | W27: 9 | X27: 9 | Y27: 9 | Z27: 7
A28: 44784 | B28: 7-10:30 | C28: 7-8:30 | D28: 7-9:30 | E28: 7-10:30 | F28: 44845 | G28: 44845 | S28: Dabb | T28: 44753 | U28: 44750 | V28: 44750 | W28: 44750 | X28: 44784 | Y28: 44784 | Z28: 44784
A29: 44784 | B29: 7-8:30 | C29: 7-9:30 | D29: 7-9:30 | E29: 7-8:30 | F29: 7-10:30 | G29: 10:30-11 | S29: slayers0n | T29: 44753 | U29: NA | V29: 44815 | W29: NA | X29: 44815 | Y29: NA | Z29: 44753
A30: 44845 | B30: 7-9:30 | C30: 7-9:30 | D30: 7:30-11 | E30: 7-9:30 | F30: 7-8:30 | G30: 7-10:30 | S30: mstell96 | T30: 44753 | U30: 44815 | V30: 44815 | W30: 44815 | X30: 44815 | Y30: 44815 | Z30: 44753
A31: 7-10:30 | B31: 7-9:30 | C31: 7:30-11 | D31: 8-8:30 | E31: 7-9:30 | F31: 7-9:30 | G31: 7-10:30 | T31: 44753 | U31: no | V31: no | W31: no | X31: 44815 | Y31: no | Z31: 44784
A32: 7-10:30 | B32: 7:30-11 | C32: 8-8:30 | D32: 8-9:30 | E32: 7:30-11 | F32: 7:30-11 | G32: 7-8:30
A33: 7-8:30 | B33: 8-8:30 | C33: 8-9:30 | D33: 8:30-10:30 | E33: 8-8:30 | F33: 8-8:30 | G33: 7-9:30
A34: 7-9:30 | B34: 8-9:30 | C34: 8:30-10:30 | D34: 8:30-10:30 | E34: 8-9:30 | F34: 8-9:30 | G34: 7:30-11
A35: 7-9:30 | B35: 8:30-10:30 | C35: 8:30-11 | D35: 8:30-11 | E35: 8:30-10:30 | F35: 8:30-10:30 | G35: 8-10:30
A36: 7:30-11 | B36: 8:30-11 | C36: 8:30-11 | D36: 8:30-11 | E36: 8:30-11 | F36: 8:30-11 | G36: 8:30-10:30
A37: 8:30-10:30 | B37: 8:30-11 | C37: 9:30-11 | D37: 9:30-11 | E37: 8:30-11 | F37: 8:30-11 | G37: 8:30-11
A38: 8:30-11 | B38: 9:30-11 | C38: 9:30-11 | D38: 9:30-11 | E38: 9:30-11 | F38: 9:30-11 | G38: 8:30-9
A39: 9:30-11 | B39: 9:30-11 | C39: NA | D39: NA | E39: 9:30-11 | F39: 9:30-11 | G39: 9:30-11
A40: 9:30-11 | B40: NA | C40: NA | D40: NA | E40: NA | F40: NA | G40: 9:30-11
...

Sheet Mock2 Page
G1: Round 1
A4: Captain | B4: Pool Total | C4: Round Credit Ended | D4: You need this left | E4: Base Value | G4: Player Name | H4: ASpence501 | J4: Amnatu | L4: AwareMosquito | N4: Dabb | P4: Almighty Tycoon | R4: Doerstopper | T4: cxrnchip | V4: gaebpls | X4: mstell96 | Z4: MuNgO PuNgO | AD4: Captain | AE4: Player 1 | AF4: Player 2 | AG4: Player 3
A5: Bear is Clutch | B5: =(600-E5)-IFERROR(VLOOKUP(A5,H$11:I$21,2,False),"")-IFERROR(VLOOKUP(A5,J$11:K$21,2,False),"")-IFERROR(VLOOKUP(A5,L$11:M$21,2,False),"")-IFERROR(VLOOKUP(A5,N$11:O$21,2,False),"")-IFERROR(VLOOKUP(A5,P$11:Q$21,2,False),"")-IFERROR(VLOOKUP(A5,R$11:S$21,2,False),"")-IFERROR(VLOOKUP(A5,T$11:U$21,2,False),"")-IFERROR(VLOOKUP(A5,V$11:W$21,2,False),"")-IFERROR(VLOOKUP(A5,X$11:Y$21,2,False),"")-IFERROR(VLOOKUP(A5,Z$11:AA$21,2,False),"") -> 570 | C5: 570 | D5: 60 | E5: =IFERROR(VLOOKUP(A5,'Bid Values'!A:F,3,0),) -> 30 | G5: Base Value | H5: {=INDEX(Signed,Match(H4,Signed!$A$1:$A$43,0),3)} -> 198 | J5: {=INDEX(Signed,Match(J4,Signed!$A$1:$A$43,0),3)} -> 30 | L5: {=INDEX(Signed,Match(L4,Signed!$A$1:$A$43,0),3)} -> 60 | N5: {=INDEX(Signed,Match(N4,Signed!$A$1:$A$43,0),3)} -> 198 | P5: {=INDEX(Signed,Match(P4,Signed!$A$1:$A$43,0),3)} -> 60 | R5: {=INDEX(Signed,Match(R4,Signed!$A$1:$A$43,0),3)} -> 60 | T5: {=INDEX(Signed,Match(T4,Signed!$A$1:$A$43,0),3)} -> 150 | V5: {=INDEX(Signed,Match(V4,Signed!$A$1:$A$43,0),3)} -> 30 | X5: {=INDEX(Signed,Match(X4,Signed!$A$1:$A$43,0),3)} -> 60 | Z5: {=INDEX(Signed,Match(Z4,Signed!$A$1:$A$43,0),3)} -> 60 | AD5: Bear is Clutch | AE5: Beam1n1 | AF5: Doerstopper | AG5: MuNgO PuNgO
A6: CaptainSev004 | B6: =(600-E6)-IFERROR(VLOOKUP(A6,H$11:I$21,2,False),"")-IFERROR(VLOOKUP(A6,J$11:K$21,2,False),"")-IFERROR(VLOOKUP(A6,L$11:M$21,2,False),"")-IFERROR(VLOOKUP(A6,N$11:O$21,2,False),"")-IFERROR(VLOOKUP(A6,P$11:Q$21,2,False),"")-IFERROR(VLOOKUP(A6,R$11:S$21,2,False),"")-IFERROR(VLOOKUP(A6,T$11:U$21,2,False),"")-IFERROR(VLOOKUP(A6,V$11:W$21,2,False),"")-IFERROR(VLOOKUP(A6,X$11:Y$21,2,False),"")-IFERROR(VLOOKUP(A6,Z$11:AA$21,2,False),"") -> 540 | C6: 279 | D6: 60 | E6: =IFERROR(VLOOKUP(A6,'Bid Values'!A:F,3,0),) -> 60 | G6: Grade | H6: {=INDEX(Signed,Match(H4,Signed!$A$1:$A$43,0),2)} -> A | J6: {=INDEX(Signed,Match(J4,Signed!$A$1:$A$43,0),2)} -> E | L6: {=INDEX(Signed,Match(L4,Signed!$A$1:$A$43,0),2)} -> C | N6: {=INDEX(Signed,Match(N4,Signed!$A$1:$A$43,0),2)} -> A | P6: {=INDEX(Signed,Match(P4,Signed!$A$1:$A$43,0),2)} -> C | R6: {=INDEX(Signed,Match(R4,Signed!$A$1:$A$43,0),2)} -> D | T6: {=INDEX(Signed,Match(T4,Signed!$A$1:$A$43,0),2)} -> B | V6: {=INDEX(Signed,Match(V4,Signed!$A$1:$A$43,0),2)} -> E | X6: {=INDEX(Signed,Match(X4,Signed!$A$1:$A$43,0),2)} -> D | Z6: {=INDEX(Signed,Match(Z4,Signed!$A$1:$A$43,0),2)} -> D | AD6: CaptainSev004 | AE6: ASpence501 | AF6: oDhmon | AG6: gaebpls
A7: G3Ohh | B7: =(600-E7)-IFERROR(VLOOKUP(A7,H$11:I$21,2,False),"")-IFERROR(VLOOKUP(A7,J$11:K$21,2,False),"")-IFERROR(VLOOKUP(A7,L$11:M$21,2,False),"")-IFERROR(VLOOKUP(A7,N$11:O$21,2,False),"")-IFERROR(VLOOKUP(A7,P$11:Q$21,2,False),"")-IFERROR(VLOOKUP(A7,R$11:S$21,2,False),"")-IFERROR(VLOOKUP(A7,T$11:U$21,2,False),"")-IFERROR(VLOOKUP(A7,V$11:W$21,2,False),"")-IFERROR(VLOOKUP(A7,X$11:Y$21,2,False),"")-IFERROR(VLOOKUP(A7,Z$11:AA$21,2,False),"") -> 540 | C7: 540 | D7: 60 | E7: =IFERROR(VLOOKUP(A7,'Bid Values'!A:F,3,0),) -> 60 | G7: Highest Bid | H7: =If(MAX('Round 11'!$C:$C)>=H5,MAX('Round 11'!$C:$C),0) -> #REF! | J7: =If(MAX('Round 11'!$D:$D)>=J5,MAX('Round 11'!$D:$D),0) -> #REF! | L7: =If(MAX('Round 11'!$E:$E)>=L5,MAX('Round 11'!$E:$E),0) -> #REF! | N7: =If(MAX('Round 11'!$F:$F)>=N5,MAX('Round 11'!$F:$F),0) -> #REF! | P7: =If(MAX('Round 11'!$G:$G)>=P5,MAX('Round 11'!$G:$G),0) -> #REF! | R7: =If(MAX('Round 11'!$H:$H)>=R5,MAX('Round 11'!$H:$H),0) -> #REF! | T7: =If(MAX('Round 11'!$I:$I)>=T5,MAX('Round 11'!$I:$I),0) -> #REF! | V7: =If(MAX('Round 11'!$J:$J)>=V5,MAX('Round 11'!$J:$J),0) -> #REF! | X7: =If(MAX('Round 11'!$K:$K)>=X5,MAX('Round 11'!$K:$K),0) -> #REF! | Z7: =If(MAX('Round 11'!$L:$L)>=Z5,MAX('Round 11'!$L:$L),0) -> #REF! | AD7: G3Ohh | AE7: Mavbrid | AF7: Reyas | AG7: Mr Epic Beast
A8: Eternlx | B8: =(600-E8)-IFERROR(VLOOKUP(A8,H$11:I$21,2,False),"")-IFERROR(VLOOKUP(A8,J$11:K$21,2,False),"")-IFERROR(VLOOKUP(A8,L$11:M$21,2,False),"")-IFERROR(VLOOKUP(A8,N$11:O$21,2,False),"")-IFERROR(VLOOKUP(A8,P$11:Q$21,2,False),"")-IFERROR(VLOOKUP(A8,R$11:S$21,2,False),"")-IFERROR(VLOOKUP(A8,T$11:U$21,2,False),"")-IFERROR(VLOOKUP(A8,V$11:W$21,2,False),"")-IFERROR(VLOOKUP(A8,X$11:Y$21,2,False),"")-IFERROR(VLOOKUP(A8,Z$11:AA$21,2,False),"") -> 540 | C8: 540 | D8: 60 | E8: =IFERROR(VLOOKUP(A8,'Bid Values'!A:F,3,0),) -> 60 | G8: Highest Bidder | H8: =H11 | I8: =I11 | J8: =J11 | K8: =K11 | L8: =L11 | M8: =M11 | N8: =N11 | O8: =O11 | ... V8: =V11 | X8: =X11 | Z8: =Z11 | AD8: Eternlx | AE8: TommyWstSide | AF8: Into Sublime | AG8: LilSkelR1926
A9: Solace | B9: =(600-E9)-IFERROR(VLOOKUP(A9,H$11:I$21,2,False),"")-IFERROR(VLOOKUP(A9,J$11:K$21,2,False),"")-IFERROR(VLOOKUP(A9,L$11:M$21,2,False),"")-IFERROR(VLOOKUP(A9,N$11:O$21,2,False),"")-IFERROR(VLOOKUP(A9,P$11:Q$21,2,False),"")-IFERROR(VLOOKUP(A9,R$11:S$21,2,False),"")-IFERROR(VLOOKUP(A9,T$11:U$21,2,False),"")-IFERROR(VLOOKUP(A9,V$11:W$21,2,False),"")-IFERROR(VLOOKUP(A9,X$11:Y$21,2,False),"")-IFERROR(VLOOKUP(A9,Z$11:AA$21,2,False),"") -> 402 | C9: 102 | D9: 60 | E9: 198 | G9: Captain Bid List | AD9: Solace | AE9: Dabb | AF9: Myst the Cold | AG9: JollyJhadIst
