Workbook

Sheet Teams
A5: Team Name: | B5: OREO | C5: The Crawller Death Squad | D5: The Grif S.A.G.A. | E5: Mystery Heroes | F5: Trespa5s | G5: Off in the Shower | H5: Ram Ranch | I5: MenZ's Grossly Large Backpack | J5: USURPER SZN | K5: Glory 2 God | L5: Quit Fuckin Betrayin’ Me
A7: Captain: | B7: OREOTHECAT | C7: Deathcrawller | D7: amnatu | E7: Holy Morals | F7: Trespa5s | G7: Doerstopper | H7: MuNgO PuNgO | I7: Scullen cx | J7: Spankatr0n | K7: ASpence501 | L7: MysticalNovice
A8: 1st Round: | B8: Clydrohsun | C8: yLuxe | D8: Ace B S1lentND1 | E8: Memorized | F8: Itzreelz | G8: DCleak | H8: Fanciest Pants | I8: Jussshhhyyy | J8: Scomancer | K8: oh zilly | L8: Mavbrid
A9: 2nd Round: | B9: Pd Craig 69 | C9: CaptainSev004 | D9: Grunt Padre | E9: Immørzlx | F9: Mr epic beast | G9: Beam1n1 | H9: Tommyywestside | I9: Its Rainin MenZ | J9: AwareMosquito | K9: NOPLEX | L9: Almighty Tycoon
A10: 3rd Round: | B10: ThePro#1771 | C10: TJP37 | D10: ABOVEAVGJ0HN | E10: Priest XYZ | F10: GeneralCornBeef | G10: WeirdPG | H10: KDSkill | I10: Ram Osneb | J10: StarMonster8129 | K10: Ken Khaneki | L10: THEChickyGod
E13: Team Standings | G13: Record
E14: Quit Fuckin Betrayin’ Me (Novice) | G14: 18-2
E15: Glory 2 God (ASpence) | G15: 16-4
E16: Mystery Heroes (Holy) | G16: 16-4
E17: The Crawller Death Squad (Death) | G17: 14-6
E18: MenZ's Grossly Large Backpack (Scullen cx) | G18: 11-9
E19: Ram Ranch (MuNgO PuNgO) | G19: 10-10
E20: USURPER SZN (Spank) | G20: 8-12
E21: The Grif S.A.G.A. (amnatu) | G21: 8-12
E22: Off In The Shower (Doerstopper) | G22: 4-16
E23: Trespa5s | G23: 2-18
E24: OREOTHECAT | G24: 2-18
E25: Off In The Shower (Doerstopper) | G25: 4-16

Sheet Team Stats
A1: Team Names | B1: Player | C1: Games | D1: Wins | E1: Losses | F1: Goals | G1: Ball Punches | H1: Kills | I1: Deaths | J1: K-D Spread | K1: Assists | L1: Game Time | M1: Sprees | N1: Frenzys+ | O1: Grand Slam | P1: Double Kills | Q1: Triple Kills | R1: Over+ | S1: Exterms | T1: Pancakes | U1: Player Grade | V1: PlayerGrade Rating
A2: The Crawller Death Squad | B2: Deathcrawller | C2: =IFERROR(VLOOKUP($B2,'Halo Infinite Stats'!$A:$AM,2,0),) -> 22 | D2: =IFERROR(VLOOKUP($B2,'Halo Infinite Stats'!$A:$AM,3,0),) -> 15 | E2: =IFERROR(VLOOKUP($B2,'Halo Infinite Stats'!$A:$AM,4,0),) -> 7 | F2: =IFERROR(VLOOKUP($B2,'Halo Infinite Stats'!$A:$AM,5,0),) -> 7 | G2: =IFERROR(VLOOKUP($B2,'Halo Infinite Stats'!$A:$AM,6,0),) -> 22 | H2: =IFERROR(VLOOKUP($B2,'Halo Infinite Stats'!$A:$AM,7,0),) -> 766 | I2: =IFERROR(VLOOKUP($B2,'Halo Infinite Stats'!$A:$AM,8,0),) -> 996 | J2: =IFERROR(VLOOKUP($B2,'Halo Infinite Stats'!$A:$AM,9,0),) -> -230 | K2: =IFERROR(VLOOKUP($B2,'Halo Infinite Stats'!$A:$AM,11,0),) -> 4 | L2: =IFERROR(TEXT(VLOOKUP($B2,'Halo Infinite Stats'!$A:$AM,12,0)/(24*60*60),"hh:mm:ss"),"") -> 05:14:55 | M2: =IFERROR(VLOOKUP($B2,'Halo Infinite Stats'!$A:$AM,14,0),) -> 5 | N2: =IFERROR(VLOOKUP($B2,'Halo Infinite Stats'!$A:$AM,15,0),)+IFERROR(VLOOKUP($B2,'Halo Infinite Stats'!$A:$AM,16,0),)+IFERROR(VLOOKUP($B2,'Halo Infinite Stats'!$A:$AM,17,0),) -> 0 | O2: =IFERROR(VLOOKUP($B2,'Halo Infinite Stats'!$A:$AM,18,0),) -> 10 | P2: =IFERROR(VLOOKUP($B2,'Halo Infinite Stats'!$A:$AM,19,0),) -> 110 | Q2: =IFERROR(VLOOKUP($B2,'Halo Infinite Stats'!$A:$AM,20,0),) -> 22 | R2: =IFERROR(VLOOKUP($B2,'Halo Infinite Stats'!$A:$AM,21,0),)+IFERROR(VLOOKUP($B2,'Halo Infinite Stats'!$A:$AM,22,0),)+IFERROR(VLOOKUP($B2,'Halo Infinite Stats'!$A:$AM,23,0),)+IFERROR(VLOOKUP($B2,'Halo Infinite Stats'!$A:$AM,24,0),)+IFERROR(VLOOKUP($B2,'Halo Infinite Stats'!$A:$AM,25,0),)+IFERROR(VLOOKUP($B2,'Halo Infinite Stats'!$A:$AM,26,0),)+IFERROR(VLOOKUP($B2,'Halo Infinite Stats'!$A:$AM,27,0),) -> 2 | S2: =IFERROR(VLOOKUP($B2,'Halo Infinite Stats'!$A:$AM,28,0),) -> 0 | T2: =IFERROR(VLOOKUP($B2,'Halo Infinite Stats'!$A:$AM,31,0),) -> 1 | U2: =IFERROR(VLOOKUP($B2,'PlayerGrades+'!$A:$W,22,0),) -> E | V2: =IFERROR(VLOOKUP($B2,'PlayerGrades+'!$A:$W,23,0),) -> 9.925 | X2: =(HOUR(L2) * 3600) + (MINUTE(L2) * 60) + SECOND(L2) -> 18895
A3: The Crawller Death Squad | B3: yLuxe | C3: =IFERROR(VLOOKUP($B3,'Halo Infinite Stats'!$A:$AM,2,0),) -> 20 | D3: =IFERROR(VLOOKUP($B3,'Halo Infinite Stats'!$A:$AM,3,0),) -> 13 | E3: =IFERROR(VLOOKUP($B3,'Halo Infinite Stats'!$A:$AM,4,0),) -> 7 | F3: =IFERROR(VLOOKUP($B3,'Halo Infinite Stats'!$A:$AM,5,0),) -> 33 | G3: =IFERROR(VLOOKUP($B3,'Halo Infinite Stats'!$A:$AM,6,0),) -> 88 | H3: =IFERROR(VLOOKUP($B3,'Halo Infinite Stats'!$A:$AM,7,0),) -> 985 | I3: =IFERROR(VLOOKUP($B3,'Halo Infinite Stats'!$A:$AM,8,0),) -> 943 | J3: =IFERROR(VLOOKUP($B3,'Halo Infinite Stats'!$A:$AM,9,0),) -> 42 | K3: =IFERROR(VLOOKUP($B3,'Halo Infinite Stats'!$A:$AM,11,0),) -> 1 | L3: =IFERROR(TEXT(VLOOKUP($B3,'Halo Infinite Stats'!$A:$AM,12,0)/(24*60*60),"hh:mm:ss"),"") -> 04:59:22 | M3: =IFERROR(VLOOKUP($B3,'Halo Infinite Stats'!$A:$AM,14,0),) -> 22 | N3: =IFERROR(VLOOKUP($B3,'Halo Infinite Stats'!$A:$AM,15,0),)+IFERROR(VLOOKUP($B3,'Halo Infinite Stats'!$A:$AM,16,0),)+IFERROR(VLOOKUP($B3,'Halo Infinite Stats'!$A:$AM,17,0),) -> 2 | O3: =IFERROR(VLOOKUP($B3,'Halo Infinite Stats'!$A:$AM,18,0),) -> 12 | P3: =IFERROR(VLOOKUP($B3,'Halo Infinite Stats'!$A:$AM,19,0),) -> 174 | Q3: =IFERROR(VLOOKUP($B3,'Halo Infinite Stats'!$A:$AM,20,0),) -> 55 | R3: =IFERROR(VLOOKUP($B3,'Halo Infinite Stats'!$A:$AM,21,0),)+IFERROR(VLOOKUP($B3,'Halo Infinite Stats'!$A:$AM,22,0),)+IFERROR(VLOOKUP($B3,'Halo Infinite Stats'!$A:$AM,23,0),)+IFERROR(VLOOKUP($B3,'Halo Infinite Stats'!$A:$AM,24,0),)+IFERROR(VLOOKUP($B3,'Halo Infinite Stats'!$A:$AM,25,0),)+IFERROR(VLOOKUP($B3,'Halo Infinite Stats'!$A:$AM,26,0),)+IFERROR(VLOOKUP($B3,'Halo Infinite Stats'!$A:$AM,27,0),) -> 28 | S3: =IFERROR(VLOOKUP($B3,'Halo Infinite Stats'!$A:$AM,28,0),) -> 1 | T3: =IFERROR(VLOOKUP($B3,'Halo Infinite Stats'!$A:$AM,31,0),) -> 1 | U3: =IFERROR(VLOOKUP($B3,'PlayerGrades+'!$A:$W,22,0),) -> S- | V3: =IFERROR(VLOOKUP($B3,'PlayerGrades+'!$A:$W,23,0),) -> 25.375 | X3: =(HOUR(L3) * 3600) + (MINUTE(L3) * 60) + SECOND(L3) -> 17962
A4: The Crawller Death Squad | B4: CaptainSev004 | C4: =IFERROR(VLOOKUP($B4,'Halo Infinite Stats'!$A:$AM,2,0),) -> 19 | D4: =IFERROR(VLOOKUP($B4,'Halo Infinite Stats'!$A:$AM,3,0),) -> 13 | E4: =IFERROR(VLOOKUP($B4,'Halo Infinite Stats'!$A:$AM,4,0),) -> 6 | F4: =IFERROR(VLOOKUP($B4,'Halo Infinite Stats'!$A:$AM,5,0),) -> 22 | G4: =IFERROR(VLOOKUP($B4,'Halo Infinite Stats'!$A:$AM,6,0),) -> 85 | H4: =IFERROR(VLOOKUP($B4,'Halo Infinite Stats'!$A:$AM,7,0),) -> 656 | I4: =IFERROR(VLOOKUP($B4,'Halo Infinite Stats'!$A:$AM,8,0),) -> 865 | J4: =IFERROR(VLOOKUP($B4,'Halo Infinite Stats'!$A:$AM,9,0),) -> -209 | K4: =IFERROR(VLOOKUP($B4,'Halo Infinite Stats'!$A:$AM,11,0),) -> 1 | L4: =IFERROR(TEXT(VLOOKUP($B4,'Halo Infinite Stats'!$A:$AM,12,0)/(24*60*60),"hh:mm:ss"),"") -> 04:40:36 | M4: =IFERROR(VLOOKUP($B4,'Halo Infinite Stats'!$A:$AM,14,0),) -> 6 | N4: =IFERROR(VLOOKUP($B4,'Halo Infinite Stats'!$A:$AM,15,0),)+IFERROR(VLOOKUP($B4,'Halo Infinite Stats'!$A:$AM,16,0),)+IFERROR(VLOOKUP($B4,'Halo Infinite Stats'!$A:$AM,17,0),) -> 0 | O4: =IFERROR(VLOOKUP($B4,'Halo Infinite Stats'!$A:$AM,18,0),) -> 8 | P4: =IFERROR(VLOOKUP($B4,'Halo Infinite Stats'!$A:$AM,19,0),) -> 96 | Q4: =IFERROR(VLOOKUP($B4,'Halo Infinite Stats'!$A:$AM,20,0),) -> 31 | R4: =IFERROR(VLOOKUP($B4,'Halo Infinite Stats'!$A:$AM,21,0),)+IFERROR(VLOOKUP($B4,'Halo Infinite Stats'!$A:$AM,22,0),)+IFERROR(VLOOKUP($B4,'Halo Infinite Stats'!$A:$AM,23,0),)+IFERROR(VLOOKUP($B4,'Halo Infinite Stats'!$A:$AM,24,0),)+IFERROR(VLOOKUP($B4,'Halo Infinite Stats'!$A:$AM,25,0),)+IFERROR(VLOOKUP($B4,'Halo Infinite Stats'!$A:$AM,26,0),)+IFERROR(VLOOKUP($B4,'Halo Infinite Stats'!$A:$AM,27,0),) -> 12 | S4: =IFERROR(VLOOKUP($B4,'Halo Infinite Stats'!$A:$AM,28,0),) -> 0 | T4: =IFERROR(VLOOKUP($B4,'Halo Infinite Stats'!$A:$AM,31,0),) -> 0 | U4: =IFERROR(VLOOKUP($B4,'PlayerGrades+'!$A:$W,22,0),) -> C | V4: =IFERROR(VLOOKUP($B4,'PlayerGrades+'!$A:$W,23,0),) -> 14.725 | X4: =(HOUR(L4) * 3600) + (MINUTE(L4) * 60) + SECOND(L4) -> 16836
A5: The Crawller Death Squad | B5: TJP37 | C5: =IFERROR(VLOOKUP($B5,'Halo Infinite Stats'!$A:$AM,2,0),) -> 22 | D5: =IFERROR(VLOOKUP($B5,'Halo Infinite Stats'!$A:$AM,3,0),) -> 13 | E5: =IFERROR(VLOOKUP($B5,'Halo Infinite Stats'!$A:$AM,4,0),) -> 9 | F5: =IFERROR(VLOOKUP($B5,'Halo Infinite Stats'!$A:$AM,5,0),) -> 18 | G5: =IFERROR(VLOOKUP($B5,'Halo Infinite Stats'!$A:$AM,6,0),) -> 72 | H5: =IFERROR(VLOOKUP($B5,'Halo Infinite Stats'!$A:$AM,7,0),) -> 1031 | I5: =IFERROR(VLOOKUP($B5,'Halo Infinite Stats'!$A:$AM,8,0),) -> 1116 | J5: =IFERROR(VLOOKUP($B5,'Halo Infinite Stats'!$A:$AM,9,0),) -> -85 | K5: =IFERROR(VLOOKUP($B5,'Halo Infinite Stats'!$A:$AM,11,0),) -> 3 | L5: =IFERROR(TEXT(VLOOKUP($B5,'Halo Infinite Stats'!$A:$AM,12,0)/(24*60*60),"hh:mm:ss"),"") -> 05:42:26 | M5: =IFERROR(VLOOKUP($B5,'Halo Infinite Stats'!$A:$AM,14,0),) -> 18 | N5: =IFERROR(VLOOKUP($B5,'Halo Infinite Stats'!$A:$AM,15,0),)+IFERROR(VLOOKUP($B5,'Halo Infinite Stats'!$A:$AM,16,0),)+IFERROR(VLOOKUP($B5,'Halo Infinite Stats'!$A:$AM,17,0),) -> 1 | O5: =IFERROR(VLOOKUP($B5,'Halo Infinite Stats'!$A:$AM,18,0),) -> 16 | P5: =IFERROR(VLOOKUP($B5,'Halo Infinite Stats'!$A:$AM,19,0),) -> 165 | Q5: =IFERROR(VLOOKUP($B5,'Halo Infinite Stats'!$A:$AM,20,0),) -> 51 | R5: =IFERROR(VLOOKUP($B5,'Halo Infinite Stats'!$A:$AM,21,0),)+IFERROR(VLOOKUP($B5,'Halo Infinite Stats'!$A:$AM,22,0),)+IFERROR(VLOOKUP($B5,'Halo Infinite Stats'!$A:$AM,23,0),)+IFERROR(VLOOKUP($B5,'Halo Infinite Stats'!$A:$AM,24,0),)+IFERROR(VLOOKUP($B5,'Halo Infinite Stats'!$A:$AM,25,0),)+IFERROR(VLOOKUP($B5,'Halo Infinite Stats'!$A:$AM,26,0),)+IFERROR(VLOOKUP($B5,'Halo Infinite Stats'!$A:$AM,27,0),) -> 14 | S5: =IFERROR(VLOOKUP($B5,'Halo Infinite Stats'!$A:$AM,28,0),) -> 1 | T5: =IFERROR(VLOOKUP($B5,'Halo Infinite Stats'!$A:$AM,31,0),) -> 4 | U5: =IFERROR(VLOOKUP($B5,'PlayerGrades+'!$A:$W,22,0),) -> A- | V5: =IFERROR(VLOOKUP($B5,'PlayerGrades+'!$A:$W,23,0),) -> 21.0125 | X5: =(HOUR(L5) * 3600) + (MINUTE(L5) * 60) + SECOND(L5) -> 20546
A6: The Crawller Death Squad | B6: TOTALS: | C6: =SUM(C2:C5) -> 83 | D6: =SUM(D2:D5) -> 54 | E6: =SUM(E2:E5) -> 29 | F6: =SUM(F2:F5) -> 80 | G6: =SUM(G2:G5) -> 267 | H6: =SUM(H2:H5) -> 3438 | I6: =SUM(I2:I5) -> 3920 | J6: =MINUS(H6,I6) -> -482 | K6: =SUM(K2:K5) -> 9 | L6: =TEXT(X12/86400, "hh:mm:ss") -> 23:41:47 | M6: =SUM(M2:M5) -> 51 | N6: =SUM(N2:N5) -> 3 | O6: =SUM(O2:O5) -> 46 | P6: =SUM(P2:P5) -> 545 | Q6: =SUM(Q2:Q5) -> 159 | R6: =SUM(R2:R5) -> 56 | S6: =SUM(S2:S5) -> 2 | T6: =SUM(T2:T5) -> 6 | U6: =IF(((V2+V3+V4+V5)/4)<='PlayerGrades+'!$Y$44,"F-",IF(((V2+V3+V4+V5)/4)<'PlayerGrades+'!$Y$43,"F",IF(((V2+V3+V4+V5)/4)<'PlayerGrades+'!$Y$42,"F+",IF(((V2+V3+V4+V5)/4)<'PlayerGrades+'!$Y$41,"E-",IF(((V2+V3+V4+V5)/4)<'PlayerGrades+'!$Y$40,"E",IF(((V2+V3+V4+V5)/4)<'PlayerGrades+'!$Y$39,"E+",IF(((V2+V3+V4+V5)/4)<'PlayerGrades+'!$Y$38,"D-",IF(((V2+V3+V4+V5)/4)<'PlayerGrades+'!$Y$37,"D",IF(((V2+V3+V4+V5)/4)<'PlayerGrades+'!$Y$36,"D+",IF(((V2+V3+V4+V5)/4)<'PlayerGrades+'!$Y$35,"C-",IF(((V2+V3+V4+V5)/4)<'PlayerGrades+'!$Y$34,"C",IF(((V2+V3+V4+V5)/4)<'PlayerGrades+'!$Y$33,"C+",IF(((V2+V3+V4+V5)/4)<'PlayerGrades+'!$Y$32,"B-",IF(((V2+V3+V4+V5)/4)<'PlayerGrades+'!$Y$31,"B",IF(((V2+V3+V4+V5)/4)<'PlayerGrades+'!$Y$30,"B+",IF(((V2+V3+V4+V5)/4)<'PlayerGrades+'!$Y$29,"A-",IF(((V2+V3+V4+V5)/4)<'PlayerGrades+'!$Y$28,"A",IF(((V2+V3+V4+V5)/4)<'PlayerGrades+'!$Y$27,"A+",IF(((V2+V3+V4+V5)/4)<'PlayerGrades+'!$Y$26,"S-",IF(((V2+V3+V4+V5)/4)<'PlayerGrades+'!$Y$25,"S","S+")))))))))))))))))))) -> B- | V6: Team AVG | X6: =SUM(X2:X5) -> 74239
A8: Mystery Heroes | B8: Holy Morals | C8: =IFERROR(VLOOKUP($B8,'Halo Infinite Stats'!$A:$AM,2,0),) -> 20 | D8: =IFERROR(VLOOKUP($B8,'Halo Infinite Stats'!$A:$AM,3,0),) -> 16 | E8: =IFERROR(VLOOKUP($B8,'Halo Infinite Stats'!$A:$AM,4,0),) -> 4 | F8: =IFERROR(VLOOKUP($B8,'Halo Infinite Stats'!$A:$AM,5,0),) -> 69 | G8: =IFERROR(VLOOKUP($B8,'Halo Infinite Stats'!$A:$AM,6,0),) -> 268 | H8: =IFERROR(VLOOKUP($B8,'Halo Infinite Stats'!$A:$AM,7,0),) -> 748 | I8: =IFERROR(VLOOKUP($B8,'Halo Infinite Stats'!$A:$AM,8,0),) -> 785 | J8: =IFERROR(VLOOKUP($B8,'Halo Infinite Stats'!$A:$AM,9,0),) -> -37 | K8: =IFERROR(VLOOKUP($B8,'Halo Infinite Stats'!$A:$AM,11,0),) -> 1 | L8: =IFERROR(TEXT(VLOOKUP($B8,'Halo Infinite Stats'!$A:$AM,12,0)/(24*60*60),"hh:mm:ss"),"") -> 04:46:12 | M8: =IFERROR(VLOOKUP($B8,'Halo Infinite Stats'!$A:$AM,14,0),) -> 16 | N8: =IFERROR(VLOOKUP($B8,'Halo Infinite Stats'!$A:$AM,15,0),)+IFERROR(VLOOKUP($B8,'Halo Infinite Stats'!$A:$AM,16,0),)+IFERROR(VLOOKUP($B8,'Halo Infinite Stats'!$A:$AM,17,0),) -> 0 | O8: =IFERROR(VLOOKUP($B8,'Halo Infinite Stats'!$A:$AM,18,0),) -> 5 | P8: =IFERROR(VLOOKUP($B8,'Halo Infinite Stats'!$A:$AM,19,0),) -> 119 | Q8: =IFERROR(VLOOKUP($B8,'Halo Infinite Stats'!$A:$AM,20,0),) -> 37 | R8: =IFERROR(VLOOKUP($B8,'Halo Infinite Stats'!$A:$AM,21,0),)+IFERROR(VLOOKUP($B8,'Halo Infinite Stats'!$A:$AM,22,0),)+IFERROR(VLOOKUP($B8,'Halo Infinite Stats'!$A:$AM,23,0),)+IFERROR(VLOOKUP($B8,'Halo Infinite Stats'!$A:$AM,24,0),)+IFERROR(VLOOKUP($B8,'Halo Infinite Stats'!$A:$AM,25,0),)+IFERROR(VLOOKUP($B8,'Halo Infinite Stats'!$A:$AM,26,0),)+IFERROR(VLOOKUP($B8,'Halo Infinite Stats'!$A:$AM,27,0),) -> 9 | S8: =IFERROR(VLOOKUP($B8,'Halo Infinite Stats'!$A:$AM,28,0),) -> 0 | T8: =IFERROR(VLOOKUP($B8,'Halo Infinite Stats'!$A:$AM,31,0),) -> 2 | U8: =IFERROR(VLOOKUP($B8,'PlayerGrades+'!$A:$W,22,0),) -> B+ | V8: =IFERROR(VLOOKUP($B8,'PlayerGrades+'!$A:$W,23,0),) -> 20.1125 | X8: =(HOUR(L8) * 3600) + (MINUTE(L8) * 60) + SECOND(L8) -> 17172
A9: Mystery Heroes | B9: Memorized | C9: =IFERROR(VLOOKUP($B9,'Halo Infinite Stats'!$A:$AM,2,0),) -> 20 | D9: =IFERROR(VLOOKUP($B9,'Halo Infinite Stats'!$A:$AM,3,0),) -> 16 | E9: =IFERROR(VLOOKUP($B9,'Halo Infinite Stats'!$A:$AM,4,0),) -> 4 | F9: =IFERROR(VLOOKUP($B9,'Halo Infinite Stats'!$A:$AM,5,0),) -> 2 | G9: =IFERROR(VLOOKUP($B9,'Halo Infinite Stats'!$A:$AM,6,0),) -> 8 | H9: =IFERROR(VLOOKUP($B9,'Halo Infinite Stats'!$A:$AM,7,0),) -> 1053 | I9: =IFERROR(VLOOKUP($B9,'Halo Infinite Stats'!$A:$AM,8,0),) -> 1071 | J9: =IFERROR(VLOOKUP($B9,'Halo Infinite Stats'!$A:$AM,9,0),) -> -18 | K9: =IFERROR(VLOOKUP($B9,'Halo Infinite Stats'!$A:$AM,11,0),) -> 4 | L9: =IFERROR(TEXT(VLOOKUP($B9,'Halo Infinite Stats'!$A:$AM,12,0)/(24*60*60),"hh:mm:ss"),"") -> 04:46:12 | M9: =IFERROR(VLOOKUP($B9,'Halo Infinite Stats'!$A:$AM,14,0),) -> 10 | N9: =IFERROR(VLOOKUP($B9,'Halo Infinite Stats'!$A:$AM,15,0),)+IFERROR(VLOOKUP($B9,'Halo Infinite Stats'!$A:$AM,16,0),)+IFERROR(VLOOKUP($B9,'Halo Infinite Stats'!$A:$AM,17,0),) -> 0 | O9: =IFERROR(VLOOKUP($B9,'Halo Infinite Stats'!$A:$AM,18,0),) -> 3 | P9: =IFERROR(VLOOKUP($B9,'Halo Infinite Stats'!$A:$AM,19,0),) -> 180 | Q9: =IFERROR(VLOOKUP($B9,'Halo Infinite Stats'!$A:$AM,20,0),) -> 42 | R9: =IFERROR(VLOOKUP($B9,'Halo Infinite Stats'!$A:$AM,21,0),)+IFERROR(VLOOKUP($B9,'Halo Infinite Stats'!$A:$AM,22,0),)+IFERROR(VLOOKUP($B9,'Halo Infinite Stats'!$A:$AM,23,0),)+IFERROR(VLOOKUP($B9,'Halo Infinite Stats'!$A:$AM,24,0),)+IFERROR(VLOOKUP($B9,'Halo Infinite Stats'!$A:$AM,25,0),)+IFERROR(VLOOKUP($B9,'Halo Infinite Stats'!$A:$AM,26,0),)+IFERROR(VLOOKUP($B9,'Halo Infinite Stats'!$A:$AM,27,0),) -> 13 | S9: =IFERROR(VLOOKUP($B9,'Halo Infinite Stats'!$A:$AM,28,0),) -> 0 | T9: =IFERROR(VLOOKUP($B9,'Halo Infinite Stats'!$A:$AM,31,0),) -> 0 | U9: =IFERROR(VLOOKUP($B9,'PlayerGrades+'!$A:$W,22,0),) -> B- | V9: =IFERROR(VLOOKUP($B9,'PlayerGrades+'!$A:$W,23,0),) -> 17.95 | X9: =(HOUR(L9) * 3600) + (MINUTE(L9) * 60) + SECOND(L9) -> 17172
A10: Mystery Heroes | B10: TommyWstSide | C10: =IFERROR(VLOOKUP($B10,'Halo Infinite Stats'!$A:$AM,2,0),) -> 37 | D10: =IFERROR(VLOOKUP($B10,'Halo Infinite Stats'!$A:$AM,3,0),) -> 22 | E10: =IFERROR(VLOOKUP($B10,'Halo Infinite Stats'!$A:$AM,4,0),) -> 15 | F10: =IFERROR(VLOOKUP($B10,'Halo Infinite Stats'!$A:$AM,5,0),) -> 22 | G10: =IFERROR(VLOOKUP($B10,'Halo Infinite Stats'!$A:$AM,6,0),) -> 62 | H10: =IFERROR(VLOOKUP($B10,'Halo Infinite Stats'!$A:$AM,7,0),) -> 1603 | I10: =IFERROR(VLOOKUP($B10,'Halo Infinite Stats'!$A:$AM,8,0),) -> 1709 | J10: =IFERROR(VLOOKUP($B10,'Halo Infinite Stats'!$A:$AM,9,0),) -> -106 | K10: =IFERROR(VLOOKUP($B10,'Halo Infinite Stats'!$A:$AM,11,0),) -> 9 | L10: =IFERROR(TEXT(VLOOKUP($B10,'Halo Infinite Stats'!$A:$AM,12,0)/(24*60*60),"hh:mm:ss"),"") -> 08:25:48 | M10: =IFERROR(VLOOKUP($B10,'Halo Infinite Stats'!$A:$AM,14,0),) -> 31 | N10: =IFERROR(VLOOKUP($B10,'Halo Infinite Stats'!$A:$AM,15,0),)+IFERROR(VLOOKUP($B10,'Halo Infinite Stats'!$A:$AM,16,0),)+IFERROR(VLOOKUP($B10,'Halo Infinite Stats'!$A:$AM,17,0),) -> 0 | O10: =IFERROR(VLOOKUP($B10,'Halo Infinite Stats'!$A:$AM,18,0),) -> 22 | P10: =IFERROR(VLOOKUP($B10,'Halo Infinite Stats'!$A:$AM,19,0),) -> 272 | Q10: =IFERROR(VLOOKUP($B10,'Halo Infinite Stats'!$A:$AM,20,0),) -> 80 | R10: =IFERROR(VLOOKUP($B10,'Halo Infinite Stats'!$A:$AM,21,0),)+IFERROR(VLOOKUP($B10,'Halo Infinite Stats'!$A:$AM,22,0),)+IFERROR(VLOOKUP($B10,'Halo Infinite Stats'!$A:$AM,23,0),)+IFERROR(VLOOKUP($B10,'Halo Infinite Stats'!$A:$AM,24,0),)+IFERROR(VLOOKUP($B10,'Halo Infinite Stats'!$A:$AM,25,0),)+IFERROR(VLOOKUP($B10,'Halo Infinite Stats'!$A:$AM,26,0),)+IFERROR(VLOOKUP($B10,'Halo Infinite Stats'!$A:$AM,27,0),) -> 37 | S10: =IFERROR(VLOOKUP($B10,'Halo Infinite Stats'!$A:$AM,28,0),) -> 0 | T10: =IFERROR(VLOOKUP($B10,'Halo Infinite Stats'!$A:$AM,31,0),) -> 0 | U10: =IFERROR(VLOOKUP($B10,'PlayerGrades+'!$A:$W,22,0),) -> A | V10: =IFERROR(VLOOKUP($B10,'PlayerGrades+'!$A:$W,23,0),) -> 21.55 | X10: =(HOUR(L10) * 3600) + (MINUTE(L10) * 60) + SECOND(L10) -> 30348
A11: Mystery Heroes | B11: Priest XYZ | C11: =IFERROR(VLOOKUP($B11,'Halo Infinite Stats'!$A:$AM,2,0),) -> 24 | D11: =IFERROR(VLOOKUP($B11,'Halo Infinite Stats'!$A:$AM,3,0),) -> 15 | E11: =IFERROR(VLOOKUP($B11,'Halo Infinite Stats'!$A:$AM,4,0),) -> 9 | F11: =IFERROR(VLOOKUP($B11,'Halo Infinite Stats'!$A:$AM,5,0),) -> 7 | G11: =IFERROR(VLOOKUP($B11,'Halo Infinite Stats'!$A:$AM,6,0),) -> 15 | H11: =IFERROR(VLOOKUP($B11,'Halo Infinite Stats'!$A:$AM,7,0),) -> 1008 | I11: =IFERROR(VLOOKUP($B11,'Halo Infinite Stats'!$A:$AM,8,0),) -> 1243 | J11: =IFERROR(VLOOKUP($B11,'Halo Infinite Stats'!$A:$AM,9,0),) -> -235 | K11: =IFERROR(VLOOKUP($B11,'Halo Infinite Stats'!$A:$AM,11,0),) -> 1 | L11: =IFERROR(TEXT(VLOOKUP($B11,'Halo Infinite Stats'!$A:$AM,12,0)/(24*60*60),"hh:mm:ss"),"") -> 05:43:35 | M11: =IFERROR(VLOOKUP($B11,'Halo Infinite Stats'!$A:$AM,14,0),) -> 9 | N11: =IFERROR(VLOOKUP($B11,'Halo Infinite Stats'!$A:$AM,15,0),)+IFERROR(VLOOKUP($B11,'Halo Infinite Stats'!$A:$AM,16,0),)+IFERROR(VLOOKUP($B11,'Halo Infinite Stats'!$A:$AM,17,0),) -> 0 | O11: =IFERROR(VLOOKUP($B11,'Halo Infinite Stats'!$A:$AM,18,0),) -> 15 | P11: =IFERROR(VLOOKUP($B11,'Halo Infinite Stats'!$A:$AM,19,0),) -> 159 | Q11: =IFERROR(VLOOKUP($B11,'Halo Infinite Stats'!$A:$AM,20,0),) -> 43 | R11: =IFERROR(VLOOKUP($B11,'Halo Infinite Stats'!$A:$AM,21,0),)+IFERROR(VLOOKUP($B11,'Halo Infinite Stats'!$A:$AM,22,0),)+IFERROR(VLOOKUP($B11,'Halo Infinite Stats'!$A:$AM,23,0),)+IFERROR(VLOOKUP($B11,'Halo Infinite Stats'!$A:$AM,24,0),)+IFERROR(VLOOKUP($B11,'Halo Infinite Stats'!$A:$AM,25,0),)+IFERROR(VLOOKUP($B11,'Halo Infinite Stats'!$A:$AM,26,0),)+IFERROR(VLOOKUP($B11,'Halo Infinite Stats'!$A:$AM,27,0),) -> 14 | S11: =IFERROR(VLOOKUP($B11,'Halo Infinite Stats'!$A:$AM,28,0),) -> 0 | T11: =IFERROR(VLOOKUP($B11,'Halo Infinite Stats'!$A:$AM,31,0),) -> 0 | U11: =IFERROR(VLOOKUP($B11,'PlayerGrades+'!$A:$W,22,0),) -> C- | V11: =IFERROR(VLOOKUP($B11,'PlayerGrades+'!$A:$W,23,0),) -> 14.5125 | X11: =(HOUR(L11) * 3600) + (MINUTE(L11) * 60) + SECOND(L11) -> 20615
A12: Mystery Heroes | B12: TOTALS: | C12: =SUM(C8:C11) -> 101 | D12: =SUM(D8:D11) -> 69 | E12: =SUM(E8:E11) -> 32 | F12: =SUM(F8:F11) -> 100 | G12: =SUM(G8:G11) -> 353 | H12: =SUM(H8:H11) -> 4412 | I12: =SUM(I8:I11) -> 4808 | J12: =MINUS(H12,I12) -> -396 | K12: =SUM(K8:K11) -> 15 | L12: =TEXT(X12/86400, "hh:mm:ss") -> 23:41:47 | M12: =SUM(M8:M11) -> 66 | N12: =SUM(N8:N11) -> 0 | O12: =SUM(O8:O11) -> 45 | P12: =SUM(P8:P11) -> 730 | Q12: =SUM(Q8:Q11) -> 202 | R12: =SUM(R8:R11) -> 73 | S12: =SUM(S8:S11) -> 0 | T12: =SUM(T8:T11) -> 2 | U12: =IF(((V8+V9+V10+V11)/4)<='PlayerGrades+'!$Y$44,"F-",IF(((V8+V9+V10+V11)/4)<'PlayerGrades+'!$Y$43,"F",IF(((V8+V9+V10+V11)/4)<'PlayerGrades+'!$Y$42,"F+",IF(((V8+V9+V10+V11)/4)<'PlayerGrades+'!$Y$41,"E-",IF(((V8+V9+V10+V11)/4)<'PlayerGrades+'!$Y$40,"E",IF(((V8+V9+V10+V11)/4)<'PlayerGrades+'!$Y$39,"E+",IF(((V8+V9+V10+V11)/4)<'PlayerGrades+'!$Y$38,"D-",IF(((V8+V9+V10+V11)/4)<'PlayerGrades+'!$Y$37,"D",IF(((V8+V9+V10+V11)/4)<'PlayerGrades+'!$Y$36,"D+",IF(((V8+V9+V10+V11)/4)<'PlayerGrades+'!$Y$35,"C-",IF(((V8+V9+V10+V11)/4)<'PlayerGrades+'!$Y$34,"C",IF(((V8+V9+V10+V11)/4)<'PlayerGrades+'!$Y$33,"C+",IF(((V8+V9+V10+V11)/4)<'PlayerGrades+'!$Y$32,"B-",IF(((V8+V9+V10+V11)/4)<'PlayerGrades+'!$Y$31,"B",IF(((V8+V9+V10+V11)/4)<'PlayerGrades+'!$Y$30,"B+",IF(((V8+V9+V10+V11)/4)<'PlayerGrades+'!$Y$29,"A-",IF(((V8+V9+V10+V11)/4)<'PlayerGrades+'!$Y$28,"A",IF(((V8+V9+V10+V11)/4)<'PlayerGrades+'!$Y$27,"A+",IF(((V8+V9+V10+V11)/4)<'PlayerGrades+'!$Y$26,"S-",IF(((V8+V9+V10+V11)/4)<'PlayerGrades+'!$Y$25,"S","S+")))))))))))))))))))) -> B | V12: Team AVG | X12: =IFERROR(SUM(X8:X11), 0) -> 85307
A14: Glory 2 God | B14: ASpence501 | C14: =IFERROR(VLOOKUP($B14,'Halo Infinite Stats'!$A:$AM,2,0),) -> 23 | D14: =IFERROR(VLOOKUP($B14,'Halo Infinite Stats'!$A:$AM,3,0),) -> 17 | E14: =IFERROR(VLOOKUP($B14,'Halo Infinite Stats'!$A:$AM,4,0),) -> 6 | F14: =IFERROR(VLOOKUP($B14,'Halo Infinite Stats'!$A:$AM,5,0),) -> 48 | G14: =IFERROR(VLOOKUP($B14,'Halo Infinite Stats'!$A:$AM,6,0),) -> 222 | H14: =IFERROR(VLOOKUP($B14,'Halo Infinite Stats'!$A:$AM,7,0),) -> 1135 | I14: =IFERROR(VLOOKUP($B14,'Halo Infinite Stats'!$A:$AM,8,0),) -> 1058 | J14: =IFERROR(VLOOKUP($B14,'Halo Infinite Stats'!$A:$AM,9,0),) -> 77 | K14: =IFERROR(VLOOKUP($B14,'Halo Infinite Stats'!$A:$AM,11,0),) -> 1 | L14: =IFERROR(TEXT(VLOOKUP($B14,'Halo Infinite Stats'!$A:$AM,12,0)/(24*60*60),"hh:mm:ss"),"") -> 05:41:06 | M14: =IFERROR(VLOOKUP($B14,'Halo Infinite Stats'!$A:$AM,14,0),) -> 22 | N14: =IFERROR(VLOOKUP($B14,'Halo Infinite Stats'!$A:$AM,15,0),)+IFERROR(VLOOKUP($B14,'Halo Infinite Stats'!$A:$AM,16,0),)+IFERROR(VLOOKUP($B14,'Halo Infinite Stats'!$A:$AM,17,0),) -> 0 | O14: =IFERROR(VLOOKUP($B14,'Halo Infinite Stats'!$A:$AM,18,0),) -> 10 | P14: =IFERROR(VLOOKUP($B14,'Halo Infinite Stats'!$A:$AM,19,0),) -> 184 | Q14: =IFERROR(VLOOKUP($B14,'Halo Infinite Stats'!$A:$AM,20,0),) -> 58 | R14: =IFERROR(VLOOKUP($B14,'Halo Infinite Stats'!$A:$AM,21,0),)+IFERROR(VLOOKUP($B14,'Halo Infinite Stats'!$A:$AM,22,0),)+IFERROR(VLOOKUP($B14,'Halo Infinite Stats'!$A:$AM,23,0),)+IFERROR(VLOOKUP($B14,'Halo Infinite Stats'!$A:$AM,24,0),)+IFERROR(VLOOKUP($B14,'Halo Infinite Stats'!$A:$AM,25,0),)+IFERROR(VLOOKUP($B14,'Halo Infinite Stats'!$A:$AM,26,0),)+IFERROR(VLOOKUP($B14,'Halo Infinite Stats'!$A:$AM,27,0),) -> 28 | S14: =IFERROR(VLOOKUP($B14,'Halo Infinite Stats'!$A:$AM,28,0),) -> 0 | T14: =IFERROR(VLOOKUP($B14,'Halo Infinite Stats'!$A:$AM,31,0),) -> 6 | U14: =IFERROR(VLOOKUP($B14,'PlayerGrades+'!$A:$W,22,0),) -> S- | V14: =IFERROR(VLOOKUP($B14,'PlayerGrades+'!$A:$W,23,0),) -> 25.25 | X14: =(HOUR(L14) * 3600) + (MINUTE(L14) * 60) + SECOND(L14) -> 20466
A15: Glory 2 God | B15: oh zilly | C15: =IFERROR(VLOOKUP($B15,'Halo Infinite Stats'!$A:$AM,2,0),) -> 16 | D15: =IFERROR(VLOOKUP($B15,'Halo Infinite Stats'!$A:$AM,3,0),) -> 11 | E15: =IFERROR(VLOOKUP($B15,'Halo Infinite Stats'!$A:$AM,4,0),) -> 5 | F15: =IFERROR(VLOOKUP($B15,'Halo Infinite Stats'!$A:$AM,5,0),) -> 13 | G15: =IFERROR(VLOOKUP($B15,'Halo Infinite Stats'!$A:$AM,6,0),) -> 25 | H15: =IFERROR(VLOOKUP($B15,'Halo Infinite Stats'!$A:$AM,7,0),) -> 818 | I15: =IFERROR(VLOOKUP($B15,'Halo Infinite Stats'!$A:$AM,8,0),) -> 939 | J15: =IFERROR(VLOOKUP($B15,'Halo Infinite Stats'!$A:$AM,9,0),) -> -121 | K15: =IFERROR(VLOOKUP($B15,'Halo Infinite Stats'!$A:$AM,11,0),) -> 1 | L15: =IFERROR(TEXT(VLOOKUP($B15,'Halo Infinite Stats'!$A:$AM,12,0)/(24*60*60),"hh:mm:ss"),"") -> 04:06:40 | M15: =IFERROR(VLOOKUP($B15,'Halo Infinite Stats'!$A:$AM,14,0),) -> 17 | N15: =IFERROR(VLOOKUP($B15,'Halo Infinite Stats'!$A:$AM,15,0),)+IFERROR(VLOOKUP($B15,'Halo Infinite Stats'!$A:$AM,16,0),)+IFERROR(VLOOKUP($B15,'Halo Infinite Stats'!$A:$AM,17,0),) -> 0 | O15: =IFERROR(VLOOKUP($B15,'Halo Infinite Stats'!$A:$AM,18,0),) -> 24 | P15: =IFERROR(VLOOKUP($B15,'Halo Infinite Stats'!$A:$AM,19,0),) -> 151 | Q15: =IFERROR(VLOOKUP($B15,'Halo Infinite Stats'!$A:$AM,20,0),) -> 46 | R15: =IFERROR(VLOOKUP($B15,'Halo Infinite Stats'!$A:$AM,21,0),)+IFERROR(VLOOKUP($B15,'Halo Infinite Stats'!$A:$AM,22,0),)+IFERROR(VLOOKUP($B15,'Halo Infinite Stats'!$A:$AM,23,0),)+IFERROR(VLOOKUP($B15,'Halo Infinite Stats'!$A:$AM,24,0),)+IFERROR(VLOOKUP($B15,'Halo Infinite Stats'!$A:$AM,25,0),)+IFERROR(VLOOKUP($B15,'Halo Infinite Stats'!$A:$AM,26,0),)+IFERROR(VLOOKUP($B15,'Halo Infinite Stats'!$A:$AM,27,0),) -> 17 | S15: =IFERROR(VLOOKUP($B15,'Halo Infinite Stats'!$A:$AM,28,0),) -> 0 | T15: =IFERROR(VLOOKUP($B15,'Halo Infinite Stats'!$A:$AM,31,0),) -> 0 | U15: =IFERROR(VLOOKUP($B15,'PlayerGrades+'!$A:$W,22,0),) -> A- | V15: =IFERROR(VLOOKUP($B15,'PlayerGrades+'!$A:$W,23,0),) -> 21.375 | X15: =(HOUR(L15) * 3600) + (MINUTE(L15) * 60) + SECOND(L15) -> 14800
A16: Glory 2 God | B16: NOPLEX | C16: =IFERROR(VLOOKUP($B16,'Halo Infinite Stats'!$A:$AM,2,0),) -> 22 | D16: =IFERROR(VLOOKUP($B16,'Halo Infinite Stats'!$A:$AM,3,0),) -> 17 | E16: =IFERROR(VLOOKUP($B16,'Halo Infinite Stats'!$A:$AM,4,0),) -> 5 | F16: =IFERROR(VLOOKUP($B16,'Halo Infinite Stats'!$A:$AM,5,0),) -> 13 | G16: =IFERROR(VLOOKUP($B16,'Halo Infinite Stats'!$A:$AM,6,0),) -> 23 | H16: =IFERROR(VLOOKUP($B16,'Halo Infinite Stats'!$A:$AM,7,0),) -> 946 | I16: =IFERROR(VLOOKUP($B16,'Halo Infinite Stats'!$A:$AM,8,0),) -> 1122 | J16: =IFERROR(VLOOKUP($B16,'Halo Infinite Stats'!$A:$AM,9,0),) -> -176 | K16: =IFERROR(VLOOKUP($B16,'Halo Infinite Stats'!$A:$AM,11,0),) -> 1 | L16: =IFERROR(TEXT(VLOOKUP($B16,'Halo Infinite Stats'!$A:$AM,12,0)/(24*60*60),"hh:mm:ss"),"") -> 05:26:40 | M16: =IFERROR(VLOOKUP($B16,'Halo Infinite Stats'!$A:$AM,14,0),) -> 9 | N16: =IFERROR(VLOOKUP($B16,'Halo Infinite Stats'!$A:$AM,15,0),)+IFERROR(VLOOKUP($B16,'Halo Infinite Stats'!$A:$AM,16,0),)+IFERROR(VLOOKUP($B16,'Halo Infinite Stats'!$A:$AM,17,0),) -> 0 | O16: =IFERROR(VLOOKUP($B16,'Halo Infinite Stats'!$A:$AM,18,0),) -> 11 | P16: =IFERROR(VLOOKUP($B16,'Halo Infinite Stats'!$A:$AM,19,0),) -> 137 | Q16: =IFERROR(VLOOKUP($B16,'Halo Infinite Stats'!$A:$AM,20,0),) -> 30 | R16: =IFERROR(VLOOKUP($B16,'Halo Infinite Stats'!$A:$AM,21,0),)+IFERROR(VLOOKUP($B16,'Halo Infinite Stats'!$A:$AM,22,0),)+IFERROR(VLOOKUP($B16,'Halo Infinite Stats'!$A:$AM,23,0),)+IFERROR(VLOOKUP($B16,'Halo Infinite Stats'!$A:$AM,24,0),)+IFERROR(VLOOKUP($B16,'Halo Infinite Stats'!$A:$AM,25,0),)+IFERROR(VLOOKUP($B16,'Halo Infinite Stats'!$A:$AM,26,0),)+IFERROR(VLOOKUP($B16,'Halo Infinite Stats'!$A:$AM,27,0),) -> 12 | S16: =IFERROR(VLOOKUP($B16,'Halo Infinite Stats'!$A:$AM,28,0),) -> 0 | T16: =IFERROR(VLOOKUP($B16,'Halo Infinite Stats'!$A:$AM,31,0),) -> 0 | U16: =IFERROR(VLOOKUP($B16,'PlayerGrades+'!$A:$W,22,0),) -> D+ | V16: =IFERROR(VLOOKUP($B16,'PlayerGrades+'!$A:$W,23,0),) -> 13.925 | X16: =(HOUR(L16) * 3600) + (MINUTE(L16) * 60) + SECOND(L16) -> 19600
A17: Glory 2 God | B17: Ken Khaneki | C17: =IFERROR(VLOOKUP($B17,'Halo Infinite Stats'!$A:$AM,2,0),) -> 26 | D17: =IFERROR(VLOOKUP($B17,'Halo Infinite Stats'!$A:$AM,3,0),) -> 17 | E17: =IFERROR(VLOOKUP($B17,'Halo Infinite Stats'!$A:$AM,4,0),) -> 8 | F17: =IFERROR(VLOOKUP($B17,'Halo Infinite Stats'!$A:$AM,5,0),) -> 7 | G17: =IFERROR(VLOOKUP($B17,'Halo Infinite Stats'!$A:$AM,6,0),) -> 17 | H17: =IFERROR(VLOOKUP($B17,'Halo Infinite Stats'!$A:$AM,7,0),) -> 1145 | I17: =IFERROR(VLOOKUP($B17,'Halo Infinite Stats'!$A:$AM,8,0),) -> 1557 | J17: =IFERROR(VLOOKUP($B17,'Halo Infinite Stats'!$A:$AM,9,0),) -> -412 | K17: =IFERROR(VLOOKUP($B17,'Halo Infinite Stats'!$A:$AM,11,0),) -> 2 | L17: =IFERROR(TEXT(VLOOKUP($B17,'Halo Infinite Stats'!$A:$AM,12,0)/(24*60*60),"hh:mm:ss"),"") -> 06:29:59 | M17: =IFERROR(VLOOKUP($B17,'Halo Infinite Stats'!$A:$AM,14,0),) -> 7 | N17: =IFERROR(VLOOKUP($B17,'Halo Infinite Stats'!$A:$AM,15,0),)+IFERROR(VLOOKUP($B17,'Halo Infinite Stats'!$A:$AM,16,0),)+IFERROR(VLOOKUP($B17,'Halo Infinite Stats'!$A:$AM,17,0),) -> 0 | O17: =IFERROR(VLOOKUP($B17,'Halo Infinite Stats'!$A:$AM,18,0),) -> 10 | P17: =IFERROR(VLOOKUP($B17,'Halo Infinite Stats'!$A:$AM,19,0),) -> 173 | Q17: =IFERROR(VLOOKUP($B17,'Halo Infinite Stats'!$A:$AM,20,0),) -> 46 | R17: =IFERROR(VLOOKUP($B17,'Halo Infinite Stats'!$A:$AM,21,0),)+IFERROR(VLOOKUP($B17,'Halo Infinite Stats'!$A:$AM,22,0),)+IFERROR(VLOOKUP($B17,'Halo Infinite Stats'!$A:$AM,23,0),)+IFERROR(VLOOKUP($B17,'Halo Infinite Stats'!$A:$AM,24,0),)+IFERROR(VLOOKUP($B17,'Halo Infinite Stats'!$A:$AM,25,0),)+IFERROR(VLOOKUP($B17,'Halo Infinite Stats'!$A:$AM,26,0),)+IFERROR(VLOOKUP($B17,'Halo Infinite Stats'!$A:$AM,27,0),) -> 11 | S17: =IFERROR(VLOOKUP($B17,'Halo Infinite Stats'!$A:$AM,28,0),) -> 0 | T17: =IFERROR(VLOOKUP($B17,'Halo Infinite Stats'!$A:$AM,31,0),) -> 0 | U17: =IFERROR(VLOOKUP($B17,'PlayerGrades+'!$A:$W,22,0),) -> E+ | V17: =IFERROR(VLOOKUP($B17,'PlayerGrades+'!$A:$W,23,0),) -> 11.55 | X17: =(HOUR(L17) * 3600) + (MINUTE(L17) * 60) + SECOND(L17) -> 23399
A18: Glory 2 God | B18: TOTALS: | C18: =SUM(C14:C17) -> 87 | D18: =SUM(D14:D17) -> 62 | E18: =SUM(E14:E17) -> 24 | F18: =SUM(F14:F17) -> 81 | G18: =SUM(G14:G17) -> 287 | H18: =SUM(H14:H17) -> 4044 | I18: =SUM(I14:I17) -> 4676 | J18: =MINUS(H18,I18) -> -632 | K18: =SUM(K14:K17) -> 5 | L18: =TEXT(X18/86400, "hh:mm:ss") -> 21:44:25 | M18: =SUM(M14:M17) -> 55 | N18: =SUM(N14:N17) -> 0 | O18: =SUM(O14:O17) -> 55 | P18: =SUM(P14:P17) -> 645 | Q18: =SUM(Q14:Q17) -> 180 | R18: =SUM(R14:R17) -> 68 | S18: =SUM(S14:S17) -> 0 | T18: =SUM(T14:T17) -> 6 | U18: =IF(((V14+V15+V16+V17)/4)<='PlayerGrades+'!$Y$44,"F-",IF(((V14+V15+V16+V17)/4)<'PlayerGrades+'!$Y$43,"F",IF(((V14+V15+V16+V17)/4)<'PlayerGrades+'!$Y$42,"F+",IF(((V14+V15+V16+V17)/4)<'PlayerGrades+'!$Y$41,"E-",IF(((V14+V15+V16+V17)/4)<'PlayerGrades+'!$Y$40,"E",IF(((V14+V15+V16+V17)/4)<'PlayerGrades+'!$Y$39,"E+",IF(((V14+V15+V16+V17)/4)<'PlayerGrades+'!$Y$38,"D-",IF(((V14+V15+V16+V17)/4)<'PlayerGrades+'!$Y$37,"D",IF(((V14+V15+V16+V17)/4)<'PlayerGrades+'!$Y$36,"D+",IF(((V14+V15+V16+V17)/4)<'PlayerGrades+'!$Y$35,"C-",IF(((V14+V15+V16+V17)/4)<'PlayerGrades+'!$Y$34,"C",IF(((V14+V15+V16+V17)/4)<'PlayerGrades+'!$Y$33,"C+",IF(((V14+V15+V16+V17)/4)<'PlayerGrades+'!$Y$32,"B-",IF(((V14+V15+V16+V17)/4)<'PlayerGrades+'!$Y$31,"B",IF(((V14+V15+V16+V17)/4)<'PlayerGrades+'!$Y$30,"B+",IF(((V14+V15+V16+V17)/4)<'PlayerGrades+'!$Y$29,"A-",IF(((V14+V15+V16+V17)/4)<'PlayerGrades+'!$Y$28,"A",IF(((V14+V15+V16+V17)/4)<'PlayerGrades+'!$Y$27,"A+",IF(((V14+V15+V16+V17)/4)<'PlayerGrades+'!$Y$26,"S-",IF(((V14+V15+V16+V17)/4)<'PlayerGrades+'!$Y$25,"S","S+")))))))))))))))))))) -> B- | V18: Team AVG | X18: =IFERROR(SUM(X14:X17), 0) -> 78265
A20: USURPER SZN | B20: SPANKATRON | C20: =IFERROR(VLOOKUP($B20,'Halo Infinite Stats'!$A:$AM,2,0),) | D20: =IFERROR(VLOOKUP($B20,'Halo Infinite Stats'!$A:$AM,3,0),) | E20: =IFERROR(VLOOKUP($B20,'Halo Infinite Stats'!$A:$AM,4,0),) | F20: =IFERROR(VLOOKUP($B20,'Halo Infinite Stats'!$A:$AM,5,0),) | G20: =IFERROR(VLOOKUP($B20,'Halo Infinite Stats'!$A:$AM,6,0),) | H20: =IFERROR(VLOOKUP($B20,'Halo Infinite Stats'!$A:$AM,7,0),) | I20: =IFERROR(VLOOKUP($B20,'Halo Infinite Stats'!$A:$AM,8,0),) | J20: =IFERROR(VLOOKUP($B20,'Halo Infinite Stats'!$A:$AM,9,0),) | K20: =IFERROR(VLOOKUP($B20,'Halo Infinite Stats'!$A:$AM,11,0),) | L20: =IFERROR(TEXT(VLOOKUP($B20,'Halo Infinite Stats'!$A:$AM,12,0)/(24*60*60),"hh:mm:ss"),"") | M20: =IFERROR(VLOOKUP($B20,'Halo Infinite Stats'!$A:$AM,14,0),) | N20: =IFERROR(VLOOKUP($B20,'Halo Infinite Stats'!$A:$AM,15,0),)+IFERROR(VLOOKUP($B20,'Halo Infinite Stats'!$A:$AM,16,0),)+IFERROR(VLOOKUP($B20,'Halo Infinite Stats'!$A:$AM,17,0),) -> 0 | O20: =IFERROR(VLOOKUP($B20,'Halo Infinite Stats'!$A:$AM,18,0),) | P20: =IFERROR(VLOOKUP($B20,'Halo Infinite Stats'!$A:$AM,19,0),) | Q20: =IFERROR(VLOOKUP($B20,'Halo Infinite Stats'!$A:$AM,20,0),) | R20: =IFERROR(VLOOKUP($B20,'Halo Infinite Stats'!$A:$AM,21,0),)+IFERROR(VLOOKUP($B20,'Halo Infinite Stats'!$A:$AM,22,0),)+IFERROR(VLOOKUP($B20,'Halo Infinite Stats'!$A:$AM,23,0),)+IFERROR(VLOOKUP($B20,'Halo Infinite Stats'!$A:$AM,24,0),)+IFERROR(VLOOKUP($B20,'Halo Infinite Stats'!$A:$AM,25,0),)+IFERROR(VLOOKUP($B20,'Halo Infinite Stats'!$A:$AM,26,0),)+IFERROR(VLOOKUP($B20,'Halo Infinite Stats'!$A:$AM,27,0),) -> 0 | S20: =IFERROR(VLOOKUP($B20,'Halo Infinite Stats'!$A:$AM,28,0),) | T20: =IFERROR(VLOOKUP($B20,'Halo Infinite Stats'!$A:$AM,31,0),) | U20: =IFERROR(VLOOKUP($B20,'PlayerGrades+'!$A:$W,22,0),) | V20: =IFERROR(VLOOKUP($B20,'PlayerGrades+'!$A:$W,23,0),) | X20: =(HOUR(L20) * 3600) + (MINUTE(L20) * 60) + SECOND(L20) -> 0
A21: USURPER SZN | B21: Jussshhhyyy | C21: =IFERROR(VLOOKUP($B21,'Halo Infinite Stats'!$A:$AM,2,0),) -> 36 | D21: =IFERROR(VLOOKUP($B21,'Halo Infinite Stats'!$A:$AM,3,0),) -> 18 | E21: =IFERROR(VLOOKUP($B21,'Halo Infinite Stats'!$A:$AM,4,0),) -> 18 | F21: =IFERROR(VLOOKUP($B21,'Halo Infinite Stats'!$A:$AM,5,0),) -> 30 | G21: =IFERROR(VLOOKUP($B21,'Halo Infinite Stats'!$A:$AM,6,0),) -> 177 | H21: =IFERROR(VLOOKUP($B21,'Halo Infinite Stats'!$A:$AM,7,0),) -> 2042 | I21: =IFERROR(VLOOKUP($B21,'Halo Infinite Stats'!$A:$AM,8,0),) -> 1484 | J21: =IFERROR(VLOOKUP($B21,'Halo Infinite Stats'!$A:$AM,9,0),) -> 558 | K21: =IFERROR(VLOOKUP($B21,'Halo Infinite Stats'!$A:$AM,11,0),) -> 7 | L21: =IFERROR(TEXT(VLOOKUP($B21,'Halo Infinite Stats'!$A:$AM,12,0)/(24*60*60),"hh:mm:ss"),"") -> 08:51:27 | M21: =IFERROR(VLOOKUP($B21,'Halo Infinite Stats'!$A:$AM,14,0),) -> 81 | N21: =IFERROR(VLOOKUP($B21,'Halo Infinite Stats'!$A:$AM,15,0),)+IFERROR(VLOOKUP($B21,'Halo Infinite Stats'!$A:$AM,16,0),)+IFERROR(VLOOKUP($B21,'Halo Infinite Stats'!$A:$AM,17,0),) -> 5 | O21: =IFERROR(VLOOKUP($B21,'Halo Infinite Stats'!$A:$AM,18,0),) -> 27 | P21: =IFERROR(VLOOKUP($B21,'Halo Infinite Stats'!$A:$AM,19,0),) -> 423 | Q21: =IFERROR(VLOOKUP($B21,'Halo Infinite Stats'!$A:$AM,20,0),) -> 128 | R21: =IFERROR(VLOOKUP($B21,'Halo Infinite Stats'!$A:$AM,21,0),)+IFERROR(VLOOKUP($B21,'Halo Infinite Stats'!$A:$AM,22,0),)+IFERROR(VLOOKUP($B21,'Halo Infinite Stats'!$A:$AM,23,0),)+IFERROR(VLOOKUP($B21,'Halo Infinite Stats'!$A:$AM,24,0),)+IFERROR(VLOOKUP($B21,'Halo Infinite Stats'!$A:$AM,25,0),)+IFERROR(VLOOKUP($B21,'Halo Infinite Stats'!$A:$AM,26,0),)+IFERROR(VLOOKUP($B21,'Halo Infinite Stats'!$A:$AM,27,0),) -> 67 | S21: =IFERROR(VLOOKUP($B21,'Halo Infinite Stats'!$A:$AM,28,0),) -> 0 | T21: =IFERROR(VLOOKUP($B21,'Halo Infinite Stats'!$A:$AM,31,0),) -> 6 | U21: =IFERROR(VLOOKUP($B21,'PlayerGrades+'!$A:$W,22,0),) -> S | V21: =IFERROR(VLOOKUP($B21,'PlayerGrades+'!$A:$W,23,0),) -> 27.275 | X21: =(HOUR(L21) * 3600) + (MINUTE(L21) * 60) + SECOND(L21) -> 31887
A22: USURPER SZN | B22: AwareMosquito | C22: =IFERROR(VLOOKUP($B22,'Halo Infinite Stats'!$A:$AM,2,0),) -> 28 | D22: =IFERROR(VLOOKUP($B22,'Halo Infinite Stats'!$A:$AM,3,0),) -> 13 | E22: =IFERROR(VLOOKUP($B22,'Halo Infinite Stats'!$A:$AM,4,0),) -> 15 | F22: =IFERROR(VLOOKUP($B22,'Halo Infinite Stats'!$A:$AM,5,0),) -> 28 | G22: =IFERROR(VLOOKUP($B22,'Halo Infinite Stats'!$A:$AM,6,0),) -> 154 | H22: =IFERROR(VLOOKUP($B22,'Halo Infinite Stats'!$A:$AM,7,0),) -> 1016 | I22: =IFERROR(VLOOKUP($B22,'Halo Infinite Stats'!$A:$AM,8,0),) -> 1384 | J22: =IFERROR(VLOOKUP($B22,'Halo Infinite Stats'!$A:$AM,9,0),) -> -368 | K22: =IFERROR(VLOOKUP($B22,'Halo Infinite Stats'!$A:$AM,11,0),) -> 4 | L22: =IFERROR(TEXT(VLOOKUP($B22,'Halo Infinite Stats'!$A:$AM,12,0)/(24*60*60),"hh:mm:ss"),"") -> 07:02:16 | M22: =IFERROR(VLOOKUP($B22,'Halo Infinite Stats'!$A:$AM,14,0),) -> 10 | N22: =IFERROR(VLOOKUP($B22,'Halo Infinite Stats'!$A:$AM,15,0),)+IFERROR(VLOOKUP($B22,'Halo Infinite Stats'!$A:$AM,16,0),)+IFERROR(VLOOKUP($B22,'Halo Infinite Stats'!$A:$AM,17,0),) -> 0 | O22: =IFERROR(VLOOKUP($B22,'Halo Infinite Stats'!$A:$AM,18,0),) -> 12 | P22: =IFERROR(VLOOKUP($B22,'Halo Infinite Stats'!$A:$AM,19,0),) -> 135 | Q22: =IFERROR(VLOOKUP($B22,'Halo Infinite Stats'!$A:$AM,20,0),) -> 24 | R22: =IFERROR(VLOOKUP($B22,'Halo Infinite Stats'!$A:$AM,21,0),)+IFERROR(VLOOKUP($B22,'Halo Infinite Stats'!$A:$AM,22,0),)+IFERROR(VLOOKUP($B22,'Halo Infinite Stats'!$A:$AM,23,0),)+IFERROR(VLOOKUP($B22,'Halo Infinite Stats'!$A:$AM,24,0),)+IFERROR(VLOOKUP($B22,'Halo Infinite Stats'!$A:$AM,25,0),)+IFERROR(VLOOKUP($B22,'Halo Infinite Stats'!$A:$AM,26,0),)+IFERROR(VLOOKUP($B22,'Halo Infinite Stats'!$A:$AM,27,0),) -> 3 | S22: =IFERROR(VLOOKUP($B22,'Halo Infinite Stats'!$A:$AM,28,0),) -> 0 | T22: =IFERROR(VLOOKUP($B22,'Halo Infinite Stats'!$A:$AM,31,0),) -> 0 | U22: =IFERROR(VLOOKUP($B22,'PlayerGrades+'!$A:$W,22,0),) -> D | V22: =IFERROR(VLOOKUP($B22,'PlayerGrades+'!$A:$W,23,0),) -> 12.6125 | X22: =(HOUR(L22) * 3600) + (MINUTE(L22) * 60) + SECOND(L22) -> 25336
A23: USURPER SZN | B23: ill Shrek u | C23: =IFERROR(VLOOKUP($B23,'Halo Infinite Stats'!$A:$AM,2,0),) -> 17 | D23: =IFERROR(VLOOKUP($B23,'Halo Infinite Stats'!$A:$AM,3,0),) -> 10 | E23: =IFERROR(VLOOKUP($B23,'Halo Infinite Stats'!$A:$AM,4,0),) -> 7 | F23: =IFERROR(VLOOKUP($B23,'Halo Infinite Stats'!$A:$AM,5,0),) -> 13 | G23: =IFERROR(VLOOKUP($B23,'Halo Infinite Stats'!$A:$AM,6,0),) -> 32 | H23: =IFERROR(VLOOKUP($B23,'Halo Infinite Stats'!$A:$AM,7,0),) -> 719 | I23: =IFERROR(VLOOKUP($B23,'Halo Infinite Stats'!$A:$AM,8,0),) -> 771 | J23: =IFERROR(VLOOKUP($B23,'Halo Infinite Stats'!$A:$AM,9,0),) -> -52 | K23: =IFERROR(VLOOKUP($B23,'Halo Infinite Stats'!$A:$AM,11,0),) -> 0 | L23: =IFERROR(TEXT(VLOOKUP($B23,'Halo Infinite Stats'!$A:$AM,12,0)/(24*60*60),"hh:mm:ss"),"") -> 04:26:01 | M23: =IFERROR(VLOOKUP($B23,'Halo Infinite Stats'!$A:$AM,14,0),) -> 15 | N23: =IFERROR(VLOOKUP($B23,'Halo Infinite Stats'!$A:$AM,15,0),)+IFERROR(VLOOKUP($B23,'Halo Infinite Stats'!$A:$AM,16,0),)+IFERROR(VLOOKUP($B23,'Halo Infinite Stats'!$A:$AM,17,0),) -> 0 | O23: =IFERROR(VLOOKUP($B23,'Halo Infinite Stats'!$A:$AM,18,0),) -> 9 | P23: =IFERROR(VLOOKUP($B23,'Halo Infinite Stats'!$A:$AM,19,0),) -> 110 | Q23: =IFERROR(VLOOKUP($B23,'Halo Infinite Stats'!$A:$AM,20,0),) -> 29 | R23: =IFERROR(VLOOKUP($B23,'Halo Infinite Stats'!$A:$AM,21,0),)+IFERROR(VLOOKUP($B23,'Halo Infinite Stats'!$A:$AM,22,0),)+IFERROR(VLOOKUP($B23,'Halo Infinite Stats'!$A:$AM,23,0),)+IFERROR(VLOOKUP($B23,'Halo Infinite Stats'!$A:$AM,24,0),)+IFERROR(VLOOKUP($B23,'Halo Infinite Stats'!$A:$AM,25,0),)+IFERROR(VLOOKUP($B23,'Halo Infinite Stats'!$A:$AM,26,0),)+IFERROR(VLOOKUP($B23,'Halo Infinite Stats'!$A:$AM,27,0),) -> 7 | S23: =IFERROR(VLOOKUP($B23,'Halo Infinite Stats'!$A:$AM,28,0),) -> 0 | T23: =IFERROR(VLOOKUP($B23,'Halo Infinite Stats'!$A:$AM,31,0),) -> 3 | U23: =IFERROR(VLOOKUP($B23,'PlayerGrades+'!$A:$W,22,0),) -> B | V23: =IFERROR(VLOOKUP($B23,'PlayerGrades+'!$A:$W,23,0),) -> 18.15 | X23: =(HOUR(L23) * 3600) + (MINUTE(L23) * 60) + SECOND(L23) -> 15961
A24: USURPER SZN | B24: TOTALS: | C24: =SUM(C20:C23) -> 81 | D24: =SUM(D20:D23) -> 41 | E24: =SUM(E20:E23) -> 40 | F24: =SUM(F20:F23) -> 71 | G24: =SUM(G20:G23) -> 363 | H24: =SUM(H20:H23) -> 3777 | I24: =SUM(I20:I23) -> 3639 | J24: =MINUS(H24,I24) -> 138 | K24: =SUM(K20:K23) -> 11 | L24: =TEXT(X24/86400, "hh:mm:ss") -> 20:19:44 | M24: =SUM(M20:M23) -> 106 | N24: =SUM(N20:N23) -> 5 | O24: =SUM(O20:O23) -> 48 | P24: =SUM(P20:P23) -> 668 | Q24: =SUM(Q20:Q23) -> 181 | R24: =SUM(R20:R23) -> 77 | S24: =SUM(S20:S23) -> 0 | T24: =SUM(T20:T23) -> 9 | U24: =IF(((V20+V21+V22+V23)/4)<='PlayerGrades+'!$Y$44,"F-",IF(((V20+V21+V22+V23)/4)<'PlayerGrades+'!$Y$43,"F",IF(((V20+V21+V22+V23)/4)<'PlayerGrades+'!$Y$42,"F+",IF(((V20+V21+V22+V23)/4)<'PlayerGrades+'!$Y$41,"E-",IF(((V20+V21+V22+V23)/4)<'PlayerGrades+'!$Y$40,"E",IF(((V20+V21+V22+V23)/4)<'PlayerGrades+'!$Y$39,"E+",IF(((V20+V21+V22+V23)/4)<'PlayerGrades+'!$Y$38,"D-",IF(((V20+V21+V22+V23)/4)<'PlayerGrades+'!$Y$37,"D",IF(((V20+V21+V22+V23)/4)<'PlayerGrades+'!$Y$36,"D+",IF(((V20+V21+V22+V23)/4)<'PlayerGrades+'!$Y$35,"C-",IF(((V20+V21+V22+V23)/4)<'PlayerGrades+'!$Y$34,"C",IF(((V20+V21+V22+V23)/4)<'PlayerGrades+'!$Y$33,"C+",IF(((V20+V21+V22+V23)/4)<'PlayerGrades+'!$Y$32,"B-",IF(((V20+V21+V22+V23)/4)<'PlayerGrades+'!$Y$31,"B",IF(((V20+V21+V22+V23)/4)<'PlayerGrades+'!$Y$30,"B+",IF(((V20+V21+V22+V23)/4)<'PlayerGrades+'!$Y$29,"A-",IF(((V20+V21+V22+V23)/4)<'PlayerGrades+'!$Y$28,"A",IF(((V20+V21+V22+V23)/4)<'PlayerGrades+'!$Y$27,"A+",IF(((V20+V21+V22+V23)/4)<'PlayerGrades+'!$Y$26,"S-",IF(((V20+V21+V22+V23)/4)<'PlayerGrades+'!$Y$25,"S","S+")))))))))))))))))))) -> C- | V24: Team AVG | X24: =IFERROR(SUM(X20:X23), 0) -> 73184
A26: MenZ's Grossly Large Backpack | B26: Scullen cx | C26: =IFERROR(VLOOKUP($B26,'Halo Infinite Stats'!$A:$AM,2,0),) -> 21 | D26: =IFERROR(VLOOKUP($B26,'Halo Infinite Stats'!$A:$AM,3,0),) -> 10 | E26: =IFERROR(VLOOKUP($B26,'Halo Infinite Stats'!$A:$AM,4,0),) -> 11 | F26: =IFERROR(VLOOKUP($B26,'Halo Infinite Stats'!$A:$AM,5,0),) -> 36 | G26: =IFERROR(VLOOKUP($B26,'Halo Infinite Stats'!$A:$AM,6,0),) -> 249 | H26: =IFERROR(VLOOKUP($B26,'Halo Infinite Stats'!$A:$AM,7,0),) -> 963 | I26: =IFERROR(VLOOKUP($B26,'Halo Infinite Stats'!$A:$AM,8,0),) -> 1023 | J26: =IFERROR(VLOOKUP($B26,'Halo Infinite Stats'!$A:$AM,9,0),) -> -60 | K26: =IFERROR(VLOOKUP($B26,'Halo Infinite Stats'!$A:$AM,11,0),) -> 3 | L26: =IFERROR(TEXT(VLOOKUP($B26,'Halo Infinite Stats'!$A:$AM,12,0)/(24*60*60),"hh:mm:ss"),"") -> 04:50:00 | M26: =IFERROR(VLOOKUP($B26,'Halo Infinite Stats'!$A:$AM,14,0),) -> 27 | N26: =IFERROR(VLOOKUP($B26,'Halo Infinite Stats'!$A:$AM,15,0),)+IFERROR(VLOOKUP($B26,'Halo Infinite Stats'!$A:$AM,16,0),)+IFERROR(VLOOKUP($B26,'Halo Infinite Stats'!$A:$AM,17,0),) -> 2 | O26: =IFERROR(VLOOKUP($B26,'Halo Infinite Stats'!$A:$AM,18,0),) -> 10 | P26: =IFERROR(VLOOKUP($B26,'Halo Infinite Stats'!$A:$AM,19,0),) -> 179 | Q26: =IFERROR(VLOOKUP($B26,'Halo Infinite Stats'!$A:$AM,20,0),) -> 50 | R26: =IFERROR(VLOOKUP($B26,'Halo Infinite Stats'!$A:$AM,21,0),)+IFERROR(VLOOKUP($B26,'Halo Infinite Stats'!$A:$AM,22,0),)+IFERROR(VLOOKUP($B26,'Halo Infinite Stats'!$A:$AM,23,0),)+IFERROR(VLOOKUP($B26,'Halo Infinite Stats'!$A:$AM,24,0),)+IFERROR(VLOOKUP($B26,'Halo Infinite Stats'!$A:$AM,25,0),)+IFERROR(VLOOKUP($B26,'Halo Infinite Stats'!$A:$AM,26,0),)+IFERROR(VLOOKUP($B26,'Halo Infinite Stats'!$A:$AM,27,0),) -> 21 | S26: =IFERROR(VLOOKUP($B26,'Halo Infinite Stats'!$A:$AM,28,0),) -> 1 | T26: =IFERROR(VLOOKUP($B26,'Halo Infinite Stats'!$A:$AM,31,0),) -> 2 | U26: =IFERROR(VLOOKUP($B26,'PlayerGrades+'!$A:$W,22,0),) -> A+ | V26: =IFERROR(VLOOKUP($B26,'PlayerGrades+'!$A:$W,23,0),) -> 25.0875 | X26: =(HOUR(L26) * 3600) + (MINUTE(L26) * 60) + SECOND(L26) -> 17400
A27: MenZ's Grossly Large Backpack | B27: Jussshhhyyy | C27: =IFERROR(VLOOKUP($B27,'Halo Infinite Stats'!$A:$AM,2,0),) -> 36 | D27: =IFERROR(VLOOKUP($B27,'Halo Infinite Stats'!$A:$AM,3,0),) -> 18 | E27: =IFERROR(VLOOKUP($B27,'Halo Infinite Stats'!$A:$AM,4,0),) -> 18 | F27: =IFERROR(VLOOKUP($B27,'Halo Infinite Stats'!$A:$AM,5,0),) -> 30 | G27: =IFERROR(VLOOKUP($B27,'Halo Infinite Stats'!$A:$AM,6,0),) -> 177 | H27: =IFERROR(VLOOKUP($B27,'Halo Infinite Stats'!$A:$AM,7,0),) -> 2042 | I27: =IFERROR(VLOOKUP($B27,'Halo Infinite Stats'!$A:$AM,8,0),) -> 1484 | J27: =IFERROR(VLOOKUP($B27,'Halo Infinite Stats'!$A:$AM,9,0),) -> 558 | K27: =IFERROR(VLOOKUP($B27,'Halo Infinite Stats'!$A:$AM,11,0),) -> 7 | L27: =IFERROR(TEXT(VLOOKUP($B27,'Halo Infinite Stats'!$A:$AM,12,0)/(24*60*60),"hh:mm:ss"),"") -> 08:51:27 | M27: =IFERROR(VLOOKUP($B27,'Halo Infinite Stats'!$A:$AM,14,0),) -> 81 | N27: =IFERROR(VLOOKUP($B27,'Halo Infinite Stats'!$A:$AM,15,0),)+IFERROR(VLOOKUP($B27,'Halo Infinite Stats'!$A:$AM,16,0),)+IFERROR(VLOOKUP($B27,'Halo Infinite Stats'!$A:$AM,17,0),) -> 5 | O27: =IFERROR(VLOOKUP($B27,'Halo Infinite Stats'!$A:$AM,18,0),) -> 27 | P27: =IFERROR(VLOOKUP($B27,'Halo Infinite Stats'!$A:$AM,19,0),) -> 423 | Q27: =IFERROR(VLOOKUP($B27,'Halo Infinite Stats'!$A:$AM,20,0),) -> 128 | R27: =IFERROR(VLOOKUP($B27,'Halo Infinite Stats'!$A:$AM,21,0),)+IFERROR(VLOOKUP($B27,'Halo Infinite Stats'!$A:$AM,22,0),)+IFERROR(VLOOKUP($B27,'Halo Infinite Stats'!$A:$AM,23,0),)+IFERROR(VLOOKUP($B27,'Halo Infinite Stats'!$A:$AM,24,0),)+IFERROR(VLOOKUP($B27,'Halo Infinite Stats'!$A:$AM,25,0),)+IFERROR(VLOOKUP($B27,'Halo Infinite Stats'!$A:$AM,26,0),)+IFERROR(VLOOKUP($B27,'Halo Infinite Stats'!$A:$AM,27,0),) -> 67 | S27: =IFERROR(VLOOKUP($B27,'Halo Infinite Stats'!$A:$AM,28,0),) -> 0 | T27: =IFERROR(VLOOKUP($B27,'Halo Infinite Stats'!$A:$AM,31,0),) -> 6 | U27: =IFERROR(VLOOKUP($B27,'PlayerGrades+'!$A:$W,22,0),) -> S | V27: =IFERROR(VLOOKUP($B27,'PlayerGrades+'!$A:$W,23,0),) -> 27.275 | X27: =(HOUR(L27) * 3600) + (MINUTE(L27) * 60) + SECOND(L27) -> 31887
A28: MenZ's Grossly Large Backpack | B28: Its Rainin MenZ | C28: =IFERROR(VLOOKUP($B28,'Halo Infinite Stats'!$A:$AM,2,0),) -> 23 | D28: =IFERROR(VLOOKUP($B28,'Halo Infinite Stats'!$A:$AM,3,0),) -> 12 | E28: =IFERROR(VLOOKUP($B28,'Halo Infinite Stats'!$A:$AM,4,0),) -> 11 | F28: =IFERROR(VLOOKUP($B28,'Halo Infinite Stats'!$A:$AM,5,0),) -> 4 | G28: =IFERROR(VLOOKUP($B28,'Halo Infinite Stats'!$A:$AM,6,0),) -> 25 | H28: =IFERROR(VLOOKUP($B28,'Halo Infinite Stats'!$A:$AM,7,0),) -> 831 | I28: =IFERROR(VLOOKUP($B28,'Halo Infinite Stats'!$A:$AM,8,0),) -> 1144 | J28: =IFERROR(VLOOKUP($B28,'Halo Infinite Stats'!$A:$AM,9,0),) -> -313 | K28: =IFERROR(VLOOKUP($B28,'Halo Infinite Stats'!$A:$AM,11,0),) -> 2 | L28: =IFERROR(TEXT(VLOOKUP($B28,'Halo Infinite Stats'!$A:$AM,12,0)/(24*60*60),"hh:mm:ss"),"") -> 05:23:44 | M28: =IFERROR(VLOOKUP($B28,'Halo Infinite Stats'!$A:$AM,14,0),) -> 13 | N28: =IFERROR(VLOOKUP($B28,'Halo Infinite Stats'!$A:$AM,15,0),)+IFERROR(VLOOKUP($B28,'Halo Infinite Stats'!$A:$AM,16,0),)+IFERROR(VLOOKUP($B28,'Halo Infinite Stats'!$A:$AM,17,0),) -> 0 | O28: =IFERROR(VLOOKUP($B28,'Halo Infinite Stats'!$A:$AM,18,0),) -> 6 | P28: =IFERROR(VLOOKUP($B28,'Halo Infinite Stats'!$A:$AM,19,0),) -> 124 | Q28: =IFERROR(VLOOKUP($B28,'Halo Infinite Stats'!$A:$AM,20,0),) -> 31 | R28: =IFERROR(VLOOKUP($B28,'Halo Infinite Stats'!$A:$AM,21,0),)+IFERROR(VLOOKUP($B28,'Halo Infinite Stats'!$A:$AM,22,0),)+IFERROR(VLOOKUP($B28,'Halo Infinite Stats'!$A:$AM,23,0),)+IFERROR(VLOOKUP($B28,'Halo Infinite Stats'!$A:$AM,24,0),)+IFERROR(VLOOKUP($B28,'Halo Infinite Stats'!$A:$AM,25,0),)+IFERROR(VLOOKUP($B28,'Halo Infinite Stats'!$A:$AM,26,0),)+IFERROR(VLOOKUP($B28,'Halo Infinite Stats'!$A:$AM,27,0),) -> 17 | S28: =IFERROR(VLOOKUP($B28,'Halo Infinite Stats'!$A:$AM,28,0),) -> 1 | T28: =IFERROR(VLOOKUP($B28,'Halo Infinite Stats'!$A:$AM,31,0),) -> 0 | U28: =IFERROR(VLOOKUP($B28,'PlayerGrades+'!$A:$W,22,0),) -> E+ | V28: =IFERROR(VLOOKUP($B28,'PlayerGrades+'!$A:$W,23,0),) -> 11.8875 | X28: =(HOUR(L28) * 3600) + (MINUTE(L28) * 60) + SECOND(L28) -> 19424
A29: MenZ's Grossly Large Backpack | B29: Ram Osneb | C29: =IFERROR(VLOOKUP($B29,'Halo Infinite Stats'!$A:$AM,2,0),) -> 15 | D29: =IFERROR(VLOOKUP($B29,'Halo Infinite Stats'!$A:$AM,3,0),) -> 6 | E29: =IFERROR(VLOOKUP($B29,'Halo Infinite Stats'!$A:$AM,4,0),) -> 9 | F29: =IFERROR(VLOOKUP($B29,'Halo Infinite Stats'!$A:$AM,5,0),) -> 6 | G29: =IFERROR(VLOOKUP($B29,'Halo Infinite Stats'!$A:$AM,6,0),) -> 15 | H29: =IFERROR(VLOOKUP($B29,'Halo Infinite Stats'!$A:$AM,7,0),) -> 467 | I29: =IFERROR(VLOOKUP($B29,'Halo Infinite Stats'!$A:$AM,8,0),) -> 780 | J29: =IFERROR(VLOOKUP($B29,'Halo Infinite Stats'!$A:$AM,9,0),) -> -313 | K29: =IFERROR(VLOOKUP($B29,'Halo Infinite Stats'!$A:$AM,11,0),) -> 0 | L29: =IFERROR(TEXT(VLOOKUP($B29,'Halo Infinite Stats'!$A:$AM,12,0)/(24*60*60),"hh:mm:ss"),"") -> 03:16:00 | M29: =IFERROR(VLOOKUP($B29,'Halo Infinite Stats'!$A:$AM,14,0),) -> 0 | N29: =IFERROR(VLOOKUP($B29,'Halo Infinite Stats'!$A:$AM,15,0),)+IFERROR(VLOOKUP($B29,'Halo Infinite Stats'!$A:$AM,16,0),)+IFERROR(VLOOKUP($B29,'Halo Infinite Stats'!$A:$AM,17,0),) -> 0 | O29: =IFERROR(VLOOKUP($B29,'Halo Infinite Stats'!$A:$AM,18,0),) -> 1 | P29: =IFERROR(VLOOKUP($B29,'Halo Infinite Stats'!$A:$AM,19,0),) -> 43 | Q29: =IFERROR(VLOOKUP($B29,'Halo Infinite Stats'!$A:$AM,20,0),) -> 7 | R29: =IFERROR(VLOOKUP($B29,'Halo Infinite Stats'!$A:$AM,21,0),)+IFERROR(VLOOKUP($B29,'Halo Infinite Stats'!$A:$AM,22,0),)+IFERROR(VLOOKUP($B29,'Halo Infinite Stats'!$A:$AM,23,0),)+IFERROR(VLOOKUP($B29,'Halo Infinite Stats'!$A:$AM,24,0),)+IFERROR(VLOOKUP($B29,'Halo Infinite Stats'!$A:$AM,25,0),)+IFERROR(VLOOKUP($B29,'Halo Infinite Stats'!$A:$AM,26,0),)+IFERROR(VLOOKUP($B29,'Halo Infinite Stats'!$A:$AM,27,0),) -> 1 | S29: =IFERROR(VLOOKUP($B29,'Halo Infinite Stats'!$A:$AM,28,0),) -> 0 | T29: =IFERROR(VLOOKUP($B29,'Halo Infinite Stats'!$A:$AM,31,0),) -> 0 | U29: =IFERROR(VLOOKUP($B29,'PlayerGrades+'!$A:$W,22,0),) -> F+ | V29: =IFERROR(VLOOKUP($B29,'PlayerGrades+'!$A:$W,23,0),) -> 7.5625 | X29: =(HOUR(L29) * 3600) + (MINUTE(L29) * 60) + SECOND(L29) -> 11760
A30: MenZ's Grossly Large Backpack | B30: TOTALS: | C30: =SUM(C26:C29) -> 95 | D30: =SUM(D26:D29) -> 46 | E30: =SUM(E26:E29) -> 49 | F30: =SUM(F26:F29) -> 76 | G30: =SUM(G26:G28) -> 451 | H30: =SUM(H26:H29) -> 4303 | I30: =SUM(I26:I29) -> 4431 | J30: =MINUS(H30,I30) -> -128 | K30: =SUM(K26:K29) -> 12 | L30: =TEXT(X30/86400, "hh:mm:ss") -> 22:21:11 | M30: =SUM(M26:M29) -> 121 | N30: =SUM(N26:N29) -> 7 | O30: =SUM(O26:O29) -> 44 | P30: =SUM(P26:P29) -> 769 | Q30: =SUM(Q26:Q29) -> 216 | R30: =SUM(R26:R29) -> 106 | S30: =SUM(S26:S29) -> 2 | T30: =SUM(T26:T29) -> 8 | U30: =IF(((V26+V27+V28+V29)/4)<='PlayerGrades+'!$Y$44,"F-",IF(((V26+V27+V28+V29)/4)<'PlayerGrades+'!$Y$43,"F",IF(((V26+V27+V28+V29)/4)<'PlayerGrades+'!$Y$42,"F+",IF(((V26+V27+V28+V29)/4)<'PlayerGrades+'!$Y$41,"E-",IF(((V26+V27+V28+V29)/4)<'PlayerGrades+'!$Y$40,"E",IF(((V26+V27+V28+V29)/4)<'PlayerGrades+'!$Y$39,"E+",IF(((V26+V27+V28+V29)/4)<'PlayerGrades+'!$Y$38,"D-",IF(((V26+V27+V28+V29)/4)<'PlayerGrades+'!$Y$37,"D",IF(((V26+V27+V28+V29)/4)<'PlayerGrades+'!$Y$36,"D+",IF(((V26+V27+V28+V29)/4)<'PlayerGrades+'!$Y$35,"C-",IF(((V26+V27+V28+V29)/4)<'PlayerGrades+'!$Y$34,"C",IF(((V26+V27+V28+V29)/4)<'PlayerGrades+'!$Y$33,"C+",IF(((V26+V27+V28+V29)/4)<'PlayerGrades+'!$Y$32,"B-",IF(((V26+V27+V28+V29)/4)<'PlayerGrades+'!$Y$31,"B",IF(((V26+V27+V28+V29)/4)<'PlayerGrades+'!$Y$30,"B+",IF(((V26+V27+V28+V29)/4)<'PlayerGrades+'!$Y$29,"A-",IF(((V26+V27+V28+V29)/4)<'PlayerGrades+'!$Y$28,"A",IF(((V26+V27+V28+V29)/4)<'PlayerGrades+'!$Y$27,"A+",IF(((V26+V27+V28+V29)/4)<'PlayerGrades+'!$Y$26,"S-",IF(((V26+V27+V28+V29)/4)<'PlayerGrades+'!$Y$25,"S","S+")))))))))))))))))))) -> B- | V30: Team AVG | X30: =IFERROR(SUM(X26:X29), 0) -> 80471
A32: Trespa5s's Team | B32: Trespa5s | C32: =IFERROR(VLOOKUP($B32,'Halo Infinite Stats'!$A:$AM,2,0),) -> 18 | D32: =IFERROR(VLOOKUP($B32,'Halo Infinite Stats'!$A:$AM,3,0),) -> 1 | E32: =IFERROR(VLOOKUP($B32,'Halo Infinite Stats'!$A:$AM,4,0),) -> 17 | F32: =IFERROR(VLOOKUP($B32,'Halo Infinite Stats'!$A:$AM,5,0),) -> 0 | G32: =IFERROR(VLOOKUP($B32,'Halo Infinite Stats'!$A:$AM,6,0),) -> 17 | H32: =IFERROR(VLOOKUP($B32,'Halo Infinite Stats'!$A:$AM,7,0),) -> 545 | I32: =IFERROR(VLOOKUP($B32,'Halo Infinite Stats'!$A:$AM,8,0),) -> 902 | J32: =IFERROR(VLOOKUP($B32,'Halo Infinite Stats'!$A:$AM,9,0),) -> -357 | K32: =IFERROR(VLOOKUP($B32,'Halo Infinite Stats'!$A:$AM,11,0),) -> 0 | L32: =IFERROR(TEXT(VLOOKUP($B32,'Halo Infinite Stats'!$A:$AM,12,0)/(24*60*60),"hh:mm:ss"),"") -> 04:06:08 | M32: =IFERROR(VLOOKUP($B32,'Halo Infinite Stats'!$A:$AM,14,0),) -> 5 | N32: =IFERROR(VLOOKUP($B32,'Halo Infinite Stats'!$A:$AM,15,0),)+IFERROR(VLOOKUP($B32,'Halo Infinite Stats'!$A:$AM,16,0),)+IFERROR(VLOOKUP($B32,'Halo Infinite Stats'!$A:$AM,17,0),) -> 0 | O32: =IFERROR(VLOOKUP($B32,'Halo Infinite Stats'!$A:$AM,18,0),) -> 9 | P32: =IFERROR(VLOOKUP($B32,'Halo Infinite Stats'!$A:$AM,19,0),) -> 75 | Q32: =IFERROR(VLOOKUP($B32,'Halo Infinite Stats'!$A:$AM,20,0),) -> 12 | R32: =IFERROR(VLOOKUP($B32,'Halo Infinite Stats'!$A:$AM,21,0),)+IFERROR(VLOOKUP($B32,'Halo Infinite Stats'!$A:$AM,22,0),)+IFERROR(VLOOKUP($B32,'Halo Infinite Stats'!$A:$AM,23,0),)+IFERROR(VLOOKUP($B32,'Halo Infinite Stats'!$A:$AM,24,0),)+IFERROR(VLOOKUP($B32,'Halo Infinite Stats'!$A:$AM,25,0),)+IFERROR(VLOOKUP($B32,'Halo Infinite Stats'!$A:$AM,26,0),)+IFERROR(VLOOKUP($B32,'Halo Infinite Stats'!$A:$AM,27,0),) -> 2 | S32: =IFERROR(VLOOKUP($B32,'Halo Infinite Stats'!$A:$AM,28,0),) -> 0 | T32: =IFERROR(VLOOKUP($B32,'Halo Infinite Stats'!$A:$AM,31,0),) -> 0 | U32: =IFERROR(VLOOKUP($B32,'PlayerGrades+'!$A:$W,22,0),) -> F- | V32: =IFERROR(VLOOKUP($B32,'PlayerGrades+'!$A:$W,23,0),) -> 5.675 | X32: =(HOUR(L32) * 3600) + (MINUTE(L32) * 60) + SECOND(L32) -> 14768
A33: Trespa5s's Team | B33: Itzreelz | C33: =IFERROR(VLOOKUP($B33,'Halo Infinite Stats'!$A:$AM,2,0),) -> 19 | D33: =IFERROR(VLOOKUP($B33,'Halo Infinite Stats'!$A:$AM,3,0),) -> 1 | E33: =IFERROR(VLOOKUP($B33,'Halo Infinite Stats'!$A:$AM,4,0),) -> 18 | F33: =IFERROR(VLOOKUP($B33,'Halo Infinite Stats'!$A:$AM,5,0),) -> 19 | G33: =IFERROR(VLOOKUP($B33,'Halo Infinite Stats'!$A:$AM,6,0),) -> 86 | H33: =IFERROR(VLOOKUP($B33,'Halo Infinite Stats'!$A:$AM,7,0),) -> 725 | I33: =IFERROR(VLOOKUP($B33,'Halo Infinite Stats'!$A:$AM,8,0),) -> 820 | J33: =IFERROR(VLOOKUP($B33,'Halo Infinite Stats'!$A:$AM,9,0),) -> -95 | K33: =IFERROR(VLOOKUP($B33,'Halo Infinite Stats'!$A:$AM,11,0),) -> 1 | L33: =IFERROR(TEXT(VLOOKUP($B33,'Halo Infinite Stats'!$A:$AM,12,0)/(24*60*60),"hh:mm:ss"),"") -> 04:17:56 | M33: =IFERROR(VLOOKUP($B33,'Halo Infinite Stats'!$A:$AM,14,0),) -> 20 | N33: =IFERROR(VLOOKUP($B33,'Halo Infinite Stats'!$A:$AM,15,0),)+IFERROR(VLOOKUP($B33,'Halo Infinite Stats'!$A:$AM,16,0),)+IFERROR(VLOOKUP($B33,'Halo Infinite Stats'!$A:$AM,17,0),) -> 0 | O33: =IFERROR(VLOOKUP($B33,'Halo Infinite Stats'!$A:$AM,18,0),) -> 12 | P33: =IFERROR(VLOOKUP($B33,'Halo Infinite Stats'!$A:$AM,19,0),) -> 105 | Q33: =IFERROR(VLOOKUP($B33,'Halo Infinite Stats'!$A:$AM,20,0),) -> 34 | R33: =IFERROR(VLOOKUP($B33,'Halo Infinite Stats'!$A:$AM,21,0),)+IFERROR(VLOOKUP($B33,'Halo Infinite Stats'!$A:$AM,22,0),)+IFERROR(VLOOKUP($B33,'Halo Infinite Stats'!$A:$AM,23,0),)+IFERROR(VLOOKUP($B33,'Halo Infinite Stats'!$A:$AM,24,0),)+IFERROR(VLOOKUP($B33,'Halo Infinite Stats'!$A:$AM,25,0),)+IFERROR(VLOOKUP($B33,'Halo Infinite Stats'!$A:$AM,26,0),)+IFERROR(VLOOKUP($B33,'Halo Infinite Stats'!$A:$AM,27,0),) -> 13 | S33: =IFERROR(VLOOKUP($B33,'Halo Infinite Stats'!$A:$AM,28,0),) -> 0 | T33: =IFERROR(VLOOKUP($B33,'Halo Infinite Stats'!$A:$AM,31,0),) -> 0 | U33: =IFERROR(VLOOKUP($B33,'PlayerGrades+'!$A:$W,22,0),) -> B | V33: =IFERROR(VLOOKUP($B33,'PlayerGrades+'!$A:$W,23,0),) -> 19.7625 | X33: =(HOUR(L33) * 3600) + (MINUTE(L33) * 60) + SECOND(L33) -> 15476
A34: Trespa5s's Team | B34: Mr epic beast | C34: =IFERROR(VLOOKUP($B34,'Halo Infinite Stats'!$A:$AM,2,0),) -> 18 | D34: =IFERROR(VLOOKUP($B34,'Halo Infinite Stats'!$A:$AM,3,0),) -> 1 | E34: =IFERROR(VLOOKUP($B34,'Halo Infinite Stats'!$A:$AM,4,0),) -> 17 | F34: =IFERROR(VLOOKUP($B34,'Halo Infinite Stats'!$A:$AM,5,0),) -> 9 | G34: =IFERROR(VLOOKUP($B34,'Halo Infinite Stats'!$A:$AM,6,0),) -> 95 | H34: =IFERROR(VLOOKUP($B34,'Halo Infinite Stats'!$A:$AM,7,0),) -> 739 | I34: =IFERROR(VLOOKUP($B34,'Halo Infinite Stats'!$A:$AM,8,0),) -> 956 | J34: =IFERROR(VLOOKUP($B34,'Halo Infinite Stats'!$A:$AM,9,0),) -> -217 | K34: =IFERROR(VLOOKUP($B34,'Halo Infinite Stats'!$A:$AM,11,0),) -> 1 | L34: =IFERROR(TEXT(VLOOKUP($B34,'Halo Infinite Stats'!$A:$AM,12,0)/(24*60*60),"hh:mm:ss"),"") -> 04:06:08 | M34: =IFERROR(VLOOKUP($B34,'Halo Infinite Stats'!$A:$AM,14,0),) -> 14 | N34: =IFERROR(VLOOKUP($B34,'Halo Infinite Stats'!$A:$AM,15,0),)+IFERROR(VLOOKUP($B34,'Halo Infinite Stats'!$A:$AM,16,0),)+IFERROR(VLOOKUP($B34,'Halo Infinite Stats'!$A:$AM,17,0),) -> 0 | O34: =IFERROR(VLOOKUP($B34,'Halo Infinite Stats'!$A:$AM,18,0),) -> 4 | P34: =IFERROR(VLOOKUP($B34,'Halo Infinite Stats'!$A:$AM,19,0),) -> 107 | Q34: =IFERROR(VLOOKUP($B34,'Halo Infinite Stats'!$A:$AM,20,0),) -> 32 | R34: =IFERROR(VLOOKUP($B34,'Halo Infinite Stats'!$A:$AM,21,0),)+IFERROR(VLOOKUP($B34,'Halo Infinite Stats'!$A:$AM,22,0),)+IFERROR(VLOOKUP($B34,'Halo Infinite Stats'!$A:$AM,23,0),)+IFERROR(VLOOKUP($B34,'Halo Infinite Stats'!$A:$AM,24,0),)+IFERROR(VLOOKUP($B34,'Halo Infinite Stats'!$A:$AM,25,0),)+IFERROR(VLOOKUP($B34,'Halo Infinite Stats'!$A:$AM,26,0),)+IFERROR(VLOOKUP($B34,'Halo Infinite Stats'!$A:$AM,27,0),) -> 7 | S34: =IFERROR(VLOOKUP($B34,'Halo Infinite Stats'!$A:$AM,28,0),) -> 0 | T34: =IFERROR(VLOOKUP($B34,'Halo Infinite Stats'!$A:$AM,31,0),) -> 1 | U34: =IFERROR(VLOOKUP($B34,'PlayerGrades+'!$A:$W,22,0),) -> B- | V34: =IFERROR(VLOOKUP($B34,'PlayerGrades+'!$A:$W,23,0),) -> 16.5625 | X34: =(HOUR(L34) * 3600) + (MINUTE(L34) * 60) + SECOND(L34) -> 14768
A35: Trespa5s's Team | B35: GeneralCornBeef | C35: =IFERROR(VLOOKUP($B35,'Halo Infinite Stats'!$A:$AM,2,0),) -> 14 | D35: =IFERROR(VLOOKUP($B35,'Halo Infinite Stats'!$A:$AM,3,0),) -> 1 | E35: =IFERROR(VLOOKUP($B35,'Halo Infinite Stats'!$A:$AM,4,0),) -> 13 | F35: =IFERROR(VLOOKUP($B35,'Halo Infinite Stats'!$A:$AM,5,0),) -> 5 | G35: =IFERROR(VLOOKUP($B35,'Halo Infinite Stats'!$A:$AM,6,0),) -> 24 | H35: =IFERROR(VLOOKUP($B35,'Halo Infinite Stats'!$A:$AM,7,0),) -> 596 | I35: =IFERROR(VLOOKUP($B35,'Halo Infinite Stats'!$A:$AM,8,0),) -> 833 | J35: =IFERROR(VLOOKUP($B35,'Halo Infinite Stats'!$A:$AM,9,0),) -> -237 | K35: =IFERROR(VLOOKUP($B35,'Halo Infinite Stats'!$A:$AM,11,0),) -> 0 | L35: =IFERROR(TEXT(VLOOKUP($B35,'Halo Infinite Stats'!$A:$AM,12,0)/(24*60*60),"hh:mm:ss"),"") -> 03:28:02 | M35: =IFERROR(VLOOKUP($B35,'Halo Infinite Stats'!$A:$AM,14,0),) -> 5 | N35: =IFERROR(VLOOKUP($B35,'Halo Infinite Stats'!$A:$AM,15,0),)+IFERROR(VLOOKUP($B35,'Halo Infinite Stats'!$A:$AM,16,0),)+IFERROR(VLOOKUP($B35,'Halo Infinite Stats'!$A:$AM,17,0),) -> 0 | O35: =IFERROR(VLOOKUP($B35,'Halo Infinite Stats'!$A:$AM,18,0),) -> 8 | P35: =IFERROR(VLOOKUP($B35,'Halo Infinite Stats'!$A:$AM,19,0),) -> 85 | Q35: =IFERROR(VLOOKUP($B35,'Halo Infinite Stats'!$A:$AM,20,0),) -> 18 | R35: =IFERROR(VLOOKUP($B35,'Halo Infinite Stats'!$A:$AM,21,0),)+IFERROR(VLOOKUP($B35,'Halo Infinite Stats'!$A:$AM,22,0),)+IFERROR(VLOOKUP($B35,'Halo Infinite Stats'!$A:$AM,23,0),)+IFERROR(VLOOKUP($B35,'Halo Infinite Stats'!$A:$AM,24,0),)+IFERROR(VLOOKUP($B35,'Halo Infinite Stats'!$A:$AM,25,0),)+IFERROR(VLOOKUP($B35,'Halo Infinite Stats'!$A:$AM,26,0),)+IFERROR(VLOOKUP($B35,'Halo Infinite Stats'!$A:$AM,27,0),) -> 10 | S35: =IFERROR(VLOOKUP($B35,'Halo Infinite Stats'!$A:$AM,28,0),) -> 0 | T35: =IFERROR(VLOOKUP($B35,'Halo Infinite Stats'!$A:$AM,31,0),) -> 0 | U35: =IFERROR(VLOOKUP($B35,'PlayerGrades+'!$A:$W,22,0),) -> D- | V35: =IFERROR(VLOOKUP($B35,'PlayerGrades+'!$A:$W,23,0),) -> 12.3375 | X35: =(HOUR(L35) * 3600) + (MINUTE(L35) * 60) + SECOND(L35) -> 12482
