Workbook

Sheet Addto
A1: Add
A2: To Halo 4 Stats | B2: Team name per player
B3: location per player
B4: system per player
A6: To Rounds | B6: Host location used for games
B7: color code team MvP
A9: in general | B9: Player grades
B10: match averages
B11: top stat players
B12: hexas stats
B13: color code match history for rounds
B14: top 10 players per stat/time average
B15: combined team stats
A17: https://challonge.com/Halo4FallSeriesEventTwo
A20: Team MVP =

Sheet MassFormulaTesting
E1: NOT ADJUSTED FOR THE TOURNAMENT
C4: 0.03 | D4: 0.05 | E4: 0.02 | F4: 0.05 | G4: 0.05 | H4: 0.04 | I4: 0.05 | J4: 0 | K4: 0 | L4: 0.05 | M4: 0.05 | N4: 0.05 | O4: 6 | P4: 0.05 | Q4: 0.05 | R4: 0.06 | S4: 0.07 | T4: 0.08 | U4: 0.09 | V4: 0.1 | W4: 0.04 | X4: 0.03 | Y4: 0.06 | Z4: 0.02 | AA4: 0.04 | AB4: 0.015 | AC4: 0.015 | AD4: 0.015 | AE4: 0.05 | AF4: 0.05 | AG4: 0.01 | AH4: 0.05 | AI4: 0.05 | AJ4: 0.05 | AK4: 0.06 | AL4: 0.02
M5: =98-(((TotalAverages!J6/MassFormulaTesting!$B$28)*0.68)+0.3) -> 97.376925
C6: 0.1 | D6: 0.04 | E6: 0.03 | F6: 0.02 | G6: 0.06 | H6: 0.03 | I6: 5 | J6: 0 | K6: 0 | L6: 0.01 | M6: 0.08 | N6: 0.06 | O6: 0.03 | P6: 0.07 | Q6: 0.08 | R6: 0.05 | S6: 0.03 | T6: 0.02 | U6: 0.02 | V6: 0.02 | W6: 0.04 | X6: 0.02 | Y6: 0.02 | Z6: 0.04 | AA6: 0.05 | AB6: 0.02 | AC6: 0.01 | AD6: 0.01 | AE6: 0.05 | AF6: 0.05 | AG6: 0.01 | AH6: 0.05 | AI6: 0.04 | AJ6: 0.02 | AK6: 0.03 | AL6: 0.01
K8: Weighting
B9: Weighting | C9: Goals | D9: Kills | E9: Assists | F9: Deaths | G9: Spread | H9: Streak | I9: Betrayals | J9: TimeAlive | K9: GameTime | L9: AverageLife | M9: BombStops | N9: KillingSprees | O9: KillingFrenzies | P9: DoubleKills | Q9: TripleKills | R9: Overkills | S9: Killtaculars | T9: Killtrocities | U9: Killamanjaros | V9: Killtastrophe | W9: Bulltrues | X9: Avengers | Y9: BallClears | Z9: CarrierKillAssists | AA9: Catches | AB9: FastBreaks | AC9: FirstStrikes | AD9: FirstTouches | AE9: GoalDefences | AF9: GoalKeepers | AG9: HammerKills | AH9: Interceptions | AI9: LongBombs | AJ9: NiceCatches | AK9: Rejections | AL9: SwordKills
A10: 36 total stats | B10: =SUM(C10:AL10) -> 127 | C10: 10 | D10: 4 | E10: 3 | F10: 2 | G10: 3 | H10: 6 | I10: 5 | J10: 0 | K10: 0 | L10: 1 | M10: 8 | N10: 6 | O10: 3 | P10: 7 | Q10: 8 | R10: 5 | S10: 3 | T10: 2 | U10: 2 | V10: 2 | W10: 4 | X10: 2 | Y10: 2 | Z10: 4 | AA10: 5 | AB10: 2 | AC10: 1 | AD10: 1 | AE10: 5 | AF10: 5 | AG10: 1 | AH10: 5 | AI10: 4 | AJ10: 2 | AK10: 3 | AL10: 1
B11: Weighting of 98 | G11: Goals | H11: Kills | I11: Assists | J11: Deaths | K11: Spread | L11: Streak | M11: Betrayals | N11: TimeAlive | O11: GameTime | P11: AverageLife | Q11: BombStops | R11: KillingSprees | S11: KillingFrenzies | T11: DoubleKills | U11: TripleKills | V11: Overkills | W11: Killtaculars | X11: Killtrocities | Y11: Killamanjaros | Z11: Killtastrophe | AA11: Bulltrues | AB11: Avengers | AC11: BallClears | AD11: CarrierKillAssists | AE11: Catches | AF11: FastBreaks | AG11: FirstStrikes | AH11: FirstTouches | AI11: GoalDefences | AJ11: GoalKeepers | AK11: HammerKills | AL11: Interceptions | AM11: LongBombs | AN11: NiceCatches | AO11: Rejections | AP11: SwordKills
C12: Bot | D12: =(MAX(F13:F57)-MIN(F13:F57)) -> 0 | E12: God LEVEL player | F12: =((((G12*C$10)+(H12*D$10)+(I12*E$10)+(J12*F$10)+(K12*G$10)+(L12*H$10)+(M12*I$10)+(N12*J$10)+(O12*K$10)+(P12*L$10)+(Q12*M$10)+(R12*N$10)+(S12*O$10)+(T12*P$10)+(U12*Q$10)+(V12*R$10)+(W12*S$10)+(X12*T$10)+(Y12*U$10)+(Z12*V$10)+(AA12*W$10)+(AB12*X$10)+(AC12*Y$10)+(AD12*Z$10)+(AE12*AA$10)+(AF12*AB$10)+(AG12*AC$10)+(AH12*AD$10)+(AI12*AE$10)+(AJ12*AF$10)+(AK12*AG$10)+(AL12*AH$10)+(AM12*AI$10)+(AN12*AJ$10)+(AO12*AK$10)+(AP12*AL$10)))) -> 117.8042 | G12: =((3.4/MassFormulaTesting!$B$16)*0.68)+0.3 -> 0.31441996 | H12: 0.98 | I12: 0.98 | J12: 0.98 | K12: 0.98 | L12: 0.98 | M12: 0.98 | N12: 0.98 | O12: 0.98 | P12: 0.98 | Q12: 0.98 | R12: 0.98 | S12: 0.98 | T12: 0.98 | U12: 0.98 | V12: 0.98 | W12: 0.98 | X12: 0.98 | Y12: 0.98 | Z12: 0.98 | AA12: 0.98 | AB12: 0.98 | AC12: 0.98 | AD12: 0.98 | AE12: 0.98 | AF12: 0.98 | AG12: 0.98 | AH12: 0.98 | AI12: 0.98 | AJ12: 0.98 | AK12: 0.98 | AL12: 0.98 | AM12: 0.98 | AN12: 0.98 | AO12: 0.98 | AP12: 0.98
C13: =MIN(F13:F57) -> 0.3 | D13: =(((F13-$C$13)/$D$12)*0.68)+0.3 -> #DIV/0! | E13: =TotalAverages!A5 | F13: =(IFERROR(((G13*C$10)+(H13*D$10)+(I13*E$10)+(J13*F$10)+(K13*G$10)+(L13*H$10)+(M13*I$10)+(N13*J$10)+(O13*K$10)+(P13*L$10)+(Q13*M$10)+(R13*N$10)+(S13*O$10)+(T13*P$10)+(U13*Q$10)+(V13*R$10)+(W13*S$10)+(X13*T$10)+(Y13*U$10)+(Z13*V$10)+(AA13*W$10)+(AB13*X$10)+(AC13*Y$10)+(AD13*Z$10)+(AE13*AA$10)+(AF13*AB$10)+(AG13*AC$10)+(AH13*AD$10)+(AI13*AE$10)+(AJ13*AF$10)+(AK13*AG$10)+(AL13*AH$10)+(AM13*AI$10)+(AN13*AJ$10)+(AO13*AK$10)+(AP13*AL$10))/F$12,"")*0.68)+0.3 -> 0.3 | G13: =((TotalAverages!D5/MassFormulaTesting!$B$16)*0.68)+0.3 -> 0.3 | H13: =((TotalAverages!E5/MassFormulaTesting!$B$18)*0.68)+0.3 -> 0.3 | I13: =((TotalAverages!F5/MassFormulaTesting!$B$20)*0.68)+0.3 -> 0.3 | J13: =(IFERROR(MassFormulaTesting!$C$22/TotalAverages!G5,"")*0.68)+0.3 -> 0.3 | K13: =(((TotalAverages!H5+118)/(MassFormulaTesting!$B$24+118))*0.68)+0.3 -> 0.93766887 | L13: =((TotalAverages!I5/MassFormulaTesting!$B$26)*0.68)+0.3 -> 0.3 | M13: =((0.98-(TotalAverages!J5/MassFormulaTesting!$B$28)*0.68)) -> 0.98 | N13: =((TotalAverages!K5/MassFormulaTesting!$B$30)*0.68)+0.3 -> 0.3 | O13: =((TotalAverages!L5/MassFormulaTesting!$B$32)*0.68)+0.3 -> 0.3 | P13: =((TotalAverages!M5/MassFormulaTesting!$B$34)*0.68)+0.3 -> 0.3 | Q13: =((TotalAverages!N5/MassFormulaTesting!$B$36)*0.68)+0.3 -> #DIV/0! | R13: =((TotalAverages!O5/MassFormulaTesting!$B$38)*0.68)+0.3 -> 0.3 | S13: =(IFERROR(TotalAverages!P5/MassFormulaTesting!$B$40,"")*0.68)+0.3 -> 0.3 | T13: =((TotalAverages!T5/MassFormulaTesting!$B$48)*0.68)+0.3 -> 0.3 | U13: =((TotalAverages!U5/MassFormulaTesting!$B$50)*0.68)+0.3 -> 0.3 | V13: =((TotalAverages!V5/MassFormulaTesting!$B$52)*0.68)+0.3 -> 0.3 | W13: =(IFERROR(TotalAverages!W5/MassFormulaTesting!$B$54,"")*0.68)+0.3 -> 0.3 | X13: =(IFERROR(TotalAverages!X5/MassFormulaTesting!$B$56,"")*0.68)+0.3 -> 0.3 | Y13: =(IFERROR(TotalAverages!Y5/MassFormulaTesting!$B$58,"")*0.68)+0.3 -> 0.3 | Z13: =(IFERROR(TotalAverages!Z5/MassFormulaTesting!$B$60,"")*0.68)+0.3 -> 0.3 | AA13: =((TotalAverages!AD5/MassFormulaTesting!$B$68)*0.68)+0.3 -> 0.3 | AB13: =((TotalAverages!AG5/MassFormulaTesting!$B$74)*0.68)+0.3 -> #DIV/0! | AC13: =((TotalAverages!AH5/MassFormulaTesting!$B$76)*0.68)+0.3 -> #DIV/0! | AD13: =((TotalAverages!AK5/MassFormulaTesting!$B$82)*0.68)+0.3 -> #DIV/0! | AE13: =((TotalAverages!AL5/MassFormulaTesting!$B$84)*0.68)+0.3 -> #DIV/0! | AF13: =((TotalAverages!AM5/MassFormulaTesting!$B$86)*0.68)+0.3 -> #DIV/0! | AG13: =((TotalAverages!AN5/MassFormulaTesting!$B$88)*0.68)+0.3 -> #DIV/0! | AH13: =((TotalAverages!AO5/MassFormulaTesting!$B$90)*0.68)+0.3 -> #DIV/0! | AI13: =((TotalAverages!AP5/MassFormulaTesting!$B$92)*0.68)+0.3 -> #DIV/0! | AJ13: =((TotalAverages!AQ5/MassFormulaTesting!$B$94)*0.68)+0.3 -> #DIV/0! | AK13: =((TotalAverages!AR5/MassFormulaTesting!$B$96)*0.68)+0.3 -> #DIV/0! | AL13: =((TotalAverages!AS5/MassFormulaTesting!$B$98)*0.68)+0.3 -> #DIV/0! | AM13: =((TotalAverages!AT5/MassFormulaTesting!$B$100)*0.68)+0.3 -> #DIV/0! | AN13: =((TotalAverages!AV5/MassFormulaTesting!$B$104)*0.68)+0.3 -> #DIV/0! | AO13: =((TotalAverages!AW5/MassFormulaTesting!$B$106)*0.68)+0.3 -> #DIV/0! | AP13: =((TotalAverages!AX5/MassFormulaTesting!$B$108)*0.68)+0.3 -> #DIV/0!
A14: Top/Lowest per stat: Raw Value | D14: =(((F14-$C$13)/$D$12)*0.68)+0.3 -> #DIV/0! | E14: =TotalAverages!A6 -> ADhillyy | F14: =((IFERROR((G14*C$10)+(H14*D$10)+(I14*E$10)+(J14*F$10)+(K14*G$10)+(L14*H$10)+(M14*I$10)+(N14*J$10)+(O14*K$10)+(P14*L$10)+(Q14*M$10)+(R14*N$10)+(S14*O$10)+(T14*P$10)+(U14*Q$10)+(V14*R$10)+(W14*S$10)+(X14*T$10)+(Y14*U$10)+(Z14*V$10)+(AA14*W$10)+(AB14*X$10)+(AC14*Y$10)+(AD14*Z$10)+(AE14*AA$10)+(AF14*AB$10)+(AG14*AC$10)+(AH14*AD$10)+(AI14*AE$10)+(AJ14*AF$10)+(AK14*AG$10)+(AL14*AH$10)+(AM14*AI$10)+(AN14*AJ$10)+(AO14*AK$10)+(AP14*AL$10),"")/F$12)*0.68)+0.3 -> 0.3 | G14: =((TotalAverages!D6/MassFormulaTesting!$B$16)*0.68)+0.3 -> 0.54629047 | H14: =((TotalAverages!E6/MassFormulaTesting!$B$18)*0.68)+0.3 -> 0.70567846 | I14: =((TotalAverages!F6/MassFormulaTesting!$B$20)*0.68)+0.3 -> -0.23119736 | J14: =(IFERROR(MassFormulaTesting!$C$22/TotalAverages!G6,"")*0.68)+0.3 -> 4.01875 | K14: =(((TotalAverages!H6+118)/(MassFormulaTesting!$B$24+118))*0.68)+0.3 -> 0.95619678 | L14: =((TotalAverages!I6/MassFormulaTesting!$B$26)*0.68)+0.3 -> 0.41657143 | M14: =((0.98-(TotalAverages!J6/MassFormulaTesting!$B$28)*0.68)) -> 0.65692496 | N14: =((TotalAverages!K6/MassFormulaTesting!$B$30)*0.68)+0.3 -> 0.65186126 | O14: =((TotalAverages!L6/MassFormulaTesting!$B$32)*0.68)+0.3 -> 0.47713459 | P14: =((TotalAverages!M6/MassFormulaTesting!$B$34)*0.68)+0.3 -> 0.30314766 | Q14: =((TotalAverages!N6/MassFormulaTesting!$B$36)*0.68)+0.3 -> #DIV/0! | R14: =((TotalAverages!O6/MassFormulaTesting!$B$38)*0.68)+0.3 -> 0.32428571 | S14: =(IFERROR(TotalAverages!P6/MassFormulaTesting!$B$40,"")*0.68)+0.3 -> 0.3 | T14: =((TotalAverages!T6/MassFormulaTesting!$B$48)*0.68)+0.3 -> 0.3 | U14: =((TotalAverages!U6/MassFormulaTesting!$B$50)*0.68)+0.3 -> 0.48082616 | V14: =((TotalAverages!V6/MassFormulaTesting!$B$52)*0.68)+0.3 -> 0.45338346 | W14: =(IFERROR(TotalAverages!W6/MassFormulaTesting!$B$54,"")*0.68)+0.3 -> 0.37915344 | X14: =(IFERROR(TotalAverages!X6/MassFormulaTesting!$B$56,"")*0.68)+0.3 -> 0.3 | Y14: =(IFERROR(TotalAverages!Y6/MassFormulaTesting!$B$58,"")*0.68)+0.3 -> 0.3 | Z14: =(IFERROR(TotalAverages!Z6/MassFormulaTesting!$B$60,"")*0.68)+0.3 -> 0.3 | AA14: =((TotalAverages!AD6/MassFormulaTesting!$B$68)*0.68)+0.3 -> 0.3 | AB14: =((TotalAverages!AG6/MassFormulaTesting!$B$74)*0.68)+0.3 -> #DIV/0! | AC14: =((TotalAverages!AH6/MassFormulaTesting!$B$76)*0.68)+0.3 -> #DIV/0! | AD14: =((TotalAverages!AK6/MassFormulaTesting!$B$82)*0.68)+0.3 -> #DIV/0! | AE14: =((TotalAverages!AL6/MassFormulaTesting!$B$84)*0.68)+0.3 -> #DIV/0! | AF14: =((TotalAverages!AM6/MassFormulaTesting!$B$86)*0.68)+0.3 -> #DIV/0! | AG14: =((TotalAverages!AN6/MassFormulaTesting!$B$88)*0.68)+0.3 -> #DIV/0! | AH14: =((TotalAverages!AO6/MassFormulaTesting!$B$90)*0.68)+0.3 -> #DIV/0! | AI14: =((TotalAverages!AP6/MassFormulaTesting!$B$92)*0.68)+0.3 -> #DIV/0! | AJ14: =((TotalAverages!AQ6/MassFormulaTesting!$B$94)*0.68)+0.3 -> #DIV/0! | AK14: =((TotalAverages!AR6/MassFormulaTesting!$B$96)*0.68)+0.3 -> #DIV/0! | AL14: =((TotalAverages!AS6/MassFormulaTesting!$B$98)*0.68)+0.3 -> #DIV/0! | AM14: =((TotalAverages!AT6/MassFormulaTesting!$B$100)*0.68)+0.3 -> #DIV/0! | AN14: =((TotalAverages!AV6/MassFormulaTesting!$B$104)*0.68)+0.3 -> #DIV/0! | AO14: =((TotalAverages!AW6/MassFormulaTesting!$B$106)*0.68)+0.3 -> #DIV/0! | AP14: =((TotalAverages!AX6/MassFormulaTesting!$B$108)*0.68)+0.3 -> #DIV/0!
A15: =IFERROR(__xludf.DUMMYFUNCTION("Query(TotalAverages!A:AV,""Select A,D where A<>'' Order by D Desc Limit 1"")"),"OVERALL") -> OVERALL | B15: =IFERROR(__xludf.DUMMYFUNCTION("""COMPUTED_VALUE"""),"avg Kills") -> avg Kills | D15: =(((F15-$C$13)/$D$12)*0.68)+0.3 -> #DIV/0! | E15: =TotalAverages!A7 -> ASpence501 | F15: =((IFERROR((G15*C$10)+(H15*D$10)+(I15*E$10)+(J15*F$10)+(K15*G$10)+(L15*H$10)+(M15*I$10)+(N15*J$10)+(O15*K$10)+(P15*L$10)+(Q15*M$10)+(R15*N$10)+(S15*O$10)+(T15*P$10)+(U15*Q$10)+(V15*R$10)+(W15*S$10)+(X15*T$10)+(Y15*U$10)+(Z15*V$10)+(AA15*W$10)+(AB15*X$10)+(AC15*Y$10)+(AD15*Z$10)+(AE15*AA$10)+(AF15*AB$10)+(AG15*AC$10)+(AH15*AD$10)+(AI15*AE$10)+(AJ15*AF$10)+(AK15*AG$10)+(AL15*AH$10)+(AM15*AI$10)+(AN15*AJ$10)+(AO15*AK$10)+(AP15*AL$10),"")/F$12)*0.68)+0.3 -> 0.3 | G15: =((TotalAverages!D7/MassFormulaTesting!$B$16)*0.68)+0.3 -> 0.72562135 | H15: =((TotalAverages!E7/MassFormulaTesting!$B$18)*0.68)+0.3 -> 0.79594862 | I15: =((TotalAverages!F7/MassFormulaTesting!$B$20)*0.68)+0.3 -> 0.28535521 | J15: =(IFERROR(MassFormulaTesting!$C$22/TotalAverages!G7,"")*0.68)+0.3 -> 2.383004 | K15: =(((TotalAverages!H7+118)/(MassFormulaTesting!$B$24+118))*0.68)+0.3 -> 0.96573467 | L15: =((TotalAverages!I7/MassFormulaTesting!$B$26)*0.68)+0.3 -> 0.41845161 | M15: =((0.98-(TotalAverages!J7/MassFormulaTesting!$B$28)*0.68)) -> 0.52734705 | N15: =((TotalAverages!K7/MassFormulaTesting!$B$30)*0.68)+0.3 -> 0.77014578 | O15: =((TotalAverages!L7/MassFormulaTesting!$B$32)*0.68)+0.3 -> 0.5108473 | P15: =((TotalAverages!M7/MassFormulaTesting!$B$34)*0.68)+0.3 -> 0.30917899 | Q15: =((TotalAverages!N7/MassFormulaTesting!$B$36)*0.68)+0.3 -> #DIV/0! | R15: =((TotalAverages!O7/MassFormulaTesting!$B$38)*0.68)+0.3 -> 0.53580645 | S15: =(IFERROR(TotalAverages!P7/MassFormulaTesting!$B$40,"")*0.68)+0.3 -> 0.3 | T15: =((TotalAverages!T7/MassFormulaTesting!$B$48)*0.68)+0.3 -> 0.3 | U15: =((TotalAverages!U7/MassFormulaTesting!$B$50)*0.68)+0.3 -> 0.68849592 | V15: =((TotalAverages!V7/MassFormulaTesting!$B$52)*0.68)+0.3 -> 0.60132428 | W15: =(IFERROR(TotalAverages!W7/MassFormulaTesting!$B$54,"")*0.68)+0.3 -> 0.550227 | X15: =(IFERROR(TotalAverages!X7/MassFormulaTesting!$B$56,"")*0.68)+0.3 -> 0.56322581 | Y15: =(IFERROR(TotalAverages!Y7/MassFormulaTesting!$B$58,"")*0.68)+0.3 -> 0.36580645 | Z15: =(IFERROR(TotalAverages!Z7/MassFormulaTesting!$B$60,"")*0.68)+0.3 -> 0.52666667 | AA15: =((TotalAverages!AD7/MassFormulaTesting!$B$68)*0.68)+0.3 -> 0.3 | AB15: =((TotalAverages!AG7/MassFormulaTesting!$B$74)*0.68)+0.3 -> #DIV/0! | AC15: =((TotalAverages!AH7/MassFormulaTesting!$B$76)*0.68)+0.3 -> #DIV/0! | AD15: =((TotalAverages!AK7/MassFormulaTesting!$B$82)*0.68)+0.3 -> #DIV/0! | AE15: =((TotalAverages!AL7/MassFormulaTesting!$B$84)*0.68)+0.3 -> #DIV/0! | AF15: =((TotalAverages!AM7/MassFormulaTesting!$B$86)*0.68)+0.3 -> #DIV/0! | AG15: =((TotalAverages!AN7/MassFormulaTesting!$B$88)*0.68)+0.3 -> #DIV/0! | AH15: =((TotalAverages!AO7/MassFormulaTesting!$B$90)*0.68)+0.3 -> #DIV/0! | AI15: =((TotalAverages!AP7/MassFormulaTesting!$B$92)*0.68)+0.3 -> #DIV/0! | AJ15: =((TotalAverages!AQ7/MassFormulaTesting!$B$94)*0.68)+0.3 -> #DIV/0! | AK15: =((TotalAverages!AR7/MassFormulaTesting!$B$96)*0.68)+0.3 -> #DIV/0! | AL15: =((TotalAverages!AS7/MassFormulaTesting!$B$98)*0.68)+0.3 -> #DIV/0! | AM15: =((TotalAverages!AT7/MassFormulaTesting!$B$100)*0.68)+0.3 -> #DIV/0! | AN15: =((TotalAverages!AV7/MassFormulaTesting!$B$104)*0.68)+0.3 -> #DIV/0! | AO15: =((TotalAverages!AW7/MassFormulaTesting!$B$106)*0.68)+0.3 -> #DIV/0! | AP15: =((TotalAverages!AX7/MassFormulaTesting!$B$108)*0.68)+0.3 -> #DIV/0!
A16: =IFERROR(__xludf.DUMMYFUNCTION("""COMPUTED_VALUE"""),"Judasey") -> Judasey | B16: =IFERROR(__xludf.DUMMYFUNCTION("""COMPUTED_VALUE"""),160.33333333333334) -> 160.33333 | D16: =(((F16-$C$13)/$D$12)*0.68)+0.3 -> #DIV/0! | E16: =TotalAverages!A8 -> ActiveHate | F16: =((IFERROR((G16*C$10)+(H16*D$10)+(I16*E$10)+(J16*F$10)+(K16*G$10)+(L16*H$10)+(M16*I$10)+(N16*J$10)+(O16*K$10)+(P16*L$10)+(Q16*M$10)+(R16*N$10)+(S16*O$10)+(T16*P$10)+(U16*Q$10)+(V16*R$10)+(W16*S$10)+(X16*T$10)+(Y16*U$10)+(Z16*V$10)+(AA16*W$10)+(AB16*X$10)+(AC16*Y$10)+(AD16*Z$10)+(AE16*AA$10)+(AF16*AB$10)+(AG16*AC$10)+(AH16*AD$10)+(AI16*AE$10)+(AJ16*AF$10)+(AK16*AG$10)+(AL16*AH$10)+(AM16*AI$10)+(AN16*AJ$10)+(AO16*AK$10)+(AP16*AL$10),"")/F$12)*0.68)+0.3 -> 0.3 | G16: =((TotalAverages!D8/MassFormulaTesting!$B$16)*0.68)+0.3 -> 0.74468607 | H16: =((TotalAverages!E8/MassFormulaTesting!$B$18)*0.68)+0.3 -> 0.97839818 | I16: =((TotalAverages!F8/MassFormulaTesting!$B$20)*0.68)+0.3 -> -0.42097688 | J16: =(IFERROR(MassFormulaTesting!$C$22/TotalAverages!G8,"")*0.68)+0.3 -> 2.4794872 | K16: =(((TotalAverages!H8+118)/(MassFormulaTesting!$B$24+118))*0.68)+0.3 -> 0.96306755 | L16: =((TotalAverages!I8/MassFormulaTesting!$B$26)*0.68)+0.3 -> 0.4122 | M16: =((0.98-(TotalAverages!J8/MassFormulaTesting!$B$28)*0.68)) -> 0.41957385 | N16: =((TotalAverages!K8/MassFormulaTesting!$B$30)*0.68)+0.3 -> 0.88906731 | O16: =((TotalAverages!L8/MassFormulaTesting!$B$32)*0.68)+0.3 -> 0.48864834 | P16: =((TotalAverages!M8/MassFormulaTesting!$B$34)*0.68)+0.3 -> 0.30166826 | Q16: =((TotalAverages!N8/MassFormulaTesting!$B$36)*0.68)+0.3 -> #DIV/0! | R16: =((TotalAverages!O8/MassFormulaTesting!$B$38)*0.68)+0.3 -> 0.4615 | S16: =(IFERROR(TotalAverages!P8/MassFormulaTesting!$B$40,"")*0.68)+0.3 -> 0.3 | T16: =((TotalAverages!T8/MassFormulaTesting!$B$48)*0.68)+0.3 -> 0.3 | U16: =((TotalAverages!U8/MassFormulaTesting!$B$50)*0.68)+0.3 -> 0.65146988 | V16: =((TotalAverages!V8/MassFormulaTesting!$B$52)*0.68)+0.3 -> 0.606 | W16: =(IFERROR(TotalAverages!W8/MassFormulaTesting!$B$54,"")*0.68)+0.3 -> 0.57703704 | X16: =(IFERROR(TotalAverages!X8/MassFormulaTesting!$B$56,"")*0.68)+0.3 -> 0.3 | Y16: =(IFERROR(TotalAverages!Y8/MassFormulaTesting!$B$58,"")*0.68)+0.3 -> 0.3 | Z16: =(IFERROR(TotalAverages!Z8/MassFormulaTesting!$B$60,"")*0.68)+0.3 -> 0.3 | AA16: =((TotalAverages!AD8/MassFormulaTesting!$B$68)*0.68)+0.3 -> 0.3 | AB16: =((TotalAverages!AG8/MassFormulaTesting!$B$74)*0.68)+0.3 -> #DIV/0! | AC16: =((TotalAverages!AH8/MassFormulaTesting!$B$76)*0.68)+0.3 -> #DIV/0! | AD16: =((TotalAverages!AK8/MassFormulaTesting!$B$82)*0.68)+0.3 -> #DIV/0! | AE16: =((TotalAverages!AL8/MassFormulaTesting!$B$84)*0.68)+0.3 -> #DIV/0! | AF16: =((TotalAverages!AM8/MassFormulaTesting!$B$86)*0.68)+0.3 -> #DIV/0! | AG16: =((TotalAverages!AN8/MassFormulaTesting!$B$88)*0.68)+0.3 -> #DIV/0! | AH16: =((TotalAverages!AO8/MassFormulaTesting!$B$90)*0.68)+0.3 -> #DIV/0! | AI16: =((TotalAverages!AP8/MassFormulaTesting!$B$92)*0.68)+0.3 -> #DIV/0! | AJ16: =((TotalAverages!AQ8/MassFormulaTesting!$B$94)*0.68)+0.3 -> #DIV/0! | AK16: =((TotalAverages!AR8/MassFormulaTesting!$B$96)*0.68)+0.3 -> #DIV/0! | AL16: =((TotalAverages!AS8/MassFormulaTesting!$B$98)*0.68)+0.3 -> #DIV/0! | AM16: =((TotalAverages!AT8/MassFormulaTesting!$B$100)*0.68)+0.3 -> #DIV/0! | AN16: =((TotalAverages!AV8/MassFormulaTesting!$B$104)*0.68)+0.3 -> #DIV/0! | AO16: =((TotalAverages!AW8/MassFormulaTesting!$B$106)*0.68)+0.3 -> #DIV/0! | AP16: =((TotalAverages!AX8/MassFormulaTesting!$B$108)*0.68)+0.3 -> #DIV/0!
A17: =IFERROR(__xludf.DUMMYFUNCTION("Query(TotalAverages!A:AV,""Select A,E where A<>'' Order by E Desc Limit 1"")"),"OVERALL") -> OVERALL | B17: =IFERROR(__xludf.DUMMYFUNCTION("""COMPUTED_VALUE"""),"avg Deaths") -> avg Deaths | D17: =(((F17-$C$13)/$D$12)*0.68)+0.3 -> #DIV/0! | E17: =TotalAverages!A9 -> Almighty Tycoon | F17: =((IFERROR((G17*C$10)+(H17*D$10)+(I17*E$10)+(J17*F$10)+(K17*G$10)+(L17*H$10)+(M17*I$10)+(N17*J$10)+(O17*K$10)+(P17*L$10)+(Q17*M$10)+(R17*N$10)+(S17*O$10)+(T17*P$10)+(U17*Q$10)+(V17*R$10)+(W17*S$10)+(X17*T$10)+(Y17*U$10)+(Z17*V$10)+(AA17*W$10)+(AB17*X$10)+(AC17*Y$10)+(AD17*Z$10)+(AE17*AA$10)+(AF17*AB$10)+(AG17*AC$10)+(AH17*AD$10)+(AI17*AE$10)+(AJ17*AF$10)+(AK17*AG$10)+(AL17*AH$10)+(AM17*AI$10)+(AN17*AJ$10)+(AO17*AK$10)+(AP17*AL$10),"")/F$12)*0.68)+0.3 -> 0.3 | G17: =((TotalAverages!D9/MassFormulaTesting!$B$16)*0.68)+0.3 -> 0.64325156 | H17: =((TotalAverages!E9/MassFormulaTesting!$B$18)*0.68)+0.3 -> 0.78466363 | I17: =((TotalAverages!F9/MassFormulaTesting!$B$20)*0.68)+0.3 -> -0.084809249 | J17: =(IFERROR(MassFormulaTesting!$C$22/TotalAverages!G9,"")*0.68)+0.3 -> 3.6552632 | K17: =(((TotalAverages!H9+118)/(MassFormulaTesting!$B$24+118))*0.68)+0.3 -> 0.96288742 | L17: =((TotalAverages!I9/MassFormulaTesting!$B$26)*0.68)+0.3 -> 0.4496 | M17: =((0.98-(TotalAverages!J9/MassFormulaTesting!$B$28)*0.68)) -> 0.50340489 | N17: =((TotalAverages!K9/MassFormulaTesting!$B$30)*0.68)+0.3 -> 0.78586538 | O17: =((TotalAverages!L9/MassFormulaTesting!$B$32)*0.68)+0.3 -> 0.52555137 | P17: =((TotalAverages!M9/MassFormulaTesting!$B$34)*0.68)+0.3 -> 0.3083518 | Q17: =((TotalAverages!N9/MassFormulaTesting!$B$36)*0.68)+0.3 -> #DIV/0! | R17: =((TotalAverages!O9/MassFormulaTesting!$B$38)*0.68)+0.3 -> 0.39066667 | S17: =(IFERROR(TotalAverages!P9/MassFormulaTesting!$B$40,"")*0.68)+0.3 -> 0.3 | T17: =((TotalAverages!T9/MassFormulaTesting!$B$48)*0.68)+0.3 -> 0.3 | U17: =((TotalAverages!U9/MassFormulaTesting!$B$50)*0.68)+0.3 -> 0.51301205 | V17: =((TotalAverages!V9/MassFormulaTesting!$B$52)*0.68)+0.3 -> 0.45747368 | W17: =(IFERROR(TotalAverages!W9/MassFormulaTesting!$B$54,"")*0.68)+0.3 -> 0.52162963 | X17: =(IFERROR(TotalAverages!X9/MassFormulaTesting!$B$56,"")*0.68)+0.3 -> 0.39066667 | Y17: =(IFERROR(TotalAverages!Y9/MassFormulaTesting!$B$58,"")*0.68)+0.3 -> 0.436 | Z17: =(IFERROR(TotalAverages!Z9/MassFormulaTesting!$B$60,"")*0.68)+0.3 -> 0.3 | AA17: =((TotalAverages!AD9/MassFormulaTesting!$B$68)*0.68)+0.3 -> 0.3 | AB17: =((TotalAverages!AG9/MassFormulaTesting!$B$74)*0.68)+0.3 -> #DIV/0! | AC17: =((TotalAverages!AH9/MassFormulaTesting!$B$76)*0.68)+0.3 -> #DIV/0! | AD17: =((TotalAverages!AK9/MassFormulaTesting!$B$82)*0.68)+0.3 -> #DIV/0! | AE17: =((TotalAverages!AL9/MassFormulaTesting!$B$84)*0.68)+0.3 -> #DIV/0! | AF17: =((TotalAverages!AM9/MassFormulaTesting!$B$86)*0.68)+0.3 -> #DIV/0! | AG17: =((TotalAverages!AN9/MassFormulaTesting!$B$88)*0.68)+0.3 -> #DIV/0! | AH17: =((TotalAverages!AO9/MassFormulaTesting!$B$90)*0.68)+0.3 -> #DIV/0! | AI17: =((TotalAverages!AP9/MassFormulaTesting!$B$92)*0.68)+0.3 -> #DIV/0! | AJ17: =((TotalAverages!AQ9/MassFormulaTesting!$B$94)*0.68)+0.3 -> #DIV/0! | AK17: =((TotalAverages!AR9/MassFormulaTesting!$B$96)*0.68)+0.3 -> #DIV/0! | AL17: =((TotalAverages!AS9/MassFormulaTesting!$B$98)*0.68)+0.3 -> #DIV/0! | AM17: =((TotalAverages!AT9/MassFormulaTesting!$B$100)*0.68)+0.3 -> #DIV/0! | AN17: =((TotalAverages!AV9/MassFormulaTesting!$B$104)*0.68)+0.3 -> #DIV/0! | AO17: =((TotalAverages!AW9/MassFormulaTesting!$B$106)*0.68)+0.3 -> #DIV/0! | AP17: =((TotalAverages!AX9/MassFormulaTesting!$B$108)*0.68)+0.3 -> #DIV/0!
A18: =IFERROR(__xludf.DUMMYFUNCTION("""COMPUTED_VALUE"""),"oh zilly") -> oh zilly | B18: =IFERROR(__xludf.DUMMYFUNCTION("""COMPUTED_VALUE"""),138.52631578947367) -> 138.52632 | D18: =(((F18-$C$13)/$D$12)*0.68)+0.3 -> #DIV/0! | E18: =TotalAverages!A10 -> AwareMosquito | F18: =((IFERROR((G18*C$10)+(H18*D$10)+(I18*E$10)+(J18*F$10)+(K18*G$10)+(L18*H$10)+(M18*I$10)+(N18*J$10)+(O18*K$10)+(P18*L$10)+(Q18*M$10)+(R18*N$10)+(S18*O$10)+(T18*P$10)+(U18*Q$10)+(V18*R$10)+(W18*S$10)+(X18*T$10)+(Y18*U$10)+(Z18*V$10)+(AA18*W$10)+(AB18*X$10)+(AC18*Y$10)+(AD18*Z$10)+(AE18*AA$10)+(AF18*AB$10)+(AG18*AC$10)+(AH18*AD$10)+(AI18*AE$10)+(AJ18*AF$10)+(AK18*AG$10)+(AL18*AH$10)+(AM18*AI$10)+(AN18*AJ$10)+(AO18*AK$10)+(AP18*AL$10),"")/F$12)*0.68)+0.3 -> 0.3 | G18: =((TotalAverages!D10/MassFormulaTesting!$B$16)*0.68)+0.3 -> 0.66049896 | H18: =((TotalAverages!E10/MassFormulaTesting!$B$18)*0.68)+0.3 -> 0.82769757 | I18: =((TotalAverages!F10/MassFormulaTesting!$B$20)*0.68)+0.3 -> -0.18641619 | J18: =(IFERROR(MassFormulaTesting!$C$22/TotalAverages!G10,"")*0.68)+0.3 -> 4.6870968 | K18: =(((TotalAverages!H10+118)/(MassFormulaTesting!$B$24+118))*0.68)+0.3 -> 0.95928477 | L18: =((TotalAverages!I10/MassFormulaTesting!$B$26)*0.68)+0.3 -> 0.3255 | M18: =((0.98-(TotalAverages!J10/MassFormulaTesting!$B$28)*0.68)) -> 0.53858903 | N18: =((TotalAverages!K10/MassFormulaTesting!$B$30)*0.68)+0.3 -> 0.77012019 | O18: =((TotalAverages!L10/MassFormulaTesting!$B$32)*0.68)+0.3 -> 0.48156295 | P18: =((TotalAverages!M10/MassFormulaTesting!$B$34)*0.68)+0.3 -> 0.36547138 | Q18: =((TotalAverages!N10/MassFormulaTesting!$B$36)*0.68)+0.3 -> #DIV/0! | R18: =((TotalAverages!O10/MassFormulaTesting!$B$38)*0.68)+0.3 -> 0.3425 | S18: =(IFERROR(TotalAverages!P10/MassFormulaTesting!$B$40,"")*0.68)+0.3 -> 0.3 | T18: =((TotalAverages!T10/MassFormulaTesting!$B$48)*0.68)+0.3 -> 0.3 | U18: =((TotalAverages!U10/MassFormulaTesting!$B$50)*0.68)+0.3 -> 0.51198795 | V18: =((TotalAverages!V10/MassFormulaTesting!$B$52)*0.68)+0.3 -> 0.42078947 | W18: =(IFERROR(TotalAverages!W10/MassFormulaTesting!$B$54,"")*0.68)+0.3 -> 0.36925926 | X18: =(IFERROR(TotalAverages!X10/MassFormulaTesting!$B$56,"")*0.68)+0.3 -> 0.3 | Y18: =(IFERROR(TotalAverages!Y10/MassFormulaTesting!$B$58,"")*0.68)+0.3 -> 0.3 | Z18: =(IFERROR(TotalAverages!Z10/MassFormulaTesting!$B$60,"")*0.68)+0.3 -> 0.3 | AA18: =((TotalAverages!AD10/MassFormulaTesting!$B$68)*0.68)+0.3 -> 0.3 | AB18: =((TotalAverages!AG10/MassFormulaTesting!$B$74)*0.68)+0.3 -> #DIV/0! | AC18: =((TotalAverages!AH10/MassFormulaTesting!$B$76)*0.68)+0.3 -> #DIV/0! | AD18: =((TotalAverages!AK10/MassFormulaTesting!$B$82)*0.68)+0.3 -> #DIV/0! | AE18: =((TotalAverages!AL10/MassFormulaTesting!$B$84)*0.68)+0.3 -> #DIV/0! | AF18: =((TotalAverages!AM10/MassFormulaTesting!$B$86)*0.68)+0.3 -> #DIV/0! | AG18: =((TotalAverages!AN10/MassFormulaTesting!$B$88)*0.68)+0.3 -> #DIV/0! | AH18: =((TotalAverages!AO10/MassFormulaTesting!$B$90)*0.68)+0.3 -> #DIV/0! | AI18: =((TotalAverages!AP10/MassFormulaTesting!$B$92)*0.68)+0.3 -> #DIV/0! | AJ18: =((TotalAverages!AQ10/MassFormulaTesting!$B$94)*0.68)+0.3 -> #DIV/0! | AK18: =((TotalAverages!AR10/MassFormulaTesting!$B$96)*0.68)+0.3 -> #DIV/0! | AL18: =((TotalAverages!AS10/MassFormulaTesting!$B$98)*0.68)+0.3 -> #DIV/0! | AM18: =((TotalAverages!AT10/MassFormulaTesting!$B$100)*0.68)+0.3 -> #DIV/0! | AN18: =((TotalAverages!AV10/MassFormulaTesting!$B$104)*0.68)+0.3 -> #DIV/0! | AO18: =((TotalAverages!AW10/MassFormulaTesting!$B$106)*0.68)+0.3 -> #DIV/0! | AP18: =((TotalAverages!AX10/MassFormulaTesting!$B$108)*0.68)+0.3 -> #DIV/0!
A19: =IFERROR(__xludf.DUMMYFUNCTION("Query(TotalAverages!A:AV,""Select A,F where A<>'' Order by F Desc Limit 1"")"),"OVERALL") -> OVERALL | B19: =IFERROR(__xludf.DUMMYFUNCTION("""COMPUTED_VALUE"""),"avg Spread") -> avg Spread | D19: =(((F19-$C$13)/$D$12)*0.68)+0.3 -> #DIV/0! | E19: =TotalAverages!A11 -> Beautytism | F19: =((IFERROR((G19*C$10)+(H19*D$10)+(I19*E$10)+(J19*F$10)+(K19*G$10)+(L19*H$10)+(M19*I$10)+(N19*J$10)+(O19*K$10)+(P19*L$10)+(Q19*M$10)+(R19*N$10)+(S19*O$10)+(T19*P$10)+(U19*Q$10)+(V19*R$10)+(W19*S$10)+(X19*T$10)+(Y19*U$10)+(Z19*V$10)+(AA19*W$10)+(AB19*X$10)+(AC19*Y$10)+(AD19*Z$10)+(AE19*AA$10)+(AF19*AB$10)+(AG19*AC$10)+(AH19*AD$10)+(AI19*AE$10)+(AJ19*AF$10)+(AK19*AG$10)+(AL19*AH$10)+(AM19*AI$10)+(AN19*AJ$10)+(AO19*AK$10)+(AP19*AL$10),"")/F$12)*0.68)+0.3 -> 0.3 | G19: =((TotalAverages!D11/MassFormulaTesting!$B$16)*0.68)+0.3 -> 0.63886902 | H19: =((TotalAverages!E11/MassFormulaTesting!$B$18)*0.68)+0.3 -> 0.63404483 | I19: =((TotalAverages!F11/MassFormulaTesting!$B$20)*0.68)+0.3 -> 0.55617919 | J19: =(IFERROR(MassFormulaTesting!$C$22/TotalAverages!G11,"")*0.68)+0.3 -> 2.6287671 | K19: =(((TotalAverages!H11+118)/(MassFormulaTesting!$B$24+118))*0.68)+0.3 -> 0.96901192 | L19: =((TotalAverages!I11/MassFormulaTesting!$B$26)*0.68)+0.3 -> 0.7182 | M19: =((0.98-(TotalAverages!J11/MassFormulaTesting!$B$28)*0.68)) -> 0.51803965 | N19: =((TotalAverages!K11/MassFormulaTesting!$B$30)*0.68)+0.3 -> 0.75292788 | O19: =((TotalAverages!L11/MassFormulaTesting!$B$32)*0.68)+0.3 -> 0.62592764 | P19: =((TotalAverages!M11/MassFormulaTesting!$B$34)*0.68)+0.3 -> 0.30689338 | Q19: =((TotalAverages!N11/MassFormulaTesting!$B$36)*0.68)+0.3 -> #DIV/0! | R19: =((TotalAverages!O11/MassFormulaTesting!$B$38)*0.68)+0.3 -> 0.6145 | S19: =(IFERROR(TotalAverages!P11/MassFormulaTesting!$B$40,"")*0.68)+0.3 -> 0.3 | T19: =((TotalAverages!T11/MassFormulaTesting!$B$48)*0.68)+0.3 -> 0.3 | U19: =((TotalAverages!U11/MassFormulaTesting!$B$50)*0.68)+0.3 -> 0.53472289 | V19: =((TotalAverages!V11/MassFormulaTesting!$B$52)*0.68)+0.3 -> 0.43421053 | W19: =(IFERROR(TotalAverages!W11/MassFormulaTesting!$B$54,"")*0.68)+0.3 -> 0.43851852 | X19: =(IFERROR(TotalAverages!X11/MassFormulaTesting!$B$56,"")*0.68)+0.3 -> 0.436 | Y19: =(IFERROR(TotalAverages!Y11/MassFormulaTesting!$B$58,"")*0.68)+0.3 -> 0.504 | Z19: =(IFERROR(TotalAverages!Z11/MassFormulaTesting!$B$60,"")*0.68)+0.3 -> 0.3 | AA19: =((TotalAverages!AD11/MassFormulaTesting!$B$68)*0.68)+0.3 -> 0.3 | AB19: =((TotalAverages!AG11/MassFormulaTesting!$B$74)*0.68)+0.3 -> #DIV/0! | AC19: =((TotalAverages!AH11/MassFormulaTesting!$B$76)*0.68)+0.3 -> #DIV/0! | AD19: =((TotalAverages!AK11/MassFormulaTesting!$B$82)*0.68)+0.3 -> #DIV/0! | AE19: =((TotalAverages!AL11/MassFormulaTesting!$B$84)*0.68)+0.3 -> #DIV/0! | AF19: =((TotalAverages!AM11/MassFormulaTesting!$B$86)*0.68)+0.3 -> #DIV/0! | AG19: =((TotalAverages!AN11/MassFormulaTesting!$B$88)*0.68)+0.3 -> #DIV/0! | AH19: =((TotalAverages!AO11/MassFormulaTesting!$B$90)*0.68)+0.3 -> #DIV/0! | AI19: =((TotalAverages!AP11/MassFormulaTesting!$B$92)*0.68)+0.3 -> #DIV/0! | AJ19: =((TotalAverages!AQ11/MassFormulaTesting!$B$94)*0.68)+0.3 -> #DIV/0! | AK19: =((TotalAverages!AR11/MassFormulaTesting!$B$96)*0.68)+0.3 -> #DIV/0! | AL19: =((TotalAverages!AS11/MassFormulaTesting!$B$98)*0.68)+0.3 -> #DIV/0! | AM19: =((TotalAverages!AT11/MassFormulaTesting!$B$100)*0.68)+0.3 -> #DIV/0! | AN19: =((TotalAverages!AV11/MassFormulaTesting!$B$104)*0.68)+0.3 -> #DIV/0! | AO19: =((TotalAverages!AW11/MassFormulaTesting!$B$106)*0.68)+0.3 -> #DIV/0! | AP19: =((TotalAverages!AX11/MassFormulaTesting!$B$108)*0.68)+0.3 -> #DIV/0!
A20: =IFERROR(__xludf.DUMMYFUNCTION("""COMPUTED_VALUE"""),"oDhmon") -> oDhmon | B20: =IFERROR(__xludf.DUMMYFUNCTION("""COMPUTED_VALUE"""),31.454545454545453) -> 31.454545 | D20: =(((F20-$C$13)/$D$12)*0.68)+0.3 -> #DIV/0! | E20: =TotalAverages!A12 -> CaptainSev004 | F20: =((IFERROR((G20*C$10)+(H20*D$10)+(I20*E$10)+(J20*F$10)+(K20*G$10)+(L20*H$10)+(M20*I$10)+(N20*J$10)+(O20*K$10)+(P20*L$10)+(Q20*M$10)+(R20*N$10)+(S20*O$10)+(T20*P$10)+(U20*Q$10)+(V20*R$10)+(W20*S$10)+(X20*T$10)+(Y20*U$10)+(Z20*V$10)+(AA20*W$10)+(AB20*X$10)+(AC20*Y$10)+(AD20*Z$10)+(AE20*AA$10)+(AF20*AB$10)+(AG20*AC$10)+(AH20*AD$10)+(AI20*AE$10)+(AJ20*AF$10)+(AK20*AG$10)+(AL20*AH$10)+(AM20*AI$10)+(AN20*AJ$10)+(AO20*AK$10)+(AP20*AL$10),"")/F$12)*0.68)+0.3 -> 0.3 | G20: =((TotalAverages!D12/MassFormulaTesting!$B$16)*0.68)+0.3 -> 0.63158193 | H20: =((TotalAverages!E12/MassFormulaTesting!$B$18)*0.68)+0.3 -> 0.76990743 | I20: =((TotalAverages!F12/MassFormulaTesting!$B$20)*0.68)+0.3 -> -0.079306358 | J20: =(IFERROR(MassFormulaTesting!$C$22/TotalAverages!G12,"")*0.68)+0.3 -> 3.8283019 | K20: =(((TotalAverages!H12+118)/(MassFormulaTesting!$B$24+118))*0.68)+0.3 -> 0.95977604 | L20: =((TotalAverages!I12/MassFormulaTesting!$B$26)*0.68)+0.3 -> 0.43909091 | M20: =((0.98-(TotalAverages!J12/MassFormulaTesting!$B$28)*0.68)) -> 0.50117683 | N20: =((TotalAverages!K12/MassFormulaTesting!$B$30)*0.68)+0.3 -> 0.78513986 | O20: =((TotalAverages!L12/MassFormulaTesting!$B$32)*0.68)+0.3 -> 0.53188528 | P20: =((TotalAverages!M12/MassFormulaTesting!$B$34)*0.68)+0.3 -> 0.30847007 | Q20: =((TotalAverages!N12/MassFormulaTesting!$B$36)*0.68)+0.3 -> #DIV/0! | R20: =((TotalAverages!O12/MassFormulaTesting!$B$38)*0.68)+0.3 -> 0.40818182 | S20: =(IFERROR(TotalAverages!P12/MassFormulaTesting!$B$40,"")*0.68)+0.3 -> 0.3 | T20: =((TotalAverages!T12/MassFormulaTesting!$B$48)*0.68)+0.3 -> 0.3 | U20: =((TotalAverages!U12/MassFormulaTesting!$B$50)*0.68)+0.3 -> 0.5256736 | V20: =((TotalAverages!V12/MassFormulaTesting!$B$52)*0.68)+0.3 -> 0.40736842 | W20: =(IFERROR(TotalAverages!W12/MassFormulaTesting!$B$54,"")*0.68)+0.3 -> 0.3 | X20: =(IFERROR(TotalAverages!X12/MassFormulaTesting!$B$56,"")*0.68)+0.3 -> 0.3 | Y20: =(IFERROR(TotalAverages!Y12/MassFormulaTesting!$B$58,"")*0.68)+0.3 -> 0.3 | Z20: =(IFERROR(TotalAverages!Z12/MassFormulaTesting!$B$60,"")*0.68)+0.3 -> 0.3 | AA20: =((TotalAverages!AD12/MassFormulaTesting!$B$68)*0.68)+0.3 -> 0.3 | AB20: =((TotalAverages!AG12/MassFormulaTesting!$B$74)*0.68)+0.3 -> #DIV/0! | AC20: =((TotalAverages!AH12/MassFormulaTesting!$B$76)*0.68)+0.3 -> #DIV/0! | AD20: =((TotalAverages!AK12/MassFormulaTesting!$B$82)*0.68)+0.3 -> #DIV/0! | AE20: =((TotalAverages!AL12/MassFormulaTesting!$B$84)*0.68)+0.3 -> #DIV/0! | AF20: =((TotalAverages!AM12/MassFormulaTesting!$B$86)*0.68)+0.3 -> #DIV/0! | AG20: =((TotalAverages!AN12/MassFormulaTesting!$B$88)*0.68)+0.3 -> #DIV/0! | AH20: =((TotalAverages!AO12/MassFormulaTesting!$B$90)*0.68)+0.3 -> #DIV/0! | AI20: =((TotalAverages!AP12/MassFormulaTesting!$B$92)*0.68)+0.3 -> #DIV/0! | AJ20: =((TotalAverages!AQ12/MassFormulaTesting!$B$94)*0.68)+0.3 -> #DIV/0! | AK20: =((TotalAverages!AR12/MassFormulaTesting!$B$96)*0.68)+0.3 -> #DIV/0! | AL20: =((TotalAverages!AS12/MassFormulaTesting!$B$98)*0.68)+0.3 -> #DIV/0! | AM20: =((TotalAverages!AT12/MassFormulaTesting!$B$100)*0.68)+0.3 -> #DIV/0! | AN20: =((TotalAverages!AV12/MassFormulaTesting!$B$104)*0.68)+0.3 -> #DIV/0! | AO20: =((TotalAverages!AW12/MassFormulaTesting!$B$106)*0.68)+0.3 -> #DIV/0! | AP20: =((TotalAverages!AX12/MassFormulaTesting!$B$108)*0.68)+0.3 -> #DIV/0!
A21: =IFERROR(__xludf.DUMMYFUNCTION("Query(TotalAverages!A:AV,""Select A,G where A<>'' Order by G Desc Limit 1"")"),"OVERALL") -> OVERALL | B21: =IFERROR(__xludf.DUMMYFUNCTION("""COMPUTED_VALUE"""),"avg Assists") -> avg Assists | C21: Lowest | D21: =(((F21-$C$13)/$D$12)*0.68)+0.3 -> #DIV/0! | E21: =TotalAverages!A13 -> Cell x2 | F21: =((IFERROR((G21*C$10)+(H21*D$10)+(I21*E$10)+(J21*F$10)+(K21*G$10)+(L21*H$10)+(M21*I$10)+(N21*J$10)+(O21*K$10)+(P21*L$10)+(Q21*M$10)+(R21*N$10)+(S21*O$10)+(T21*P$10)+(U21*Q$10)+(V21*R$10)+(W21*S$10)+(X21*T$10)+(Y21*U$10)+(Z21*V$10)+(AA21*W$10)+(AB21*X$10)+(AC21*Y$10)+(AD21*Z$10)+(AE21*AA$10)+(AF21*AB$10)+(AG21*AC$10)+(AH21*AD$10)+(AI21*AE$10)+(AJ21*AF$10)+(AK21*AG$10)+(AL21*AH$10)+(AM21*AI$10)+(AN21*AJ$10)+(AO21*AK$10)+(AP21*AL$10),"")/F$12)*0.68)+0.3 -> 0.3 | G21: =((TotalAverages!D13/MassFormulaTesting!$B$16)*0.68)+0.3 -> 0.61384615 | H21: =((TotalAverages!E13/MassFormulaTesting!$B$18)*0.68)+0.3 -> 0.68930676 | I21: =((TotalAverages!F13/MassFormulaTesting!$B$20)*0.68)+0.3 -> 0.18525567 | J21: =(IFERROR(MassFormulaTesting!$C$22/TotalAverages!G13,"")*0.68)+0.3 -> 3.8645161 | K21: =(((TotalAverages!H13+118)/(MassFormulaTesting!$B$24+118))*0.68)+0.3 -> 0.96261029 | L21: =((TotalAverages!I13/MassFormulaTesting!$B$26)*0.68)+0.3 -> 0.42553846 | M21: =((0.98-(TotalAverages!J13/MassFormulaTesting!$B$28)*0.68)) -> 0.59698325 | N21: =((TotalAverages!K13/MassFormulaTesting!$B$30)*0.68)+0.3 -> 0.69667899 | O21: =((TotalAverages!L13/MassFormulaTesting!$B$32)*0.68)+0.3 -> 0.52482467 | P21: =((TotalAverages!M13/MassFormulaTesting!$B$34)*0.68)+0.3 -> 0.37714194 | Q21: =((TotalAverages!N13/MassFormulaTesting!$B$36)*0.68)+0.3 -> #DIV/0! | R21: =((TotalAverages!O13/MassFormulaTesting!$B$38)*0.68)+0.3 -> 0.41769231 | S21: =(IFERROR(TotalAverages!P13/MassFormulaTesting!$B$40,"")*0.68)+0.3 -> 0.3 | T21: =((TotalAverages!T13/MassFormulaTesting!$B$48)*0.68)+0.3 -> 0.3 | U21: =((TotalAverages!U13/MassFormulaTesting!$B$50)*0.68)+0.3 -> 0.54956441 | V21: =((TotalAverages!V13/MassFormulaTesting!$B$52)*0.68)+0.3 -> 0.51473684 | W21: =(IFERROR(TotalAverages!W13/MassFormulaTesting!$B$54,"")*0.68)+0.3 -> 0.51310541 | X21: =(IFERROR(TotalAverages!X13/MassFormulaTesting!$B$56,"")*0.68)+0.3 -> 0.3 | Y21: =(IFERROR(TotalAverages!Y13/MassFormulaTesting!$B$58,"")*0.68)+0.3 -> 0.3 | Z21: =(IFERROR(TotalAverages!Z13/MassFormulaTesting!$B$60,"")*0.68)+0.3 -> 0.3 | AA21: =((TotalAverages!AD13/MassFormulaTesting!$B$68)*0.68)+0.3 -> 0.3 | AB21: =((TotalAverages!AG13/MassFormulaTesting!$B$74)*0.68)+0.3 -> #DIV/0! | AC21: =((TotalAverages!AH13/MassFormulaTesting!$B$76)*0.68)+0.3 -> #DIV/0! | AD21: =((TotalAverages!AK13/MassFormulaTesting!$B$82)*0.68)+0.3 -> #DIV/0! | AE21: =((TotalAverages!AL13/MassFormulaTesting!$B$84)*0.68)+0.3 -> #DIV/0! | AF21: =((TotalAverages!AM13/MassFormulaTesting!$B$86)*0.68)+0.3 -> #DIV/0! | AG21: =((TotalAverages!AN13/MassFormulaTesting!$B$88)*0.68)+0.3 -> #DIV/0! | AH21: =((TotalAverages!AO13/MassFormulaTesting!$B$90)*0.68)+0.3 -> #DIV/0! | AI21: =((TotalAverages!AP13/MassFormulaTesting!$B$92)*0.68)+0.3 -> #DIV/0! | AJ21: =((TotalAverages!AQ13/MassFormulaTesting!$B$94)*0.68)+0.3 -> #DIV/0! | AK21: =((TotalAverages!AR13/MassFormulaTesting!$B$96)*0.68)+0.3 -> #DIV/0! | AL21: =((TotalAverages!AS13/MassFormulaTesting!$B$98)*0.68)+0.3 -> #DIV/0! | AM21: =((TotalAverages!AT13/MassFormulaTesting!$B$100)*0.68)+0.3 -> #DIV/0! | AN21: =((TotalAverages!AV13/MassFormulaTesting!$B$104)*0.68)+0.3 -> #DIV/0! | AO21: =((TotalAverages!AW13/MassFormulaTesting!$B$106)*0.68)+0.3 -> #DIV/0! | AP21: =((TotalAverages!AX13/MassFormulaTesting!$B$108)*0.68)+0.3 -> #DIV/0!
A22: =IFERROR(__xludf.DUMMYFUNCTION("""COMPUTED_VALUE"""),"Judasey") -> Judasey | B22: =IFERROR(__xludf.DUMMYFUNCTION("""COMPUTED_VALUE"""),11.666666666666666) -> 11.666667 | C22: 25 | D22: =(((F22-$C$13)/$D$12)*0.68)+0.3 -> #DIV/0! | E22: =TotalAverages!A14 -> Dhlyn | F22: =((IFERROR((G22*C$10)+(H22*D$10)+(I22*E$10)+(J22*F$10)+(K22*G$10)+(L22*H$10)+(M22*I$10)+(N22*J$10)+(O22*K$10)+(P22*L$10)+(Q22*M$10)+(R22*N$10)+(S22*O$10)+(T22*P$10)+(U22*Q$10)+(V22*R$10)+(W22*S$10)+(X22*T$10)+(Y22*U$10)+(Z22*V$10)+(AA22*W$10)+(AB22*X$10)+(AC22*Y$10)+(AD22*Z$10)+(AE22*AA$10)+(AF22*AB$10)+(AG22*AC$10)+(AH22*AD$10)+(AI22*AE$10)+(AJ22*AF$10)+(AK22*AG$10)+(AL22*AH$10)+(AM22*AI$10)+(AN22*AJ$10)+(AO22*AK$10)+(AP22*AL$10),"")/F$12)*0.68)+0.3 -> 0.3 | G22: =((TotalAverages!D14/MassFormulaTesting!$B$16)*0.68)+0.3 -> 0.60735967 | H22: =((TotalAverages!E14/MassFormulaTesting!$B$18)*0.68)+0.3 -> 0.61589666 | I22: =((TotalAverages!F14/MassFormulaTesting!$B$20)*0.68)+0.3 -> 0.47549133 | J22: =(IFERROR(MassFormulaTesting!$C$22/TotalAverages!G14,"")*0.68)+0.3 -> 5.2827586 | K22: =(((TotalAverages!H14+118)/(MassFormulaTesting!$B$24+118))*0.68)+0.3 -> 0.97613245 | L22: =((TotalAverages!I14/MassFormulaTesting!$B$26)*0.68)+0.3 -> 0.408 | M22: =((0.98-(TotalAverages!J14/MassFormulaTesting!$B$28)*0.68)) -> 0.49256296 | N22: =((TotalAverages!K14/MassFormulaTesting!$B$30)*0.68)+0.3 -> 0.76946267 | O22: =((TotalAverages!L14/MassFormulaTesting!$B$32)*0.68)+0.3 -> 0.69490593 | P22: =((TotalAverages!M14/MassFormulaTesting!$B$34)*0.68)+0.3 -> 0.69019904 | Q22: =((TotalAverages!N14/MassFormulaTesting!$B$36)*0.68)+0.3 -> #DIV/0! | R22: =((TotalAverages!O14/MassFormulaTesting!$B$38)*0.68)+0.3 -> 0.67 | S22: =(IFERROR(TotalAverages!P14/MassFormulaTesting!$B$40,"")*0.68)+0.3 -> 0.98 | T22: =((TotalAverages!T14/MassFormulaTesting!$B$48)*0.68)+0.3 -> 0.3 | U22: =((TotalAverages!U14/MassFormulaTesting!$B$50)*0.68)+0.3 -> 0.55301205 | V22: =((TotalAverages!V14/MassFormulaTesting!$B$52)*0.68)+0.3 -> 0.49578947 | W22: =(IFERROR(TotalAverages!W14/MassFormulaTesting!$B$54,"")*0.68)+0.3 -> 0.56074074 | X22: =(IFERROR(TotalAverages!X14/MassFormulaTesting!$B$56,"")*0.68)+0.3 -> 0.54 | Y22: =(IFERROR(TotalAverages!Y14/MassFormulaTesting!$B$58,"")*0.68)+0.3 -> 0.3 | Z22: =(IFERROR(TotalAverages!Z14/MassFormulaTesting!$B$60,"")*0.68)+0.3 -> 0.3 | AA22: =((TotalAverages!AD14/MassFormulaTesting!$B$68)*0.68)+0.3 -> 0.3 | AB22: =((TotalAverages!AG14/MassFormulaTesting!$B$74)*0.68)+0.3 -> #DIV/0! | AC22: =((TotalAverages!AH14/MassFormulaTesting!$B$76)*0.68)+0.3 -> #DIV/0! | AD22: =((TotalAverages!AK14/MassFormulaTesting!$B$82)*0.68)+0.3 -> #DIV/0! | AE22: =((TotalAverages!AL14/MassFormulaTesting!$B$84)*0.68)+0.3 -> #DIV/0! | AF22: =((TotalAverages!AM14/MassFormulaTesting!$B$86)*0.68)+0.3 -> #DIV/0! | AG22: =((TotalAverages!AN14/MassFormulaTesting!$B$88)*0.68)+0.3 -> #DIV/0! | AH22: =((TotalAverages!AO14/MassFormulaTesting!$B$90)*0.68)+0.3 -> #DIV/0! | AI22: =((TotalAverages!AP14/MassFormulaTesting!$B$92)*0.68)+0.3 -> #DIV/0! | AJ22: =((TotalAverages!AQ14/MassFormulaTesting!$B$94)*0.68)+0.3 -> #DIV/0! | AK22: =((TotalAverages!AR14/MassFormulaTesting!$B$96)*0.68)+0.3 -> #DIV/0! | AL22: =((TotalAverages!AS14/MassFormulaTesting!$B$98)*0.68)+0.3 -> #DIV/0! | AM22: =((TotalAverages!AT14/MassFormulaTesting!$B$100)*0.68)+0.3 -> #DIV/0! | AN22: =((TotalAverages!AV14/MassFormulaTesting!$B$104)*0.68)+0.3 -> #DIV/0! | AO22: =((TotalAverages!AW14/MassFormulaTesting!$B$106)*0.68)+0.3 -> #DIV/0! | AP22: =((TotalAverages!AX14/MassFormulaTesting!$B$108)*0.68)+0.3 -> #DIV/0!
A23: =IFERROR(__xludf.DUMMYFUNCTION("Query(TotalAverages!A:AV,""Select A,H where A<>'' Order by H Desc Limit 1"")"),"OVERALL") -> OVERALL | B23: =IFERROR(__xludf.DUMMYFUNCTION("""COMPUTED_VALUE"""),"avg Streak") -> avg Streak | C23: Lowest | D23: =(((F23-$C$13)/$D$12)*0.68)+0.3 -> #DIV/0! | E23: =TotalAverages!A15 -> Dior Glori | F23: =((IFERROR((G23*C$10)+(H23*D$10)+(I23*E$10)+(J23*F$10)+(K23*G$10)+(L23*H$10)+(M23*I$10)+(N23*J$10)+(O23*K$10)+(P23*L$10)+(Q23*M$10)+(R23*N$10)+(S23*O$10)+(T23*P$10)+(U23*Q$10)+(V23*R$10)+(W23*S$10)+(X23*T$10)+(Y23*U$10)+(Z23*V$10)+(AA23*W$10)+(AB23*X$10)+(AC23*Y$10)+(AD23*Z$10)+(AE23*AA$10)+(AF23*AB$10)+(AG23*AC$10)+(AH23*AD$10)+(AI23*AE$10)+(AJ23*AF$10)+(AK23*AG$10)+(AL23*AH$10)+(AM23*AI$10)+(AN23*AJ$10)+(AO23*AK$10)+(AP23*AL$10),"")/F$12)*0.68)+0.3 -> 0.3 | G23: =((TotalAverages!D15/MassFormulaTesting!$B$16)*0.68)+0.3 -> 0.56840511 | H23: =((TotalAverages!E15/MassFormulaTesting!$B$18)*0.68)+0.3 -> 0.65553843 | I23: =((TotalAverages!F15/MassFormulaTesting!$B$20)*0.68)+0.3 -> 0.10234517 | J23: =(IFERROR(MassFormulaTesting!$C$22/TotalAverages!G15,"")*0.68)+0.3 -> 3.8 | K23: =(((TotalAverages!H15+118)/(MassFormulaTesting!$B$24+118))*0.68)+0.3 -> 0.96430274 | L23: =((TotalAverages!I15/MassFormulaTesting!$B$26)*0.68)+0.3 -> 0.53314286 | M23: =((0.98-(TotalAverages!J15/MassFormulaTesting!$B$28)*0.68)) -> 0.58663129 | N23: =((TotalAverages!K15/MassFormulaTesting!$B$30)*0.68)+0.3 -> 0.69918956 | O23: =((TotalAverages!L15/MassFormulaTesting!$B$32)*0.68)+0.3 -> 0.55304941 | P23: =((TotalAverages!M15/MassFormulaTesting!$B$34)*0.68)+0.3 -> 0.39042784 | Q23: =((TotalAverages!N15/MassFormulaTesting!$B$36)*0.68)+0.3 -> #DIV/0! | R23: =((TotalAverages!O15/MassFormulaTesting!$B$38)*0.68)+0.3 -> 0.39714286 | S23: =(IFERROR(TotalAverages!P15/MassFormulaTesting!$B$40,"")*0.68)+0.3 -> 0.3 | T23: =((TotalAverages!T15/MassFormulaTesting!$B$48)*0.68)+0.3 -> 0.3 | U23: =((TotalAverages!U15/MassFormulaTesting!$B$50)*0.68)+0.3 -> 0.48784854 | V23: =((TotalAverages!V15/MassFormulaTesting!$B$52)*0.68)+0.3 -> 0.39969925 | W23: =(IFERROR(TotalAverages!W15/MassFormulaTesting!$B$54,"")*0.68)+0.3 -> 0.33957672 | X23: =(IFERROR(TotalAverages!X15/MassFormulaTesting!$B$56,"")*0.68)+0.3 -> 0.3 | Y23: =(IFERROR(TotalAverages!Y15/MassFormulaTesting!$B$58,"")*0.68)+0.3 -> 0.3 | Z23: =(IFERROR(TotalAverages!Z15/MassFormulaTesting!$B$60,"")*0.68)+0.3 -> 0.3 | AA23: =((TotalAverages!AD15/MassFormulaTesting!$B$68)*0.68)+0.3 -> 0.3 | AB23: =((TotalAverages!AG15/MassFormulaTesting!$B$74)*0.68)+0.3 -> #DIV/0! | AC23: =((TotalAverages!AH15/MassFormulaTesting!$B$76)*0.68)+0.3 -> #DIV/0! | AD23: =((TotalAverages!AK15/MassFormulaTesting!$B$82)*0.68)+0.3 -> #DIV/0! | AE23: =((TotalAverages!AL15/MassFormulaTesting!$B$84)*0.68)+0.3 -> #DIV/0! | AF23: =((TotalAverages!AM15/MassFormulaTesting!$B$86)*0.68)+0.3 -> #DIV/0! | AG23: =((TotalAverages!AN15/MassFormulaTesting!$B$88)*0.68)+0.3 -> #DIV/0! | AH23: =((TotalAverages!AO15/MassFormulaTesting!$B$90)*0.68)+0.3 -> #DIV/0! | AI23: =((TotalAverages!AP15/MassFormulaTesting!$B$92)*0.68)+0.3 -> #DIV/0! | AJ23: =((TotalAverages!AQ15/MassFormulaTesting!$B$94)*0.68)+0.3 -> #DIV/0! | AK23: =((TotalAverages!AR15/MassFormulaTesting!$B$96)*0.68)+0.3 -> #DIV/0! | AL23: =((TotalAverages!AS15/MassFormulaTesting!$B$98)*0.68)+0.3 -> #DIV/0! | AM23: =((TotalAverages!AT15/MassFormulaTesting!$B$100)*0.68)+0.3 -> #DIV/0! | AN23: =((TotalAverages!AV15/MassFormulaTesting!$B$104)*0.68)+0.3 -> #DIV/0! | AO23: =((TotalAverages!AW15/MassFormulaTesting!$B$106)*0.68)+0.3 -> #DIV/0! | AP23: =((TotalAverages!AX15/MassFormulaTesting!$B$108)*0.68)+0.3 -> #DIV/0!
A24: =IFERROR(__xludf.DUMMYFUNCTION("""COMPUTED_VALUE"""),"yLuxe") -> yLuxe | B24: =IFERROR(__xludf.DUMMYFUNCTION("""COMPUTED_VALUE"""),7.833333333333333) -> 7.8333333 | C24: -118 | D24: =(((F24-$C$13)/$D$12)*0.68)+0.3 -> #DIV/0! | E24: =TotalAverages!A16 -> DlGITAL PAIN | F24: =((IFERROR((G24*C$10)+(H24*D$10)+(I24*E$10)+(J24*F$10)+(K24*G$10)+(L24*H$10)+(M24*I$10)+(N24*J$10)+(O24*K$10)+(P24*L$10)+(Q24*M$10)+(R24*N$10)+(S24*O$10)+(T24*P$10)+(U24*Q$10)+(V24*R$10)+(W24*S$10)+(X24*T$10)+(Y24*U$10)+(Z24*V$10)+(AA24*W$10)+(AB24*X$10)+(AC24*Y$10)+(AD24*Z$10)+(AE24*AA$10)+(AF24*AB$10)+(AG24*AC$10)+(AH24*AD$10)+(AI24*AE$10)+(AJ24*AF$10)+(AK24*AG$10)+(AL24*AH$10)+(AM24*AI$10)+(AN24*AJ$10)+(AO24*AK$10)+(AP24*AL$10),"")/F$12)*0.68)+0.3 -> 0.3 | G24: =((TotalAverages!D16/MassFormulaTesting!$B$16)*0.68)+0.3 -> 0.80675072 | H24: =((TotalAverages!E16/MassFormulaTesting!$B$18)*0.68)+0.3 -> 0.76396215 | I24: =((TotalAverages!F16/MassFormulaTesting!$B$20)*0.68)+0.3 -> 0.83976506 | J24: =(IFERROR(MassFormulaTesting!$C$22/TotalAverages!G16,"")*0.68)+0.3 -> 2.6738739 | K24: =(((TotalAverages!H16+118)/(MassFormulaTesting!$B$24+118))*0.68)+0.3 -> 0.97427644 | L24: =((TotalAverages!I16/MassFormulaTesting!$B$26)*0.68)+0.3 -> 0.47109677 | M24: =((0.98-(TotalAverages!J16/MassFormulaTesting!$B$28)*0.68)) -> 0.43424955 | N24: =((TotalAverages!K16/MassFormulaTesting!$B$30)*0.68)+0.3 -> 0.83995347 | O24: =((TotalAverages!L16/MassFormulaTesting!$B$32)*0.68)+0.3 -> 0.57484431 | P24: =((TotalAverages!M16/MassFormulaTesting!$B$34)*0.68)+0.3 -> 0.31614446 | Q24: =((TotalAverages!N16/MassFormulaTesting!$B$36)*0.68)+0.3 -> #DIV/0! | R24: =((TotalAverages!O16/MassFormulaTesting!$B$38)*0.68)+0.3 -> 0.80451613 | S24: =(IFERROR(TotalAverages!P16/MassFormulaTesting!$B$40,"")*0.68)+0.3 -> 0.44916129 | T24: =((TotalAverages!T16/MassFormulaTesting!$B$48)*0.68)+0.3 -> 0.3 | U24: =((TotalAverages!U16/MassFormulaTesting!$B$50)*0.68)+0.3 -> 0.80266615 | V24: =((TotalAverages!V16/MassFormulaTesting!$B$52)*0.68)+0.3 -> 0.69483871 | W24: =(IFERROR(TotalAverages!W16/MassFormulaTesting!$B$54,"")*0.68)+0.3 -> 0.71108722 | X24: =(IFERROR(TotalAverages!X16/MassFormulaTesting!$B$56,"")*0.68)+0.3 -> 0.73870968 | Y24: =(IFERROR(TotalAverages!Y16/MassFormulaTesting!$B$58,"")*0.68)+0.3 -> 0.69483871 | Z24: =(IFERROR(TotalAverages!Z16/MassFormulaTesting!$B$60,"")*0.68)+0.3 -> 0.98 | AA24: =((TotalAverages!AD16/MassFormulaTesting!$B$68)*0.68)+0.3 -> 0.98 | AB24: =((TotalAverages!AG16/MassFormulaTesting!$B$74)*0.68)+0.3 -> #DIV/0! | AC24: =((TotalAverages!AH16/MassFormulaTesting!$B$76)*0.68)+0.3 -> #DIV/0! | AD24: =((TotalAverages!AK16/MassFormulaTesting!$B$82)*0.68)+0.3 -> #DIV/0! | AE24: =((TotalAverages!AL16/MassFormulaTesting!$B$84)*0.68)+0.3 -> #DIV/0! | AF24: =((TotalAverages!AM16/MassFormulaTesting!$B$86)*0.68)+0.3 -> #DIV/0! | AG24: =((TotalAverages!AN16/MassFormulaTesting!$B$88)*0.68)+0.3 -> #DIV/0! | AH24: =((TotalAverages!AO16/MassFormulaTesting!$B$90)*0.68)+0.3 -> #DIV/0! | AI24: =((TotalAverages!AP16/MassFormulaTesting!$B$92)*0.68)+0.3 -> #DIV/0! | AJ24: =((TotalAverages!AQ16/MassFormulaTesting!$B$94)*0.68)+0.3 -> #DIV/0! | AK24: =((TotalAverages!AR16/MassFormulaTesting!$B$96)*0.68)+0.3 -> #DIV/0! | AL24: =((TotalAverages!AS16/MassFormulaTesting!$B$98)*0.68)+0.3 -> #DIV/0! | AM24: =((TotalAverages!AT16/MassFormulaTesting!$B$100)*0.68)+0.3 -> #DIV/0! | AN24: =((TotalAverages!AV16/MassFormulaTesting!$B$104)*0.68)+0.3 -> #DIV/0! | AO24: =((TotalAverages!AW16/MassFormulaTesting!$B$106)*0.68)+0.3 -> #DIV/0! | AP24: =((TotalAverages!AX16/MassFormulaTesting!$B$108)*0.68)+0.3 -> #DIV/0!
A25: =IFERROR(__xludf.DUMMYFUNCTION("Query(TotalAverages!A:AV,""Select A,I where A<>'' Order by I Desc Limit 1"")"),"OVERALL") -> OVERALL | B25: =IFERROR(__xludf.DUMMYFUNCTION("""COMPUTED_VALUE"""),"avg Betrayals") -> avg Betrayals | D25: =(((F25-$C$13)/$D$12)*0.68)+0.3 -> #DIV/0! | E25: =TotalAverages!A17 -> Doerstopper | F25: =((IFERROR((G25*C$10)+(H25*D$10)+(I25*E$10)+(J25*F$10)+(K25*G$10)+(L25*H$10)+(M25*I$10)+(N25*J$10)+(O25*K$10)+(P25*L$10)+(Q25*M$10)+(R25*N$10)+(S25*O$10)+(T25*P$10)+(U25*Q$10)+(V25*R$10)+(W25*S$10)+(X25*T$10)+(Y25*U$10)+(Z25*V$10)+(AA25*W$10)+(AB25*X$10)+(AC25*Y$10)+(AD25*Z$10)+(AE25*AA$10)+(AF25*AB$10)+(AG25*AC$10)+(AH25*AD$10)+(AI25*AE$10)+(AJ25*AF$10)+(AK25*AG$10)+(AL25*AH$10)+(AM25*AI$10)+(AN25*AJ$10)+(AO25*AK$10)+(AP25*AL$10),"")/F$12)*0.68)+0.3 -> 0.3 | G25: =((TotalAverages!D17/MassFormulaTesting!$B$16)*0.68)+0.3 -> 0.57544006 | H25: =((TotalAverages!E17/MassFormulaTesting!$B$18)*0.68)+0.3 -> 0.7848818 | I25: =((TotalAverages!F17/MassFormulaTesting!$B$20)*0.68)+0.3 -> -0.43142582 | J25: =(IFERROR(MassFormulaTesting!$C$22/TotalAverages!G17,"")*0.68)+0.3 -> 12.069231 | K25: =(((TotalAverages!H17+118)/(MassFormulaTesting!$B$24+118))*0.68)+0.3 -> 0.95808389 | L25: =((TotalAverages!I17/MassFormulaTesting!$B$26)*0.68)+0.3 -> 0.36233333 | M25: =((0.98-(TotalAverages!J17/MassFormulaTesting!$B$28)*0.68)) -> 0.44116568 | N25: =((TotalAverages!K17/MassFormulaTesting!$B$30)*0.68)+0.3 -> 0.83559295 | O25: =((TotalAverages!L17/MassFormulaTesting!$B$32)*0.68)+0.3 -> 0.59030391 | P25: =((TotalAverages!M17/MassFormulaTesting!$B$34)*0.68)+0.3 -> 0.67908347 | Q25: =((TotalAverages!N17/MassFormulaTesting!$B$36)*0.68)+0.3 -> #DIV/0! | R25: =((TotalAverages!O17/MassFormulaTesting!$B$38)*0.68)+0.3 -> 0.35666667 | S25: =(IFERROR(TotalAverages!P17/MassFormulaTesting!$B$40,"")*0.68)+0.3 -> 0.3 | T25: =((TotalAverages!T17/MassFormulaTesting!$B$48)*0.68)+0.3 -> 0.98 | U25: =((TotalAverages!U17/MassFormulaTesting!$B$50)*0.68)+0.3 -> 0.4324498 | V25: =((TotalAverages!V17/MassFormulaTesting!$B$52)*0.68)+0.3 -> 0.33578947 | W25: =(IFERROR(TotalAverages!W17/MassFormulaTesting!$B$54,"")*0.68)+0.3 -> 0.33078189 | X25: =(IFERROR(TotalAverages!X17/MassFormulaTesting!$B$56,"")*0.68)+0.3 -> 0.37555556 | Y25: =(IFERROR(TotalAverages!Y17/MassFormulaTesting!$B$58,"")*0.68)+0.3 -> 0.3 | Z25: =(IFERROR(TotalAverages!Z17/MassFormulaTesting!$B$60,"")*0.68)+0.3 -> 0.3 | AA25: =((TotalAverages!AD17/MassFormulaTesting!$B$68)*0.68)+0.3 -> 0.3 | AB25: =((TotalAverages!AG17/MassFormulaTesting!$B$74)*0.68)+0.3 -> #DIV/0! | AC25: =((TotalAverages!AH17/MassFormulaTesting!$B$76)*0.68)+0.3 -> #DIV/0! | AD25: =((TotalAverages!AK17/MassFormulaTesting!$B$82)*0.68)+0.3 -> #DIV/0! | AE25: =((TotalAverages!AL17/MassFormulaTesting!$B$84)*0.68)+0.3 -> #DIV/0! | AF25: =((TotalAverages!AM17/MassFormulaTesting!$B$86)*0.68)+0.3 -> #DIV/0! | AG25: =((TotalAverages!AN17/MassFormulaTesting!$B$88)*0.68)+0.3 -> #DIV/0! | AH25: =((TotalAverages!AO17/MassFormulaTesting!$B$90)*0.68)+0.3 -> #DIV/0! | AI25: =((TotalAverages!AP17/MassFormulaTesting!$B$92)*0.68)+0.3 -> #DIV/0! | AJ25: =((TotalAverages!AQ17/MassFormulaTesting!$B$94)*0.68)+0.3 -> #DIV/0! | AK25: =((TotalAverages!AR17/MassFormulaTesting!$B$96)*0.68)+0.3 -> #DIV/0! | AL25: =((TotalAverages!AS17/MassFormulaTesting!$B$98)*0.68)+0.3 -> #DIV/0! | AM25: =((TotalAverages!AT17/MassFormulaTesting!$B$100)*0.68)+0.3 -> #DIV/0! | AN25: =((TotalAverages!AV17/MassFormulaTesting!$B$104)*0.68)+0.3 -> #DIV/0! | AO25: =((TotalAverages!AW17/MassFormulaTesting!$B$106)*0.68)+0.3 -> #DIV/0! | AP25: =((TotalAverages!AX17/MassFormulaTesting!$B$108)*0.68)+0.3 -> #DIV/0!
A26: =IFERROR(__xludf.DUMMYFUNCTION("""COMPUTED_VALUE"""),"Judasey") -> Judasey | B26: =IFERROR(__xludf.DUMMYFUNCTION("""COMPUTED_VALUE"""),6.666666666666667) -> 6.6666667 | D26: =(((F26-$C$13)/$D$12)*0.68)+0.3 -> #DIV/0! | E26: =TotalAverages!A18 -> EllisGotMyPills | F26: =((IFERROR((G26*C$10)+(H26*D$10)+(I26*E$10)+(J26*F$10)+(K26*G$10)+(L26*H$10)+(M26*I$10)+(N26*J$10)+(O26*K$10)+(P26*L$10)+(Q26*M$10)+(R26*N$10)+(S26*O$10)+(T26*P$10)+(U26*Q$10)+(V26*R$10)+(W26*S$10)+(X26*T$10)+(Y26*U$10)+(Z26*V$10)+(AA26*W$10)+(AB26*X$10)+(AC26*Y$10)+(AD26*Z$10)+(AE26*AA$10)+(AF26*AB$10)+(AG26*AC$10)+(AH26*AD$10)+(AI26*AE$10)+(AJ26*AF$10)+(AK26*AG$10)+(AL26*AH$10)+(AM26*AI$10)+(AN26*AJ$10)+(AO26*AK$10)+(AP26*AL$10),"")/F$12)*0.68)+0.3 -> 0.3 | G26: =((TotalAverages!D18/MassFormulaTesting!$B$16)*0.68)+0.3 -> 0.56248094 | H26: =((TotalAverages!E18/MassFormulaTesting!$B$18)*0.68)+0.3 -> 0.53071429 | I26: =((TotalAverages!F18/MassFormulaTesting!$B$20)*0.68)+0.3 -> 0.6218754 | J26: =(IFERROR(MassFormulaTesting!$C$22/TotalAverages!G18,"")*0.68)+0.3 -> 6.8106383 | K26: =(((TotalAverages!H18+118)/(MassFormulaTesting!$B$24+118))*0.68)+0.3 -> 0.97429581 | L26: =((TotalAverages!I18/MassFormulaTesting!$B$26)*0.68)+0.3 -> 0.37366667 | M26: =((0.98-(TotalAverages!J18/MassFormulaTesting!$B$28)*0.68)) -> 0.3355242 | N26: =((TotalAverages!K18/MassFormulaTesting!$B$30)*0.68)+0.3 -> 0.87774038 | O26: =((TotalAverages!L18/MassFormulaTesting!$B$32)*0.68)+0.3 -> 0.98 | P26: =((TotalAverages!M18/MassFormulaTesting!$B$34)*0.68)+0.3 -> 0.98 | Q26: =((TotalAverages!N18/MassFormulaTesting!$B$36)*0.68)+0.3 -> #DIV/0! | R26: =((TotalAverages!O18/MassFormulaTesting!$B$38)*0.68)+0.3 -> 0.64 | S26: =(IFERROR(TotalAverages!P18/MassFormulaTesting!$B$40,"")*0.68)+0.3 -> 0.68533333 | T26: =((TotalAverages!T18/MassFormulaTesting!$B$48)*0.68)+0.3 -> 0.3 | U26: =((TotalAverages!U18/MassFormulaTesting!$B$50)*0.68)+0.3 -> 0.45702811 | V26: =((TotalAverages!V18/MassFormulaTesting!$B$52)*0.68)+0.3 -> 0.38947368 | W26: =(IFERROR(TotalAverages!W18/MassFormulaTesting!$B$54,"")*0.68)+0.3 -> 0.39234568 | X26: =(IFERROR(TotalAverages!X18/MassFormulaTesting!$B$56,"")*0.68)+0.3 -> 0.3 | Y26: =(IFERROR(TotalAverages!Y18/MassFormulaTesting!$B$58,"")*0.68)+0.3 -> 0.3 | Z26: =(IFERROR(TotalAverages!Z18/MassFormulaTesting!$B$60,"")*0.68)+0.3 -> 0.3 | AA26: =((TotalAverages!AD18/MassFormulaTesting!$B$68)*0.68)+0.3 -> 0.3 | AB26: =((TotalAverages!AG18/MassFormulaTesting!$B$74)*0.68)+0.3 -> #DIV/0! | AC26: =((TotalAverages!AH18/MassFormulaTesting!$B$76)*0.68)+0.3 -> #DIV/0! | AD26: =((TotalAverages!AK18/MassFormulaTesting!$B$82)*0.68)+0.3 -> #DIV/0! | AE26: =((TotalAverages!AL18/MassFormulaTesting!$B$84)*0.68)+0.3 -> #DIV/0! | AF26: =((TotalAverages!AM18/MassFormulaTesting!$B$86)*0.68)+0.3 -> #DIV/0! | AG26: =((TotalAverages!AN18/MassFormulaTesting!$B$88)*0.68)+0.3 -> #DIV/0! | AH26: =((TotalAverages!AO18/MassFormulaTesting!$B$90)*0.68)+0.3 -> #DIV/0! | AI26: =((TotalAverages!AP18/MassFormulaTesting!$B$92)*0.68)+0.3 -> #DIV/0! | AJ26: =((TotalAverages!AQ18/MassFormulaTesting!$B$94)*0.68)+0.3 -> #DIV/0! | AK26: =((TotalAverages!AR18/MassFormulaTesting!$B$96)*0.68)+0.3 -> #DIV/0! | AL26: =((TotalAverages!AS18/MassFormulaTesting!$B$98)*0.68)+0.3 -> #DIV/0! | AM26: =((TotalAverages!AT18/MassFormulaTesting!$B$100)*0.68)+0.3 -> #DIV/0! | AN26: =((TotalAverages!AV18/MassFormulaTesting!$B$104)*0.68)+0.3 -> #DIV/0! | AO26: =((TotalAverages!AW18/MassFormulaTesting!$B$106)*0.68)+0.3 -> #DIV/0! | AP26: =((TotalAverages!AX18/MassFormulaTesting!$B$108)*0.68)+0.3 -> #DIV/0!
A27: =IFERROR(__xludf.DUMMYFUNCTION("Query(TotalAverages!A:AV,""Select A,J where A<>'' Order by J Desc Limit 1"")"),"OVERALL") -> OVERALL | B27: =IFERROR(__xludf.DUMMYFUNCTION("""COMPUTED_VALUE"""),"avg Time Alive") -> avg Time Alive | C27: Lowest | D27: =(((F27-$C$13)/$D$12)*0.68)+0.3 -> #DIV/0! | E27: =TotalAverages!A19 -> Finesse God24 | F27: =((IFERROR((G27*C$10)+(H27*D$10)+(I27*E$10)+(J27*F$10)+(K27*G$10)+(L27*H$10)+(M27*I$10)+(N27*J$10)+(O27*K$10)+(P27*L$10)+(Q27*M$10)+(R27*N$10)+(S27*O$10)+(T27*P$10)+(U27*Q$10)+(V27*R$10)+(W27*S$10)+(X27*T$10)+(Y27*U$10)+(Z27*V$10)+(AA27*W$10)+(AB27*X$10)+(AC27*Y$10)+(AD27*Z$10)+(AE27*AA$10)+(AF27*AB$10)+(AG27*AC$10)+(AH27*AD$10)+(AI27*AE$10)+(AJ27*AF$10)+(AK27*AG$10)+(AL27*AH$10)+(AM27*AI$10)+(AN27*AJ$10)+(AO27*AK$10)+(AP27*AL$10),"")/F$12)*0.68)+0.3 -> 0.3 | G27: =((TotalAverages!D19/MassFormulaTesting!$B$16)*0.68)+0.3 -> 0.50428274 | H27: =((TotalAverages!E19/MassFormulaTesting!$B$18)*0.68)+0.3 -> 0.5814387 | I27: =((TotalAverages!F19/MassFormulaTesting!$B$20)*0.68)+0.3 -> 0.10183044 | J27: =(IFERROR(MassFormulaTesting!$C$22/TotalAverages!G19,"")*0.68)+0.3 -> 7.1 | K27: =(((TotalAverages!H19+118)/(MassFormulaTesting!$B$24+118))*0.68)+0.3 -> 0.95478146 | L27: =((TotalAverages!I19/MassFormulaTesting!$B$26)*0.68)+0.3 -> 0.402 | M27: =((0.98-(TotalAverages!J19/MassFormulaTesting!$B$28)*0.68)) -> 0.73764601 | N27: =((TotalAverages!K19/MassFormulaTesting!$B$30)*0.68)+0.3 -> 0.561875 | O27: =((TotalAverages!L19/MassFormulaTesting!$B$32)*0.68)+0.3 -> 0.49780029 | P27: =((TotalAverages!M19/MassFormulaTesting!$B$34)*0.68)+0.3 -> 0.30220336 | Q27: =((TotalAverages!N19/MassFormulaTesting!$B$36)*0.68)+0.3 -> #DIV/0! | R27: =((TotalAverages!O19/MassFormulaTesting!$B$38)*0.68)+0.3 -> 0.3 | S27: =(IFERROR(TotalAverages!P19/MassFormulaTesting!$B$40,"")*0.68)+0.3 -> 0.3 | T27: =((TotalAverages!T19/MassFormulaTesting!$B$48)*0.68)+0.3 -> 0.3 | U27: =((TotalAverages!U19/MassFormulaTesting!$B$50)*0.68)+0.3 -> 0.45156627 | V27: =((TotalAverages!V19/MassFormulaTesting!$B$52)*0.68)+0.3 -> 0.37157895 | W27: =(IFERROR(TotalAverages!W19/MassFormulaTesting!$B$54,"")*0.68)+0.3 -> 0.3 | X27: =(IFERROR(TotalAverages!X19/MassFormulaTesting!$B$56,"")*0.68)+0.3 -> 0.3 | Y27: =(IFERROR(TotalAverages!Y19/MassFormulaTesting!$B$58,"")*0.68)+0.3 -> 0.3 | Z27: =(IFERROR(TotalAverages!Z19/MassFormulaTesting!$B$60,"")*0.68)+0.3 -> 0.3 | AA27: =((TotalAverages!AD19/MassFormulaTesting!$B$68)*0.68)+0.3 -> 0.3 | AB27: =((TotalAverages!AG19/MassFormulaTesting!$B$74)*0.68)+0.3 -> #DIV/0! | AC27: =((TotalAverages!AH19/MassFormulaTesting!$B$76)*0.68)+0.3 -> #DIV/0! | AD27: =((TotalAverages!AK19/MassFormulaTesting!$B$82)*0.68)+0.3 -> #DIV/0! | AE27: =((TotalAverages!AL19/MassFormulaTesting!$B$84)*0.68)+0.3 -> #DIV/0! | AF27: =((TotalAverages!AM19/MassFormulaTesting!$B$86)*0.68)+0.3 -> #DIV/0! | AG27: =((TotalAverages!AN19/MassFormulaTesting!$B$88)*0.68)+0.3 -> #DIV/0! | AH27: =((TotalAverages!AO19/MassFormulaTesting!$B$90)*0.68)+0.3 -> #DIV/0! | AI27: =((TotalAverages!AP19/MassFormulaTesting!$B$92)*0.68)+0.3 -> #DIV/0! | AJ27: =((TotalAverages!AQ19/MassFormulaTesting!$B$94)*0.68)+0.3 -> #DIV/0! | AK27: =((TotalAverages!AR19/MassFormulaTesting!$B$96)*0.68)+0.3 -> #DIV/0! | AL27: =((TotalAverages!AS19/MassFormulaTesting!$B$98)*0.68)+0.3 -> #DIV/0! | AM27: =((TotalAverages!AT19/MassFormulaTesting!$B$100)*0.68)+0.3 -> #DIV/0! | AN27: =((TotalAverages!AV19/MassFormulaTesting!$B$104)*0.68)+0.3 -> #DIV/0! | AO27: =((TotalAverages!AW19/MassFormulaTesting!$B$106)*0.68)+0.3 -> #DIV/0! | AP27: =((TotalAverages!AX19/MassFormulaTesting!$B$108)*0.68)+0.3 -> #DIV/0!
