Workbook

Sheet Team Chart
A1: 7
B2: HALO INFINITE Spring Bid League 2025 GRIFBALL SEASON
B6: Season Standings | C6: 5th | D6: 3rd | E6: 6th | F6: 7th | G6: 4th | H6: 13th | I6: 1st | J6: 8th | K6: 9th | L6: 2nd | M6: 10th | N6: 14th | O6: 11th | P6: 12th
B7: Playoff Ending | C7: 3rd (Semi-Finals) | D7: 3rd (Semi-Finals) | E7: 4th (Quarter Finals) | F7: 4th (Quarter Finals) | G7: 4th (Quarter Finals) | I7: 2nd (Finals) | J7: 4th (Quarter Finals) | L7: 1st (Season Winner)
B8: Team Name: | C8: First Strike | D8: Clip Hunters | E8: Hammers are for Losers | F8: Skill Differential | G8: Chick-fil-Ass Grabbers | H8: Intervention | I8: Chemical Imbalance | J8: Cosmic Oblivion | K8: Murder Incorporated | L8: Like Clockwork | M8: Ascension | N8: Junkyard Dogs | O8: Underrated | P8: NeuraLink II
B9: Captain: | C9: NecessaryEvil | D9: ASpence501 | E9: Mr Epic Beast | F9: KDSkill | G9: MysticalNovice | H9: Scullen cx | I9: Chemical | J9: DaedricKindred | K9: MasterSquirre | L9: yLuxe | M9: Solace VII | N9: Nkot | O9: NOPLEX | P9: TcT AVENGER
B10: Bid 1 | C10: Mavbrid | D10: Fanciest Pants | E10: Triumph Penguin | F10: Invayda Zim | G10: Dhlyn | H10: ShadowPandah | I10: PoisonxPoptart | J10: Cosmos5024 | K10: mxrvine | L10: Its Low Mane | M10: Grunt Padre | N10: PapasnipezX | O10: Sabasaurus rex | P10: Deathcrawller
B11: Bid 2 | C11: PsyDuck54 | D11: Boss Tycoon | E11: ill shrek u | F11: AwareMosquito | G11: Trespa5s | H11: The Goosler2948 | I11: Priest XYZ | J11: Rechargen | K11: Ump Double Ump | L11: ixGingy | M11: Inactive Spoon | N11: iReign 7 | O11: Big Al 60 | P11: Havoc Puppies
B12: Bid 3 | C12: TcT Demon | D12: Sauted Smurf | E12: Rage More Nerd | F12: II Panther Lily | G12: itsRiskE | H12: SPANKTR0N | I12: CaptainSev004 | J12: VwS Executioner | K12: ENDASIS ZX5080 | L12: TommyWstSide | M12: MuNgO PuNgO | N12: Legion of Toast | O12: Pacfan010 | P12: El Diablo

Sheet Schedule ListStandings
A1: h | B1: All Times Are Eastern Daylight Time
B2: ALL IN CONFERENCE MATCHES ARE DOUBLE HEADERS | K2: Hammer Conference | P2: Sword Conference
B3: ALL OUT OF CONFERENCE MATCHES ARE SINGLES
A4: Week 1 (March) | B4: Bouts | C4: Times | D4: In/Out of Conference | F4: Reschedules | G4: In/Out | H4: Free Scheduling | K4: Team Standings | L4: Wins | M4: Loss | N4: Games | P4: Team Standings | Q4: Wins | R4: Loss | S4: Games
A5: Monday 24th | B5: ASpence vs Solace | C5: 0.875 | D5: Out | H5: Evil vs kdskill (out) | I5: Sunday | J5: 1 | K5: Chemical Imbalance (chemical) | L5: 16 | M5: 3 | N5: =19-L5-M5 -> 0 | P5: Clip Hunters (aspence) | Q5: 15 | R5: 4 | S5: =19-Q5-R5 -> 0
B6: Chemical vs KDSkill | C6: 0.8125 | D6: Out | H6: Evil vs Daedric (in) | I6: Monday | J6: 2 | K6: Like Clockwork (luxe) | L6: 16 | M6: 3 | N6: =19-L6-M6 -> 0 | P6: Chick-fil-Ass Grabbers (novice) | Q6: 14 | R6: 5 | S6: =19-Q6-R6 -> 0
A7: Tuesday 25th | F7: Luxe vs Noplex 9:30 PM | G7: in | H7: Evil vs Solace (in) | I7: Tuesday | J7: 3 | K7: First Strike (evil) | L7: 13 | M7: 6 | N7: =19-L7-M7 -> 0 | P7: Hammers are for Losers (epic) | Q7: 11 | R7: 8 | S7: =19-Q7-R7 -> 0
B8: Luxe vs Nkot | C8: 0.83333333 | D8: Out | H8: Evil vs Epic (out) | I8: Wednesday | J8: 4 | K8: Cosmic Oblivion (Daedric) | L8: 9 | M8: 10 | N8: =19-L8-M8 -> 0 | P8: Skill Differential (kdskill) | Q8: 10 | R8: 9 | S8: =19-Q8-R8 -> 0
A9: Wednesday 26th | B9: Evil vs Avenger | C9: 0.83333333 | D9: In | H9: ASpence vs Scullen (in) | I9: Thursday | J9: 5 | K9: Ascension (solace) | L9: 8 | M9: 11 | N9: =19-L9-M9 -> 0 | P9: Murder Incorporated (squirell) | Q9: 8 | R9: 11 | S9: =19-Q9-R9 -> 0
H10: ASpence vs Daedric (out) | I10: Friday | J10: 6 | K10: Underrated (noplex) | L10: 6 | M10: 13 | N10: =19-L10-M10 -> 0 | P10: Intervention (scullen) | Q10: 2 | R10: 17 | S10: =19-Q10-R10 -> 0
A11: Thursday 27th | B11: Nkot vs Noplex | C11: 0.8125 | D11: Out | F11: Nkot vs Noplex 9:00 PM | G11: out | H11: ASpence vs Luxe (out) | I11: Saturday | J11: 7 | K11: NeuraLink II (avenger) | L11: 4 | M11: 15 | N11: =19-L11-M11 -> 0 | P11: Junkyard Dogs (nkot) | Q11: 1 | R11: 18 | S11: =19-Q11-R11 -> 0
A12: Friday 28th | B12: Noplex vs Epic | C12: 0.89583333 | D12: Out | H12: ASpence vs Nkot (in) | I12: Reschedule Thread Opened
A13: Saturday 29th | B13: Daedric vs Solace | C13: 0.79166667 | D13: In | H13: ASpence vs Noplex (out) | I13: Reschedule Locked in
A14: Week 2 (April) | B14: Bouts | C14: Times | F14: Reschedules | H14: ASpence vs Avenger (out)
A15: Sunday 30th | B15: Scullen vs Luxe | C15: 0.83333333 | D15: In | H15: ASpence vs Epic (in)
H16: kdskill vs scullen (in)
A17: Monday 31st | B17: KDSkill vs Solace | C17: 7:00 PM | D17: Out | H17: kdskill vs chemical (out)
B18: Scullen vs Avenger | C18: 0.83333333 | D18: Out | H18: kdskill vs daedric (out)
B19: Novice vs Solace | C19: 0.83333333 | D19: Out
B20: Solace vs Novice | C20: 0.83333333 | D20: Out
B21: Chemical vs Nkot | C21: 0.85416667 | D21: Out | H21: kdskill vs luxe (out)
B22: Chemical vs Noplex | C22: 0.89583333 | D22: In | H22: kdskill vs solace (out)
A23: Tuesday 1st | B23: Luxe vs Noplex | C23: 0.83333333 | D23: In | H23: kdskill vs nkot (in)
H24: kdskill vs avenger (out)
A25: Wednesday 2nd | B25: Evil vs KDSkill | C25: 8:00 PM | D25: Out
B26: Novice vs Luxe | C26: 8:00 PM | D26: Out | H26: kdskill vs epic (in)
B27: Evil vs ASpence | C27: 0.875 | D27: Out | H27: kdskill vs noplex (out)
A28: Thursday 3rd | B28: Evil vs Scullen | C28: 0.83333333 | D28: Out | F28: Evil vs Noplex 9:00 PM | G28: in | H28: scullen vs chemical (out)
H29: scullen vs daedric (out)
A30: Friday 4th | B30: Evil vs Noplex | C30: 0.83333333 | D30: In | H30: scullen vs squirell (in)
H31: chemical vs daedrice (in)
A32: Saturday 5th | B32: Daedric vs Avenger | C32: 0.79166667 | D32: In | H32: chemical vs luxe (in)
H33: chemical vs nkot (out)
A34: Week 3 | B34: Bouts | C34: Times | F34: Reschedules | H34: chemical vs noplex (in)
A35: Sunday 6th | B35: Scullen vs Solace | C35: 0.83333333 | D35: Out
B36: Evil vs Epic | C36: 0.85416667 | D36: Out | H36: chemical vs avenger (in)
B37: Evil vs Solace | C37: 0.875 | D37: in | H37: chemical vs epic (out)
A38: Monday 7th | B38: Scullen vs Noplex | C38: 0.83333333 | D38: out | F38: Solace vs Nkot 8 PM | G38: out | H38: daedric vs squirell (out)
B39: Solace vs Nkot | C39: 0.79166667 | D39: out | F39: Scullen vs Avenger 9 PM | G39: out | H39: daedric vs luxe (in)
F40: Scullen vs Noplex 9:30 PM | G40: out | H40: daedric vs nkot (out)
...

Sheet Game History
B1: Home | C1: Away | D1: Score | E1: Time | F1: Waypoint URL | H1: VOD | J1: 4/5th used Home | K1: 4/5th used Away | M1: Home Win | N1: Away Win | P1: Team | Q1: Win | R1: Loss | S1: Games left | T1: 4th/5th played | U1: Captain
A3: Week 1 | B3: Chemical | C3: KDSkill | D3: 5-1 | E3: 16:23 | F3: https://www.halowaypoint.com/en-gb/halo-infinite/players/Chemical/matches/6b04f745-3a8d-4679-85e7-be5c1782c44f
B4: Solace | C4: ASpence501 | D4: 5-4 | E4: 19:56 | F4: https://www.halowaypoint.com/en-gb/halo-infinite/players/ASpence501/matches/a559a9da-7b4f-41ca-a85f-17c65d017d54
B5: Luxe | C5: Nkot | D5: 5-1 | E5: 08:22 | F5: https://www.halowaypoint.com/halo-infinite/players/yLuxe/matches/8925f53b-02b3-4889-973f-7f849ee60098
B6: Luxe | C6: Noplex | D6: 5-2 | E6: 09:52 | F6: https://www.halowaypoint.com/halo-infinite/players/yLuxe/matches/979ec3c6-991d-42c9-b022-2d9377c804dd
B7: Noplex | C7: Luxe | D7: 1-5 | E7: 16:26 | F7: https://www.halowaypoint.com/halo-infinite/players/yLuxe/matches/a75c3aae-868c-4e8a-be13-3b5b7e31f39d
B8: Evil | C8: Avenger | D8: 5-3 | E8: 18:27 | F8: https://www.halowaypoint.com/halo-infinite/players/NecessaryEvil10/matches/243ac8c8-bc77-42b5-8577-d8b408f79f92
B9: Avenger | C9: Evil | D9: 4-5 | E9: 23:01 | F9: https://www.halowaypoint.com/halo-infinite/players/NecessaryEvil10/matches/c25a6dca-7d33-41f8-bd7b-e389d5d16b62
B10: Noplex | C10: Nkot | D10: 5-3 | E10: 16:02 | F10: https://www.halowaypoint.com/halo-infinite/players/noplex/matches/4247275d-eb0f-4dfb-8031-baa1ac87b009
B11: Noplex | C11: Epic | D11: 5-2 | E11: 7:51 | F11: https://www.halowaypoint.com/halo-infinite/players/Mr%20Epic%20Beast/matches/147b7287-6958-4b3c-bfd9-fbfbbbfb5204
A13: Week 2 | B13: Solace | C13: KDSkill | D13: 5-1 | E13: 25:08 | F13: https://www.halowaypoint.com/halo-infinite/players/KDSkill/matches/562b2b3b-74c6-42b7-988a-bc6061615728
B14: Novice | C14: Solace | D14: 5-4 | E14: 11:24 | F14: https://www.halowaypoint.com/halo-infinite/players/Mungo%20pungo/matches/6127c510-2bf9-4945-94b8-72cec1e79ae9
B15: Chemical | C15: Nkot | D15: 5-1 | E15: 19:30 | F15: https://halodatahive.com/Infinite/Match/fea4d761-ea75-4c72-b4ad-d7f08f76b334?gamertag=Chemical
B16: Chemical | C16: Noplex | D16: 5-0 | E16: 13:02 | F16: https://halodatahive.com/Infinite/Match/7a842a4f-c607-41dd-aa80-b753002d0656?gamertag=Chemical
B17: Noplex | C17: Chemical | D17: 0-5 | E17: 8:23 | F17: https://halodatahive.com/Infinite/Match/22872b17-5658-4660-bc25-69581dba40b7?gamertag=Chemical
B18: Evil | C18: KDSkill | D18: 5-2 | E18: 23:53 | F18: https://www.halowaypoint.com/halo-infinite/players/Kdskill/matches/679cb4ab-bdb3-4436-b407-caf11086a5da
B19: ASpence501 | C19: Evil | D19: 5-4 | E19: 33:58 | F19: https://www.halowaypoint.com/halo-infinite/players/ASpence501/matches/2d636f46-43f8-41d1-851f-81ddf09b294d
B20: Luxe | C20: Scullen | D20: 5-0 | E20: 10:00 | F20: https://www.halowaypoint.com/halo-infinite/players/yLuxe/matches/c9dcaa9b-272a-408f-a20a-a75d1507633a
B21: Evil | C21: Noplex | D21: 5-3 | E21: 19:28 | F21: https://halodatahive.com/Infinite/Match/e3b3b9e0-b1fb-479d-ae50-88b33473a98d?gamertag=Mavbrid&type=Custom&page=0
B22: Noplex | C22: Evil | D22: 2-5 | E22: 9:57 | F22: https://halodatahive.com/Infinite/Match/527affdf-9d67-4586-b073-66fa56fd8bcb?gamertag=Mavbrid&type=Custom&page=0
B23: Avenger | C23: Daedric | D23: 2-5 | E23: 13:29 | F23: https://halodatahive.com/Infinite/Match/e3524393-bdfd-446e-994b-dce3e80baa2a?gamertag=KindredDaedric&type=Custom&page=0
B24: Daedric | C24: Avenger | D24: 2-5 | E24: 21:08 | F24: https://halodatahive.com/Infinite/Match/805a2658-b0e4-4106-9fbb-958e3deef4a9?gamertag=KindredDaedric&type=Custom&page=0
A25: Week 3
B26: Evil | C26: Epic | D26: 5-1 | E26: 13:21 | F26: https://halodatahive.com/Infinite/Match/791d8a3d-689b-4dbc-82d4-9c90e35edcde?gamertag=Mavbrid&type=Custom&page=0
B27: Evil | C27: Solace | D27: 5-1 | E27: 16:11 | F27: https://halodatahive.com/Infinite/Match/0fefe2b0-c9c4-47fd-ba4b-43289929c576?gamertag=Mavbrid&type=Custom&page=0
B28: Solace | C28: Evil | D28: 4-5 | E28: 26:11 | F28: https://halodatahive.com/Infinite/Match/b9cced5e-9dae-458b-ad97-d16572f2e7c3?gamertag=Mavbrid&type=Custom&page=0
B29: Solace | C29: nkot | D29: 5-1 | E29: 9:16 | F29: https://www.halowaypoint.com/halo-infinite/players/solace%20viii/matches/01100ef7-3c69-439a-b46c-956086914c7f
B30: Avenger | C30: Scullen | D30: 5-1 | E30: 11:40 | F30: https://www.halowaypoint.com/halo-infinite/players/Scullen%20cx/matches/ee3e9266-fc11-4f37-b84c-04863b4f162f
B31: Noplex | C31: Scullen | D31: 5-0 | E31: 7:10 | F31: https://halodatahive.com/Infinite/Match/79e753e0-210e-4232-9fe0-965d14a785a6?gamertag=NOPLEX&type=Custom&page=0
B32: Luxe | C32: KDSkill | D32: 5-2 | E32: 19:23 | F32: https://halodatahive.com/Infinite/Match/ada7be7a-85df-4036-8299-0df24c9c44e1?gamertag=yLuxe&type=Custom&page=0
B33: Chemical | C33: Novice | D33: 5-1 | E33: 8:30 | F33: https://halodatahive.com/Infinite/Match/b6276562-691c-49b7-a230-dc013f186244?gamertag=Chemical
B34: Chemical | C34: Evil | D34: 5-1 | E34: 7:11 | F34: https://halodatahive.com/Infinite/Match/32906473-85fe-43f4-a535-801d8d6025d3?gamertag=Chemical
B35: Evil | C35: Chemical | D35: 45780 | E35: 9:44 | F35: https://halodatahive.com/Infinite/Match/633ed321-ec37-416d-8c98-89384ef84853?gamertag=Chemical
B36: Chemical | C36: Epic | D36: 5-1 | E36: 17:22 | F36: https://halodatahive.com/Infinite/Match/4ad5c405-45f0-4c19-94b7-cb0d1b5b884b?gamertag=Chemicall
B37: Novice | C37: Luxe | D37: 5-3 | E37: 12:36 | F37: https://halodatahive.com/Infinite/Match/34f11d6b-1b84-4938-b248-0b92647583c9?gamertag=yLuxe&type=Custom&page=0
B38: Nkot | C38: Daedric | D38: 0-5 | E38: 22:39 | F38: https://halodatahive.com/Infinite/Match/3ea6823b-92b4-4c91-b67d-b26c975cc620?gamertag=KindredDaedric&type=Custom&page=0
B39: kdskill | C39: noplex | D39: 5-3 | E39: 11:23 | F39: https://www.halowaypoint.com/halo-infinite/players/KDSkill/matches/0e2d86a6-084c-4c23-a551-3f7b8180ad38
B40: Luxe | C40: Daedric | D40: 5-1 | E40: 7:22 | F40: https://www.halowaypoint.com/halo-infinite/players/yLuxe/matches/60d1e8af-39fa-4877-b6b4-b4122991f43c
B41: Daedric | C41: Luxe | D41: 0-5 | E41: 6:20 | F41: https://www.halowaypoint.com/halo-infinite/players/yLuxe/matches/e3128434-4d40-4621-b1df-81277e3af6af
A43: Week 4 | B43: Epic | C43: Scullen | D43: 5-1 | E43: 12:19 | F43: https://www.halowaypoint.com/halo-infinite/players/Mr%20Epic%20Beast/matches/6da69fc1-1df4-42cc-89e7-b9119aca057c
...

Sheet Playoffs
C1: Auto Updates
B2: S1 | C2: =D37 -> Chemical Imbalance (chemical) | I2: Day 4
C4: vs (2-0)
B5: S8 | C5: =D44 -> Cosmic Oblivion (Daedric) | G5: =C2 -> Chemical Imbalance (chemical)
G7: vs (2-0)
B8: S4 | C8: =D40 -> Chick-fil-Ass Grabbers (novice) | G8: First Strike (evil)
C10: vs (2-0)
B11: S5 | C11: =D41 -> First Strike (evil) | J11: =G5 -> Chemical Imbalance (chemical)
L12: Winner
J13: vs (3-1) | L13: =J14 -> Like Clockwork (luxe)
B14: S3 | C14: =D39 -> Clip Hunters (aspence) | J14: =G20 -> Like Clockwork (luxe)
C16: vs (2-0)
B17: S6 | C17: =D42 -> Hammers are for Losers (epic) | G17: =C14 -> Clip Hunters (aspence)
G19: vs (2-1)
B20: S2 | C20: =D38 -> Like Clockwork (luxe) | G20: =C20 -> Like Clockwork (luxe)
C22: vs (2-0)
B23: S7 | C23: =D43 -> Skill Differential (kdskill)
D28: Roster
D29: Captain
D30: R1
D31: R2
D32: R3
D33: SUB
D34: SUB ALT
E35: Teams MUST play their full roster. Subs may only be used when a player has quit.
D37: =IFERROR(__xludf.DUMMYFUNCTION("QUERY(D49:F56,""Select D,E,F ORDER BY E DESC"")"),"Chemical Imbalance (chemical)") -> Chemical Imbalance (chemical) | E37: =IFERROR(__xludf.DUMMYFUNCTION("""COMPUTED_VALUE"""),16.0) -> 16 | F37: =IFERROR(__xludf.DUMMYFUNCTION("""COMPUTED_VALUE"""),3.0) -> 3 | H37: =E37/20 -> 0.8 | J37: Seed 1
D38: =IFERROR(__xludf.DUMMYFUNCTION("""COMPUTED_VALUE"""),"Like Clockwork (luxe)") -> Like Clockwork (luxe) | E38: =IFERROR(__xludf.DUMMYFUNCTION("""COMPUTED_VALUE"""),16.0) -> 16 | F38: =IFERROR(__xludf.DUMMYFUNCTION("""COMPUTED_VALUE"""),3.0) -> 3 | H38: =E38/20 -> 0.8 | J38: Seed 2
D39: =IFERROR(__xludf.DUMMYFUNCTION("""COMPUTED_VALUE"""),"Clip Hunters (aspence)") -> Clip Hunters (aspence) | E39: =IFERROR(__xludf.DUMMYFUNCTION("""COMPUTED_VALUE"""),15.0) -> 15 | F39: =IFERROR(__xludf.DUMMYFUNCTION("""COMPUTED_VALUE"""),4.0) -> 4 | H39: =E39/20 -> 0.75 | J39: Seed 3
D40: =IFERROR(__xludf.DUMMYFUNCTION("""COMPUTED_VALUE"""),"Chick-fil-Ass Grabbers (novice)") -> Chick-fil-Ass Grabbers (novice) | E40: =IFERROR(__xludf.DUMMYFUNCTION("""COMPUTED_VALUE"""),14.0) -> 14 | F40: =IFERROR(__xludf.DUMMYFUNCTION("""COMPUTED_VALUE"""),5.0) -> 5 | H40: =E40/20 -> 0.7 | J40: Seed 4
D41: =IFERROR(__xludf.DUMMYFUNCTION("""COMPUTED_VALUE"""),"First Strike (evil)") -> First Strike (evil) | E41: =IFERROR(__xludf.DUMMYFUNCTION("""COMPUTED_VALUE"""),13.0) -> 13 | F41: =IFERROR(__xludf.DUMMYFUNCTION("""COMPUTED_VALUE"""),6.0) -> 6 | H41: =E41/20 -> 0.65 | J41: Seed 5
D42: =IFERROR(__xludf.DUMMYFUNCTION("""COMPUTED_VALUE"""),"Hammers are for Losers (epic)") -> Hammers are for Losers (epic) | E42: =IFERROR(__xludf.DUMMYFUNCTION("""COMPUTED_VALUE"""),11.0) -> 11 | F42: =IFERROR(__xludf.DUMMYFUNCTION("""COMPUTED_VALUE"""),8.0) -> 8 | H42: =E42/20 -> 0.55 | J42: Seed 6
D43: =IFERROR(__xludf.DUMMYFUNCTION("""COMPUTED_VALUE"""),"Skill Differential (kdskill)") -> Skill Differential (kdskill) | E43: =IFERROR(__xludf.DUMMYFUNCTION("""COMPUTED_VALUE"""),10.0) -> 10 | F43: =IFERROR(__xludf.DUMMYFUNCTION("""COMPUTED_VALUE"""),9.0) -> 9 | H43: =E43/20 -> 0.5 | J43: Seed 7
D44: =IFERROR(__xludf.DUMMYFUNCTION("""COMPUTED_VALUE"""),"Cosmic Oblivion (Daedric)") -> Cosmic Oblivion (Daedric) | E44: =IFERROR(__xludf.DUMMYFUNCTION("""COMPUTED_VALUE"""),9.0) -> 9 | F44: =IFERROR(__xludf.DUMMYFUNCTION("""COMPUTED_VALUE"""),10.0) -> 10 | H44: =E44/20 -> 0.45 | J44: Seed 8
H45: =E45/20 -> 0
H46: =E46/20 -> 0
H47: =E47/20 -> 0
D49: ='Schedule ListStandings'!K5 -> Chemical Imbalance (chemical) | E49: ='Schedule ListStandings'!L5 -> 16 | F49: ='Schedule ListStandings'!M5 -> 3
D50: ='Schedule ListStandings'!K6 -> Like Clockwork (luxe) | E50: ='Schedule ListStandings'!L6 -> 16 | F50: ='Schedule ListStandings'!M6 -> 3
D51: ='Schedule ListStandings'!K7 -> First Strike (evil) | E51: ='Schedule ListStandings'!L7 -> 13 | F51: ='Schedule ListStandings'!M7 -> 6
D52: ='Schedule ListStandings'!K8 -> Cosmic Oblivion (Daedric) | E52: ='Schedule ListStandings'!L8 -> 9 | F52: ='Schedule ListStandings'!M8 -> 10
...

Sheet Schedule
S1: unavailable | T1: Available
C5: Sunday | D5: Monday | E5: Tuesday | F5: Wednesday | G5: Thursday | H5: Friday | I5: Saturday | M5: Based on top 3 players
L6: Sun | M6: Mon | N6: Tue | O6: Wed | P6: Thu | Q6: Fri | R6: Sat | S6: aspence | T6: Captain Sev
J7: 1 | K7: NecessaryEvil | L7: - | M7: - | N7: - | O7: 8-10 | P7: 8-10 | Q7: 8-10 | R7: - | S7: 3/19, 3/20, 3/26, 3/30-4/1, 4/7-4/10
J8: 2 | K8: Aspence | L8: - | M8: 45912 | N8: 45912 | O8: 45912 | P8: - | Q8: - | R8: -
J9: 3 | K9: KDskill | L9: - | M9: - | N9: - | O9: 45942 | P9: - | Q9: - | R9: - | S9: Evil
J10: 4 | K10: novice | L10: ? | M10: ? | N10: ? | O10: ? | P10: ? | Q10: ? | R10: ? | S10: 5/8-5/11
J11: 5 | K11: scullen | L11: 45878 | M11: 45878 | N11: - | O11: 45878 | P11: 45878 | Q11: - | R11: -
J12: 6 | K12: chemical | L12: - | M12: 9-9:30 | N12: - | O12: 9-9:30 | P12: - | Q12: - | R12: - | S12: Mav
J13: 7 | K13: daedric | L13: - | M13: - | N13: - | O13: - | P13: - | Q13: - | R13: 7-8:30 | S13: 4/11- 4/13
J14: 8 | K14: squire | L14: 45912 | M14: 45912 | N14: 45912 | O14: 45912 | P14: 45912 | Q14: 45912 | R14: 45912
J15: 9 | K15: luxe | L15: 45878 | M15: - | N15: 45878 | O15: - | P15: 45878 | Q15: - | R15: -
J16: 10 | K16: solace | L16: 7-9:30 | M16: 7-9:30 | N16: - | O16: - | P16: - | Q16: - | R16: 7-9:30
J17: 11 | K17: nkot | L17: - | M17: 45847 | N17: 45847 | O17: - | P17: 45847 | Q17: - | R17: -
J18: 12 | K18: noplex | L18: - | M18: 7:30-8:30 | N18: 7:30-8:30 | O18: - | P18: 7:30-8:30 | Q18: 7:30-8:30 | R18: -
J19: 13 | K19: avenger | L19: - | M19: 7:30-9 | N19: - | O19: 7:30-9 | P19: - | Q19: - | R19: 7:30-9
J20: 14 | K20: epic | L20: 7-9 | M20: - | N20: - | O20: - | P20: - | Q20: - | R20: 7-9
O27: Hammer | P27: Sword
O28: luxe | P28: novice
L29: =6+7 -> 13 | O29: solace | P29: aspence
O30: chemical | P30: nkot
O31: necessevil | P31: kdskill
O32: daedrice | P32: epic
O33: noplex | P33: scullen
O34: avenger | P34: squirell
D38: March | E38: May
D39: 23rd | E39: 18th
A43: Week | B43: Home | C43: Day | D43: Date | E43: Time | F43: Away | G43: 4th round can? | H43: Conference
B44: ASpence | C44: Monday | D44: 45740 | E44: 0.875 | F44: Solace | H44: out
B45: ASpence | C45: Tuesday | D45: 45741 | E45: 0.875 | F45: Squirell | H45: in
B46: Luxe | C46: Tuesday | D46: 45741 | E46: 0.83333333 | F46: Nkot | H46: out
B47: NecessaryEvil | C47: Wednesday | D47: 45742 | E47: 0.83333333 | F47: avenger | H47: in
B48: KDSkill | C48: Wednesday | D48: 45742 | E48: 0.91666667 | F48: Squirell | H48: in
B49: Nkot | C49: Thursday | D49: 45743 | E49: 0.8125 | F49: Noplex | H49: out
B50: NecessaryEvil | C50: Friday | D50: 45744 | E50: 0.875 | F50: Squirell | H50: out
B51: Daedric | C51: Saturday | D51: 45745 | E51: 0.79166667 | F51: Solace | H51: in
B52: Scullen | C52: Sunday | D52: 45746 | E52: 0.83333333 | F52: Luxe | H52: out
B53: Scullen | C53: Monday | D53: 45747 | E53: 0.83333333 | F53: Avenger | H53: out
B54: Luxe | C54: Tuesday | D54: 45748 | E54: 0.83333333 | F54: Noplex | H54: in
B55: NecessaryEvil | C55: Wednesday | D55: 45749 | E55: 0.875 | F55: Aspence | H55: out
...

Sheet Copy of Draft Sheet
A1: 7
B2: HALO INFINITE Winter League 2025 GRIFBALL SEASON
B6: Ending
B7: Team Name: | C7: B.U.R.T | D7: Knocked Goose | E7: 9th Place | F7: Coup De Puff | G7: The Shrek Republic | H7: Employees of the Month | I7: Ascension | J7: Like clockwork | K7: F.C Barcelona | L7: EXTORTION SZN
B8: Captain: | C8: Sauted Smurf | D8: NecessaryEvil10 | E8: MuNgO PuNgO | F8: Hells Angel cx | G8: ill shrek u | H8: Cosmos5024 | I8: Solace VIII | J8: Sabasauros rex | K8: MysticalNovice | L8: SPANKTR0N
B9: 1st Round: | C9: ASpence | D9: Mavbrid | E9: KDSkill | F9: Chemical | G9: Spanktron | H9: MasterSquirre | I9: Scullen cx | L9: Cosmos5024(R1P9)
B10: 2nd Round: | L10: Mastersquirrel (R3P9)
B11: 3rd Round: | L11: TJP37
B12: 4th Round: | L12: GankedYoAss
B14: Gamertag | C14: Skill Estimate | D14: Last Season | E14: Region | F14: Input | K14: Captains
K16: Gamertag
K17: NecessaryEvil10 | N17: Free Sub Pool
K18: MysticalNovice
B19: ASpence | C19: KDSkill | D19: Mavbrid | E19: iNf3ktion | F19: Havoc Puppies | G19: Chemical | H19: Mr Epic Beast | I19: Dhlyn | J19: Spanktron | K19: Cosmos5024
B20: Noplex | C20: MasterSquirre | D20: Scullen cx | E20: Grunt Padre | F20: Psyduck | G20: Big Al | H20: Deathcrawller | I20: Avenger | J20: AwareMosquito | K20: Solace VIII
B21: Priest | C21: itsRiskE | D21: mxrvine | E21: Ram Osneb | F21: BloodenNick | G21: Reign | H21: Rechargen | I21: CaptainSev004 | J21: Panther Lily | K21: MuNgO PuNgO
B22: Trespa5s | C22: Endasis zx | D22: G3ohh | E22: Clutch Academy | F22: MajesticKittens | G22: KindredDaedric | K22: Sauted Smurf
K23: Hells Angel cx
A24: w | K24: ill shrek u
K25: Sabasauros rex

Sheet Substitution List
A1: 7
B2: Substitution List
B6: Ending
B7: Team Name: | C7: Bad Intentions | D7: NeuraLink | E7: Crazy Guys 2.0 | F7: Wang Industries | G7: The @MenZ Fan Club | H7: Chemical Imbalance | I7: Ken no senshi | J7: Asking Alexandra | K7: 4G1B | L7: EXTORTION SZN
B8: Captain: | C8: NecessaryEvil10 | D8: TcT AVENGER | E8: PsyDucky54 | F8: Inactive Spoon | G8: Deathcrawller | H8: Chemical | I8: PoisonxPoptart | J8: Hells Angel cx | K8: Invayda Zim | L8: SPANKTR0N
B9: 1st Round: | C9: PapasnipezX | D9: solace viii | E9: ASpence501 | F9: MysticalNovice | G9: Digital Pain | H9: Sabasauros rex | I9: mavbrid | J9: ill Shrek u | K9: Cosmos5024 | L9: Gingy
C10: A | D10: A | E10: S | F10: S | G10: A | H10: A | I10: A | J10: A | K10: A | L10: A
B11: 2nd Round: | C11: Fancy | D11: KDSkill | E11: TommyWstSide | F11: Dhyln | G11: Scullen cx | H11: DCleak | I11: IReign 77 | J11: iNF3ktioN | K11: AwareMosquito | L11: NOPLEX
C12: A | D12: B | E12: B | F12: B | G12: B | H12: C | I12: D | J12: B | K12: C | L12: D
B13: 3rd Round: | C13: MuNgO PuNgO | D13: Blooden nick | E13: Mr Epic Beast | F13: about73puppies | G13: Squarebarton | H13: CaptainSev004 | I13: Endasis zx | J13: Grunt Padre | K13: Mastersquirrel | L13: TJP37
C14: C | D14: UNKNOWN | E14: C | F14: UNKNOWN | G14: UNKNOWN | H14: C | I14: UNKNOWN | J14: C | K14: UNKNOWN | L14: D
B15: 4th Round: | C15: Priest XYZ | D15: TcT J Bomb | E15: Recharged | F15: NinjadYoAss | G15: MajesticKittens | H15: The Goosler | I15: II Panther Lily | J15: Trespa5s | K15: Itsriske | L15: GankedYoAss
C16: D | D16: UNKNOWN | E16: D | F16: UNKNOWN | G16: E | H16: E | I16: UNKNOWN | J16: E | K16: UNKNOWN | L16: UNKNOWN
B17: 5th Round: | C17: OREOTHECAT | D17: Jceyyy | E17: DuffyCreates
C18: E | D18: UNKNOWN | E18: UNKNOWN

Sheet Schedule Lookup Tool
D1: Use this to search the schedule sheet for your or other captain's games. UPDATES AUTOMATICALLY FROM ADMIN SHEET, refer to schedule for captain name spelling
A2: Captain Search: | B2: Death | D2: N/A means there isn't anything in the category
A4: Scheduled Games | F4: Reschedules | L4: Free Scheduling
A5: Date | C5: Matchup/Time | F5: Date | J5: Matchup/Time | L5: Matchup
A6: =IFERROR(__xludf.DUMMYFUNCTION("FILTER(A90:D384, ARRAYFORMULA(ISNUMBER(SEARCH(B2, C90:C384)))) "),"Monday Aug 26") -> Monday Aug 26 | B6: =IFERROR(__xludf.DUMMYFUNCTION("""COMPUTED_VALUE"""),"Monday Aug 26") -> Monday Aug 26 | C6: =IFERROR(__xludf.DUMMYFUNCTION("""COMPUTED_VALUE"""),"Ducky vs Death 8 PM") -> Ducky vs Death 8 PM | F6: =IFERROR(__xludf.DUMMYFUNCTION("FILTER(A90:E384, ARRAYFORMULA(ISNUMBER(SEARCH(B2, E90:E384)))) "),"Monday Aug 26") -> Monday Aug 26 | H6: =IFERROR(__xludf.DUMMYFUNCTION("""COMPUTED_VALUE"""),"Death vs Evil 8:45 PM") -> Death vs Evil 8:45 PM | J6: =IFERROR(__xludf.DUMMYFUNCTION("""COMPUTED_VALUE"""),"Death vs Ducky 8:30 PM") -> Death vs Ducky 8:30 PM | L6: =IFERROR(__xludf.DUMMYFUNCTION("FILTER(F90:F384, ARRAYFORMULA(ISNUMBER(SEARCH(B2, F90:F384)))) "),"Spoon vs Death") -> Spoon vs Death
A7: =IFERROR(__xludf.DUMMYFUNCTION("""COMPUTED_VALUE"""),"Monday Aug 26") -> Monday Aug 26 | C7: =IFERROR(__xludf.DUMMYFUNCTION("""COMPUTED_VALUE"""),"Death vs Evil 8:45 PM") -> Death vs Evil 8:45 PM | F7: =IFERROR(__xludf.DUMMYFUNCTION("""COMPUTED_VALUE"""),"Monday Sept 2") -> Monday Sept 2 | G7: =IFERROR(__xludf.DUMMYFUNCTION("""COMPUTED_VALUE"""),"Monday Sept 2") -> Monday Sept 2 | H7: =IFERROR(__xludf.DUMMYFUNCTION("""COMPUTED_VALUE"""),"Ducky vs Spank 8pm ") -> Ducky vs Spank 8pm | J7: =IFERROR(__xludf.DUMMYFUNCTION("""COMPUTED_VALUE"""),"Death vs Avenger 8:00 PM") -> Death vs Avenger 8:00 PM | L7: =IFERROR(__xludf.DUMMYFUNCTION("""COMPUTED_VALUE"""),"Death vs Avenger") -> Death vs Avenger
A8: =IFERROR(__xludf.DUMMYFUNCTION("""COMPUTED_VALUE"""),"Saturday Aug 31") -> Saturday Aug 31 | C8: =IFERROR(__xludf.DUMMYFUNCTION("""COMPUTED_VALUE"""),"Hells vs Death 9:30 PM") -> Hells vs Death 9:30 PM | F8: =IFERROR(__xludf.DUMMYFUNCTION("""COMPUTED_VALUE"""),"Monday Sept 2") -> Monday Sept 2 | H8: =IFERROR(__xludf.DUMMYFUNCTION("""COMPUTED_VALUE"""),"Evil vs Avenger 9 PM") -> Evil vs Avenger 9 PM | J8: =IFERROR(__xludf.DUMMYFUNCTION("""COMPUTED_VALUE"""),"Death vs Evil 8:30 PM") -> Death vs Evil 8:30 PM | L8: =IFERROR(__xludf.DUMMYFUNCTION("""COMPUTED_VALUE"""),"Death vs Chemical") -> Death vs Chemical
A9: =IFERROR(__xludf.DUMMYFUNCTION("""COMPUTED_VALUE"""),"Monday Sept 9") -> Monday Sept 9 | C9: =IFERROR(__xludf.DUMMYFUNCTION("""COMPUTED_VALUE"""),"Death vs Spoon 8:30 PM") -> Death vs Spoon 8:30 PM | F9: =IFERROR(__xludf.DUMMYFUNCTION("""COMPUTED_VALUE"""),"Monday Sept 9") -> Monday Sept 9 | H9: =IFERROR(__xludf.DUMMYFUNCTION("""COMPUTED_VALUE"""),"Avenger vs Evil 9 PM") -> Avenger vs Evil 9 PM | J9: =IFERROR(__xludf.DUMMYFUNCTION("""COMPUTED_VALUE"""),"Death vs Spoon 10 PM") -> Death vs Spoon 10 PM | L9: =IFERROR(__xludf.DUMMYFUNCTION("""COMPUTED_VALUE"""),"Death vs Hells") -> Death vs Hells
A10: =IFERROR(__xludf.DUMMYFUNCTION("""COMPUTED_VALUE"""),"Wednesday Sept 11") -> Wednesday Sept 11 | B10: =IFERROR(__xludf.DUMMYFUNCTION("""COMPUTED_VALUE"""),"Wednesday Sept 11") -> Wednesday Sept 11 | C10: =IFERROR(__xludf.DUMMYFUNCTION("""COMPUTED_VALUE"""),"Death vs Poptart 8:00 PM") -> Death vs Poptart 8:00 PM | F10: =IFERROR(__xludf.DUMMYFUNCTION("""COMPUTED_VALUE"""),"Wednesday Sept 11") -> Wednesday Sept 11 | H10: =IFERROR(__xludf.DUMMYFUNCTION("""COMPUTED_VALUE"""),"Spank vs Chemical 9:30 PM") -> Spank vs Chemical 9:30 PM | J10: =IFERROR(__xludf.DUMMYFUNCTION("""COMPUTED_VALUE"""),"Death vs Poptart 9:30 pm") -> Death vs Poptart 9:30 pm | L10: =IFERROR(__xludf.DUMMYFUNCTION("""COMPUTED_VALUE"""),"Death vs Zim") -> Death vs Zim
A11: =IFERROR(__xludf.DUMMYFUNCTION("""COMPUTED_VALUE"""),"Monday Sept 16") -> Monday Sept 16 | B11: =IFERROR(__xludf.DUMMYFUNCTION("""COMPUTED_VALUE"""),"Monday Sept 16") -> Monday Sept 16 | C11: =IFERROR(__xludf.DUMMYFUNCTION("""COMPUTED_VALUE"""),"Death vs Ducky 8 PM") -> Death vs Ducky 8 PM | F11: =IFERROR(__xludf.DUMMYFUNCTION("""COMPUTED_VALUE"""),"Wednesday Sept 11") -> Wednesday Sept 11 | J11: =IFERROR(__xludf.DUMMYFUNCTION("""COMPUTED_VALUE"""),"Poptart vs Death 10:00 pm") -> Poptart vs Death 10:00 pm | L11: =IFERROR(__xludf.DUMMYFUNCTION("""COMPUTED_VALUE"""),"Death vs Spank") -> Death vs Spank
A12: =IFERROR(__xludf.DUMMYFUNCTION("""COMPUTED_VALUE"""),"Monday Sept 16") -> Monday Sept 16 | C12: =IFERROR(__xludf.DUMMYFUNCTION("""COMPUTED_VALUE"""),"Avenger vs Death 9 PM") -> Avenger vs Death 9 PM | F12: =IFERROR(__xludf.DUMMYFUNCTION("""COMPUTED_VALUE"""),"Thursday Sept 19") -> Thursday Sept 19 | H12: =IFERROR(__xludf.DUMMYFUNCTION("""COMPUTED_VALUE"""),"Chemical vs Death 8:30 PM") -> Chemical vs Death 8:30 PM | J12: =IFERROR(__xludf.DUMMYFUNCTION("""COMPUTED_VALUE"""),"Evil vs Death 9:00") -> Evil vs Death 9:00 | L12: =IFERROR(__xludf.DUMMYFUNCTION("""COMPUTED_VALUE"""),"Chemical vs Death") -> Chemical vs Death
A13: =IFERROR(__xludf.DUMMYFUNCTION("""COMPUTED_VALUE"""),"Wednesday Sept 18") -> Wednesday Sept 18 | B13: =IFERROR(__xludf.DUMMYFUNCTION("""COMPUTED_VALUE"""),"Wednesday Sept 18") -> Wednesday Sept 18 | C13: =IFERROR(__xludf.DUMMYFUNCTION("""COMPUTED_VALUE"""),"Poptart vs Death 8 PM") -> Poptart vs Death 8 PM | L13: =IFERROR(__xludf.DUMMYFUNCTION("""COMPUTED_VALUE"""),"Hells vs Death") -> Hells vs Death
A14: =IFERROR(__xludf.DUMMYFUNCTION("""COMPUTED_VALUE"""),"Wednesday Sept 18") -> Wednesday Sept 18 | C14: =IFERROR(__xludf.DUMMYFUNCTION("""COMPUTED_VALUE"""),"Death vs Zim 7:30 PM") -> Death vs Zim 7:30 PM | L14: =IFERROR(__xludf.DUMMYFUNCTION("""COMPUTED_VALUE"""),"Zim vs Death") -> Zim vs Death
A15: =IFERROR(__xludf.DUMMYFUNCTION("""COMPUTED_VALUE"""),"Wednesday Sept 18") -> Wednesday Sept 18 | C15: =IFERROR(__xludf.DUMMYFUNCTION("""COMPUTED_VALUE"""),"Zim vs Death 8:00 PM") -> Zim vs Death 8:00 PM | L15: =IFERROR(__xludf.DUMMYFUNCTION("""COMPUTED_VALUE"""),"Spank vs Death") -> Spank vs Death
A16: =IFERROR(__xludf.DUMMYFUNCTION("""COMPUTED_VALUE"""),"Thursday Sept 19") -> Thursday Sept 19 | C16: =IFERROR(__xludf.DUMMYFUNCTION("""COMPUTED_VALUE"""),"Death vs Chemical 8 PM") -> Death vs Chemical 8 PM
A17: =IFERROR(__xludf.DUMMYFUNCTION("""COMPUTED_VALUE"""),"Thursday Sept 19") -> Thursday Sept 19 | C17: =IFERROR(__xludf.DUMMYFUNCTION("""COMPUTED_VALUE"""),"Chemical vs Death 8:30 PM") -> Chemical vs Death 8:30 PM
A18: =IFERROR(__xludf.DUMMYFUNCTION("""COMPUTED_VALUE"""),"Thursday Sept 19") -> Thursday Sept 19 | C18: =IFERROR(__xludf.DUMMYFUNCTION("""COMPUTED_VALUE"""),"Death vs Hells 9:30 PM") -> Death vs Hells 9:30 PM
A19: =IFERROR(__xludf.DUMMYFUNCTION("""COMPUTED_VALUE"""),"Thursday Sept 19") -> Thursday Sept 19 | C19: =IFERROR(__xludf.DUMMYFUNCTION("""COMPUTED_VALUE"""),"Death vs Spank 10 PM") -> Death vs Spank 10 PM
A20: =IFERROR(__xludf.DUMMYFUNCTION("""COMPUTED_VALUE"""),"Thursday Sept 19") -> Thursday Sept 19 | C20: =IFERROR(__xludf.DUMMYFUNCTION("""COMPUTED_VALUE"""),"Spank vs Death 10:30 PM") -> Spank vs Death 10:30 PM
A21: =IFERROR(__xludf.DUMMYFUNCTION("""COMPUTED_VALUE"""),"Monday Sept 23") -> Monday Sept 23 | B21: =IFERROR(__xludf.DUMMYFUNCTION("""COMPUTED_VALUE"""),"Monday Sept 23") -> Monday Sept 23 | C21: =IFERROR(__xludf.DUMMYFUNCTION("""COMPUTED_VALUE"""),"Evil vs Death 8:30 PM") -> Evil vs Death 8:30 PM
C87: IGNORE, RAW INPUT
A90: {=IF(B90:B384="", LOOKUP(ROW(B90:B384), ROW(B90:B384) / (B90:B384 <> ""), B90:B384), B90:B384)} -> Augest 25 - 31 | B90: =IFERROR(__xludf.DUMMYFUNCTION("IMPORTRANGE(""https://docs.google.com/spreadsheets/d/1schmXjzORQ75nk63hR3QZGtUZsONwDsQNiis-5gm33I/edit?gid=147354809#gid=147354809"",""Schedule List/Standings!A3:E110"")"),"Augest 25 - 31 ") -> Augest 25 - 31 | C90: =IFERROR(__xludf.DUMMYFUNCTION("""COMPUTED_VALUE"""),"Week 1") -> Week 1 | E90: =IFERROR(__xludf.DUMMYFUNCTION("""COMPUTED_VALUE"""),"Reschedules") -> Reschedules | F90: =IFERROR(__xludf.DUMMYFUNCTION("""COMPUTED_VALUE"""),"Free Scheduling") -> Free Scheduling
A91: Sunday Aug 25 | B91: =IFERROR(__xludf.DUMMYFUNCTION("""COMPUTED_VALUE"""),"Sunday Aug 25") -> Sunday Aug 25 | C91: =IFERROR(__xludf.DUMMYFUNCTION("""COMPUTED_VALUE"""),"Spoon vs Avenger 10 PM") -> Spoon vs Avenger 10 PM | E91: =IFERROR(__xludf.DUMMYFUNCTION("""COMPUTED_VALUE"""),"Avenger vs Poptart 9:30 PM") -> Avenger vs Poptart 9:30 PM | F91: =IFERROR(__xludf.DUMMYFUNCTION("""COMPUTED_VALUE"""),"Ducky vs Hells") -> Ducky vs Hells
A92: Sunday Aug 25 | E92: =IFERROR(__xludf.DUMMYFUNCTION("""COMPUTED_VALUE"""),"Poptart vs Avenger 10 PM") -> Poptart vs Avenger 10 PM | F92: =IFERROR(__xludf.DUMMYFUNCTION("""COMPUTED_VALUE"""),"Spoon vs Death") -> Spoon vs Death
A93: Sunday Aug 25 | F93: =IFERROR(__xludf.DUMMYFUNCTION("""COMPUTED_VALUE"""),"Death vs Avenger") -> Death vs Avenger
A94: Monday Aug 26 | B94: =IFERROR(__xludf.DUMMYFUNCTION("""COMPUTED_VALUE"""),"Monday Aug 26") -> Monday Aug 26 | C94: =IFERROR(__xludf.DUMMYFUNCTION("""COMPUTED_VALUE"""),"Ducky vs Death 8 PM") -> Ducky vs Death 8 PM | E94: =IFERROR(__xludf.DUMMYFUNCTION("""COMPUTED_VALUE"""),"Spank vs Avenger 8 PM") -> Spank vs Avenger 8 PM | F94: =IFERROR(__xludf.DUMMYFUNCTION("""COMPUTED_VALUE"""),"Death vs Chemical") -> Death vs Chemical
A95: Monday Aug 26 | C95: =IFERROR(__xludf.DUMMYFUNCTION("""COMPUTED_VALUE"""),"Death vs Evil 8:45 PM") -> Death vs Evil 8:45 PM | E95: =IFERROR(__xludf.DUMMYFUNCTION("""COMPUTED_VALUE"""),"Death vs Ducky 8:30 PM") -> Death vs Ducky 8:30 PM | F95: =IFERROR(__xludf.DUMMYFUNCTION("""COMPUTED_VALUE"""),"Death vs Hells") -> Death vs Hells
A96: Monday Aug 26 | F96: =IFERROR(__xludf.DUMMYFUNCTION("""COMPUTED_VALUE"""),"Death vs Zim") -> Death vs Zim
A97: Tuesday Aug 27 | B97: =IFERROR(__xludf.DUMMYFUNCTION("""COMPUTED_VALUE"""),"Tuesday Aug 27") -> Tuesday Aug 27 | C97: =IFERROR(__xludf.DUMMYFUNCTION("""COMPUTED_VALUE"""),"NO GAMES") -> NO GAMES | F97: =IFERROR(__xludf.DUMMYFUNCTION("""COMPUTED_VALUE"""),"Death vs Spank") -> Death vs Spank
A98: Tuesday Aug 27 | F98: =IFERROR(__xludf.DUMMYFUNCTION("""COMPUTED_VALUE"""),"Chemical vs Ducky") -> Chemical vs Ducky
A99: Wednesday Aug 28 | B99: =IFERROR(__xludf.DUMMYFUNCTION("""COMPUTED_VALUE"""),"Wednesday Aug 28") -> Wednesday Aug 28 | C99: =IFERROR(__xludf.DUMMYFUNCTION("""COMPUTED_VALUE"""),"NO GAMES") -> NO GAMES | F99: =IFERROR(__xludf.DUMMYFUNCTION("""COMPUTED_VALUE"""),"Chemical vs Death") -> Chemical vs Death
A100: Wednesday Aug 28 | F100: =IFERROR(__xludf.DUMMYFUNCTION("""COMPUTED_VALUE"""),"Hells vs Ducky") -> Hells vs Ducky
A101: Wednesday Aug 28 | F101: =IFERROR(__xludf.DUMMYFUNCTION("""COMPUTED_VALUE"""),"Hells vs Death") -> Hells vs Death
A102: Thursday Aug 29 | B102: =IFERROR(__xludf.DUMMYFUNCTION("""COMPUTED_VALUE"""),"Thursday Aug 29") -> Thursday Aug 29 | C102: =IFERROR(__xludf.DUMMYFUNCTION("""COMPUTED_VALUE"""),"Ducky vs Chemical 8:30 PM") -> Ducky vs Chemical 8:30 PM | F102: =IFERROR(__xludf.DUMMYFUNCTION("""COMPUTED_VALUE"""),"Zim vs Spoon") -> Zim vs Spoon
A103: Thursday Aug 29 | E103: =IFERROR(__xludf.DUMMYFUNCTION("""COMPUTED_VALUE"""),"Zim vs Chemical 8:30 PM") -> Zim vs Chemical 8:30 PM | F103: =IFERROR(__xludf.DUMMYFUNCTION("""COMPUTED_VALUE"""),"Zim vs Death") -> Zim vs Death
A104: Thursday Aug 29 | E104: =IFERROR(__xludf.DUMMYFUNCTION("""COMPUTED_VALUE"""),"Chemical vs Zim 9:00 PM") -> Chemical vs Zim 9:00 PM | F104: =IFERROR(__xludf.DUMMYFUNCTION("""COMPUTED_VALUE"""),"Zim vs Chemical") -> Zim vs Chemical
A105: Friday Aug 30 | B105: =IFERROR(__xludf.DUMMYFUNCTION("""COMPUTED_VALUE"""),"Friday Aug 30") -> Friday Aug 30 | C105: =IFERROR(__xludf.DUMMYFUNCTION("""COMPUTED_VALUE"""),"Ducky vs Zim 8 PM") -> Ducky vs Zim 8 PM | E105: =IFERROR(__xludf.DUMMYFUNCTION("""COMPUTED_VALUE"""),"Evil vs Ducky 8:30 PM") -> Evil vs Ducky 8:30 PM | F105: =IFERROR(__xludf.DUMMYFUNCTION("""COMPUTED_VALUE"""),"Zim vs Hells") -> Zim vs Hells
A106: Friday Aug 30 | C106: =IFERROR(__xludf.DUMMYFUNCTION("""COMPUTED_VALUE"""),"Hells vs Zim 9 PM") -> Hells vs Zim 9 PM | F106: =IFERROR(__xludf.DUMMYFUNCTION("""COMPUTED_VALUE"""),"Zim vs Spank") -> Zim vs Spank
A107: Friday Aug 30 | F107: =IFERROR(__xludf.DUMMYFUNCTION("""COMPUTED_VALUE"""),"Spank vs Ducky") -> Spank vs Ducky
A108: Saturday Aug 31 | B108: =IFERROR(__xludf.DUMMYFUNCTION("""COMPUTED_VALUE"""),"Saturday Aug 31") -> Saturday Aug 31 | C108: =IFERROR(__xludf.DUMMYFUNCTION("""COMPUTED_VALUE"""),"Hells vs Chemical 10 PM") -> Hells vs Chemical 10 PM | E108: =IFERROR(__xludf.DUMMYFUNCTION("""COMPUTED_VALUE"""),"Ducky vs Chemical 8 PM") -> Ducky vs Chemical 8 PM | F108: =IFERROR(__xludf.DUMMYFUNCTION("""COMPUTED_VALUE"""),"Spank vs Death") -> Spank vs Death
...

Sheet Alt Draft Sheet
A1: 7
B2: HALO INFINITE SPRING LEAGUE 2024 GRIFBALL SEASON
B6: Ending
B7: Team Name: | C7: Buff Oily Men (& Women) | D7: Post Grif Depression | E7: Crazy Guys | F7: Sarge’s Squad | G7: Operation: Doomsday | H7: Angry Duck Noises | I7: Puffy Grifbussy | J7: Skill Diff | K7: GET SHREKT | L7: Separate Intelligence | M7: Paradox Warriors | N7: Moist grapefruit
B8: Captain: | C8: commandstation | D8: DMar7in69 | E8: Sauted Smurf | F8: NecessaryEvil10 | G8: Deathcrawller | H8: PsyDucky54 | I8: iNF3ktioN | J8: KDSkill | K8: ill shrek u | L8: Dhlyn | M8: PoisonxPoptart | N8: IxGingy
C9: D- | E9: E- | F9: F+ | G9: E+ | H9: D | I9: B- | J9: C+ | K9: S+ | L9: B | M9: B- | N9: A+
B10: 1st Round: | C10: MysticalNovice | D10: Ace B S1lentND1 | E10: ASpence501 | F10: Fanciest Pants | G10: Solace VIII | H10: Mavbrid | I10: SPANKTR0N | J10: Sabasauros rex | K10: Papasnipezx | L10: Scullen cx | M10: Sherbetshake | N10: Icey Tanker
C11: B | D11: S+ | E11: S+ | F11: A | G11: A | H11: S | I11: S- | J11: A+ | K11: S | L11: A- | M11: B+ | N11: D-
B12: 2nd Round: | C12: oh zilly | D12: Invayda Zim | E12: TommyWestSide | F12: TJP37 | G12: Chemical | H12: DCleak | I12: Hells Angel cx | J12: MuNgO PuNgO | K12: Cosmos5024 | L12: Its Rainin Menz | M12: Inactive Spoon | N12: Mr epic beast
C13: B+ | D13: S- | E13: B- | F13: D | G13: C+ | H13: D+ | I13: A | J13: C | K13: A- | L13: E- | M13: D+ | N13: C-
B14: 3rd Round: | C14: CaptainSev004 | D14: NOPLEX | E14: Grunt Padre | F14: Reyas | G14: Doerstopper | H14: IReign 77 | I14: AwareMosquito | J14: Listless DK | K14: TcT AVENGER | L14: El Diablo X230X | M14: I iTz Bear I | N14: JOEPRO v2
C15: E+ | D15: E | E15: C | F15: D+ | G15: E | H15: F+ | I15: C- | J15: F | K15: F | L15: F- | M15: F- | N15: E
B16: 4th Round: | C16: GamezoWinselot | D16: Trespa5s | E16: OREOTHECAT5618
D17: F-
B18: Draft Pool | L18: Captains
B20: Gamertag | C20: Skill Estimate | D20: Last Season | E20: Current Season | F20: Region | G20: Experience: | L20: Gamertag | N20: 1
B21: Ace B S1lentND1 | C21: S | D21: S | E21: S+ | F21: Central North America | L21: IxGingy | M21: Banned Player List
B22: ASpence501 | C22: S | D22: S | E22: S+ | F22: East North America | L22: Dhlyn | M22: DMar7in69 | P22: Free Sub Pool
B23: AwareMosquito | C23: D | D23: D | E23: C- | F23: North Europe | L23: PoisonxPoptart
B24: CaptainSev004 | C24: C | D24: C | E24: E+ | F24: North Europe | L24: Deathcrawller
B25: Chemical | C25: B | E25: C+ | F25: East North America | L25: KDSkill
B26: Cosmos5024 | C26: D | E26: A- | F26: Central North America | L26: commandstation
B27: DCleak | C27: C | D27: C- | E27: D+ | F27: Central North America | L27: Sauted Smurf
B28: Doerstopper | C28: E | D28: E- | E28: E | F28: Central North America | L28: ill shrek u
B29: El Diablo X230X | C29: D | E29: F- | F29: Central North America | L29: DMar7in69
B30: Fanciest Pants | C30: B | D30: A | E30: A | F30: Central North America | L30: PsyDucky54
B31: GamezoWinselot | C31: E | F31: East North America | L31: NecessaryEvil10
B32: Grunt Padre | C32: C | D32: C | E32: C | F32: East North America | L32: iNF3ktioN
B33: Hells Angel cx | C33: B | E33: A | F33: East North America
B34: I iTz Bear I | C34: E | E34: F- | F34: West North America
B35: Icey Tanker | C35: B | E35: D- | F35: West North America
B36: Inactive Spoon | C36: C | E36: D+ | F36: East North America
B37: Invayda Zim | C37: A | E37: S- | F37: Central North America
B38: IReign 77 | C38: D | E38: F+ | F38: Central North America
B39: Its Rainin Menz | C39: C | D39: E+ | E39: E- | F39: East North America
B40: JOEPRO v2 | C40: UNKNOWN | E40: E | F40: West North America
B41: Listless DK | C41: UNKNOWN | E41: F | F41: West North America
B42: Mavbrid | C42: A | D42: A+ | E42: S | F42: East North America
B43: Mr epic beast | C43: C | D43: C+ | E43: C- | F43: West North America
B44: MuNgO PuNgO | C44: C | D44: D+ | E44: C | F44: East North America
...

Sheet Sheet5
A1: https://docs.google.com/spreadsheets/d/1d-JA1rtr6SsQ3KDwXKl9d69yCGp7i6YiLm1GlgrUU-M/edit#gid=1265428282
A3: =IFERROR(__xludf.DUMMYFUNCTION("IMPORTRANGE(A1, ""S4:T51"")"),"#REF!") -> #REF!

Sheet Game History (OLD)
B1: Home | C1: Away | D1: Score | E1: Time | F1: Waypoint URL | H1: VOD | J1: 4/5th used Home | K1: 4/5th used Away
A3: Week 1 | B3: Avenger | C3: Poptart | D3: 5-3 | E3: 27:45 | F3: https://www.halowaypoint.com/halo-infinite/players/poisonxpoptart/matches/d499aa43-c785-435c-83a6-a5050b9443bb | H3: https://www.youtube.com/watch?v=rI0O9YwUeBA | K3: panther lily 4th
B4: Poptart | C4: Avenger | D4: 5-1 | E4: 14:09 | F4: https://www.halowaypoint.com/halo-infinite/players/poisonxpoptart/matches/3eb32b53-159a-456e-925f-cace43cf6f33 | H4: https://www.youtube.com/watch?v=rI0O9YwUeBA | K4: tct j bomb 4th
B5: Ducky | C5: Deathcrawller | D5: 5-2 | E5: 12:20 | F5: https://www.halowaypoint.com/halo-infinite/players/ASpence501/matches/8334ccd4-6be3-456b-a29a-470db18c98a7 | H5: https://www.youtube.com/watch?v=xe_gW5uLgP0 | I5: https://www.youtube.com/watch?v=i1o9OyYhTxs | K5: majestickittens 4th
B6: Deathcrawller | C6: Ducky | D6: 5-3 | E6: 13:02 | F6: https://www.halowaypoint.com/halo-infinite/players/ASpence501/matches/3dc50d1f-7b2c-4c0b-941c-acf68ecebe6c | H6: https://www.youtube.com/watch?v=xe_gW5uLgP0 | I6: https://www.youtube.com/watch?v=i1o9OyYhTxs | J6: majestickittens 4th
B7: Avenger | C7: Spankatron | D7: 5-3 | E7: 26:10 | F7: https://www.halowaypoint.com/halo-infinite/players/KDSkill/matches/758ddf71-f680-4309-a927-e4cc67deb427 | H7: https://www.youtube.com/watch?v=NCrpquy6Eo0
B8: Invayda Zim | C8: Chemical | D8: 3-5 | E8: 25:28 | F8: https://www.halowaypoint.com/halo-infinite/players/Chemical/matches/7cbfde02-c8ed-471b-ba15-008fd15c770c
B9: Chemical | C9: Invayda Zim | D9: 5-2 | E9: 13:52 | F9: https://www.halowaypoint.com/halo-infinite/players/Chemical/matches/a8f552ed-6d75-489c-aba9-4c5d70c4717a, https://www.halowaypoint.com/halo-infinite/players/Chemical/matches/c4cbfc1a-b2b3-4de5-9e45-e2298859d762 | H9: https://youtu.be/rttZonE5nAk | I9: https://youtu.be/842VD3NilSY | K9: riske 4th
B10: Evil | C10: Ducky | D10: 5-2 | E10: 20:49 | F10: https://www.halowaypoint.com/halo-infinite/players/ASpence501/matches/5b9e267a-3135-42de-a34f-6130ce72b474 | H10: https://youtu.be/DyfXzLx2LgA
B11: Ducky | C11: Chemical | D11: 5-4 | E11: 32:48 | F11: https://www.halowaypoint.com/halo-infinite/players/ASpence501/matches/2beec333-28e4-40f8-9642-f42f32cb5a6a , https://www.halowaypoint.com/halo-infinite/players/ASpence501/matches/eee0debe-77fa-477a-a085-3802fd7bdcce , https://www.halowaypoint.com/halo-infinite/players/ASpence501/matches/8f25ba83-fe35-49c1-a716-07cef05c012a | H11: https://youtu.be/C3tvPuI_KCc | I11: https://youtu.be/6fPsh-3dDSk
B12: Chemical | C12: Ducky | D12: 2-5 | E12: 12:33 | F12: https://www.halowaypoint.com/halo-infinite/players/ASpence501/matches/0e35a3b4-4ea6-4df3-acc5-c8d7a593efbb | H12: https://youtu.be/C3tvPuI_KCc
B13: Hells | C13: Chemical | D13: 1-5 | E13: 16:56 | F13: https://www.halowaypoint.com/halo-infinite/players/Hells%20Angel%20cx/matches/286885ae-380b-4d28-9a5f-5cd8aed463eb | H13: https://youtu.be/VPVhcmPZSvk | J13: trespass 4th
B14: Hells | C14: Deathcrawller | D14: 5-0 | E14: 06:07 | F14: https://www.halowaypoint.com/halo-infinite/players/Hells%20Angel%20cx/matches/b977d1ad-5f5c-437c-9fc4-cc491d6c2fd6 | J14: trespass 4th
A15: Week 2
B16: Avenger | C16: Zim | D16: 5-4 | E16: 21:53 | F16: https://www.halowaypoint.com/halo-infinite/players/KDSkill/matches/dace01d5-f4e4-467f-a4a4-a71ec1b3e43b | H16: https://youtu.be/GnKqU3PEd8M
B17: Ducky | C17: Avenger | D17: 5-3 | E17: 15:59 | F17: https://www.halowaypoint.com/halo-infinite/players/ASpence501/matches/26e0c67b-b804-4cbe-9843-0a576830c0cb | H17: https://youtu.be/YfmkFymlaO8 | I17: https://youtu.be/ibxQd3DAyqU | J17: recharged 4th
B18: Deathcrawller | C18: Avenger | D18: 2-5 | E18: 38:33 | F18: https://www.halowaypoint.com/halo-infinite/players/tct%20avenger/matches/05f1b78b-fd7b-4c06-a561-b729bfefd4ed | H18: https://youtu.be/nAHq7XU4d3g | I18: https://youtu.be/mXX2RC7Jqlw | J18: majestickittens 4th
B19: Deathcrawller | C19: Evil | D19: 1-5 | E19: 11:02 | F19: https://www.halowaypoint.com/halo-infinite/players/dlgital%20pain/matches/ee0426e9-5bda-4260-a5b1-b0d49fd978b9 | H19: https://youtu.be/MePKeNTRLzU | J19: majestickittens 4th
B20: Evil | C20: Avenger | D20: 1-5 | E20: 10:05 | F20: https://www.halowaypoint.com/halo-infinite/players/tct%20avenger/matches/ec453e42-b5a3-4cdc-be5f-7d63aece1877 | H20: https://youtu.be/tdL1OWiP8Jg | I20: https://youtu.be/wTxtC2Kv3i4 | J20: priest 4th
B21: Chemical | C21: Spankatron | D21: 5-1 | E21: 14:47 | F21: https://www.halowaypoint.com/halo-infinite/players/Chemical/matches/c8035678-8279-4fc0-8ad1-05274081ee43 | H21: https://youtu.be/dAOBCJc3Ff4
B22: Spankatron | C22: Chemical | D22: 3-5 | E22: 21:37 | F22: https://www.halowaypoint.com/halo-infinite/players/Chemical/matches/1356c312-401b-4669-ba5c-aaf0c3005088 | H22: https://youtu.be/cIBGI6FiEWA
B23: Invayda Zim | C23: Evil | D23: 4-5 | E23: 30:03 | F23: https://www.halowaypoint.com/halo-infinite/players/necessaryevil10/matches/8e947422-10c9-4079-abb2-2583a3737e31 | H23: https://youtu.be/tXVmC_mSsp4
B24: Evil | C24: Chemical | D24: 2-5 | E24: 26:40 | F24: https://www.halowaypoint.com/halo-infinite/players/chemical/matches/ff5aa4bc-b98a-47e9-b323-827bbf26e48e
B25: Ducky | C25: Poptart | D25: 5-2 | E25: 24:31 | F25: https://www.halowaypoint.com/halo-infinite/players/ASpence501/matches/b7717934-48a6-40c4-8360-e5dcb9eb44ce , https://www.halowaypoint.com/halo-infinite/players/ASpence501/matches/9fd23735-63d2-4df9-854d-dbe9e16d68b6 | H25: https://youtu.be/OdbfxO1d1J0 | J25: recharged 4th
B26: Chemical | C26: Hells | D26: 5-1 | E26: 16:59 | F26: https://www.halowaypoint.com/halo-infinite/players/chemical/matches/b972d93b-4e07-43f5-90c3-d406b81b6ab6 | H26: https://youtu.be/3jzKrWpolxE
B27: Zim | C27: Spoon | D27: 3-5 | E27: 10:23 | F27: https://www.halowaypoint.com/halo-infinite/players/Inactive%20Spoon/matches/3577a745-a9ed-4be2-bdbf-b2350251843c
B28: Spoon | C28: Zim | D28: 5-2 | E28: 15:01 | F28: https://www.halowaypoint.com/halo-infinite/players/Inactive%20Spoon/matches/3165a244-f289-4940-9295-a54ea2b66362
B29: Avenger | C29: Evil | D29: 4-5 | E29: 41:06 | F29: https://www.halowaypoint.com/halo-infinite/players/NecessaryEvil10/matches/9d9838e8-eb04-4d91-8740-d65e87e6bdfe | H29: https://www.twitch.tv/videos/2245464514 | J29: TcT J Bomb
B30: Poptart | C30: Hells | D30: 0-5 | E30: 15:35 | F30: https://www.halowaypoint.com/halo-infinite/players/Hells%20Angel%20cx/matches/12a5ece9-951b-4387-862c-359377d510ac
B31: Hells | C31: Poptart | D31: 5-1 | E31: 09:50 | F31: https://www.halowaypoint.com/halo-infinite/players/Hells%20Angel%20cx/matches/e6218524-0d8d-46ca-bfdf-1b507ff6d588 | J31: Trespass | K31: Panther Lily
B32: Spoon | C32: Evil | D32: 5-2 | E32: 14:42 | F32: https://www.halowaypoint.com/halo-infinite/players/inactive%20spoon/matches/a9d1df5b-1af6-4ac3-9aad-f847b04863d8
B33: Avenger | C33: Chemical | D33: 5-3 | E33: 24:35 | F33: https://www.halowaypoint.com/halo-infinite/players/TcT%20Avenger/matches/2e0dbb70-bbe1-4c37-9452-c12559be0c80 | H33: https://youtu.be/alTyLyCAXWM
B34: Chemical | C34: Avenger | D34: 45327 | E34: 17:28 | F34: https://www.halowaypoint.com/halo-infinite/players/TcT%20Avenger/matches/f72a17e6-c6a4-4be8-abd4-9ccffd36d4fb , https://www.halowaypoint.com/halo-infinite/players/TcT%20Avenger/matches/9a40d417-48cc-44a8-984f-a9d0984cf86f | H34: https://youtu.be/kRh1-tNw5c8 | J34: goosler 4th
A36: Week 3 | B36: Ducky | C36: Spoon | D36: 5-2 | E36: 17:11 | F36: https://www.halowaypoint.com/halo-infinite/players/ASpence501/matches/eb2f8686-35ae-4c21-aceb-b37ef668f447 | H36: https://youtu.be/JhZvE035KF4 | J36: NinjadYoAss 4th
B37: Deathcrawller | C37: Spoon | D37: 1-5 | E37: 13:22 | F37: https://www.halowaypoint.com/halo-infinite/players/Inactive%20Spoon/matches/ad0104ef-7c1a-4127-aa85-48b470d3f078 | J37: majestickittens 4th | K37: NinjadyoAss 4th
B38: Spoon | C38: Deathcrawller | D38: 5-3 | E38: 14:29 | F38: https://www.halowaypoint.com/halo-infinite/players/InactiveSpoon/matches/4a1415c2-1989-4ce1-85b5-0d9239de7eb9 | K38: majestickittens 4th
B39: Avenger | C39: Spankatron | D39: 5-3 | E39: 32:07 | F39: https://www.halowaypoint.com/halo-infinite/players/TcT%20Avenger/matches/2bc2d388-07df-486c-adbb-9f37584a9681
B40: Spoon | C40: Avenger | D40: 5-4 | E40: 21:10 | F40: https://www.halowaypoint.com/halo-infinite/players/TcT%20Avenger/matches/372ca0d1-62fa-47b8-a75d-fa4c3108412d
B41: Spoon | C41: Poptart | D41: 5-4 | E41: 21:59 | F41: https://www.halowaypoint.com/halo-infinite/players/poisonxpoptart/matches/1432fced-0913-4163-adc4-737760ac4362 | K41: PantherLily 4th
B42: REMAKE | C42: SPOON V POPTAR | F42: https://www.halowaypoint.com/halo-infinite/players/poisonxpoptart/matches/839f9623-e6ae-4dfa-b67c-3d2e2f40283e
...
