Workbook

Sheet Addto
A1: Add
A2: To Halo 4 Stats | B2: Team name per player
B3: location per player
B4: system per player
A6: To Rounds | B6: Host location used for games
B7: color code team MvP
A9: in general | B9: Player grades
B10: match averages
B11: top stat players
B12: hexas stats
B13: color code match history for rounds
B14: top 10 players per stat/time average
B15: combined team stats
A17: https://challonge.com/Halo4FallSeriesEventTwo
A20: Team MVP =

Sheet MassFormulaTesting
E1: NOT ADJUSTED FOR THE TOURNAMENT
C4: 0.03 | D4: 0.05 | E4: 0.02 | F4: 0.05 | G4: 0.05 | H4: 0.04 | I4: 0.05 | J4: 0 | K4: 0 | L4: 0.05 | M4: 0.05 | N4: 0.05 | O4: 6 | P4: 0.05 | Q4: 0.05 | R4: 0.06 | S4: 0.07 | T4: 0.08 | U4: 0.09 | V4: 0.1 | W4: 0.04 | X4: 0.03 | Y4: 0.06 | Z4: 0.02 | AA4: 0.04 | AB4: 0.015 | AC4: 0.015 | AD4: 0.015 | AE4: 0.05 | AF4: 0.05 | AG4: 0.01 | AH4: 0.05 | AI4: 0.05 | AJ4: 0.05 | AK4: 0.06 | AL4: 0.02
M5: =98-(((TotalTournamentAverages!J6/MassFormulaTesting!$B$28)*0.68)+0.3) -> 97.639556
C6: 0.1 | D6: 0.04 | E6: 0.03 | F6: 0.02 | G6: 0.06 | H6: 0.03 | I6: 5 | J6: 0 | K6: 0 | L6: 0.01 | M6: 0.08 | N6: 0.06 | O6: 0.03 | P6: 0.07 | Q6: 0.08 | R6: 0.05 | S6: 0.03 | T6: 0.02 | U6: 0.02 | V6: 0.02 | W6: 0.04 | X6: 0.02 | Y6: 0.02 | Z6: 0.04 | AA6: 0.05 | AB6: 0.02 | AC6: 0.01 | AD6: 0.01 | AE6: 0.05 | AF6: 0.05 | AG6: 0.01 | AH6: 0.05 | AI6: 0.04 | AJ6: 0.02 | AK6: 0.03 | AL6: 0.01
K8: Weighting
B9: Weighting | C9: Goals | D9: Kills | E9: Assists | F9: Deaths | G9: Spread | H9: Streak | I9: Betrayals | J9: TimeAlive | K9: GameTime | L9: AverageLife | M9: BombStops | N9: KillingSprees | O9: KillingFrenzies | P9: DoubleKills | Q9: TripleKills | R9: Overkills | S9: Killtaculars | T9: Killtrocities | U9: Killamanjaros | V9: Killtastrophe | W9: Bulltrues | X9: Avengers | Y9: BallClears | Z9: CarrierKillAssists | AA9: Catches | AB9: FastBreaks | AC9: FirstStrikes | AD9: FirstTouches | AE9: GoalDefences | AF9: GoalKeepers | AG9: HammerKills | AH9: Interceptions | AI9: LongBombs | AJ9: NiceCatches | AK9: Rejections | AL9: SwordKills
A10: 36 total stats | B10: =SUM(C10:AL10) -> 127 | C10: 10 | D10: 4 | E10: 3 | F10: 2 | G10: 3 | H10: 6 | I10: 5 | J10: 0 | K10: 0 | L10: 1 | M10: 8 | N10: 6 | O10: 3 | P10: 7 | Q10: 8 | R10: 5 | S10: 3 | T10: 2 | U10: 2 | V10: 2 | W10: 4 | X10: 2 | Y10: 2 | Z10: 4 | AA10: 5 | AB10: 2 | AC10: 1 | AD10: 1 | AE10: 5 | AF10: 5 | AG10: 1 | AH10: 5 | AI10: 4 | AJ10: 2 | AK10: 3 | AL10: 1
B11: Weighting of 98 | G11: Goals | H11: Kills | I11: Assists | J11: Deaths | K11: Spread | L11: Streak | M11: Betrayals | N11: TimeAlive | O11: GameTime | P11: AverageLife | Q11: BombStops | R11: KillingSprees | S11: KillingFrenzies | T11: DoubleKills | U11: TripleKills | V11: Overkills | W11: Killtaculars | X11: Killtrocities | Y11: Killamanjaros | Z11: Killtastrophe | AA11: Bulltrues | AB11: Avengers | AC11: BallClears | AD11: CarrierKillAssists | AE11: Catches | AF11: FastBreaks | AG11: FirstStrikes | AH11: FirstTouches | AI11: GoalDefences | AJ11: GoalKeepers | AK11: HammerKills | AL11: Interceptions | AM11: LongBombs | AN11: NiceCatches | AO11: Rejections | AP11: SwordKills
C12: Bot | D12: =(MAX(F13:F57)-MIN(F13:F57)) -> 0 | E12: God LEVEL player | F12: =((((G12*C$10)+(H12*D$10)+(I12*E$10)+(J12*F$10)+(K12*G$10)+(L12*H$10)+(M12*I$10)+(N12*J$10)+(O12*K$10)+(P12*L$10)+(Q12*M$10)+(R12*N$10)+(S12*O$10)+(T12*P$10)+(U12*Q$10)+(V12*R$10)+(W12*S$10)+(X12*T$10)+(Y12*U$10)+(Z12*V$10)+(AA12*W$10)+(AB12*X$10)+(AC12*Y$10)+(AD12*Z$10)+(AE12*AA$10)+(AF12*AB$10)+(AG12*AC$10)+(AH12*AD$10)+(AI12*AE$10)+(AJ12*AF$10)+(AK12*AG$10)+(AL12*AH$10)+(AM12*AI$10)+(AN12*AJ$10)+(AO12*AK$10)+(AP12*AL$10)))) -> 124.26571 | G12: =((3.4/MassFormulaTesting!$B$16)*0.68)+0.3 -> 0.96057143 | H12: 0.98 | I12: 0.98 | J12: 0.98 | K12: 0.98 | L12: 0.98 | M12: 0.98 | N12: 0.98 | O12: 0.98 | P12: 0.98 | Q12: 0.98 | R12: 0.98 | S12: 0.98 | T12: 0.98 | U12: 0.98 | V12: 0.98 | W12: 0.98 | X12: 0.98 | Y12: 0.98 | Z12: 0.98 | AA12: 0.98 | AB12: 0.98 | AC12: 0.98 | AD12: 0.98 | AE12: 0.98 | AF12: 0.98 | AG12: 0.98 | AH12: 0.98 | AI12: 0.98 | AJ12: 0.98 | AK12: 0.98 | AL12: 0.98 | AM12: 0.98 | AN12: 0.98 | AO12: 0.98 | AP12: 0.98
C13: =MIN(F13:F57) -> 0.3 | D13: =(((F13-$C$13)/$D$12)*0.68)+0.3 -> #DIV/0! | E13: =TotalTournamentAverages!A5 | F13: =(IFERROR(((G13*C$10)+(H13*D$10)+(I13*E$10)+(J13*F$10)+(K13*G$10)+(L13*H$10)+(M13*I$10)+(N13*J$10)+(O13*K$10)+(P13*L$10)+(Q13*M$10)+(R13*N$10)+(S13*O$10)+(T13*P$10)+(U13*Q$10)+(V13*R$10)+(W13*S$10)+(X13*T$10)+(Y13*U$10)+(Z13*V$10)+(AA13*W$10)+(AB13*X$10)+(AC13*Y$10)+(AD13*Z$10)+(AE13*AA$10)+(AF13*AB$10)+(AG13*AC$10)+(AH13*AD$10)+(AI13*AE$10)+(AJ13*AF$10)+(AK13*AG$10)+(AL13*AH$10)+(AM13*AI$10)+(AN13*AJ$10)+(AO13*AK$10)+(AP13*AL$10))/F$12,"")*0.68)+0.3 -> 0.3 | G13: =((TotalTournamentAverages!D5/MassFormulaTesting!$B$16)*0.68)+0.3 -> 0.3 | H13: =((TotalTournamentAverages!E5/MassFormulaTesting!$B$18)*0.68)+0.3 -> 0.3 | I13: =((TotalTournamentAverages!F5/MassFormulaTesting!$B$20)*0.68)+0.3 -> 0.3 | J13: =(IFERROR(MassFormulaTesting!$C$22/TotalTournamentAverages!G5,"")*0.68)+0.3 -> 0.3 | K13: =(((TotalTournamentAverages!H5+118)/(MassFormulaTesting!$B$24+118))*0.68)+0.3 -> 0.82702791 | L13: =((TotalTournamentAverages!I5/MassFormulaTesting!$B$26)*0.68)+0.3 -> 0.3 | M13: =((0.98-(TotalTournamentAverages!J5/MassFormulaTesting!$B$28)*0.68)) -> 0.98 | N13: =((TotalTournamentAverages!K5/MassFormulaTesting!$B$30)*0.68)+0.3 -> 0.3 | O13: =((TotalTournamentAverages!L5/MassFormulaTesting!$B$32)*0.68)+0.3 -> 0.3 | P13: =((TotalTournamentAverages!M5/MassFormulaTesting!$B$34)*0.68)+0.3 -> 0.3 | Q13: =((TotalTournamentAverages!N5/MassFormulaTesting!$B$36)*0.68)+0.3 -> 0.3 | R13: =((TotalTournamentAverages!O5/MassFormulaTesting!$B$38)*0.68)+0.3 -> 0.3 | S13: =(IFERROR(TotalTournamentAverages!P5/MassFormulaTesting!$B$40,"")*0.68)+0.3 -> 0.3 | T13: =((TotalTournamentAverages!T5/MassFormulaTesting!$B$48)*0.68)+0.3 -> 0.3 | U13: =((TotalTournamentAverages!U5/MassFormulaTesting!$B$50)*0.68)+0.3 -> 0.3 | V13: =((TotalTournamentAverages!V5/MassFormulaTesting!$B$52)*0.68)+0.3 -> 0.3 | W13: =(IFERROR(TotalTournamentAverages!W5/MassFormulaTesting!$B$54,"")*0.68)+0.3 -> 0.3 | X13: =(IFERROR(TotalTournamentAverages!X5/MassFormulaTesting!$B$56,"")*0.68)+0.3 -> 0.3 | Y13: =(IFERROR(TotalTournamentAverages!Y5/MassFormulaTesting!$B$58,"")*0.68)+0.3 -> 0.3 | Z13: =(IFERROR(TotalTournamentAverages!Z5/MassFormulaTesting!$B$60,"")*0.68)+0.3 -> 0.3 | AA13: =((TotalTournamentAverages!AD5/MassFormulaTesting!$B$68)*0.68)+0.3 -> 0.3 | AB13: =((TotalTournamentAverages!AG5/MassFormulaTesting!$B$74)*0.68)+0.3 -> #DIV/0! | AC13: =((TotalTournamentAverages!AH5/MassFormulaTesting!$B$76)*0.68)+0.3 -> #DIV/0! | AD13: =((TotalTournamentAverages!AK5/MassFormulaTesting!$B$82)*0.68)+0.3 -> #DIV/0! | AE13: =((TotalTournamentAverages!AL5/MassFormulaTesting!$B$84)*0.68)+0.3 -> #DIV/0! | AF13: =((TotalTournamentAverages!AM5/MassFormulaTesting!$B$86)*0.68)+0.3 -> #DIV/0! | AG13: =((TotalTournamentAverages!AN5/MassFormulaTesting!$B$88)*0.68)+0.3 -> #DIV/0! | AH13: =((TotalTournamentAverages!AO5/MassFormulaTesting!$B$90)*0.68)+0.3 -> #DIV/0! | AI13: =((TotalTournamentAverages!AP5/MassFormulaTesting!$B$92)*0.68)+0.3 -> #DIV/0! | AJ13: =((TotalTournamentAverages!AQ5/MassFormulaTesting!$B$94)*0.68)+0.3 -> #DIV/0! | AK13: =((TotalTournamentAverages!AR5/MassFormulaTesting!$B$96)*0.68)+0.3 -> #DIV/0! | AL13: =((TotalTournamentAverages!AS5/MassFormulaTesting!$B$98)*0.68)+0.3 -> #DIV/0! | AM13: =((TotalTournamentAverages!AT5/MassFormulaTesting!$B$100)*0.68)+0.3 -> #DIV/0! | AN13: =((TotalTournamentAverages!AV5/MassFormulaTesting!$B$104)*0.68)+0.3 -> #DIV/0! | AO13: =((TotalTournamentAverages!AW5/MassFormulaTesting!$B$106)*0.68)+0.3 -> #DIV/0! | AP13: =((TotalTournamentAverages!AX5/MassFormulaTesting!$B$108)*0.68)+0.3 -> #DIV/0!
A14: Top/Lowest per stat: Raw Value | D14: =(((F14-$C$13)/$D$12)*0.68)+0.3 -> #DIV/0! | E14: =TotalTournamentAverages!A6 -> ACE B S1lentND1 | F14: =((IFERROR((G14*C$10)+(H14*D$10)+(I14*E$10)+(J14*F$10)+(K14*G$10)+(L14*H$10)+(M14*I$10)+(N14*J$10)+(O14*K$10)+(P14*L$10)+(Q14*M$10)+(R14*N$10)+(S14*O$10)+(T14*P$10)+(U14*Q$10)+(V14*R$10)+(W14*S$10)+(X14*T$10)+(Y14*U$10)+(Z14*V$10)+(AA14*W$10)+(AB14*X$10)+(AC14*Y$10)+(AD14*Z$10)+(AE14*AA$10)+(AF14*AB$10)+(AG14*AC$10)+(AH14*AD$10)+(AI14*AE$10)+(AJ14*AF$10)+(AK14*AG$10)+(AL14*AH$10)+(AM14*AI$10)+(AN14*AJ$10)+(AO14*AK$10)+(AP14*AL$10),"")/F$12)*0.68)+0.3 -> 0.3 | G14: =((TotalTournamentAverages!D6/MassFormulaTesting!$B$16)*0.68)+0.3 -> 0.49428571 | H14: =((TotalTournamentAverages!E6/MassFormulaTesting!$B$18)*0.68)+0.3 -> 0.747979 | I14: =((TotalTournamentAverages!F6/MassFormulaTesting!$B$20)*0.68)+0.3 -> 0.64 | J14: =(IFERROR(MassFormulaTesting!$C$22/TotalTournamentAverages!G6,"")*0.68)+0.3 -> 0.58651685 | K14: =(((TotalTournamentAverages!H6+118)/(MassFormulaTesting!$B$24+118))*0.68)+0.3 -> 0.93570881 | L14: =((TotalTournamentAverages!I6/MassFormulaTesting!$B$26)*0.68)+0.3 -> 0.74 | M14: =((0.98-(TotalTournamentAverages!J6/MassFormulaTesting!$B$28)*0.68)) -> 0.91955556 | N14: =((TotalTournamentAverages!K6/MassFormulaTesting!$B$30)*0.68)+0.3 -> 0.83426703 | O14: =((TotalTournamentAverages!L6/MassFormulaTesting!$B$32)*0.68)+0.3 -> 0.81915364 | P14: =((TotalTournamentAverages!M6/MassFormulaTesting!$B$34)*0.68)+0.3 -> 0.7189899 | Q14: =((TotalTournamentAverages!N6/MassFormulaTesting!$B$36)*0.68)+0.3 -> 0.85636364 | R14: =((TotalTournamentAverages!O6/MassFormulaTesting!$B$38)*0.68)+0.3 -> 0.52666667 | S14: =(IFERROR(TotalTournamentAverages!P6/MassFormulaTesting!$B$40,"")*0.68)+0.3 -> 0.3 | T14: =((TotalTournamentAverages!T6/MassFormulaTesting!$B$48)*0.68)+0.3 -> 0.56444444 | U14: =((TotalTournamentAverages!U6/MassFormulaTesting!$B$50)*0.68)+0.3 -> 0.47 | V14: =((TotalTournamentAverages!V6/MassFormulaTesting!$B$52)*0.68)+0.3 -> 0.52666667 | W14: =(IFERROR(TotalTournamentAverages!W6/MassFormulaTesting!$B$54,"")*0.68)+0.3 -> 0.3 | X14: =(IFERROR(TotalTournamentAverages!X6/MassFormulaTesting!$B$56,"")*0.68)+0.3 -> 0.3 | Y14: =(IFERROR(TotalTournamentAverages!Y6/MassFormulaTesting!$B$58,"")*0.68)+0.3 -> 0.3 | Z14: =(IFERROR(TotalTournamentAverages!Z6/MassFormulaTesting!$B$60,"")*0.68)+0.3 -> 0.3 | AA14: =((TotalTournamentAverages!AD6/MassFormulaTesting!$B$68)*0.68)+0.3 -> 0.3 | AB14: =((TotalTournamentAverages!AG6/MassFormulaTesting!$B$74)*0.68)+0.3 -> #DIV/0! | AC14: =((TotalTournamentAverages!AH6/MassFormulaTesting!$B$76)*0.68)+0.3 -> #DIV/0! | AD14: =((TotalTournamentAverages!AK6/MassFormulaTesting!$B$82)*0.68)+0.3 -> #DIV/0! | AE14: =((TotalTournamentAverages!AL6/MassFormulaTesting!$B$84)*0.68)+0.3 -> #DIV/0! | AF14: =((TotalTournamentAverages!AM6/MassFormulaTesting!$B$86)*0.68)+0.3 -> #DIV/0! | AG14: =((TotalTournamentAverages!AN6/MassFormulaTesting!$B$88)*0.68)+0.3 -> #DIV/0! | AH14: =((TotalTournamentAverages!AO6/MassFormulaTesting!$B$90)*0.68)+0.3 -> #DIV/0! | AI14: =((TotalTournamentAverages!AP6/MassFormulaTesting!$B$92)*0.68)+0.3 -> #DIV/0! | AJ14: =((TotalTournamentAverages!AQ6/MassFormulaTesting!$B$94)*0.68)+0.3 -> #DIV/0! | AK14: =((TotalTournamentAverages!AR6/MassFormulaTesting!$B$96)*0.68)+0.3 -> #DIV/0! | AL14: =((TotalTournamentAverages!AS6/MassFormulaTesting!$B$98)*0.68)+0.3 -> #DIV/0! | AM14: =((TotalTournamentAverages!AT6/MassFormulaTesting!$B$100)*0.68)+0.3 -> #DIV/0! | AN14: =((TotalTournamentAverages!AV6/MassFormulaTesting!$B$104)*0.68)+0.3 -> #DIV/0! | AO14: =((TotalTournamentAverages!AW6/MassFormulaTesting!$B$106)*0.68)+0.3 -> #DIV/0! | AP14: =((TotalTournamentAverages!AX6/MassFormulaTesting!$B$108)*0.68)+0.3 -> #DIV/0!
A15: =IFERROR(__xludf.DUMMYFUNCTION("Query(TotalTournamentAverages!A:AV,""Select A,D where A<>'' Order by D Desc Limit 1"")"),"OVERALL") -> OVERALL | B15: =IFERROR(__xludf.DUMMYFUNCTION("""COMPUTED_VALUE"""),"avg Goals") -> avg Goals | D15: =(((F15-$C$13)/$D$12)*0.68)+0.3 -> #DIV/0! | E15: =TotalTournamentAverages!A7 -> ADhillyy | F15: =((IFERROR((G15*C$10)+(H15*D$10)+(I15*E$10)+(J15*F$10)+(K15*G$10)+(L15*H$10)+(M15*I$10)+(N15*J$10)+(O15*K$10)+(P15*L$10)+(Q15*M$10)+(R15*N$10)+(S15*O$10)+(T15*P$10)+(U15*Q$10)+(V15*R$10)+(W15*S$10)+(X15*T$10)+(Y15*U$10)+(Z15*V$10)+(AA15*W$10)+(AB15*X$10)+(AC15*Y$10)+(AD15*Z$10)+(AE15*AA$10)+(AF15*AB$10)+(AG15*AC$10)+(AH15*AD$10)+(AI15*AE$10)+(AJ15*AF$10)+(AK15*AG$10)+(AL15*AH$10)+(AM15*AI$10)+(AN15*AJ$10)+(AO15*AK$10)+(AP15*AL$10),"")/F$12)*0.68)+0.3 -> 0.3 | G15: =((TotalTournamentAverages!D7/MassFormulaTesting!$B$16)*0.68)+0.3 -> 0.3 | H15: =((TotalTournamentAverages!E7/MassFormulaTesting!$B$18)*0.68)+0.3 -> 0.4311811 | I15: =((TotalTournamentAverages!F7/MassFormulaTesting!$B$20)*0.68)+0.3 -> 0.368 | J15: =(IFERROR(MassFormulaTesting!$C$22/TotalTournamentAverages!G7,"")*0.68)+0.3 -> 0.78571429 | K15: =(((TotalTournamentAverages!H7+118)/(MassFormulaTesting!$B$24+118))*0.68)+0.3 -> 0.78013136 | L15: =((TotalTournamentAverages!I7/MassFormulaTesting!$B$26)*0.68)+0.3 -> 0.48 | M15: =((0.98-(TotalTournamentAverages!J7/MassFormulaTesting!$B$28)*0.68)) -> 0.98 | N15: =((TotalTournamentAverages!K7/MassFormulaTesting!$B$30)*0.68)+0.3 -> 0.45698346 | O15: =((TotalTournamentAverages!L7/MassFormulaTesting!$B$32)*0.68)+0.3 -> 0.48425391 | P15: =((TotalTournamentAverages!M7/MassFormulaTesting!$B$34)*0.68)+0.3 -> 0.51636364 | Q15: =((TotalTournamentAverages!N7/MassFormulaTesting!$B$36)*0.68)+0.3 -> 0.3 | R15: =((TotalTournamentAverages!O7/MassFormulaTesting!$B$38)*0.68)+0.3 -> 0.3 | S15: =(IFERROR(TotalTournamentAverages!P7/MassFormulaTesting!$B$40,"")*0.68)+0.3 -> 0.3 | T15: =((TotalTournamentAverages!T7/MassFormulaTesting!$B$48)*0.68)+0.3 -> 0.35666667 | U15: =((TotalTournamentAverages!U7/MassFormulaTesting!$B$50)*0.68)+0.3 -> 0.3 | V15: =((TotalTournamentAverages!V7/MassFormulaTesting!$B$52)*0.68)+0.3 -> 0.3 | W15: =(IFERROR(TotalTournamentAverages!W7/MassFormulaTesting!$B$54,"")*0.68)+0.3 -> 0.3 | X15: =(IFERROR(TotalTournamentAverages!X7/MassFormulaTesting!$B$56,"")*0.68)+0.3 -> 0.3 | Y15: =(IFERROR(TotalTournamentAverages!Y7/MassFormulaTesting!$B$58,"")*0.68)+0.3 -> 0.3 | Z15: =(IFERROR(TotalTournamentAverages!Z7/MassFormulaTesting!$B$60,"")*0.68)+0.3 -> 0.3 | AA15: =((TotalTournamentAverages!AD7/MassFormulaTesting!$B$68)*0.68)+0.3 -> 0.3 | AB15: =((TotalTournamentAverages!AG7/MassFormulaTesting!$B$74)*0.68)+0.3 -> #DIV/0! | AC15: =((TotalTournamentAverages!AH7/MassFormulaTesting!$B$76)*0.68)+0.3 -> #DIV/0! | AD15: =((TotalTournamentAverages!AK7/MassFormulaTesting!$B$82)*0.68)+0.3 -> #DIV/0! | AE15: =((TotalTournamentAverages!AL7/MassFormulaTesting!$B$84)*0.68)+0.3 -> #DIV/0! | AF15: =((TotalTournamentAverages!AM7/MassFormulaTesting!$B$86)*0.68)+0.3 -> #DIV/0! | AG15: =((TotalTournamentAverages!AN7/MassFormulaTesting!$B$88)*0.68)+0.3 -> #DIV/0! | AH15: =((TotalTournamentAverages!AO7/MassFormulaTesting!$B$90)*0.68)+0.3 -> #DIV/0! | AI15: =((TotalTournamentAverages!AP7/MassFormulaTesting!$B$92)*0.68)+0.3 -> #DIV/0! | AJ15: =((TotalTournamentAverages!AQ7/MassFormulaTesting!$B$94)*0.68)+0.3 -> #DIV/0! | AK15: =((TotalTournamentAverages!AR7/MassFormulaTesting!$B$96)*0.68)+0.3 -> #DIV/0! | AL15: =((TotalTournamentAverages!AS7/MassFormulaTesting!$B$98)*0.68)+0.3 -> #DIV/0! | AM15: =((TotalTournamentAverages!AT7/MassFormulaTesting!$B$100)*0.68)+0.3 -> #DIV/0! | AN15: =((TotalTournamentAverages!AV7/MassFormulaTesting!$B$104)*0.68)+0.3 -> #DIV/0! | AO15: =((TotalTournamentAverages!AW7/MassFormulaTesting!$B$106)*0.68)+0.3 -> #DIV/0! | AP15: =((TotalTournamentAverages!AX7/MassFormulaTesting!$B$108)*0.68)+0.3 -> #DIV/0!
A16: =IFERROR(__xludf.DUMMYFUNCTION("""COMPUTED_VALUE"""),"yLuxe") -> yLuxe | B16: =IFERROR(__xludf.DUMMYFUNCTION("""COMPUTED_VALUE"""),3.5) -> 3.5 | D16: =(((F16-$C$13)/$D$12)*0.68)+0.3 -> #DIV/0! | E16: =TotalTournamentAverages!A8 -> Almighty Tycoon | F16: =((IFERROR((G16*C$10)+(H16*D$10)+(I16*E$10)+(J16*F$10)+(K16*G$10)+(L16*H$10)+(M16*I$10)+(N16*J$10)+(O16*K$10)+(P16*L$10)+(Q16*M$10)+(R16*N$10)+(S16*O$10)+(T16*P$10)+(U16*Q$10)+(V16*R$10)+(W16*S$10)+(X16*T$10)+(Y16*U$10)+(Z16*V$10)+(AA16*W$10)+(AB16*X$10)+(AC16*Y$10)+(AD16*Z$10)+(AE16*AA$10)+(AF16*AB$10)+(AG16*AC$10)+(AH16*AD$10)+(AI16*AE$10)+(AJ16*AF$10)+(AK16*AG$10)+(AL16*AH$10)+(AM16*AI$10)+(AN16*AJ$10)+(AO16*AK$10)+(AP16*AL$10),"")/F$12)*0.68)+0.3 -> 0.3 | G16: =((TotalTournamentAverages!D8/MassFormulaTesting!$B$16)*0.68)+0.3 -> 0.3 | H16: =((TotalTournamentAverages!E8/MassFormulaTesting!$B$18)*0.68)+0.3 -> 0.53023622 | I16: =((TotalTournamentAverages!F8/MassFormulaTesting!$B$20)*0.68)+0.3 -> 0.674 | J16: =(IFERROR(MassFormulaTesting!$C$22/TotalTournamentAverages!G8,"")*0.68)+0.3 -> 0.59824561 | K16: =(((TotalTournamentAverages!H8+118)/(MassFormulaTesting!$B$24+118))*0.68)+0.3 -> 0.76449918 | L16: =((TotalTournamentAverages!I8/MassFormulaTesting!$B$26)*0.68)+0.3 -> 0.51 | M16: =((0.98-(TotalTournamentAverages!J8/MassFormulaTesting!$B$28)*0.68)) -> 0.79866667 | N16: =((TotalTournamentAverages!K8/MassFormulaTesting!$B$30)*0.68)+0.3 -> 0.59689496 | O16: =((TotalTournamentAverages!L8/MassFormulaTesting!$B$32)*0.68)+0.3 -> 0.62244434 | P16: =((TotalTournamentAverages!M8/MassFormulaTesting!$B$34)*0.68)+0.3 -> 0.56787879 | Q16: =((TotalTournamentAverages!N8/MassFormulaTesting!$B$36)*0.68)+0.3 -> 0.3 | R16: =((TotalTournamentAverages!O8/MassFormulaTesting!$B$38)*0.68)+0.3 -> 0.3 | S16: =(IFERROR(TotalTournamentAverages!P8/MassFormulaTesting!$B$40,"")*0.68)+0.3 -> 0.3 | T16: =((TotalTournamentAverages!T8/MassFormulaTesting!$B$48)*0.68)+0.3 -> 0.35666667 | U16: =((TotalTournamentAverages!U8/MassFormulaTesting!$B$50)*0.68)+0.3 -> 0.3 | V16: =((TotalTournamentAverages!V8/MassFormulaTesting!$B$52)*0.68)+0.3 -> 0.3 | W16: =(IFERROR(TotalTournamentAverages!W8/MassFormulaTesting!$B$54,"")*0.68)+0.3 -> 0.3 | X16: =(IFERROR(TotalTournamentAverages!X8/MassFormulaTesting!$B$56,"")*0.68)+0.3 -> 0.3 | Y16: =(IFERROR(TotalTournamentAverages!Y8/MassFormulaTesting!$B$58,"")*0.68)+0.3 -> 0.3 | Z16: =(IFERROR(TotalTournamentAverages!Z8/MassFormulaTesting!$B$60,"")*0.68)+0.3 -> 0.3 | AA16: =((TotalTournamentAverages!AD8/MassFormulaTesting!$B$68)*0.68)+0.3 -> 0.3 | AB16: =((TotalTournamentAverages!AG8/MassFormulaTesting!$B$74)*0.68)+0.3 -> #DIV/0! | AC16: =((TotalTournamentAverages!AH8/MassFormulaTesting!$B$76)*0.68)+0.3 -> #DIV/0! | AD16: =((TotalTournamentAverages!AK8/MassFormulaTesting!$B$82)*0.68)+0.3 -> #DIV/0! | AE16: =((TotalTournamentAverages!AL8/MassFormulaTesting!$B$84)*0.68)+0.3 -> #DIV/0! | AF16: =((TotalTournamentAverages!AM8/MassFormulaTesting!$B$86)*0.68)+0.3 -> #DIV/0! | AG16: =((TotalTournamentAverages!AN8/MassFormulaTesting!$B$88)*0.68)+0.3 -> #DIV/0! | AH16: =((TotalTournamentAverages!AO8/MassFormulaTesting!$B$90)*0.68)+0.3 -> #DIV/0! | AI16: =((TotalTournamentAverages!AP8/MassFormulaTesting!$B$92)*0.68)+0.3 -> #DIV/0! | AJ16: =((TotalTournamentAverages!AQ8/MassFormulaTesting!$B$94)*0.68)+0.3 -> #DIV/0! | AK16: =((TotalTournamentAverages!AR8/MassFormulaTesting!$B$96)*0.68)+0.3 -> #DIV/0! | AL16: =((TotalTournamentAverages!AS8/MassFormulaTesting!$B$98)*0.68)+0.3 -> #DIV/0! | AM16: =((TotalTournamentAverages!AT8/MassFormulaTesting!$B$100)*0.68)+0.3 -> #DIV/0! | AN16: =((TotalTournamentAverages!AV8/MassFormulaTesting!$B$104)*0.68)+0.3 -> #DIV/0! | AO16: =((TotalTournamentAverages!AW8/MassFormulaTesting!$B$106)*0.68)+0.3 -> #DIV/0! | AP16: =((TotalTournamentAverages!AX8/MassFormulaTesting!$B$108)*0.68)+0.3 -> #DIV/0!
A17: =IFERROR(__xludf.DUMMYFUNCTION("Query(TotalTournamentAverages!A:AV,""Select A,E where A<>'' Order by E Desc Limit 1"")"),"OVERALL") -> OVERALL | B17: =IFERROR(__xludf.DUMMYFUNCTION("""COMPUTED_VALUE"""),"avg Kills") -> avg Kills | D17: =(((F17-$C$13)/$D$12)*0.68)+0.3 -> #DIV/0! | E17: =TotalTournamentAverages!A9 -> AwareMosquito | F17: =((IFERROR((G17*C$10)+(H17*D$10)+(I17*E$10)+(J17*F$10)+(K17*G$10)+(L17*H$10)+(M17*I$10)+(N17*J$10)+(O17*K$10)+(P17*L$10)+(Q17*M$10)+(R17*N$10)+(S17*O$10)+(T17*P$10)+(U17*Q$10)+(V17*R$10)+(W17*S$10)+(X17*T$10)+(Y17*U$10)+(Z17*V$10)+(AA17*W$10)+(AB17*X$10)+(AC17*Y$10)+(AD17*Z$10)+(AE17*AA$10)+(AF17*AB$10)+(AG17*AC$10)+(AH17*AD$10)+(AI17*AE$10)+(AJ17*AF$10)+(AK17*AG$10)+(AL17*AH$10)+(AM17*AI$10)+(AN17*AJ$10)+(AO17*AK$10)+(AP17*AL$10),"")/F$12)*0.68)+0.3 -> 0.3 | G17: =((TotalTournamentAverages!D9/MassFormulaTesting!$B$16)*0.68)+0.3 -> 0.3 | H17: =((TotalTournamentAverages!E9/MassFormulaTesting!$B$18)*0.68)+0.3 -> 0.69889764 | I17: =((TotalTournamentAverages!F9/MassFormulaTesting!$B$20)*0.68)+0.3 -> 0.436 | J17: =(IFERROR(MassFormulaTesting!$C$22/TotalTournamentAverages!G9,"")*0.68)+0.3 -> 0.46666667 | K17: =(((TotalTournamentAverages!H9+118)/(MassFormulaTesting!$B$24+118))*0.68)+0.3 -> 0.70420361 | L17: =((TotalTournamentAverages!I9/MassFormulaTesting!$B$26)*0.68)+0.3 -> 0.525 | M17: =((0.98-(TotalTournamentAverages!J9/MassFormulaTesting!$B$28)*0.68)) -> 0.88933333 | N17: =((TotalTournamentAverages!K9/MassFormulaTesting!$B$30)*0.68)+0.3 -> 0.75103309 | O17: =((TotalTournamentAverages!L9/MassFormulaTesting!$B$32)*0.68)+0.3 -> 0.79276646 | P17: =((TotalTournamentAverages!M9/MassFormulaTesting!$B$34)*0.68)+0.3 -> 0.51121212 | Q17: =((TotalTournamentAverages!N9/MassFormulaTesting!$B$36)*0.68)+0.3 -> 0.34636364 | R17: =((TotalTournamentAverages!O9/MassFormulaTesting!$B$38)*0.68)+0.3 -> 0.3 | S17: =(IFERROR(TotalTournamentAverages!P9/MassFormulaTesting!$B$40,"")*0.68)+0.3 -> 0.3 | T17: =((TotalTournamentAverages!T9/MassFormulaTesting!$B$48)*0.68)+0.3 -> 0.385 | U17: =((TotalTournamentAverages!U9/MassFormulaTesting!$B$50)*0.68)+0.3 -> 0.3 | V17: =((TotalTournamentAverages!V9/MassFormulaTesting!$B$52)*0.68)+0.3 -> 0.3 | W17: =(IFERROR(TotalTournamentAverages!W9/MassFormulaTesting!$B$54,"")*0.68)+0.3 -> 0.3 | X17: =(IFERROR(TotalTournamentAverages!X9/MassFormulaTesting!$B$56,"")*0.68)+0.3 -> 0.3 | Y17: =(IFERROR(TotalTournamentAverages!Y9/MassFormulaTesting!$B$58,"")*0.68)+0.3 -> 0.3 | Z17: =(IFERROR(TotalTournamentAverages!Z9/MassFormulaTesting!$B$60,"")*0.68)+0.3 -> 0.3 | AA17: =((TotalTournamentAverages!AD9/MassFormulaTesting!$B$68)*0.68)+0.3 -> 0.98 | AB17: =((TotalTournamentAverages!AG9/MassFormulaTesting!$B$74)*0.68)+0.3 -> #DIV/0! | AC17: =((TotalTournamentAverages!AH9/MassFormulaTesting!$B$76)*0.68)+0.3 -> #DIV/0! | AD17: =((TotalTournamentAverages!AK9/MassFormulaTesting!$B$82)*0.68)+0.3 -> #DIV/0! | AE17: =((TotalTournamentAverages!AL9/MassFormulaTesting!$B$84)*0.68)+0.3 -> #DIV/0! | AF17: =((TotalTournamentAverages!AM9/MassFormulaTesting!$B$86)*0.68)+0.3 -> #DIV/0! | AG17: =((TotalTournamentAverages!AN9/MassFormulaTesting!$B$88)*0.68)+0.3 -> #DIV/0! | AH17: =((TotalTournamentAverages!AO9/MassFormulaTesting!$B$90)*0.68)+0.3 -> #DIV/0! | AI17: =((TotalTournamentAverages!AP9/MassFormulaTesting!$B$92)*0.68)+0.3 -> #DIV/0! | AJ17: =((TotalTournamentAverages!AQ9/MassFormulaTesting!$B$94)*0.68)+0.3 -> #DIV/0! | AK17: =((TotalTournamentAverages!AR9/MassFormulaTesting!$B$96)*0.68)+0.3 -> #DIV/0! | AL17: =((TotalTournamentAverages!AS9/MassFormulaTesting!$B$98)*0.68)+0.3 -> #DIV/0! | AM17: =((TotalTournamentAverages!AT9/MassFormulaTesting!$B$100)*0.68)+0.3 -> #DIV/0! | AN17: =((TotalTournamentAverages!AV9/MassFormulaTesting!$B$104)*0.68)+0.3 -> #DIV/0! | AO17: =((TotalTournamentAverages!AW9/MassFormulaTesting!$B$106)*0.68)+0.3 -> #DIV/0! | AP17: =((TotalTournamentAverages!AX9/MassFormulaTesting!$B$108)*0.68)+0.3 -> #DIV/0!
A18: =IFERROR(__xludf.DUMMYFUNCTION("""COMPUTED_VALUE"""),"Yejis Aegyo") -> Yejis Aegyo | B18: =IFERROR(__xludf.DUMMYFUNCTION("""COMPUTED_VALUE"""),127.0) -> 127 | D18: =(((F18-$C$13)/$D$12)*0.68)+0.3 -> #DIV/0! | E18: =TotalTournamentAverages!A10 -> Dabb | F18: =((IFERROR((G18*C$10)+(H18*D$10)+(I18*E$10)+(J18*F$10)+(K18*G$10)+(L18*H$10)+(M18*I$10)+(N18*J$10)+(O18*K$10)+(P18*L$10)+(Q18*M$10)+(R18*N$10)+(S18*O$10)+(T18*P$10)+(U18*Q$10)+(V18*R$10)+(W18*S$10)+(X18*T$10)+(Y18*U$10)+(Z18*V$10)+(AA18*W$10)+(AB18*X$10)+(AC18*Y$10)+(AD18*Z$10)+(AE18*AA$10)+(AF18*AB$10)+(AG18*AC$10)+(AH18*AD$10)+(AI18*AE$10)+(AJ18*AF$10)+(AK18*AG$10)+(AL18*AH$10)+(AM18*AI$10)+(AN18*AJ$10)+(AO18*AK$10)+(AP18*AL$10),"")/F$12)*0.68)+0.3 -> 0.3 | G18: =((TotalTournamentAverages!D10/MassFormulaTesting!$B$16)*0.68)+0.3 -> 0.68857143 | H18: =((TotalTournamentAverages!E10/MassFormulaTesting!$B$18)*0.68)+0.3 -> 0.6016273 | I18: =((TotalTournamentAverages!F10/MassFormulaTesting!$B$20)*0.68)+0.3 -> 0.52666667 | J18: =(IFERROR(MassFormulaTesting!$C$22/TotalTournamentAverages!G10,"")*0.68)+0.3 -> 0.68059701 | K18: =(((TotalTournamentAverages!H10+118)/(MassFormulaTesting!$B$24+118))*0.68)+0.3 -> 0.87913519 | L18: =((TotalTournamentAverages!I10/MassFormulaTesting!$B$26)*0.68)+0.3 -> 0.88 | M18: =((0.98-(TotalTournamentAverages!J10/MassFormulaTesting!$B$28)*0.68)) -> 0.85911111 | N18: =((TotalTournamentAverages!K10/MassFormulaTesting!$B$30)*0.68)+0.3 -> 0.68774913 | O18: =((TotalTournamentAverages!L10/MassFormulaTesting!$B$32)*0.68)+0.3 -> 0.68450655 | P18: =((TotalTournamentAverages!M10/MassFormulaTesting!$B$34)*0.68)+0.3 -> 0.76020202 | Q18: =((TotalTournamentAverages!N10/MassFormulaTesting!$B$36)*0.68)+0.3 -> 0.79454545 | R18: =((TotalTournamentAverages!O10/MassFormulaTesting!$B$38)*0.68)+0.3 -> 0.75333333 | S18: =(IFERROR(TotalTournamentAverages!P10/MassFormulaTesting!$B$40,"")*0.68)+0.3 -> 0.3 | T18: =((TotalTournamentAverages!T10/MassFormulaTesting!$B$48)*0.68)+0.3 -> 0.45111111 | U18: =((TotalTournamentAverages!U10/MassFormulaTesting!$B$50)*0.68)+0.3 -> 0.3 | V18: =((TotalTournamentAverages!V10/MassFormulaTesting!$B$52)*0.68)+0.3 -> 0.3 | W18: =(IFERROR(TotalTournamentAverages!W10/MassFormulaTesting!$B$54,"")*0.68)+0.3 -> 0.3 | X18: =(IFERROR(TotalTournamentAverages!X10/MassFormulaTesting!$B$56,"")*0.68)+0.3 -> 0.3 | Y18: =(IFERROR(TotalTournamentAverages!Y10/MassFormulaTesting!$B$58,"")*0.68)+0.3 -> 0.3 | Z18: =(IFERROR(TotalTournamentAverages!Z10/MassFormulaTesting!$B$60,"")*0.68)+0.3 -> 0.3 | AA18: =((TotalTournamentAverages!AD10/MassFormulaTesting!$B$68)*0.68)+0.3 -> 0.3 | AB18: =((TotalTournamentAverages!AG10/MassFormulaTesting!$B$74)*0.68)+0.3 -> #DIV/0! | AC18: =((TotalTournamentAverages!AH10/MassFormulaTesting!$B$76)*0.68)+0.3 -> #DIV/0! | AD18: =((TotalTournamentAverages!AK10/MassFormulaTesting!$B$82)*0.68)+0.3 -> #DIV/0! | AE18: =((TotalTournamentAverages!AL10/MassFormulaTesting!$B$84)*0.68)+0.3 -> #DIV/0! | AF18: =((TotalTournamentAverages!AM10/MassFormulaTesting!$B$86)*0.68)+0.3 -> #DIV/0! | AG18: =((TotalTournamentAverages!AN10/MassFormulaTesting!$B$88)*0.68)+0.3 -> #DIV/0! | AH18: =((TotalTournamentAverages!AO10/MassFormulaTesting!$B$90)*0.68)+0.3 -> #DIV/0! | AI18: =((TotalTournamentAverages!AP10/MassFormulaTesting!$B$92)*0.68)+0.3 -> #DIV/0! | AJ18: =((TotalTournamentAverages!AQ10/MassFormulaTesting!$B$94)*0.68)+0.3 -> #DIV/0! | AK18: =((TotalTournamentAverages!AR10/MassFormulaTesting!$B$96)*0.68)+0.3 -> #DIV/0! | AL18: =((TotalTournamentAverages!AS10/MassFormulaTesting!$B$98)*0.68)+0.3 -> #DIV/0! | AM18: =((TotalTournamentAverages!AT10/MassFormulaTesting!$B$100)*0.68)+0.3 -> #DIV/0! | AN18: =((TotalTournamentAverages!AV10/MassFormulaTesting!$B$104)*0.68)+0.3 -> #DIV/0! | AO18: =((TotalTournamentAverages!AW10/MassFormulaTesting!$B$106)*0.68)+0.3 -> #DIV/0! | AP18: =((TotalTournamentAverages!AX10/MassFormulaTesting!$B$108)*0.68)+0.3 -> #DIV/0!
A19: =IFERROR(__xludf.DUMMYFUNCTION("Query(TotalTournamentAverages!A:AV,""Select A,F where A<>'' Order by F Desc Limit 1"")"),"OVERALL") -> OVERALL | B19: =IFERROR(__xludf.DUMMYFUNCTION("""COMPUTED_VALUE"""),"avg Assists") -> avg Assists | D19: =(((F19-$C$13)/$D$12)*0.68)+0.3 -> #DIV/0! | E19: =TotalTournamentAverages!A11 -> Dat Twinkie | F19: =((IFERROR((G19*C$10)+(H19*D$10)+(I19*E$10)+(J19*F$10)+(K19*G$10)+(L19*H$10)+(M19*I$10)+(N19*J$10)+(O19*K$10)+(P19*L$10)+(Q19*M$10)+(R19*N$10)+(S19*O$10)+(T19*P$10)+(U19*Q$10)+(V19*R$10)+(W19*S$10)+(X19*T$10)+(Y19*U$10)+(Z19*V$10)+(AA19*W$10)+(AB19*X$10)+(AC19*Y$10)+(AD19*Z$10)+(AE19*AA$10)+(AF19*AB$10)+(AG19*AC$10)+(AH19*AD$10)+(AI19*AE$10)+(AJ19*AF$10)+(AK19*AG$10)+(AL19*AH$10)+(AM19*AI$10)+(AN19*AJ$10)+(AO19*AK$10)+(AP19*AL$10),"")/F$12)*0.68)+0.3 -> 0.3 | G19: =((TotalTournamentAverages!D11/MassFormulaTesting!$B$16)*0.68)+0.3 -> 0.3 | H19: =((TotalTournamentAverages!E11/MassFormulaTesting!$B$18)*0.68)+0.3 -> 0.63464567 | I19: =((TotalTournamentAverages!F11/MassFormulaTesting!$B$20)*0.68)+0.3 -> 0.436 | J19: =(IFERROR(MassFormulaTesting!$C$22/TotalTournamentAverages!G11,"")*0.68)+0.3 -> 0.52368421 | K19: =(((TotalTournamentAverages!H11+118)/(MassFormulaTesting!$B$24+118))*0.68)+0.3 -> 0.76673235 | L19: =((TotalTournamentAverages!I11/MassFormulaTesting!$B$26)*0.68)+0.3 -> 0.63 | M19: =((0.98-(TotalTournamentAverages!J11/MassFormulaTesting!$B$28)*0.68)) -> 0.708 | N19: =((TotalTournamentAverages!K11/MassFormulaTesting!$B$30)*0.68)+0.3 -> 0.63005771 | O19: =((TotalTournamentAverages!L11/MassFormulaTesting!$B$32)*0.68)+0.3 -> 0.66641402 | P19: =((TotalTournamentAverages!M11/MassFormulaTesting!$B$34)*0.68)+0.3 -> 0.51636364 | Q19: =((TotalTournamentAverages!N11/MassFormulaTesting!$B$36)*0.68)+0.3 -> 0.76363636 | R19: =((TotalTournamentAverages!O11/MassFormulaTesting!$B$38)*0.68)+0.3 -> 0.3 | S19: =(IFERROR(TotalTournamentAverages!P11/MassFormulaTesting!$B$40,"")*0.68)+0.3 -> 0.3 | T19: =((TotalTournamentAverages!T11/MassFormulaTesting!$B$48)*0.68)+0.3 -> 0.52666667 | U19: =((TotalTournamentAverages!U11/MassFormulaTesting!$B$50)*0.68)+0.3 -> 0.3 | V19: =((TotalTournamentAverages!V11/MassFormulaTesting!$B$52)*0.68)+0.3 -> 0.3 | W19: =(IFERROR(TotalTournamentAverages!W11/MassFormulaTesting!$B$54,"")*0.68)+0.3 -> 0.3 | X19: =(IFERROR(TotalTournamentAverages!X11/MassFormulaTesting!$B$56,"")*0.68)+0.3 -> 0.3 | Y19: =(IFERROR(TotalTournamentAverages!Y11/MassFormulaTesting!$B$58,"")*0.68)+0.3 -> 0.3 | Z19: =(IFERROR(TotalTournamentAverages!Z11/MassFormulaTesting!$B$60,"")*0.68)+0.3 -> 0.3 | AA19: =((TotalTournamentAverages!AD11/MassFormulaTesting!$B$68)*0.68)+0.3 -> 0.3 | AB19: =((TotalTournamentAverages!AG11/MassFormulaTesting!$B$74)*0.68)+0.3 -> #DIV/0! | AC19: =((TotalTournamentAverages!AH11/MassFormulaTesting!$B$76)*0.68)+0.3 -> #DIV/0! | AD19: =((TotalTournamentAverages!AK11/MassFormulaTesting!$B$82)*0.68)+0.3 -> #DIV/0! | AE19: =((TotalTournamentAverages!AL11/MassFormulaTesting!$B$84)*0.68)+0.3 -> #DIV/0! | AF19: =((TotalTournamentAverages!AM11/MassFormulaTesting!$B$86)*0.68)+0.3 -> #DIV/0! | AG19: =((TotalTournamentAverages!AN11/MassFormulaTesting!$B$88)*0.68)+0.3 -> #DIV/0! | AH19: =((TotalTournamentAverages!AO11/MassFormulaTesting!$B$90)*0.68)+0.3 -> #DIV/0! | AI19: =((TotalTournamentAverages!AP11/MassFormulaTesting!$B$92)*0.68)+0.3 -> #DIV/0! | AJ19: =((TotalTournamentAverages!AQ11/MassFormulaTesting!$B$94)*0.68)+0.3 -> #DIV/0! | AK19: =((TotalTournamentAverages!AR11/MassFormulaTesting!$B$96)*0.68)+0.3 -> #DIV/0! | AL19: =((TotalTournamentAverages!AS11/MassFormulaTesting!$B$98)*0.68)+0.3 -> #DIV/0! | AM19: =((TotalTournamentAverages!AT11/MassFormulaTesting!$B$100)*0.68)+0.3 -> #DIV/0! | AN19: =((TotalTournamentAverages!AV11/MassFormulaTesting!$B$104)*0.68)+0.3 -> #DIV/0! | AO19: =((TotalTournamentAverages!AW11/MassFormulaTesting!$B$106)*0.68)+0.3 -> #DIV/0! | AP19: =((TotalTournamentAverages!AX11/MassFormulaTesting!$B$108)*0.68)+0.3 -> #DIV/0!
A20: =IFERROR(__xludf.DUMMYFUNCTION("""COMPUTED_VALUE"""),"L1ght5aber") -> L1ght5aber | B20: =IFERROR(__xludf.DUMMYFUNCTION("""COMPUTED_VALUE"""),10.0) -> 10 | D20: =(((F20-$C$13)/$D$12)*0.68)+0.3 -> #DIV/0! | E20: =TotalTournamentAverages!A12 -> Dhlyn | F20: =((IFERROR((G20*C$10)+(H20*D$10)+(I20*E$10)+(J20*F$10)+(K20*G$10)+(L20*H$10)+(M20*I$10)+(N20*J$10)+(O20*K$10)+(P20*L$10)+(Q20*M$10)+(R20*N$10)+(S20*O$10)+(T20*P$10)+(U20*Q$10)+(V20*R$10)+(W20*S$10)+(X20*T$10)+(Y20*U$10)+(Z20*V$10)+(AA20*W$10)+(AB20*X$10)+(AC20*Y$10)+(AD20*Z$10)+(AE20*AA$10)+(AF20*AB$10)+(AG20*AC$10)+(AH20*AD$10)+(AI20*AE$10)+(AJ20*AF$10)+(AK20*AG$10)+(AL20*AH$10)+(AM20*AI$10)+(AN20*AJ$10)+(AO20*AK$10)+(AP20*AL$10),"")/F$12)*0.68)+0.3 -> 0.3 | G20: =((TotalTournamentAverages!D12/MassFormulaTesting!$B$16)*0.68)+0.3 -> 0.3 | H20: =((TotalTournamentAverages!E12/MassFormulaTesting!$B$18)*0.68)+0.3 -> 0.52488189 | I20: =((TotalTournamentAverages!F12/MassFormulaTesting!$B$20)*0.68)+0.3 -> 0.538 | J20: =(IFERROR(MassFormulaTesting!$C$22/TotalTournamentAverages!G12,"")*0.68)+0.3 -> 0.60630631 | K20: =(((TotalTournamentAverages!H12+118)/(MassFormulaTesting!$B$24+118))*0.68)+0.3 -> 0.76673235 | L20: =((TotalTournamentAverages!I12/MassFormulaTesting!$B$26)*0.68)+0.3 -> 0.51 | M20: =((0.98-(TotalTournamentAverages!J12/MassFormulaTesting!$B$28)*0.68)) -> 0.88933333 | N20: =((TotalTournamentAverages!K12/MassFormulaTesting!$B$30)*0.68)+0.3 -> 0.56196614 | O20: =((TotalTournamentAverages!L12/MassFormulaTesting!$B$32)*0.68)+0.3 -> 0.58894363 | P20: =((TotalTournamentAverages!M12/MassFormulaTesting!$B$34)*0.68)+0.3 -> 0.54727273 | Q20: =((TotalTournamentAverages!N12/MassFormulaTesting!$B$36)*0.68)+0.3 -> 0.3 | R20: =((TotalTournamentAverages!O12/MassFormulaTesting!$B$38)*0.68)+0.3 -> 0.3 | S20: =(IFERROR(TotalTournamentAverages!P12/MassFormulaTesting!$B$40,"")*0.68)+0.3 -> 0.3 | T20: =((TotalTournamentAverages!T12/MassFormulaTesting!$B$48)*0.68)+0.3 -> 0.41333333 | U20: =((TotalTournamentAverages!U12/MassFormulaTesting!$B$50)*0.68)+0.3 -> 0.81 | V20: =((TotalTournamentAverages!V12/MassFormulaTesting!$B$52)*0.68)+0.3 -> 0.3 | W20: =(IFERROR(TotalTournamentAverages!W12/MassFormulaTesting!$B$54,"")*0.68)+0.3 -> 0.3 | X20: =(IFERROR(TotalTournamentAverages!X12/MassFormulaTesting!$B$56,"")*0.68)+0.3 -> 0.3 | Y20: =(IFERROR(TotalTournamentAverages!Y12/MassFormulaTesting!$B$58,"")*0.68)+0.3 -> 0.3 | Z20: =(IFERROR(TotalTournamentAverages!Z12/MassFormulaTesting!$B$60,"")*0.68)+0.3 -> 0.3 | AA20: =((TotalTournamentAverages!AD12/MassFormulaTesting!$B$68)*0.68)+0.3 -> 0.3 | AB20: =((TotalTournamentAverages!AG12/MassFormulaTesting!$B$74)*0.68)+0.3 -> #DIV/0! | AC20: =((TotalTournamentAverages!AH12/MassFormulaTesting!$B$76)*0.68)+0.3 -> #DIV/0! | AD20: =((TotalTournamentAverages!AK12/MassFormulaTesting!$B$82)*0.68)+0.3 -> #DIV/0! | AE20: =((TotalTournamentAverages!AL12/MassFormulaTesting!$B$84)*0.68)+0.3 -> #DIV/0! | AF20: =((TotalTournamentAverages!AM12/MassFormulaTesting!$B$86)*0.68)+0.3 -> #DIV/0! | AG20: =((TotalTournamentAverages!AN12/MassFormulaTesting!$B$88)*0.68)+0.3 -> #DIV/0! | AH20: =((TotalTournamentAverages!AO12/MassFormulaTesting!$B$90)*0.68)+0.3 -> #DIV/0! | AI20: =((TotalTournamentAverages!AP12/MassFormulaTesting!$B$92)*0.68)+0.3 -> #DIV/0! | AJ20: =((TotalTournamentAverages!AQ12/MassFormulaTesting!$B$94)*0.68)+0.3 -> #DIV/0! | AK20: =((TotalTournamentAverages!AR12/MassFormulaTesting!$B$96)*0.68)+0.3 -> #DIV/0! | AL20: =((TotalTournamentAverages!AS12/MassFormulaTesting!$B$98)*0.68)+0.3 -> #DIV/0! | AM20: =((TotalTournamentAverages!AT12/MassFormulaTesting!$B$100)*0.68)+0.3 -> #DIV/0! | AN20: =((TotalTournamentAverages!AV12/MassFormulaTesting!$B$104)*0.68)+0.3 -> #DIV/0! | AO20: =((TotalTournamentAverages!AW12/MassFormulaTesting!$B$106)*0.68)+0.3 -> #DIV/0! | AP20: =((TotalTournamentAverages!AX12/MassFormulaTesting!$B$108)*0.68)+0.3 -> #DIV/0!
A21: =IFERROR(__xludf.DUMMYFUNCTION("Query(TotalTournamentAverages!A:AV,""Select A,G where A<>'' Order by G Desc Limit 1"")"),"OVERALL") -> OVERALL | B21: =IFERROR(__xludf.DUMMYFUNCTION("""COMPUTED_VALUE"""),"avg Deaths") -> avg Deaths | C21: Lowest | D21: =(((F21-$C$13)/$D$12)*0.68)+0.3 -> #DIV/0! | E21: =TotalTournamentAverages!A13 -> Fanciest Pants | F21: =((IFERROR((G21*C$10)+(H21*D$10)+(I21*E$10)+(J21*F$10)+(K21*G$10)+(L21*H$10)+(M21*I$10)+(N21*J$10)+(O21*K$10)+(P21*L$10)+(Q21*M$10)+(R21*N$10)+(S21*O$10)+(T21*P$10)+(U21*Q$10)+(V21*R$10)+(W21*S$10)+(X21*T$10)+(Y21*U$10)+(Z21*V$10)+(AA21*W$10)+(AB21*X$10)+(AC21*Y$10)+(AD21*Z$10)+(AE21*AA$10)+(AF21*AB$10)+(AG21*AC$10)+(AH21*AD$10)+(AI21*AE$10)+(AJ21*AF$10)+(AK21*AG$10)+(AL21*AH$10)+(AM21*AI$10)+(AN21*AJ$10)+(AO21*AK$10)+(AP21*AL$10),"")/F$12)*0.68)+0.3 -> 0.3 | G21: =((TotalTournamentAverages!D13/MassFormulaTesting!$B$16)*0.68)+0.3 -> 0.3 | H21: =((TotalTournamentAverages!E13/MassFormulaTesting!$B$18)*0.68)+0.3 -> 0.6551706 | I21: =((TotalTournamentAverages!F13/MassFormulaTesting!$B$20)*0.68)+0.3 -> 0.61733333 | J21: =(IFERROR(MassFormulaTesting!$C$22/TotalTournamentAverages!G13,"")*0.68)+0.3 -> 0.50731707 | K21: =(((TotalTournamentAverages!H13+118)/(MassFormulaTesting!$B$24+118))*0.68)+0.3 -> 0.75705528 | L21: =((TotalTournamentAverages!I13/MassFormulaTesting!$B$26)*0.68)+0.3 -> 0.52 | M21: =((0.98-(TotalTournamentAverages!J13/MassFormulaTesting!$B$28)*0.68)) -> 0.79866667 | N21: =((TotalTournamentAverages!K13/MassFormulaTesting!$B$30)*0.68)+0.3 -> 0.64196229 | O21: =((TotalTournamentAverages!L13/MassFormulaTesting!$B$32)*0.68)+0.3 -> 0.68450655 | P21: =((TotalTournamentAverages!M13/MassFormulaTesting!$B$34)*0.68)+0.3 -> 0.50606061 | Q21: =((TotalTournamentAverages!N13/MassFormulaTesting!$B$36)*0.68)+0.3 -> 0.3 | R21: =((TotalTournamentAverages!O13/MassFormulaTesting!$B$38)*0.68)+0.3 -> 0.3 | S21: =(IFERROR(TotalTournamentAverages!P13/MassFormulaTesting!$B$40,"")*0.68)+0.3 -> 0.3 | T21: =((TotalTournamentAverages!T13/MassFormulaTesting!$B$48)*0.68)+0.3 -> 0.37555556 | U21: =((TotalTournamentAverages!U13/MassFormulaTesting!$B$50)*0.68)+0.3 -> 0.3 | V21: =((TotalTournamentAverages!V13/MassFormulaTesting!$B$52)*0.68)+0.3 -> 0.3 | W21: =(IFERROR(TotalTournamentAverages!W13/MassFormulaTesting!$B$54,"")*0.68)+0.3 -> 0.3 | X21: =(IFERROR(TotalTournamentAverages!X13/MassFormulaTesting!$B$56,"")*0.68)+0.3 -> 0.3 | Y21: =(IFERROR(TotalTournamentAverages!Y13/MassFormulaTesting!$B$58,"")*0.68)+0.3 -> 0.3 | Z21: =(IFERROR(TotalTournamentAverages!Z13/MassFormulaTesting!$B$60,"")*0.68)+0.3 -> 0.3 | AA21: =((TotalTournamentAverages!AD13/MassFormulaTesting!$B$68)*0.68)+0.3 -> 0.3 | AB21: =((TotalTournamentAverages!AG13/MassFormulaTesting!$B$74)*0.68)+0.3 -> #DIV/0! | AC21: =((TotalTournamentAverages!AH13/MassFormulaTesting!$B$76)*0.68)+0.3 -> #DIV/0! | AD21: =((TotalTournamentAverages!AK13/MassFormulaTesting!$B$82)*0.68)+0.3 -> #DIV/0! | AE21: =((TotalTournamentAverages!AL13/MassFormulaTesting!$B$84)*0.68)+0.3 -> #DIV/0! | AF21: =((TotalTournamentAverages!AM13/MassFormulaTesting!$B$86)*0.68)+0.3 -> #DIV/0! | AG21: =((TotalTournamentAverages!AN13/MassFormulaTesting!$B$88)*0.68)+0.3 -> #DIV/0! | AH21: =((TotalTournamentAverages!AO13/MassFormulaTesting!$B$90)*0.68)+0.3 -> #DIV/0! | AI21: =((TotalTournamentAverages!AP13/MassFormulaTesting!$B$92)*0.68)+0.3 -> #DIV/0! | AJ21: =((TotalTournamentAverages!AQ13/MassFormulaTesting!$B$94)*0.68)+0.3 -> #DIV/0! | AK21: =((TotalTournamentAverages!AR13/MassFormulaTesting!$B$96)*0.68)+0.3 -> #DIV/0! | AL21: =((TotalTournamentAverages!AS13/MassFormulaTesting!$B$98)*0.68)+0.3 -> #DIV/0! | AM21: =((TotalTournamentAverages!AT13/MassFormulaTesting!$B$100)*0.68)+0.3 -> #DIV/0! | AN21: =((TotalTournamentAverages!AV13/MassFormulaTesting!$B$104)*0.68)+0.3 -> #DIV/0! | AO21: =((TotalTournamentAverages!AW13/MassFormulaTesting!$B$106)*0.68)+0.3 -> #DIV/0! | AP21: =((TotalTournamentAverages!AX13/MassFormulaTesting!$B$108)*0.68)+0.3 -> #DIV/0!
A22: =IFERROR(__xludf.DUMMYFUNCTION("""COMPUTED_VALUE"""),"Yejis Aegyo") -> Yejis Aegyo | B22: =IFERROR(__xludf.DUMMYFUNCTION("""COMPUTED_VALUE"""),129.66666666666666) -> 129.66667 | C22: 25 | D22: =(((F22-$C$13)/$D$12)*0.68)+0.3 -> #DIV/0! | E22: =TotalTournamentAverages!A14 -> Finesse God24 | F22: =((IFERROR((G22*C$10)+(H22*D$10)+(I22*E$10)+(J22*F$10)+(K22*G$10)+(L22*H$10)+(M22*I$10)+(N22*J$10)+(O22*K$10)+(P22*L$10)+(Q22*M$10)+(R22*N$10)+(S22*O$10)+(T22*P$10)+(U22*Q$10)+(V22*R$10)+(W22*S$10)+(X22*T$10)+(Y22*U$10)+(Z22*V$10)+(AA22*W$10)+(AB22*X$10)+(AC22*Y$10)+(AD22*Z$10)+(AE22*AA$10)+(AF22*AB$10)+(AG22*AC$10)+(AH22*AD$10)+(AI22*AE$10)+(AJ22*AF$10)+(AK22*AG$10)+(AL22*AH$10)+(AM22*AI$10)+(AN22*AJ$10)+(AO22*AK$10)+(AP22*AL$10),"")/F$12)*0.68)+0.3 -> 0.3 | G22: =((TotalTournamentAverages!D14/MassFormulaTesting!$B$16)*0.68)+0.3 -> 0.3647619 | H22: =((TotalTournamentAverages!E14/MassFormulaTesting!$B$18)*0.68)+0.3 -> 0.66230971 | I22: =((TotalTournamentAverages!F14/MassFormulaTesting!$B$20)*0.68)+0.3 -> 0.61733333 | J22: =(IFERROR(MassFormulaTesting!$C$22/TotalTournamentAverages!G14,"")*0.68)+0.3 -> 0.53943662 | K22: =(((TotalTournamentAverages!H14+118)/(MassFormulaTesting!$B$24+118))*0.68)+0.3 -> 0.81214012 | L22: =((TotalTournamentAverages!I14/MassFormulaTesting!$B$26)*0.68)+0.3 -> 0.56 | M22: =((0.98-(TotalTournamentAverages!J14/MassFormulaTesting!$B$28)*0.68)) -> 0.98 | N22: =((TotalTournamentAverages!K14/MassFormulaTesting!$B$30)*0.68)+0.3 -> 0.59748365 | O22: =((TotalTournamentAverages!L14/MassFormulaTesting!$B$32)*0.68)+0.3 -> 0.63930207 | P22: =((TotalTournamentAverages!M14/MassFormulaTesting!$B$34)*0.68)+0.3 -> 0.50606061 | Q22: =((TotalTournamentAverages!N14/MassFormulaTesting!$B$36)*0.68)+0.3 -> 0.42363636 | R22: =((TotalTournamentAverages!O14/MassFormulaTesting!$B$38)*0.68)+0.3 -> 0.3 | S22: =(IFERROR(TotalTournamentAverages!P14/MassFormulaTesting!$B$40,"")*0.68)+0.3 -> 0.3 | T22: =((TotalTournamentAverages!T14/MassFormulaTesting!$B$48)*0.68)+0.3 -> 0.52666667 | U22: =((TotalTournamentAverages!U14/MassFormulaTesting!$B$50)*0.68)+0.3 -> 0.3 | V22: =((TotalTournamentAverages!V14/MassFormulaTesting!$B$52)*0.68)+0.3 -> 0.3 | W22: =(IFERROR(TotalTournamentAverages!W14/MassFormulaTesting!$B$54,"")*0.68)+0.3 -> 0.3 | X22: =(IFERROR(TotalTournamentAverages!X14/MassFormulaTesting!$B$56,"")*0.68)+0.3 -> 0.3 | Y22: =(IFERROR(TotalTournamentAverages!Y14/MassFormulaTesting!$B$58,"")*0.68)+0.3 -> 0.3 | Z22: =(IFERROR(TotalTournamentAverages!Z14/MassFormulaTesting!$B$60,"")*0.68)+0.3 -> 0.3 | AA22: =((TotalTournamentAverages!AD14/MassFormulaTesting!$B$68)*0.68)+0.3 -> 0.3 | AB22: =((TotalTournamentAverages!AG14/MassFormulaTesting!$B$74)*0.68)+0.3 -> #DIV/0! | AC22: =((TotalTournamentAverages!AH14/MassFormulaTesting!$B$76)*0.68)+0.3 -> #DIV/0! | AD22: =((TotalTournamentAverages!AK14/MassFormulaTesting!$B$82)*0.68)+0.3 -> #DIV/0! | AE22: =((TotalTournamentAverages!AL14/MassFormulaTesting!$B$84)*0.68)+0.3 -> #DIV/0! | AF22: =((TotalTournamentAverages!AM14/MassFormulaTesting!$B$86)*0.68)+0.3 -> #DIV/0! | AG22: =((TotalTournamentAverages!AN14/MassFormulaTesting!$B$88)*0.68)+0.3 -> #DIV/0! | AH22: =((TotalTournamentAverages!AO14/MassFormulaTesting!$B$90)*0.68)+0.3 -> #DIV/0! | AI22: =((TotalTournamentAverages!AP14/MassFormulaTesting!$B$92)*0.68)+0.3 -> #DIV/0! | AJ22: =((TotalTournamentAverages!AQ14/MassFormulaTesting!$B$94)*0.68)+0.3 -> #DIV/0! | AK22: =((TotalTournamentAverages!AR14/MassFormulaTesting!$B$96)*0.68)+0.3 -> #DIV/0! | AL22: =((TotalTournamentAverages!AS14/MassFormulaTesting!$B$98)*0.68)+0.3 -> #DIV/0! | AM22: =((TotalTournamentAverages!AT14/MassFormulaTesting!$B$100)*0.68)+0.3 -> #DIV/0! | AN22: =((TotalTournamentAverages!AV14/MassFormulaTesting!$B$104)*0.68)+0.3 -> #DIV/0! | AO22: =((TotalTournamentAverages!AW14/MassFormulaTesting!$B$106)*0.68)+0.3 -> #DIV/0! | AP22: =((TotalTournamentAverages!AX14/MassFormulaTesting!$B$108)*0.68)+0.3 -> #DIV/0!
A23: =IFERROR(__xludf.DUMMYFUNCTION("Query(TotalTournamentAverages!A:AV,""Select A,H where A<>'' Order by H Desc Limit 1"")"),"OVERALL") -> OVERALL | B23: =IFERROR(__xludf.DUMMYFUNCTION("""COMPUTED_VALUE"""),"avg Spread") -> avg Spread | C23: Lowest | D23: =(((F23-$C$13)/$D$12)*0.68)+0.3 -> #DIV/0! | E23: =TotalTournamentAverages!A15 -> Galvann | F23: =((IFERROR((G23*C$10)+(H23*D$10)+(I23*E$10)+(J23*F$10)+(K23*G$10)+(L23*H$10)+(M23*I$10)+(N23*J$10)+(O23*K$10)+(P23*L$10)+(Q23*M$10)+(R23*N$10)+(S23*O$10)+(T23*P$10)+(U23*Q$10)+(V23*R$10)+(W23*S$10)+(X23*T$10)+(Y23*U$10)+(Z23*V$10)+(AA23*W$10)+(AB23*X$10)+(AC23*Y$10)+(AD23*Z$10)+(AE23*AA$10)+(AF23*AB$10)+(AG23*AC$10)+(AH23*AD$10)+(AI23*AE$10)+(AJ23*AF$10)+(AK23*AG$10)+(AL23*AH$10)+(AM23*AI$10)+(AN23*AJ$10)+(AO23*AK$10)+(AP23*AL$10),"")/F$12)*0.68)+0.3 -> 0.3 | G23: =((TotalTournamentAverages!D15/MassFormulaTesting!$B$16)*0.68)+0.3 -> 0.3 | H23: =((TotalTournamentAverages!E15/MassFormulaTesting!$B$18)*0.68)+0.3 -> 0.70692913 | I23: =((TotalTournamentAverages!F15/MassFormulaTesting!$B$20)*0.68)+0.3 -> 0.844 | J23: =(IFERROR(MassFormulaTesting!$C$22/TotalTournamentAverages!G15,"")*0.68)+0.3 -> 0.57868852 | K23: =(((TotalTournamentAverages!H15+118)/(MassFormulaTesting!$B$24+118))*0.68)+0.3 -> 0.89402299 | L23: =((TotalTournamentAverages!I15/MassFormulaTesting!$B$26)*0.68)+0.3 -> 0.6 | M23: =((0.98-(TotalTournamentAverages!J15/MassFormulaTesting!$B$28)*0.68)) -> 0.61733333 | N23: =((TotalTournamentAverages!K15/MassFormulaTesting!$B$30)*0.68)+0.3 -> 0.56922663 | O23: =((TotalTournamentAverages!L15/MassFormulaTesting!$B$32)*0.68)+0.3 -> 0.60054003 | P23: =((TotalTournamentAverages!M15/MassFormulaTesting!$B$34)*0.68)+0.3 -> 0.52666667 | Q23: =((TotalTournamentAverages!N15/MassFormulaTesting!$B$36)*0.68)+0.3 -> 0.48545455 | R23: =((TotalTournamentAverages!O15/MassFormulaTesting!$B$38)*0.68)+0.3 -> 0.3 | S23: =(IFERROR(TotalTournamentAverages!P15/MassFormulaTesting!$B$40,"")*0.68)+0.3 -> 0.3 | T23: =((TotalTournamentAverages!T15/MassFormulaTesting!$B$48)*0.68)+0.3 -> 0.98 | U23: =((TotalTournamentAverages!U15/MassFormulaTesting!$B$50)*0.68)+0.3 -> 0.81 | V23: =((TotalTournamentAverages!V15/MassFormulaTesting!$B$52)*0.68)+0.3 -> 0.3 | W23: =(IFERROR(TotalTournamentAverages!W15/MassFormulaTesting!$B$54,"")*0.68)+0.3 -> 0.3 | X23: =(IFERROR(TotalTournamentAverages!X15/MassFormulaTesting!$B$56,"")*0.68)+0.3 -> 0.3 | Y23: =(IFERROR(TotalTournamentAverages!Y15/MassFormulaTesting!$B$58,"")*0.68)+0.3 -> 0.3 | Z23: =(IFERROR(TotalTournamentAverages!Z15/MassFormulaTesting!$B$60,"")*0.68)+0.3 -> 0.3 | AA23: =((TotalTournamentAverages!AD15/MassFormulaTesting!$B$68)*0.68)+0.3 -> 0.3 | AB23: =((TotalTournamentAverages!AG15/MassFormulaTesting!$B$74)*0.68)+0.3 -> #DIV/0! | AC23: =((TotalTournamentAverages!AH15/MassFormulaTesting!$B$76)*0.68)+0.3 -> #DIV/0! | AD23: =((TotalTournamentAverages!AK15/MassFormulaTesting!$B$82)*0.68)+0.3 -> #DIV/0! | AE23: =((TotalTournamentAverages!AL15/MassFormulaTesting!$B$84)*0.68)+0.3 -> #DIV/0! | AF23: =((TotalTournamentAverages!AM15/MassFormulaTesting!$B$86)*0.68)+0.3 -> #DIV/0! | AG23: =((TotalTournamentAverages!AN15/MassFormulaTesting!$B$88)*0.68)+0.3 -> #DIV/0! | AH23: =((TotalTournamentAverages!AO15/MassFormulaTesting!$B$90)*0.68)+0.3 -> #DIV/0! | AI23: =((TotalTournamentAverages!AP15/MassFormulaTesting!$B$92)*0.68)+0.3 -> #DIV/0! | AJ23: =((TotalTournamentAverages!AQ15/MassFormulaTesting!$B$94)*0.68)+0.3 -> #DIV/0! | AK23: =((TotalTournamentAverages!AR15/MassFormulaTesting!$B$96)*0.68)+0.3 -> #DIV/0! | AL23: =((TotalTournamentAverages!AS15/MassFormulaTesting!$B$98)*0.68)+0.3 -> #DIV/0! | AM23: =((TotalTournamentAverages!AT15/MassFormulaTesting!$B$100)*0.68)+0.3 -> #DIV/0! | AN23: =((TotalTournamentAverages!AV15/MassFormulaTesting!$B$104)*0.68)+0.3 -> #DIV/0! | AO23: =((TotalTournamentAverages!AW15/MassFormulaTesting!$B$106)*0.68)+0.3 -> #DIV/0! | AP23: =((TotalTournamentAverages!AX15/MassFormulaTesting!$B$108)*0.68)+0.3 -> #DIV/0!
A24: =IFERROR(__xludf.DUMMYFUNCTION("""COMPUTED_VALUE"""),"Genesiology") -> Genesiology | B24: =IFERROR(__xludf.DUMMYFUNCTION("""COMPUTED_VALUE"""),34.25) -> 34.25 | C24: -118 | D24: =(((F24-$C$13)/$D$12)*0.68)+0.3 -> #DIV/0! | E24: =TotalTournamentAverages!A16 -> Genesiology | F24: =((IFERROR((G24*C$10)+(H24*D$10)+(I24*E$10)+(J24*F$10)+(K24*G$10)+(L24*H$10)+(M24*I$10)+(N24*J$10)+(O24*K$10)+(P24*L$10)+(Q24*M$10)+(R24*N$10)+(S24*O$10)+(T24*P$10)+(U24*Q$10)+(V24*R$10)+(W24*S$10)+(X24*T$10)+(Y24*U$10)+(Z24*V$10)+(AA24*W$10)+(AB24*X$10)+(AC24*Y$10)+(AD24*Z$10)+(AE24*AA$10)+(AF24*AB$10)+(AG24*AC$10)+(AH24*AD$10)+(AI24*AE$10)+(AJ24*AF$10)+(AK24*AG$10)+(AL24*AH$10)+(AM24*AI$10)+(AN24*AJ$10)+(AO24*AK$10)+(AP24*AL$10),"")/F$12)*0.68)+0.3 -> 0.3 | G24: =((TotalTournamentAverages!D16/MassFormulaTesting!$B$16)*0.68)+0.3 -> 0.34857143 | H24: =((TotalTournamentAverages!E16/MassFormulaTesting!$B$18)*0.68)+0.3 -> 0.86086614 | I24: =((TotalTournamentAverages!F16/MassFormulaTesting!$B$20)*0.68)+0.3 -> 0.912 | J24: =(IFERROR(MassFormulaTesting!$C$22/TotalTournamentAverages!G16,"")*0.68)+0.3 -> 0.54113475 | K24: =(((TotalTournamentAverages!H16+118)/(MassFormulaTesting!$B$24+118))*0.68)+0.3 -> 0.98 | L24: =((TotalTournamentAverages!I16/MassFormulaTesting!$B$26)*0.68)+0.3 -> 0.675 | M24: =((0.98-(TotalTournamentAverages!J16/MassFormulaTesting!$B$28)*0.68)) -> 0.34533333 | N24: =((TotalTournamentAverages!K16/MassFormulaTesting!$B$30)*0.68)+0.3 -> 0.79135821 | O24: =((TotalTournamentAverages!L16/MassFormulaTesting!$B$32)*0.68)+0.3 -> 0.7973567 | P24: =((TotalTournamentAverages!M16/MassFormulaTesting!$B$34)*0.68)+0.3 -> 0.65545455 | Q24: =((TotalTournamentAverages!N16/MassFormulaTesting!$B$36)*0.68)+0.3 -> 0.94909091 | R24: =((TotalTournamentAverages!O16/MassFormulaTesting!$B$38)*0.68)+0.3 -> 0.3 | S24: =(IFERROR(TotalTournamentAverages!P16/MassFormulaTesting!$B$40,"")*0.68)+0.3 -> 0.3 | T24: =((TotalTournamentAverages!T16/MassFormulaTesting!$B$48)*0.68)+0.3 -> 0.64 | U24: =((TotalTournamentAverages!U16/MassFormulaTesting!$B$50)*0.68)+0.3 -> 0.81 | V24: =((TotalTournamentAverages!V16/MassFormulaTesting!$B$52)*0.68)+0.3 -> 0.64 | W24: =(IFERROR(TotalTournamentAverages!W16/MassFormulaTesting!$B$54,"")*0.68)+0.3 -> 0.81 | X24: =(IFERROR(TotalTournamentAverages!X16/MassFormulaTesting!$B$56,"")*0.68)+0.3 -> 0.3 | Y24: =(IFERROR(TotalTournamentAverages!Y16/MassFormulaTesting!$B$58,"")*0.68)+0.3 -> 0.3 | Z24: =(IFERROR(TotalTournamentAverages!Z16/MassFormulaTesting!$B$60,"")*0.68)+0.3 -> 0.3 | AA24: =((TotalTournamentAverages!AD16/MassFormulaTesting!$B$68)*0.68)+0.3 -> 0.3 | AB24: =((TotalTournamentAverages!AG16/MassFormulaTesting!$B$74)*0.68)+0.3 -> #DIV/0! | AC24: =((TotalTournamentAverages!AH16/MassFormulaTesting!$B$76)*0.68)+0.3 -> #DIV/0! | AD24: =((TotalTournamentAverages!AK16/MassFormulaTesting!$B$82)*0.68)+0.3 -> #DIV/0! | AE24: =((TotalTournamentAverages!AL16/MassFormulaTesting!$B$84)*0.68)+0.3 -> #DIV/0! | AF24: =((TotalTournamentAverages!AM16/MassFormulaTesting!$B$86)*0.68)+0.3 -> #DIV/0! | AG24: =((TotalTournamentAverages!AN16/MassFormulaTesting!$B$88)*0.68)+0.3 -> #DIV/0! | AH24: =((TotalTournamentAverages!AO16/MassFormulaTesting!$B$90)*0.68)+0.3 -> #DIV/0! | AI24: =((TotalTournamentAverages!AP16/MassFormulaTesting!$B$92)*0.68)+0.3 -> #DIV/0! | AJ24: =((TotalTournamentAverages!AQ16/MassFormulaTesting!$B$94)*0.68)+0.3 -> #DIV/0! | AK24: =((TotalTournamentAverages!AR16/MassFormulaTesting!$B$96)*0.68)+0.3 -> #DIV/0! | AL24: =((TotalTournamentAverages!AS16/MassFormulaTesting!$B$98)*0.68)+0.3 -> #DIV/0! | AM24: =((TotalTournamentAverages!AT16/MassFormulaTesting!$B$100)*0.68)+0.3 -> #DIV/0! | AN24: =((TotalTournamentAverages!AV16/MassFormulaTesting!$B$104)*0.68)+0.3 -> #DIV/0! | AO24: =((TotalTournamentAverages!AW16/MassFormulaTesting!$B$106)*0.68)+0.3 -> #DIV/0! | AP24: =((TotalTournamentAverages!AX16/MassFormulaTesting!$B$108)*0.68)+0.3 -> #DIV/0!
A25: =IFERROR(__xludf.DUMMYFUNCTION("Query(TotalTournamentAverages!A:AV,""Select A,I where A<>'' Order by I Desc Limit 1"")"),"OVERALL") -> OVERALL | B25: =IFERROR(__xludf.DUMMYFUNCTION("""COMPUTED_VALUE"""),"avg Streak") -> avg Streak | D25: =(((F25-$C$13)/$D$12)*0.68)+0.3 -> #DIV/0! | E25: =TotalTournamentAverages!A17 -> GodSnipezX | F25: =((IFERROR((G25*C$10)+(H25*D$10)+(I25*E$10)+(J25*F$10)+(K25*G$10)+(L25*H$10)+(M25*I$10)+(N25*J$10)+(O25*K$10)+(P25*L$10)+(Q25*M$10)+(R25*N$10)+(S25*O$10)+(T25*P$10)+(U25*Q$10)+(V25*R$10)+(W25*S$10)+(X25*T$10)+(Y25*U$10)+(Z25*V$10)+(AA25*W$10)+(AB25*X$10)+(AC25*Y$10)+(AD25*Z$10)+(AE25*AA$10)+(AF25*AB$10)+(AG25*AC$10)+(AH25*AD$10)+(AI25*AE$10)+(AJ25*AF$10)+(AK25*AG$10)+(AL25*AH$10)+(AM25*AI$10)+(AN25*AJ$10)+(AO25*AK$10)+(AP25*AL$10),"")/F$12)*0.68)+0.3 -> 0.3 | G25: =((TotalTournamentAverages!D17/MassFormulaTesting!$B$16)*0.68)+0.3 -> 0.34857143 | H25: =((TotalTournamentAverages!E17/MassFormulaTesting!$B$18)*0.68)+0.3 -> 0.96393701 | I25: =((TotalTournamentAverages!F17/MassFormulaTesting!$B$20)*0.68)+0.3 -> 0.81 | J25: =(IFERROR(MassFormulaTesting!$C$22/TotalTournamentAverages!G17,"")*0.68)+0.3 -> 0.43229572 | K25: =(((TotalTournamentAverages!H17+118)/(MassFormulaTesting!$B$24+118))*0.68)+0.3 -> 0.80692939 | L25: =((TotalTournamentAverages!I17/MassFormulaTesting!$B$26)*0.68)+0.3 -> 0.66 | M25: =((0.98-(TotalTournamentAverages!J17/MassFormulaTesting!$B$28)*0.68)) -> 0.75333333 | N25: =((TotalTournamentAverages!K17/MassFormulaTesting!$B$30)*0.68)+0.3 -> 0.79145633 | O25: =((TotalTournamentAverages!L17/MassFormulaTesting!$B$32)*0.68)+0.3 -> 0.85590242 | P25: =((TotalTournamentAverages!M17/MassFormulaTesting!$B$34)*0.68)+0.3 -> 0.50090909 | Q25: =((TotalTournamentAverages!N17/MassFormulaTesting!$B$36)*0.68)+0.3 -> 0.67090909 | R25: =((TotalTournamentAverages!O17/MassFormulaTesting!$B$38)*0.68)+0.3 -> 0.3 | S25: =(IFERROR(TotalTournamentAverages!P17/MassFormulaTesting!$B$40,"")*0.68)+0.3 -> 0.3 | T25: =((TotalTournamentAverages!T17/MassFormulaTesting!$B$48)*0.68)+0.3 -> 0.66833333 | U25: =((TotalTournamentAverages!U17/MassFormulaTesting!$B$50)*0.68)+0.3 -> 0.555 | V25: =((TotalTournamentAverages!V17/MassFormulaTesting!$B$52)*0.68)+0.3 -> 0.3 | W25: =(IFERROR(TotalTournamentAverages!W17/MassFormulaTesting!$B$54,"")*0.68)+0.3 -> 0.3 | X25: =(IFERROR(TotalTournamentAverages!X17/MassFormulaTesting!$B$56,"")*0.68)+0.3 -> 0.3 | Y25: =(IFERROR(TotalTournamentAverages!Y17/MassFormulaTesting!$B$58,"")*0.68)+0.3 -> 0.3 | Z25: =(IFERROR(TotalTournamentAverages!Z17/MassFormulaTesting!$B$60,"")*0.68)+0.3 -> 0.3 | AA25: =((TotalTournamentAverages!AD17/MassFormulaTesting!$B$68)*0.68)+0.3 -> 0.3 | AB25: =((TotalTournamentAverages!AG17/MassFormulaTesting!$B$74)*0.68)+0.3 -> #DIV/0! | AC25: =((TotalTournamentAverages!AH17/MassFormulaTesting!$B$76)*0.68)+0.3 -> #DIV/0! | AD25: =((TotalTournamentAverages!AK17/MassFormulaTesting!$B$82)*0.68)+0.3 -> #DIV/0! | AE25: =((TotalTournamentAverages!AL17/MassFormulaTesting!$B$84)*0.68)+0.3 -> #DIV/0! | AF25: =((TotalTournamentAverages!AM17/MassFormulaTesting!$B$86)*0.68)+0.3 -> #DIV/0! | AG25: =((TotalTournamentAverages!AN17/MassFormulaTesting!$B$88)*0.68)+0.3 -> #DIV/0! | AH25: =((TotalTournamentAverages!AO17/MassFormulaTesting!$B$90)*0.68)+0.3 -> #DIV/0! | AI25: =((TotalTournamentAverages!AP17/MassFormulaTesting!$B$92)*0.68)+0.3 -> #DIV/0! | AJ25: =((TotalTournamentAverages!AQ17/MassFormulaTesting!$B$94)*0.68)+0.3 -> #DIV/0! | AK25: =((TotalTournamentAverages!AR17/MassFormulaTesting!$B$96)*0.68)+0.3 -> #DIV/0! | AL25: =((TotalTournamentAverages!AS17/MassFormulaTesting!$B$98)*0.68)+0.3 -> #DIV/0! | AM25: =((TotalTournamentAverages!AT17/MassFormulaTesting!$B$100)*0.68)+0.3 -> #DIV/0! | AN25: =((TotalTournamentAverages!AV17/MassFormulaTesting!$B$104)*0.68)+0.3 -> #DIV/0! | AO25: =((TotalTournamentAverages!AW17/MassFormulaTesting!$B$106)*0.68)+0.3 -> #DIV/0! | AP25: =((TotalTournamentAverages!AX17/MassFormulaTesting!$B$108)*0.68)+0.3 -> #DIV/0!
A26: =IFERROR(__xludf.DUMMYFUNCTION("""COMPUTED_VALUE"""),"Vile") -> Vile | B26: =IFERROR(__xludf.DUMMYFUNCTION("""COMPUTED_VALUE"""),11.333333333333334) -> 11.333333 | D26: =(((F26-$C$13)/$D$12)*0.68)+0.3 -> #DIV/0! | E26: =TotalTournamentAverages!A18 -> Hells Angel cx | F26: =((IFERROR((G26*C$10)+(H26*D$10)+(I26*E$10)+(J26*F$10)+(K26*G$10)+(L26*H$10)+(M26*I$10)+(N26*J$10)+(O26*K$10)+(P26*L$10)+(Q26*M$10)+(R26*N$10)+(S26*O$10)+(T26*P$10)+(U26*Q$10)+(V26*R$10)+(W26*S$10)+(X26*T$10)+(Y26*U$10)+(Z26*V$10)+(AA26*W$10)+(AB26*X$10)+(AC26*Y$10)+(AD26*Z$10)+(AE26*AA$10)+(AF26*AB$10)+(AG26*AC$10)+(AH26*AD$10)+(AI26*AE$10)+(AJ26*AF$10)+(AK26*AG$10)+(AL26*AH$10)+(AM26*AI$10)+(AN26*AJ$10)+(AO26*AK$10)+(AP26*AL$10),"")/F$12)*0.68)+0.3 -> 0.3 | G26: =((TotalTournamentAverages!D18/MassFormulaTesting!$B$16)*0.68)+0.3 -> 0.73714286 | H26: =((TotalTournamentAverages!E18/MassFormulaTesting!$B$18)*0.68)+0.3 -> 0.71228346 | I26: =((TotalTournamentAverages!F18/MassFormulaTesting!$B$20)*0.68)+0.3 -> 0.623 | J26: =(IFERROR(MassFormulaTesting!$C$22/TotalTournamentAverages!G18,"")*0.68)+0.3 -> 0.51935484 | K26: =(((TotalTournamentAverages!H18+118)/(MassFormulaTesting!$B$24+118))*0.68)+0.3 -> 0.82479475 | L26: =((TotalTournamentAverages!I18/MassFormulaTesting!$B$26)*0.68)+0.3 -> 0.645 | M26: =((0.98-(TotalTournamentAverages!J18/MassFormulaTesting!$B$28)*0.68)) -> 0.3 | N26: =((TotalTournamentAverages!K18/MassFormulaTesting!$B$30)*0.68)+0.3 -> 0.78341093 | O26: =((TotalTournamentAverages!L18/MassFormulaTesting!$B$32)*0.68)+0.3 -> 0.7973567 | P26: =((TotalTournamentAverages!M18/MassFormulaTesting!$B$34)*0.68)+0.3 -> 0.60909091 | Q26: =((TotalTournamentAverages!N18/MassFormulaTesting!$B$36)*0.68)+0.3 -> 0.39272727 | R26: =((TotalTournamentAverages!O18/MassFormulaTesting!$B$38)*0.68)+0.3 -> 0.47 | S26: =(IFERROR(TotalTournamentAverages!P18/MassFormulaTesting!$B$40,"")*0.68)+0.3 -> 0.3 | T26: =((TotalTournamentAverages!T18/MassFormulaTesting!$B$48)*0.68)+0.3 -> 0.44166667 | U26: =((TotalTournamentAverages!U18/MassFormulaTesting!$B$50)*0.68)+0.3 -> 0.3 | V26: =((TotalTournamentAverages!V18/MassFormulaTesting!$B$52)*0.68)+0.3 -> 0.3 | W26: =(IFERROR(TotalTournamentAverages!W18/MassFormulaTesting!$B$54,"")*0.68)+0.3 -> 0.3 | X26: =(IFERROR(TotalTournamentAverages!X18/MassFormulaTesting!$B$56,"")*0.68)+0.3 -> 0.3 | Y26: =(IFERROR(TotalTournamentAverages!Y18/MassFormulaTesting!$B$58,"")*0.68)+0.3 -> 0.3 | Z26: =(IFERROR(TotalTournamentAverages!Z18/MassFormulaTesting!$B$60,"")*0.68)+0.3 -> 0.3 | AA26: =((TotalTournamentAverages!AD18/MassFormulaTesting!$B$68)*0.68)+0.3 -> 0.3 | AB26: =((TotalTournamentAverages!AG18/MassFormulaTesting!$B$74)*0.68)+0.3 -> #DIV/0! | AC26: =((TotalTournamentAverages!AH18/MassFormulaTesting!$B$76)*0.68)+0.3 -> #DIV/0! | AD26: =((TotalTournamentAverages!AK18/MassFormulaTesting!$B$82)*0.68)+0.3 -> #DIV/0! | AE26: =((TotalTournamentAverages!AL18/MassFormulaTesting!$B$84)*0.68)+0.3 -> #DIV/0! | AF26: =((TotalTournamentAverages!AM18/MassFormulaTesting!$B$86)*0.68)+0.3 -> #DIV/0! | AG26: =((TotalTournamentAverages!AN18/MassFormulaTesting!$B$88)*0.68)+0.3 -> #DIV/0! | AH26: =((TotalTournamentAverages!AO18/MassFormulaTesting!$B$90)*0.68)+0.3 -> #DIV/0! | AI26: =((TotalTournamentAverages!AP18/MassFormulaTesting!$B$92)*0.68)+0.3 -> #DIV/0! | AJ26: =((TotalTournamentAverages!AQ18/MassFormulaTesting!$B$94)*0.68)+0.3 -> #DIV/0! | AK26: =((TotalTournamentAverages!AR18/MassFormulaTesting!$B$96)*0.68)+0.3 -> #DIV/0! | AL26: =((TotalTournamentAverages!AS18/MassFormulaTesting!$B$98)*0.68)+0.3 -> #DIV/0! | AM26: =((TotalTournamentAverages!AT18/MassFormulaTesting!$B$100)*0.68)+0.3 -> #DIV/0! | AN26: =((TotalTournamentAverages!AV18/MassFormulaTesting!$B$104)*0.68)+0.3 -> #DIV/0! | AO26: =((TotalTournamentAverages!AW18/MassFormulaTesting!$B$106)*0.68)+0.3 -> #DIV/0! | AP26: =((TotalTournamentAverages!AX18/MassFormulaTesting!$B$108)*0.68)+0.3 -> #DIV/0!
